Internal Server Error: /admin/sitios/foto/
Traceback (most recent call last):
  File "/usr/local/lib/python2.7/dist-packages/django/core/handlers/base.py", line 164, in get_response
    response = response.render()
  File "/usr/local/lib/python2.7/dist-packages/django/template/response.py", line 158, in render
    self.content = self.rendered_content
  File "/usr/local/lib/python2.7/dist-packages/django/template/response.py", line 135, in rendered_content
    content = template.render(context, self._request)
  File "/usr/local/lib/python2.7/dist-packages/django/template/backends/django.py", line 74, in render
    return self.template.render(context)
  File "/usr/local/lib/python2.7/dist-packages/django/template/base.py", line 209, in render
    return self._render(context)
  File "/usr/local/lib/python2.7/dist-packages/django/template/base.py", line 201, in _render
    return self.nodelist.render(context)
  File "/usr/local/lib/python2.7/dist-packages/django/template/base.py", line 903, in render
    bit = self.render_node(node, context)
  File "/usr/local/lib/python2.7/dist-packages/django/template/debug.py", line 79, in render_node
    return node.render(context)
  File "/usr/local/lib/python2.7/dist-packages/django/template/loader_tags.py", line 135, in render
    return compiled_parent._render(context)
  File "/usr/local/lib/python2.7/dist-packages/django/template/base.py", line 201, in _render
    return self.nodelist.render(context)
  File "/usr/local/lib/python2.7/dist-packages/django/template/base.py", line 903, in render
    bit = self.render_node(node, context)
  File "/usr/local/lib/python2.7/dist-packages/django/template/debug.py", line 79, in render_node
    return node.render(context)
  File "/usr/local/lib/python2.7/dist-packages/django/template/loader_tags.py", line 135, in render
    return compiled_parent._render(context)
  File "/usr/local/lib/python2.7/dist-packages/django/template/base.py", line 201, in _render
    return self.nodelist.render(context)
  File "/usr/local/lib/python2.7/dist-packages/django/template/base.py", line 903, in render
    bit = self.render_node(node, context)
  File "/usr/local/lib/python2.7/dist-packages/django/template/debug.py", line 79, in render_node
    return node.render(context)
  File "/usr/local/lib/python2.7/dist-packages/django/template/loader_tags.py", line 65, in render
    result = block.nodelist.render(context)
  File "/usr/local/lib/python2.7/dist-packages/django/template/base.py", line 903, in render
    bit = self.render_node(node, context)
  File "/usr/local/lib/python2.7/dist-packages/django/template/debug.py", line 79, in render_node
    return node.render(context)
  File "/usr/local/lib/python2.7/dist-packages/django/template/loader_tags.py", line 65, in render
    result = block.nodelist.render(context)
  File "/usr/local/lib/python2.7/dist-packages/django/template/base.py", line 903, in render
    bit = self.render_node(node, context)
  File "/usr/local/lib/python2.7/dist-packages/django/template/debug.py", line 79, in render_node
    return node.render(context)
  File "/usr/local/lib/python2.7/dist-packages/django/template/loader_tags.py", line 65, in render
    result = block.nodelist.render(context)
  File "/usr/local/lib/python2.7/dist-packages/django/template/base.py", line 903, in render
    bit = self.render_node(node, context)
  File "/usr/local/lib/python2.7/dist-packages/django/template/debug.py", line 79, in render_node
    return node.render(context)
  File "/usr/local/lib/python2.7/dist-packages/django/template/loader_tags.py", line 65, in render
    result = block.nodelist.render(context)
  File "/usr/local/lib/python2.7/dist-packages/django/template/base.py", line 903, in render
    bit = self.render_node(node, context)
  File "/usr/local/lib/python2.7/dist-packages/django/template/debug.py", line 79, in render_node
    return node.render(context)
  File "/usr/local/lib/python2.7/dist-packages/django/template/defaulttags.py", line 329, in render
    return nodelist.render(context)
  File "/usr/local/lib/python2.7/dist-packages/django/template/base.py", line 903, in render
    bit = self.render_node(node, context)
  File "/usr/local/lib/python2.7/dist-packages/django/template/debug.py", line 79, in render_node
    return node.render(context)
  File "/usr/local/lib/python2.7/dist-packages/django/template/base.py", line 1271, in render
    _dict = func(*resolved_args, **resolved_kwargs)
  File "/usr/local/lib/python2.7/dist-packages/suit/templatetags/suit_list.py", line 189, in result_list_with_context
    res = result_list(cl)
  File "/usr/local/lib/python2.7/dist-packages/django/contrib/admin/templatetags/admin_list.py", line 320, in result_list
    'results': list(results(cl))}
  File "/usr/local/lib/python2.7/dist-packages/django/contrib/admin/templatetags/admin_list.py", line 296, in results
    yield ResultList(None, items_for_result(cl, res, None))
  File "/usr/local/lib/python2.7/dist-packages/django/contrib/admin/templatetags/admin_list.py", line 287, in __init__
    super(ResultList, self).__init__(*items)
  File "/usr/local/lib/python2.7/dist-packages/django/contrib/admin/templatetags/admin_list.py", line 199, in items_for_result
    f, attr, value = lookup_field(field_name, result, cl.model_admin)
  File "/usr/local/lib/python2.7/dist-packages/django/contrib/admin/utils.py", line 282, in lookup_field
    value = attr()
  File "/usr/local/lib/python2.7/dist-packages/django/db/models/base.py", line 503, in __str__
    return force_text(self).encode('utf-8')
  File "/usr/local/lib/python2.7/dist-packages/django/utils/encoding.py", line 92, in force_text
    s = six.text_type(s)
TypeError: coercing to Unicode: need string or buffer, Sitio found
Internal Server Error: /admin/sitios/sitio/1920/
Traceback (most recent call last):
  File "/usr/local/lib/python2.7/dist-packages/django/core/handlers/base.py", line 164, in get_response
    response = response.render()
  File "/usr/local/lib/python2.7/dist-packages/django/template/response.py", line 158, in render
    self.content = self.rendered_content
  File "/usr/local/lib/python2.7/dist-packages/django/template/response.py", line 135, in rendered_content
    content = template.render(context, self._request)
  File "/usr/local/lib/python2.7/dist-packages/django/template/backends/django.py", line 74, in render
    return self.template.render(context)
  File "/usr/local/lib/python2.7/dist-packages/django/template/base.py", line 209, in render
    return self._render(context)
  File "/usr/local/lib/python2.7/dist-packages/django/template/base.py", line 201, in _render
    return self.nodelist.render(context)
  File "/usr/local/lib/python2.7/dist-packages/django/template/base.py", line 903, in render
    bit = self.render_node(node, context)
  File "/usr/local/lib/python2.7/dist-packages/django/template/debug.py", line 79, in render_node
    return node.render(context)
  File "/usr/local/lib/python2.7/dist-packages/django/template/loader_tags.py", line 135, in render
    return compiled_parent._render(context)
  File "/usr/local/lib/python2.7/dist-packages/django/template/base.py", line 201, in _render
    return self.nodelist.render(context)
  File "/usr/local/lib/python2.7/dist-packages/django/template/base.py", line 903, in render
    bit = self.render_node(node, context)
  File "/usr/local/lib/python2.7/dist-packages/django/template/debug.py", line 79, in render_node
    return node.render(context)
  File "/usr/local/lib/python2.7/dist-packages/django/template/loader_tags.py", line 135, in render
    return compiled_parent._render(context)
  File "/usr/local/lib/python2.7/dist-packages/django/template/base.py", line 201, in _render
    return self.nodelist.render(context)
  File "/usr/local/lib/python2.7/dist-packages/django/template/base.py", line 903, in render
    bit = self.render_node(node, context)
  File "/usr/local/lib/python2.7/dist-packages/django/template/debug.py", line 79, in render_node
    return node.render(context)
  File "/usr/local/lib/python2.7/dist-packages/django/template/loader_tags.py", line 65, in render
    result = block.nodelist.render(context)
  File "/usr/local/lib/python2.7/dist-packages/django/template/base.py", line 903, in render
    bit = self.render_node(node, context)
  File "/usr/local/lib/python2.7/dist-packages/django/template/debug.py", line 79, in render_node
    return node.render(context)
  File "/usr/local/lib/python2.7/dist-packages/django/template/loader_tags.py", line 65, in render
    result = block.nodelist.render(context)
  File "/usr/local/lib/python2.7/dist-packages/django/template/base.py", line 903, in render
    bit = self.render_node(node, context)
  File "/usr/local/lib/python2.7/dist-packages/django/template/debug.py", line 79, in render_node
    return node.render(context)
  File "/usr/local/lib/python2.7/dist-packages/django/template/loader_tags.py", line 65, in render
    result = block.nodelist.render(context)
  File "/usr/local/lib/python2.7/dist-packages/django/template/base.py", line 903, in render
    bit = self.render_node(node, context)
  File "/usr/local/lib/python2.7/dist-packages/django/template/debug.py", line 79, in render_node
    return node.render(context)
  File "/usr/local/lib/python2.7/dist-packages/django/template/loader_tags.py", line 65, in render
    result = block.nodelist.render(context)
  File "/usr/local/lib/python2.7/dist-packages/django/template/base.py", line 903, in render
    bit = self.render_node(node, context)
  File "/usr/local/lib/python2.7/dist-packages/django/template/debug.py", line 79, in render_node
    return node.render(context)
  File "/usr/local/lib/python2.7/dist-packages/django/template/defaulttags.py", line 217, in render
    nodelist.append(node.render(context))
  File "/usr/local/lib/python2.7/dist-packages/django/template/loader_tags.py", line 159, in render
    return template.render(context)
  File "/usr/local/lib/python2.7/dist-packages/django/template/base.py", line 211, in render
    return self._render(context)
  File "/usr/local/lib/python2.7/dist-packages/django/template/base.py", line 201, in _render
    return self.nodelist.render(context)
  File "/usr/local/lib/python2.7/dist-packages/django/template/base.py", line 903, in render
    bit = self.render_node(node, context)
  File "/usr/local/lib/python2.7/dist-packages/django/template/debug.py", line 79, in render_node
    return node.render(context)
  File "/usr/local/lib/python2.7/dist-packages/django/template/defaulttags.py", line 217, in render
    nodelist.append(node.render(context))
  File "/usr/local/lib/python2.7/dist-packages/django/template/defaulttags.py", line 576, in render
    return self.nodelist.render(context)
  File "/usr/local/lib/python2.7/dist-packages/django/template/base.py", line 903, in render
    bit = self.render_node(node, context)
  File "/usr/local/lib/python2.7/dist-packages/django/template/debug.py", line 79, in render_node
    return node.render(context)
  File "/usr/local/lib/python2.7/dist-packages/django/template/defaulttags.py", line 217, in render
    nodelist.append(node.render(context))
  File "/usr/local/lib/python2.7/dist-packages/django/template/defaulttags.py", line 444, in render
    return strip_spaces_between_tags(self.nodelist.render(context).strip())
  File "/usr/local/lib/python2.7/dist-packages/django/template/base.py", line 903, in render
    bit = self.render_node(node, context)
  File "/usr/local/lib/python2.7/dist-packages/django/template/debug.py", line 79, in render_node
    return node.render(context)
  File "/usr/local/lib/python2.7/dist-packages/django/template/defaulttags.py", line 329, in render
    return nodelist.render(context)
  File "/usr/local/lib/python2.7/dist-packages/django/template/base.py", line 903, in render
    bit = self.render_node(node, context)
  File "/usr/local/lib/python2.7/dist-packages/django/template/debug.py", line 79, in render_node
    return node.render(context)
  File "/usr/local/lib/python2.7/dist-packages/django/template/debug.py", line 92, in render
    output = force_text(output)
  File "/usr/local/lib/python2.7/dist-packages/django/utils/encoding.py", line 92, in force_text
    s = six.text_type(s)
  File "/usr/local/lib/python2.7/dist-packages/django/utils/html.py", line 390, in <lambda>
    klass.__unicode__ = lambda self: mark_safe(klass_unicode(self))
  File "/usr/local/lib/python2.7/dist-packages/django/forms/forms.py", line 537, in __str__
    return self.as_widget()
  File "/usr/local/lib/python2.7/dist-packages/django/forms/forms.py", line 593, in as_widget
    return force_text(widget.render(name, self.value(), attrs=attrs))
  File "/usr/local/lib/python2.7/dist-packages/django/contrib/admin/widgets.py", line 292, in render
    'widget': self.widget.render(name, value, *args, **kwargs),
  File "/usr/local/lib/python2.7/dist-packages/django/forms/widgets.py", line 513, in render
    options = self.render_options(choices, [value])
  File "/usr/local/lib/python2.7/dist-packages/django/forms/widgets.py", line 539, in render_options
    for option_value, option_label in chain(self.choices, choices):
  File "/usr/local/lib/python2.7/dist-packages/django/forms/models.py", line 1104, in __iter__
    yield self.choice(obj)
  File "/usr/local/lib/python2.7/dist-packages/django/forms/models.py", line 1111, in choice
    return (self.field.prepare_value(obj), self.field.label_from_instance(obj))
  File "/usr/local/lib/python2.7/dist-packages/django/forms/models.py", line 1182, in label_from_instance
    return smart_text(obj)
  File "/usr/local/lib/python2.7/dist-packages/django/utils/encoding.py", line 56, in smart_text
    return force_text(s, encoding, strings_only, errors)
  File "/usr/local/lib/python2.7/dist-packages/django/utils/encoding.py", line 92, in force_text
    s = six.text_type(s)
TypeError: coercing to Unicode: need string or buffer, NoneType found
Internal Server Error: /categorias
Traceback (most recent call last):
  File "/usr/local/lib/python2.7/dist-packages/django/core/handlers/base.py", line 108, in get_response
    response = middleware_method(request)
  File "/usr/local/lib/python2.7/dist-packages/django/middleware/common.py", line 74, in process_request
    if (not urlresolvers.is_valid_path(request.path_info, urlconf) and
  File "/usr/local/lib/python2.7/dist-packages/django/core/urlresolvers.py", line 646, in is_valid_path
    resolve(path, urlconf)
  File "/usr/local/lib/python2.7/dist-packages/django/core/urlresolvers.py", line 521, in resolve
    return get_resolver(urlconf).resolve(path)
  File "/usr/local/lib/python2.7/dist-packages/django/core/urlresolvers.py", line 365, in resolve
    for pattern in self.url_patterns:
  File "/usr/local/lib/python2.7/dist-packages/django/core/urlresolvers.py", line 401, in url_patterns
    patterns = getattr(self.urlconf_module, "urlpatterns", self.urlconf_module)
  File "/usr/local/lib/python2.7/dist-packages/django/core/urlresolvers.py", line 395, in urlconf_module
    self._urlconf_module = import_module(self.urlconf_name)
  File "/usr/lib/python2.7/importlib/__init__.py", line 37, in import_module
    __import__(name)
  File "/home/camilo/Documentos/djangoprojects/plataforma/turismo/urls.py", line 28, in <module>
    url(r'^rest-auth/registration/', include('rest_auth.registration.urls')),
  File "/usr/local/lib/python2.7/dist-packages/django/conf/urls/__init__.py", line 33, in include
    urlconf_module = import_module(urlconf_module)
  File "/usr/lib/python2.7/importlib/__init__.py", line 37, in import_module
    __import__(name)
  File "/home/camilo/Documentos/djangoprojects/plataforma/rest_auth/registration/urls.py", line 4, in <module>
    from .views import RegisterView, VerifyEmailView
  File "/home/camilo/Documentos/djangoprojects/plataforma/rest_auth/registration/views.py", line 18, in <module>
    from rest_auth.registration.serializers import (SocialLoginSerializer,
  File "/home/camilo/Documentos/djangoprojects/plataforma/rest_auth/registration/serializers.py", line 157
SyntaxError: Non-ASCII character '\xc3' in file /home/camilo/Documentos/djangoprojects/plataforma/rest_auth/registration/serializers.py on line 157, but no encoding declared; see http://www.python.org/peps/pep-0263.html for details
Internal Server Error: /municipios
Traceback (most recent call last):
  File "/usr/local/lib/python2.7/dist-packages/django/core/handlers/base.py", line 108, in get_response
    response = middleware_method(request)
  File "/usr/local/lib/python2.7/dist-packages/django/middleware/common.py", line 74, in process_request
    if (not urlresolvers.is_valid_path(request.path_info, urlconf) and
  File "/usr/local/lib/python2.7/dist-packages/django/core/urlresolvers.py", line 646, in is_valid_path
    resolve(path, urlconf)
  File "/usr/local/lib/python2.7/dist-packages/django/core/urlresolvers.py", line 521, in resolve
    return get_resolver(urlconf).resolve(path)
  File "/usr/local/lib/python2.7/dist-packages/django/core/urlresolvers.py", line 365, in resolve
    for pattern in self.url_patterns:
  File "/usr/local/lib/python2.7/dist-packages/django/core/urlresolvers.py", line 401, in url_patterns
    patterns = getattr(self.urlconf_module, "urlpatterns", self.urlconf_module)
  File "/usr/local/lib/python2.7/dist-packages/django/core/urlresolvers.py", line 395, in urlconf_module
    self._urlconf_module = import_module(self.urlconf_name)
  File "/usr/lib/python2.7/importlib/__init__.py", line 37, in import_module
    __import__(name)
  File "/home/camilo/Documentos/djangoprojects/plataforma/turismo/urls.py", line 28, in <module>
    url(r'^rest-auth/registration/', include('rest_auth.registration.urls')),
  File "/usr/local/lib/python2.7/dist-packages/django/conf/urls/__init__.py", line 33, in include
    urlconf_module = import_module(urlconf_module)
  File "/usr/lib/python2.7/importlib/__init__.py", line 37, in import_module
    __import__(name)
  File "/home/camilo/Documentos/djangoprojects/plataforma/rest_auth/registration/urls.py", line 4, in <module>
    from .views import RegisterView, VerifyEmailView
  File "/home/camilo/Documentos/djangoprojects/plataforma/rest_auth/registration/views.py", line 18, in <module>
    from rest_auth.registration.serializers import (SocialLoginSerializer,
  File "/home/camilo/Documentos/djangoprojects/plataforma/rest_auth/registration/serializers.py", line 157
SyntaxError: Non-ASCII character '\xc3' in file /home/camilo/Documentos/djangoprojects/plataforma/rest_auth/registration/serializers.py on line 157, but no encoding declared; see http://www.python.org/peps/pep-0263.html for details
Internal Server Error: /municipios
Traceback (most recent call last):
  File "/usr/local/lib/python2.7/dist-packages/django/core/handlers/base.py", line 108, in get_response
    response = middleware_method(request)
  File "/usr/local/lib/python2.7/dist-packages/django/middleware/common.py", line 74, in process_request
    if (not urlresolvers.is_valid_path(request.path_info, urlconf) and
  File "/usr/local/lib/python2.7/dist-packages/django/core/urlresolvers.py", line 646, in is_valid_path
    resolve(path, urlconf)
  File "/usr/local/lib/python2.7/dist-packages/django/core/urlresolvers.py", line 521, in resolve
    return get_resolver(urlconf).resolve(path)
  File "/usr/local/lib/python2.7/dist-packages/django/core/urlresolvers.py", line 365, in resolve
    for pattern in self.url_patterns:
  File "/usr/local/lib/python2.7/dist-packages/django/core/urlresolvers.py", line 401, in url_patterns
    patterns = getattr(self.urlconf_module, "urlpatterns", self.urlconf_module)
  File "/usr/local/lib/python2.7/dist-packages/django/core/urlresolvers.py", line 395, in urlconf_module
    self._urlconf_module = import_module(self.urlconf_name)
  File "/usr/lib/python2.7/importlib/__init__.py", line 37, in import_module
    __import__(name)
  File "/home/camilo/Documentos/djangoprojects/plataforma/turismo/urls.py", line 28, in <module>
    url(r'^rest-auth/registration/', include('rest_auth.registration.urls')),
  File "/usr/local/lib/python2.7/dist-packages/django/conf/urls/__init__.py", line 33, in include
    urlconf_module = import_module(urlconf_module)
  File "/usr/lib/python2.7/importlib/__init__.py", line 37, in import_module
    __import__(name)
  File "/home/camilo/Documentos/djangoprojects/plataforma/rest_auth/registration/urls.py", line 4, in <module>
    from .views import RegisterView, VerifyEmailView
  File "/home/camilo/Documentos/djangoprojects/plataforma/rest_auth/registration/views.py", line 18, in <module>
    from rest_auth.registration.serializers import (SocialLoginSerializer,
  File "/home/camilo/Documentos/djangoprojects/plataforma/rest_auth/registration/serializers.py", line 157
SyntaxError: Non-ASCII character '\xc3' in file /home/camilo/Documentos/djangoprojects/plataforma/rest_auth/registration/serializers.py on line 157, but no encoding declared; see http://www.python.org/peps/pep-0263.html for details
Internal Server Error: /municipios
Traceback (most recent call last):
  File "/usr/local/lib/python2.7/dist-packages/django/core/handlers/base.py", line 108, in get_response
    response = middleware_method(request)
  File "/usr/local/lib/python2.7/dist-packages/django/middleware/common.py", line 74, in process_request
    if (not urlresolvers.is_valid_path(request.path_info, urlconf) and
  File "/usr/local/lib/python2.7/dist-packages/django/core/urlresolvers.py", line 646, in is_valid_path
    resolve(path, urlconf)
  File "/usr/local/lib/python2.7/dist-packages/django/core/urlresolvers.py", line 521, in resolve
    return get_resolver(urlconf).resolve(path)
  File "/usr/local/lib/python2.7/dist-packages/django/core/urlresolvers.py", line 365, in resolve
    for pattern in self.url_patterns:
  File "/usr/local/lib/python2.7/dist-packages/django/core/urlresolvers.py", line 401, in url_patterns
    patterns = getattr(self.urlconf_module, "urlpatterns", self.urlconf_module)
  File "/usr/local/lib/python2.7/dist-packages/django/core/urlresolvers.py", line 395, in urlconf_module
    self._urlconf_module = import_module(self.urlconf_name)
  File "/usr/lib/python2.7/importlib/__init__.py", line 37, in import_module
    __import__(name)
  File "/home/camilo/Documentos/djangoprojects/plataforma/turismo/urls.py", line 28, in <module>
    url(r'^rest-auth/registration/', include('rest_auth.registration.urls')),
  File "/usr/local/lib/python2.7/dist-packages/django/conf/urls/__init__.py", line 33, in include
    urlconf_module = import_module(urlconf_module)
  File "/usr/lib/python2.7/importlib/__init__.py", line 37, in import_module
    __import__(name)
  File "/home/camilo/Documentos/djangoprojects/plataforma/rest_auth/registration/urls.py", line 4, in <module>
    from .views import RegisterView, VerifyEmailView
  File "/home/camilo/Documentos/djangoprojects/plataforma/rest_auth/registration/views.py", line 18, in <module>
    from rest_auth.registration.serializers import (SocialLoginSerializer,
  File "/home/camilo/Documentos/djangoprojects/plataforma/rest_auth/registration/serializers.py", line 157
SyntaxError: Non-ASCII character '\xc3' in file /home/camilo/Documentos/djangoprojects/plataforma/rest_auth/registration/serializers.py on line 157, but no encoding declared; see http://www.python.org/peps/pep-0263.html for details
Internal Server Error: /categorias
Traceback (most recent call last):
  File "/usr/local/lib/python2.7/dist-packages/django/core/handlers/base.py", line 108, in get_response
    response = middleware_method(request)
  File "/usr/local/lib/python2.7/dist-packages/django/middleware/common.py", line 74, in process_request
    if (not urlresolvers.is_valid_path(request.path_info, urlconf) and
  File "/usr/local/lib/python2.7/dist-packages/django/core/urlresolvers.py", line 646, in is_valid_path
    resolve(path, urlconf)
  File "/usr/local/lib/python2.7/dist-packages/django/core/urlresolvers.py", line 521, in resolve
    return get_resolver(urlconf).resolve(path)
  File "/usr/local/lib/python2.7/dist-packages/django/core/urlresolvers.py", line 365, in resolve
    for pattern in self.url_patterns:
  File "/usr/local/lib/python2.7/dist-packages/django/core/urlresolvers.py", line 401, in url_patterns
    patterns = getattr(self.urlconf_module, "urlpatterns", self.urlconf_module)
  File "/usr/local/lib/python2.7/dist-packages/django/core/urlresolvers.py", line 395, in urlconf_module
    self._urlconf_module = import_module(self.urlconf_name)
  File "/usr/lib/python2.7/importlib/__init__.py", line 37, in import_module
    __import__(name)
  File "/home/camilo/Documentos/djangoprojects/plataforma/turismo/urls.py", line 28, in <module>
    url(r'^rest-auth/registration/', include('rest_auth.registration.urls')),
  File "/usr/local/lib/python2.7/dist-packages/django/conf/urls/__init__.py", line 33, in include
    urlconf_module = import_module(urlconf_module)
  File "/usr/lib/python2.7/importlib/__init__.py", line 37, in import_module
    __import__(name)
  File "/home/camilo/Documentos/djangoprojects/plataforma/rest_auth/registration/urls.py", line 4, in <module>
    from .views import RegisterView, VerifyEmailView
  File "/home/camilo/Documentos/djangoprojects/plataforma/rest_auth/registration/views.py", line 18, in <module>
    from rest_auth.registration.serializers import (SocialLoginSerializer,
  File "/home/camilo/Documentos/djangoprojects/plataforma/rest_auth/registration/serializers.py", line 157
SyntaxError: Non-ASCII character '\xc3' in file /home/camilo/Documentos/djangoprojects/plataforma/rest_auth/registration/serializers.py on line 157, but no encoding declared; see http://www.python.org/peps/pep-0263.html for details
Internal Server Error: /municipios
Traceback (most recent call last):
  File "/usr/local/lib/python2.7/dist-packages/django/core/handlers/base.py", line 108, in get_response
    response = middleware_method(request)
  File "/usr/local/lib/python2.7/dist-packages/django/middleware/common.py", line 74, in process_request
    if (not urlresolvers.is_valid_path(request.path_info, urlconf) and
  File "/usr/local/lib/python2.7/dist-packages/django/core/urlresolvers.py", line 646, in is_valid_path
    resolve(path, urlconf)
  File "/usr/local/lib/python2.7/dist-packages/django/core/urlresolvers.py", line 521, in resolve
    return get_resolver(urlconf).resolve(path)
  File "/usr/local/lib/python2.7/dist-packages/django/core/urlresolvers.py", line 365, in resolve
    for pattern in self.url_patterns:
  File "/usr/local/lib/python2.7/dist-packages/django/core/urlresolvers.py", line 401, in url_patterns
    patterns = getattr(self.urlconf_module, "urlpatterns", self.urlconf_module)
  File "/usr/local/lib/python2.7/dist-packages/django/core/urlresolvers.py", line 395, in urlconf_module
    self._urlconf_module = import_module(self.urlconf_name)
  File "/usr/lib/python2.7/importlib/__init__.py", line 37, in import_module
    __import__(name)
  File "/home/camilo/Documentos/djangoprojects/plataforma/turismo/urls.py", line 28, in <module>
    url(r'^rest-auth/registration/', include('rest_auth.registration.urls')),
  File "/usr/local/lib/python2.7/dist-packages/django/conf/urls/__init__.py", line 33, in include
    urlconf_module = import_module(urlconf_module)
  File "/usr/lib/python2.7/importlib/__init__.py", line 37, in import_module
    __import__(name)
  File "/home/camilo/Documentos/djangoprojects/plataforma/rest_auth/registration/urls.py", line 4, in <module>
    from .views import RegisterView, VerifyEmailView
  File "/home/camilo/Documentos/djangoprojects/plataforma/rest_auth/registration/views.py", line 18, in <module>
    from rest_auth.registration.serializers import (SocialLoginSerializer,
  File "/home/camilo/Documentos/djangoprojects/plataforma/rest_auth/registration/serializers.py", line 157
SyntaxError: Non-ASCII character '\xc3' in file /home/camilo/Documentos/djangoprojects/plataforma/rest_auth/registration/serializers.py on line 157, but no encoding declared; see http://www.python.org/peps/pep-0263.html for details
Internal Server Error: /municipios
Traceback (most recent call last):
  File "/usr/local/lib/python2.7/dist-packages/django/core/handlers/base.py", line 108, in get_response
    response = middleware_method(request)
  File "/usr/local/lib/python2.7/dist-packages/django/middleware/common.py", line 74, in process_request
    if (not urlresolvers.is_valid_path(request.path_info, urlconf) and
  File "/usr/local/lib/python2.7/dist-packages/django/core/urlresolvers.py", line 646, in is_valid_path
    resolve(path, urlconf)
  File "/usr/local/lib/python2.7/dist-packages/django/core/urlresolvers.py", line 521, in resolve
    return get_resolver(urlconf).resolve(path)
  File "/usr/local/lib/python2.7/dist-packages/django/core/urlresolvers.py", line 365, in resolve
    for pattern in self.url_patterns:
  File "/usr/local/lib/python2.7/dist-packages/django/core/urlresolvers.py", line 401, in url_patterns
    patterns = getattr(self.urlconf_module, "urlpatterns", self.urlconf_module)
  File "/usr/local/lib/python2.7/dist-packages/django/core/urlresolvers.py", line 395, in urlconf_module
    self._urlconf_module = import_module(self.urlconf_name)
  File "/usr/lib/python2.7/importlib/__init__.py", line 37, in import_module
    __import__(name)
  File "/home/camilo/Documentos/djangoprojects/plataforma/turismo/urls.py", line 28, in <module>
    url(r'^rest-auth/registration/', include('rest_auth.registration.urls')),
  File "/usr/local/lib/python2.7/dist-packages/django/conf/urls/__init__.py", line 33, in include
    urlconf_module = import_module(urlconf_module)
  File "/usr/lib/python2.7/importlib/__init__.py", line 37, in import_module
    __import__(name)
  File "/home/camilo/Documentos/djangoprojects/plataforma/rest_auth/registration/urls.py", line 4, in <module>
    from .views import RegisterView, VerifyEmailView
  File "/home/camilo/Documentos/djangoprojects/plataforma/rest_auth/registration/views.py", line 18, in <module>
    from rest_auth.registration.serializers import (SocialLoginSerializer,
  File "/home/camilo/Documentos/djangoprojects/plataforma/rest_auth/registration/serializers.py", line 157
SyntaxError: Non-ASCII character '\xc3' in file /home/camilo/Documentos/djangoprojects/plataforma/rest_auth/registration/serializers.py on line 157, but no encoding declared; see http://www.python.org/peps/pep-0263.html for details
Internal Server Error: /municipios
Traceback (most recent call last):
  File "/usr/local/lib/python2.7/dist-packages/django/core/handlers/base.py", line 108, in get_response
    response = middleware_method(request)
  File "/usr/local/lib/python2.7/dist-packages/django/middleware/common.py", line 74, in process_request
    if (not urlresolvers.is_valid_path(request.path_info, urlconf) and
  File "/usr/local/lib/python2.7/dist-packages/django/core/urlresolvers.py", line 646, in is_valid_path
    resolve(path, urlconf)
  File "/usr/local/lib/python2.7/dist-packages/django/core/urlresolvers.py", line 521, in resolve
    return get_resolver(urlconf).resolve(path)
  File "/usr/local/lib/python2.7/dist-packages/django/core/urlresolvers.py", line 365, in resolve
    for pattern in self.url_patterns:
  File "/usr/local/lib/python2.7/dist-packages/django/core/urlresolvers.py", line 401, in url_patterns
    patterns = getattr(self.urlconf_module, "urlpatterns", self.urlconf_module)
  File "/usr/local/lib/python2.7/dist-packages/django/core/urlresolvers.py", line 395, in urlconf_module
    self._urlconf_module = import_module(self.urlconf_name)
  File "/usr/lib/python2.7/importlib/__init__.py", line 37, in import_module
    __import__(name)
  File "/home/camilo/Documentos/djangoprojects/plataforma/turismo/urls.py", line 28, in <module>
    url(r'^rest-auth/registration/', include('rest_auth.registration.urls')),
  File "/usr/local/lib/python2.7/dist-packages/django/conf/urls/__init__.py", line 33, in include
    urlconf_module = import_module(urlconf_module)
  File "/usr/lib/python2.7/importlib/__init__.py", line 37, in import_module
    __import__(name)
  File "/home/camilo/Documentos/djangoprojects/plataforma/rest_auth/registration/urls.py", line 4, in <module>
    from .views import RegisterView, VerifyEmailView
  File "/home/camilo/Documentos/djangoprojects/plataforma/rest_auth/registration/views.py", line 18, in <module>
    from rest_auth.registration.serializers import (SocialLoginSerializer,
  File "/home/camilo/Documentos/djangoprojects/plataforma/rest_auth/registration/serializers.py", line 157
SyntaxError: Non-ASCII character '\xc3' in file /home/camilo/Documentos/djangoprojects/plataforma/rest_auth/registration/serializers.py on line 157, but no encoding declared; see http://www.python.org/peps/pep-0263.html for details
Internal Server Error: /categorias
Traceback (most recent call last):
  File "/usr/local/lib/python2.7/dist-packages/django/core/handlers/base.py", line 108, in get_response
    response = middleware_method(request)
  File "/usr/local/lib/python2.7/dist-packages/django/middleware/common.py", line 74, in process_request
    if (not urlresolvers.is_valid_path(request.path_info, urlconf) and
  File "/usr/local/lib/python2.7/dist-packages/django/core/urlresolvers.py", line 646, in is_valid_path
    resolve(path, urlconf)
  File "/usr/local/lib/python2.7/dist-packages/django/core/urlresolvers.py", line 521, in resolve
    return get_resolver(urlconf).resolve(path)
  File "/usr/local/lib/python2.7/dist-packages/django/core/urlresolvers.py", line 365, in resolve
    for pattern in self.url_patterns:
  File "/usr/local/lib/python2.7/dist-packages/django/core/urlresolvers.py", line 401, in url_patterns
    patterns = getattr(self.urlconf_module, "urlpatterns", self.urlconf_module)
  File "/usr/local/lib/python2.7/dist-packages/django/core/urlresolvers.py", line 395, in urlconf_module
    self._urlconf_module = import_module(self.urlconf_name)
  File "/usr/lib/python2.7/importlib/__init__.py", line 37, in import_module
    __import__(name)
  File "/home/camilo/Documentos/djangoprojects/plataforma/turismo/urls.py", line 28, in <module>
    url(r'^rest-auth/registration/', include('rest_auth.registration.urls')),
  File "/usr/local/lib/python2.7/dist-packages/django/conf/urls/__init__.py", line 33, in include
    urlconf_module = import_module(urlconf_module)
  File "/usr/lib/python2.7/importlib/__init__.py", line 37, in import_module
    __import__(name)
  File "/home/camilo/Documentos/djangoprojects/plataforma/rest_auth/registration/urls.py", line 4, in <module>
    from .views import RegisterView, VerifyEmailView
  File "/home/camilo/Documentos/djangoprojects/plataforma/rest_auth/registration/views.py", line 18, in <module>
    from rest_auth.registration.serializers import (SocialLoginSerializer,
  File "/home/camilo/Documentos/djangoprojects/plataforma/rest_auth/registration/serializers.py", line 157
SyntaxError: Non-ASCII character '\xc3' in file /home/camilo/Documentos/djangoprojects/plataforma/rest_auth/registration/serializers.py on line 157, but no encoding declared; see http://www.python.org/peps/pep-0263.html for details
Internal Server Error: /municipios
Traceback (most recent call last):
  File "/usr/local/lib/python2.7/dist-packages/django/core/handlers/base.py", line 108, in get_response
    response = middleware_method(request)
  File "/usr/local/lib/python2.7/dist-packages/django/middleware/common.py", line 74, in process_request
    if (not urlresolvers.is_valid_path(request.path_info, urlconf) and
  File "/usr/local/lib/python2.7/dist-packages/django/core/urlresolvers.py", line 646, in is_valid_path
    resolve(path, urlconf)
  File "/usr/local/lib/python2.7/dist-packages/django/core/urlresolvers.py", line 521, in resolve
    return get_resolver(urlconf).resolve(path)
  File "/usr/local/lib/python2.7/dist-packages/django/core/urlresolvers.py", line 365, in resolve
    for pattern in self.url_patterns:
  File "/usr/local/lib/python2.7/dist-packages/django/core/urlresolvers.py", line 401, in url_patterns
    patterns = getattr(self.urlconf_module, "urlpatterns", self.urlconf_module)
  File "/usr/local/lib/python2.7/dist-packages/django/core/urlresolvers.py", line 395, in urlconf_module
    self._urlconf_module = import_module(self.urlconf_name)
  File "/usr/lib/python2.7/importlib/__init__.py", line 37, in import_module
    __import__(name)
  File "/home/camilo/Documentos/djangoprojects/plataforma/turismo/urls.py", line 28, in <module>
    url(r'^rest-auth/registration/', include('rest_auth.registration.urls')),
  File "/usr/local/lib/python2.7/dist-packages/django/conf/urls/__init__.py", line 33, in include
    urlconf_module = import_module(urlconf_module)
  File "/usr/lib/python2.7/importlib/__init__.py", line 37, in import_module
    __import__(name)
  File "/home/camilo/Documentos/djangoprojects/plataforma/rest_auth/registration/urls.py", line 4, in <module>
    from .views import RegisterView, VerifyEmailView
  File "/home/camilo/Documentos/djangoprojects/plataforma/rest_auth/registration/views.py", line 18, in <module>
    from rest_auth.registration.serializers import (SocialLoginSerializer,
  File "/home/camilo/Documentos/djangoprojects/plataforma/rest_auth/registration/serializers.py", line 157
SyntaxError: Non-ASCII character '\xc3' in file /home/camilo/Documentos/djangoprojects/plataforma/rest_auth/registration/serializers.py on line 157, but no encoding declared; see http://www.python.org/peps/pep-0263.html for details
Internal Server Error: /municipios
Traceback (most recent call last):
  File "/usr/local/lib/python2.7/dist-packages/django/core/handlers/base.py", line 108, in get_response
    response = middleware_method(request)
  File "/usr/local/lib/python2.7/dist-packages/django/middleware/common.py", line 74, in process_request
    if (not urlresolvers.is_valid_path(request.path_info, urlconf) and
  File "/usr/local/lib/python2.7/dist-packages/django/core/urlresolvers.py", line 646, in is_valid_path
    resolve(path, urlconf)
  File "/usr/local/lib/python2.7/dist-packages/django/core/urlresolvers.py", line 521, in resolve
    return get_resolver(urlconf).resolve(path)
  File "/usr/local/lib/python2.7/dist-packages/django/core/urlresolvers.py", line 365, in resolve
    for pattern in self.url_patterns:
  File "/usr/local/lib/python2.7/dist-packages/django/core/urlresolvers.py", line 401, in url_patterns
    patterns = getattr(self.urlconf_module, "urlpatterns", self.urlconf_module)
  File "/usr/local/lib/python2.7/dist-packages/django/core/urlresolvers.py", line 395, in urlconf_module
    self._urlconf_module = import_module(self.urlconf_name)
  File "/usr/lib/python2.7/importlib/__init__.py", line 37, in import_module
    __import__(name)
  File "/home/camilo/Documentos/djangoprojects/plataforma/turismo/urls.py", line 28, in <module>
    url(r'^rest-auth/registration/', include('rest_auth.registration.urls')),
  File "/usr/local/lib/python2.7/dist-packages/django/conf/urls/__init__.py", line 33, in include
    urlconf_module = import_module(urlconf_module)
  File "/usr/lib/python2.7/importlib/__init__.py", line 37, in import_module
    __import__(name)
  File "/home/camilo/Documentos/djangoprojects/plataforma/rest_auth/registration/urls.py", line 4, in <module>
    from .views import RegisterView, VerifyEmailView
  File "/home/camilo/Documentos/djangoprojects/plataforma/rest_auth/registration/views.py", line 18, in <module>
    from rest_auth.registration.serializers import (SocialLoginSerializer,
  File "/home/camilo/Documentos/djangoprojects/plataforma/rest_auth/registration/serializers.py", line 157
SyntaxError: Non-ASCII character '\xc3' in file /home/camilo/Documentos/djangoprojects/plataforma/rest_auth/registration/serializers.py on line 157, but no encoding declared; see http://www.python.org/peps/pep-0263.html for details
Internal Server Error: /municipios
Traceback (most recent call last):
  File "/usr/local/lib/python2.7/dist-packages/django/core/handlers/base.py", line 108, in get_response
    response = middleware_method(request)
  File "/usr/local/lib/python2.7/dist-packages/django/middleware/common.py", line 74, in process_request
    if (not urlresolvers.is_valid_path(request.path_info, urlconf) and
  File "/usr/local/lib/python2.7/dist-packages/django/core/urlresolvers.py", line 646, in is_valid_path
    resolve(path, urlconf)
  File "/usr/local/lib/python2.7/dist-packages/django/core/urlresolvers.py", line 521, in resolve
    return get_resolver(urlconf).resolve(path)
  File "/usr/local/lib/python2.7/dist-packages/django/core/urlresolvers.py", line 365, in resolve
    for pattern in self.url_patterns:
  File "/usr/local/lib/python2.7/dist-packages/django/core/urlresolvers.py", line 401, in url_patterns
    patterns = getattr(self.urlconf_module, "urlpatterns", self.urlconf_module)
  File "/usr/local/lib/python2.7/dist-packages/django/core/urlresolvers.py", line 395, in urlconf_module
    self._urlconf_module = import_module(self.urlconf_name)
  File "/usr/lib/python2.7/importlib/__init__.py", line 37, in import_module
    __import__(name)
  File "/home/camilo/Documentos/djangoprojects/plataforma/turismo/urls.py", line 28, in <module>
    url(r'^rest-auth/registration/', include('rest_auth.registration.urls')),
  File "/usr/local/lib/python2.7/dist-packages/django/conf/urls/__init__.py", line 33, in include
    urlconf_module = import_module(urlconf_module)
  File "/usr/lib/python2.7/importlib/__init__.py", line 37, in import_module
    __import__(name)
  File "/home/camilo/Documentos/djangoprojects/plataforma/rest_auth/registration/urls.py", line 4, in <module>
    from .views import RegisterView, VerifyEmailView
  File "/home/camilo/Documentos/djangoprojects/plataforma/rest_auth/registration/views.py", line 18, in <module>
    from rest_auth.registration.serializers import (SocialLoginSerializer,
  File "/home/camilo/Documentos/djangoprojects/plataforma/rest_auth/registration/serializers.py", line 157
SyntaxError: Non-ASCII character '\xc3' in file /home/camilo/Documentos/djangoprojects/plataforma/rest_auth/registration/serializers.py on line 157, but no encoding declared; see http://www.python.org/peps/pep-0263.html for details
