Internal Server Error: /sitio/detail/1
Traceback (most recent call last):
  File "/usr/local/lib/python2.7/dist-packages/django/core/handlers/base.py", line 132, in get_response
    response = wrapped_callback(request, *callback_args, **callback_kwargs)
  File "/usr/local/lib/python2.7/dist-packages/django/views/decorators/csrf.py", line 58, in wrapped_view
    return view_func(*args, **kwargs)
  File "/usr/local/lib/python2.7/dist-packages/django/views/generic/base.py", line 71, in view
    return self.dispatch(request, *args, **kwargs)
  File "/usr/local/lib/python2.7/dist-packages/rest_framework/views.py", line 407, in dispatch
    response = self.handle_exception(exc)
  File "/usr/local/lib/python2.7/dist-packages/rest_framework/views.py", line 404, in dispatch
    response = handler(request, *args, **kwargs)
  File "/usr/local/lib/python2.7/dist-packages/rest_framework/generics.py", line 357, in put
    return self.update(request, *args, **kwargs)
  File "/home/camilo/Documents/BackEnd/sitios/views.py", line 74, in update
    if serializer.is_valid():
NameError: global name 'serializer' is not defined
Internal Server Error: /sitio/detail/1
Traceback (most recent call last):
  File "/usr/local/lib/python2.7/dist-packages/django/core/handlers/base.py", line 132, in get_response
    response = wrapped_callback(request, *callback_args, **callback_kwargs)
  File "/usr/local/lib/python2.7/dist-packages/django/views/decorators/csrf.py", line 58, in wrapped_view
    return view_func(*args, **kwargs)
  File "/usr/local/lib/python2.7/dist-packages/django/views/generic/base.py", line 71, in view
    return self.dispatch(request, *args, **kwargs)
  File "/usr/local/lib/python2.7/dist-packages/rest_framework/views.py", line 407, in dispatch
    response = self.handle_exception(exc)
  File "/usr/local/lib/python2.7/dist-packages/rest_framework/views.py", line 404, in dispatch
    response = handler(request, *args, **kwargs)
  File "/usr/local/lib/python2.7/dist-packages/rest_framework/generics.py", line 357, in put
    return self.update(request, *args, **kwargs)
  File "/home/camilo/Documents/BackEnd/sitios/views.py", line 74, in update
    if serializer.is_valid():
NameError: global name 'serializer' is not defined
Internal Server Error: /sitio/detail/1
Traceback (most recent call last):
  File "/usr/local/lib/python2.7/dist-packages/django/core/handlers/base.py", line 132, in get_response
    response = wrapped_callback(request, *callback_args, **callback_kwargs)
  File "/usr/local/lib/python2.7/dist-packages/django/views/decorators/csrf.py", line 58, in wrapped_view
    return view_func(*args, **kwargs)
  File "/usr/local/lib/python2.7/dist-packages/django/views/generic/base.py", line 71, in view
    return self.dispatch(request, *args, **kwargs)
  File "/usr/local/lib/python2.7/dist-packages/rest_framework/views.py", line 407, in dispatch
    response = self.handle_exception(exc)
  File "/usr/local/lib/python2.7/dist-packages/rest_framework/views.py", line 404, in dispatch
    response = handler(request, *args, **kwargs)
  File "/usr/local/lib/python2.7/dist-packages/rest_framework/generics.py", line 357, in put
    return self.update(request, *args, **kwargs)
  File "/home/camilo/Documents/BackEnd/sitios/views.py", line 74, in update
    if serializer.is_valid():
NameError: global name 'serializer' is not defined
Internal Server Error: /sitio/detail/1
Traceback (most recent call last):
  File "/usr/local/lib/python2.7/dist-packages/django/core/handlers/base.py", line 132, in get_response
    response = wrapped_callback(request, *callback_args, **callback_kwargs)
  File "/usr/local/lib/python2.7/dist-packages/django/views/decorators/csrf.py", line 58, in wrapped_view
    return view_func(*args, **kwargs)
  File "/usr/local/lib/python2.7/dist-packages/django/views/generic/base.py", line 71, in view
    return self.dispatch(request, *args, **kwargs)
  File "/usr/local/lib/python2.7/dist-packages/rest_framework/views.py", line 407, in dispatch
    response = self.handle_exception(exc)
  File "/usr/local/lib/python2.7/dist-packages/rest_framework/views.py", line 404, in dispatch
    response = handler(request, *args, **kwargs)
  File "/usr/local/lib/python2.7/dist-packages/rest_framework/generics.py", line 357, in put
    return self.update(request, *args, **kwargs)
  File "/home/camilo/Documents/BackEnd/sitios/views.py", line 75, in update
    if serializer.is_valid():
  File "/usr/local/lib/python2.7/dist-packages/rest_framework/serializers.py", line 180, in is_valid
    'Cannot call `.is_valid()` as no `data=` keyword argument was '
AssertionError: Cannot call `.is_valid()` as no `data=` keyword argument was passed when instantiating the serializer instance.
Internal Server Error: /sitio/detail/1
Traceback (most recent call last):
  File "/usr/local/lib/python2.7/dist-packages/django/core/handlers/base.py", line 132, in get_response
    response = wrapped_callback(request, *callback_args, **callback_kwargs)
  File "/usr/local/lib/python2.7/dist-packages/django/views/decorators/csrf.py", line 58, in wrapped_view
    return view_func(*args, **kwargs)
  File "/usr/local/lib/python2.7/dist-packages/django/views/generic/base.py", line 71, in view
    return self.dispatch(request, *args, **kwargs)
  File "/usr/local/lib/python2.7/dist-packages/rest_framework/views.py", line 407, in dispatch
    response = self.handle_exception(exc)
  File "/usr/local/lib/python2.7/dist-packages/rest_framework/views.py", line 404, in dispatch
    response = handler(request, *args, **kwargs)
  File "/usr/local/lib/python2.7/dist-packages/rest_framework/generics.py", line 357, in put
    return self.update(request, *args, **kwargs)
  File "/home/camilo/Documents/BackEnd/sitios/views.py", line 75, in update
    if serializer.is_valid():
  File "/usr/local/lib/python2.7/dist-packages/rest_framework/serializers.py", line 180, in is_valid
    'Cannot call `.is_valid()` as no `data=` keyword argument was '
AssertionError: Cannot call `.is_valid()` as no `data=` keyword argument was passed when instantiating the serializer instance.
Internal Server Error: /sitio/detail/1
Traceback (most recent call last):
  File "/usr/local/lib/python2.7/dist-packages/django/core/handlers/base.py", line 132, in get_response
    response = wrapped_callback(request, *callback_args, **callback_kwargs)
  File "/usr/local/lib/python2.7/dist-packages/django/views/decorators/csrf.py", line 58, in wrapped_view
    return view_func(*args, **kwargs)
  File "/usr/local/lib/python2.7/dist-packages/django/views/generic/base.py", line 71, in view
    return self.dispatch(request, *args, **kwargs)
  File "/usr/local/lib/python2.7/dist-packages/rest_framework/views.py", line 407, in dispatch
    response = self.handle_exception(exc)
  File "/usr/local/lib/python2.7/dist-packages/rest_framework/views.py", line 404, in dispatch
    response = handler(request, *args, **kwargs)
  File "/usr/local/lib/python2.7/dist-packages/rest_framework/generics.py", line 357, in put
    return self.update(request, *args, **kwargs)
  File "/home/camilo/Documents/BackEnd/sitios/views.py", line 75, in update
    if serializer.is_valid():
  File "/usr/local/lib/python2.7/dist-packages/rest_framework/serializers.py", line 180, in is_valid
    'Cannot call `.is_valid()` as no `data=` keyword argument was '
AssertionError: Cannot call `.is_valid()` as no `data=` keyword argument was passed when instantiating the serializer instance.
Internal Server Error: /sitio/detail/1
Traceback (most recent call last):
  File "/usr/local/lib/python2.7/dist-packages/django/core/handlers/base.py", line 132, in get_response
    response = wrapped_callback(request, *callback_args, **callback_kwargs)
  File "/usr/local/lib/python2.7/dist-packages/django/views/decorators/csrf.py", line 58, in wrapped_view
    return view_func(*args, **kwargs)
  File "/usr/local/lib/python2.7/dist-packages/django/views/generic/base.py", line 71, in view
    return self.dispatch(request, *args, **kwargs)
  File "/usr/local/lib/python2.7/dist-packages/rest_framework/views.py", line 407, in dispatch
    response = self.handle_exception(exc)
  File "/usr/local/lib/python2.7/dist-packages/rest_framework/views.py", line 404, in dispatch
    response = handler(request, *args, **kwargs)
  File "/usr/local/lib/python2.7/dist-packages/rest_framework/generics.py", line 357, in put
    return self.update(request, *args, **kwargs)
  File "/home/camilo/Documents/BackEnd/sitios/views.py", line 75, in update
    if serializer.is_valid():
  File "/usr/local/lib/python2.7/dist-packages/rest_framework/serializers.py", line 180, in is_valid
    'Cannot call `.is_valid()` as no `data=` keyword argument was '
AssertionError: Cannot call `.is_valid()` as no `data=` keyword argument was passed when instantiating the serializer instance.
Internal Server Error: /sitio/detail/1
Traceback (most recent call last):
  File "/usr/local/lib/python2.7/dist-packages/django/core/handlers/base.py", line 132, in get_response
    response = wrapped_callback(request, *callback_args, **callback_kwargs)
  File "/usr/local/lib/python2.7/dist-packages/django/views/decorators/csrf.py", line 58, in wrapped_view
    return view_func(*args, **kwargs)
  File "/usr/local/lib/python2.7/dist-packages/django/views/generic/base.py", line 71, in view
    return self.dispatch(request, *args, **kwargs)
  File "/usr/local/lib/python2.7/dist-packages/rest_framework/views.py", line 407, in dispatch
    response = self.handle_exception(exc)
  File "/usr/local/lib/python2.7/dist-packages/rest_framework/views.py", line 404, in dispatch
    response = handler(request, *args, **kwargs)
  File "/usr/local/lib/python2.7/dist-packages/rest_framework/generics.py", line 357, in put
    return self.update(request, *args, **kwargs)
  File "/home/camilo/Documents/BackEnd/sitios/views.py", line 75, in update
    if serializer.is_valid():
  File "/usr/local/lib/python2.7/dist-packages/rest_framework/serializers.py", line 180, in is_valid
    'Cannot call `.is_valid()` as no `data=` keyword argument was '
AssertionError: Cannot call `.is_valid()` as no `data=` keyword argument was passed when instantiating the serializer instance.
Internal Server Error: /sitio/detail/1
Traceback (most recent call last):
  File "/usr/local/lib/python2.7/dist-packages/django/core/handlers/base.py", line 132, in get_response
    response = wrapped_callback(request, *callback_args, **callback_kwargs)
  File "/usr/local/lib/python2.7/dist-packages/django/views/decorators/csrf.py", line 58, in wrapped_view
    return view_func(*args, **kwargs)
  File "/usr/local/lib/python2.7/dist-packages/django/views/generic/base.py", line 71, in view
    return self.dispatch(request, *args, **kwargs)
  File "/usr/local/lib/python2.7/dist-packages/rest_framework/views.py", line 407, in dispatch
    response = self.handle_exception(exc)
  File "/usr/local/lib/python2.7/dist-packages/rest_framework/views.py", line 404, in dispatch
    response = handler(request, *args, **kwargs)
  File "/usr/local/lib/python2.7/dist-packages/rest_framework/generics.py", line 357, in put
    return self.update(request, *args, **kwargs)
  File "/home/camilo/Documents/BackEnd/sitios/views.py", line 75, in update
    if serializer.is_valid():
  File "/usr/local/lib/python2.7/dist-packages/rest_framework/serializers.py", line 180, in is_valid
    'Cannot call `.is_valid()` as no `data=` keyword argument was '
AssertionError: Cannot call `.is_valid()` as no `data=` keyword argument was passed when instantiating the serializer instance.
Internal Server Error: /sitio/detail/1
Traceback (most recent call last):
  File "/usr/local/lib/python2.7/dist-packages/django/core/handlers/base.py", line 132, in get_response
    response = wrapped_callback(request, *callback_args, **callback_kwargs)
  File "/usr/local/lib/python2.7/dist-packages/django/views/decorators/csrf.py", line 58, in wrapped_view
    return view_func(*args, **kwargs)
  File "/usr/local/lib/python2.7/dist-packages/django/views/generic/base.py", line 71, in view
    return self.dispatch(request, *args, **kwargs)
  File "/usr/local/lib/python2.7/dist-packages/rest_framework/views.py", line 407, in dispatch
    response = self.handle_exception(exc)
  File "/usr/local/lib/python2.7/dist-packages/rest_framework/views.py", line 404, in dispatch
    response = handler(request, *args, **kwargs)
  File "/usr/local/lib/python2.7/dist-packages/rest_framework/generics.py", line 357, in put
    return self.update(request, *args, **kwargs)
  File "/home/camilo/Documents/BackEnd/sitios/views.py", line 74, in update
    print data
NameError: global name 'data' is not defined
Internal Server Error: /sitio/detail/1
Traceback (most recent call last):
  File "/usr/local/lib/python2.7/dist-packages/django/core/handlers/base.py", line 132, in get_response
    response = wrapped_callback(request, *callback_args, **callback_kwargs)
  File "/usr/local/lib/python2.7/dist-packages/django/views/decorators/csrf.py", line 58, in wrapped_view
    return view_func(*args, **kwargs)
  File "/usr/local/lib/python2.7/dist-packages/django/views/generic/base.py", line 71, in view
    return self.dispatch(request, *args, **kwargs)
  File "/usr/local/lib/python2.7/dist-packages/rest_framework/views.py", line 407, in dispatch
    response = self.handle_exception(exc)
  File "/usr/local/lib/python2.7/dist-packages/rest_framework/views.py", line 404, in dispatch
    response = handler(request, *args, **kwargs)
  File "/usr/local/lib/python2.7/dist-packages/rest_framework/generics.py", line 357, in put
    return self.update(request, *args, **kwargs)
  File "/home/camilo/Documents/BackEnd/sitios/views.py", line 74, in update
    print data
NameError: global name 'data' is not defined
Internal Server Error: /sitio/detail/1
Traceback (most recent call last):
  File "/usr/local/lib/python2.7/dist-packages/django/core/handlers/base.py", line 132, in get_response
    response = wrapped_callback(request, *callback_args, **callback_kwargs)
  File "/usr/local/lib/python2.7/dist-packages/django/views/decorators/csrf.py", line 58, in wrapped_view
    return view_func(*args, **kwargs)
  File "/usr/local/lib/python2.7/dist-packages/django/views/generic/base.py", line 71, in view
    return self.dispatch(request, *args, **kwargs)
  File "/usr/local/lib/python2.7/dist-packages/rest_framework/views.py", line 407, in dispatch
    response = self.handle_exception(exc)
  File "/usr/local/lib/python2.7/dist-packages/rest_framework/views.py", line 404, in dispatch
    response = handler(request, *args, **kwargs)
  File "/usr/local/lib/python2.7/dist-packages/rest_framework/generics.py", line 357, in put
    return self.update(request, *args, **kwargs)
  File "/home/camilo/Documents/BackEnd/sitios/views.py", line 74, in update
    print data
NameError: global name 'data' is not defined
Internal Server Error: /sitio/detail/1
Traceback (most recent call last):
  File "/usr/local/lib/python2.7/dist-packages/django/core/handlers/base.py", line 132, in get_response
    response = wrapped_callback(request, *callback_args, **callback_kwargs)
  File "/usr/local/lib/python2.7/dist-packages/django/views/decorators/csrf.py", line 58, in wrapped_view
    return view_func(*args, **kwargs)
  File "/usr/local/lib/python2.7/dist-packages/django/views/generic/base.py", line 71, in view
    return self.dispatch(request, *args, **kwargs)
  File "/usr/local/lib/python2.7/dist-packages/rest_framework/views.py", line 407, in dispatch
    response = self.handle_exception(exc)
  File "/usr/local/lib/python2.7/dist-packages/rest_framework/views.py", line 404, in dispatch
    response = handler(request, *args, **kwargs)
  File "/usr/local/lib/python2.7/dist-packages/rest_framework/generics.py", line 357, in put
    return self.update(request, *args, **kwargs)
  File "/home/camilo/Documents/BackEnd/sitios/views.py", line 76, in update
    if serializer.is_valid():
  File "/usr/local/lib/python2.7/dist-packages/rest_framework/serializers.py", line 186, in is_valid
    self._validated_data = self.run_validation(self.initial_data)
  File "/usr/local/lib/python2.7/dist-packages/rest_framework/serializers.py", line 364, in run_validation
    value = self.to_internal_value(data)
  File "/home/camilo/Documents/BackEnd/sitios/serializers.py", line 40, in to_internal_value
    data["latitud"]=float(data.get("latitud")[0])
TypeError: 'float' object has no attribute '__getitem__'
Internal Server Error: /sitio/detail/1
Traceback (most recent call last):
  File "/usr/local/lib/python2.7/dist-packages/django/core/handlers/base.py", line 132, in get_response
    response = wrapped_callback(request, *callback_args, **callback_kwargs)
  File "/usr/local/lib/python2.7/dist-packages/django/views/decorators/csrf.py", line 58, in wrapped_view
    return view_func(*args, **kwargs)
  File "/usr/local/lib/python2.7/dist-packages/django/views/generic/base.py", line 71, in view
    return self.dispatch(request, *args, **kwargs)
  File "/usr/local/lib/python2.7/dist-packages/rest_framework/views.py", line 407, in dispatch
    response = self.handle_exception(exc)
  File "/usr/local/lib/python2.7/dist-packages/rest_framework/views.py", line 404, in dispatch
    response = handler(request, *args, **kwargs)
  File "/usr/local/lib/python2.7/dist-packages/rest_framework/generics.py", line 357, in put
    return self.update(request, *args, **kwargs)
  File "/home/camilo/Documents/BackEnd/sitios/views.py", line 70, in update
    print request.PUT
  File "/usr/local/lib/python2.7/dist-packages/rest_framework/request.py", line 501, in __getattribute__
    six.reraise(info[0], info[1], info[2].tb_next)
  File "<string>", line 2, in reraise
AttributeError: 'Request' object has no attribute 'PUT'
Internal Server Error: /sitio/detail/1
Traceback (most recent call last):
  File "/usr/local/lib/python2.7/dist-packages/django/core/handlers/base.py", line 132, in get_response
    response = wrapped_callback(request, *callback_args, **callback_kwargs)
  File "/usr/local/lib/python2.7/dist-packages/django/views/decorators/csrf.py", line 58, in wrapped_view
    return view_func(*args, **kwargs)
  File "/usr/local/lib/python2.7/dist-packages/django/views/generic/base.py", line 71, in view
    return self.dispatch(request, *args, **kwargs)
  File "/usr/local/lib/python2.7/dist-packages/rest_framework/views.py", line 407, in dispatch
    response = self.handle_exception(exc)
  File "/usr/local/lib/python2.7/dist-packages/rest_framework/views.py", line 404, in dispatch
    response = handler(request, *args, **kwargs)
  File "/usr/local/lib/python2.7/dist-packages/rest_framework/generics.py", line 357, in put
    return self.update(request, *args, **kwargs)
  File "/home/camilo/Documents/BackEnd/sitios/views.py", line 70, in update
    print request.PUT
  File "/usr/local/lib/python2.7/dist-packages/rest_framework/request.py", line 501, in __getattribute__
    six.reraise(info[0], info[1], info[2].tb_next)
  File "<string>", line 2, in reraise
AttributeError: 'Request' object has no attribute 'PUT'
Internal Server Error: /sitio/detail/1
Traceback (most recent call last):
  File "/usr/local/lib/python2.7/dist-packages/django/core/handlers/base.py", line 132, in get_response
    response = wrapped_callback(request, *callback_args, **callback_kwargs)
  File "/usr/local/lib/python2.7/dist-packages/django/views/decorators/csrf.py", line 58, in wrapped_view
    return view_func(*args, **kwargs)
  File "/usr/local/lib/python2.7/dist-packages/django/views/generic/base.py", line 71, in view
    return self.dispatch(request, *args, **kwargs)
  File "/usr/local/lib/python2.7/dist-packages/rest_framework/views.py", line 407, in dispatch
    response = self.handle_exception(exc)
  File "/usr/local/lib/python2.7/dist-packages/rest_framework/views.py", line 404, in dispatch
    response = handler(request, *args, **kwargs)
  File "/usr/local/lib/python2.7/dist-packages/rest_framework/generics.py", line 357, in put
    return self.update(request, *args, **kwargs)
  File "/home/camilo/Documents/BackEnd/sitios/views.py", line 70, in update
    print request.PUT
  File "/usr/local/lib/python2.7/dist-packages/rest_framework/request.py", line 501, in __getattribute__
    six.reraise(info[0], info[1], info[2].tb_next)
  File "<string>", line 2, in reraise
AttributeError: 'Request' object has no attribute 'PUT'
Internal Server Error: /sitio/detail/1
Traceback (most recent call last):
  File "/usr/local/lib/python2.7/dist-packages/django/core/handlers/base.py", line 132, in get_response
    response = wrapped_callback(request, *callback_args, **callback_kwargs)
  File "/usr/local/lib/python2.7/dist-packages/django/views/decorators/csrf.py", line 58, in wrapped_view
    return view_func(*args, **kwargs)
  File "/usr/local/lib/python2.7/dist-packages/django/views/generic/base.py", line 71, in view
    return self.dispatch(request, *args, **kwargs)
  File "/usr/local/lib/python2.7/dist-packages/rest_framework/views.py", line 407, in dispatch
    response = self.handle_exception(exc)
  File "/usr/local/lib/python2.7/dist-packages/rest_framework/views.py", line 404, in dispatch
    response = handler(request, *args, **kwargs)
  File "/usr/local/lib/python2.7/dist-packages/rest_framework/generics.py", line 357, in put
    return self.update(request, *args, **kwargs)
  File "/home/camilo/Documents/BackEnd/sitios/views.py", line 70, in update
    print request.PUT
  File "/usr/local/lib/python2.7/dist-packages/rest_framework/request.py", line 501, in __getattribute__
    six.reraise(info[0], info[1], info[2].tb_next)
  File "<string>", line 2, in reraise
AttributeError: 'Request' object has no attribute 'PUT'
Internal Server Error: /sitio/detail/1
Traceback (most recent call last):
  File "/usr/local/lib/python2.7/dist-packages/django/core/handlers/base.py", line 132, in get_response
    response = wrapped_callback(request, *callback_args, **callback_kwargs)
  File "/usr/local/lib/python2.7/dist-packages/django/views/decorators/csrf.py", line 58, in wrapped_view
    return view_func(*args, **kwargs)
  File "/usr/local/lib/python2.7/dist-packages/django/views/generic/base.py", line 71, in view
    return self.dispatch(request, *args, **kwargs)
  File "/usr/local/lib/python2.7/dist-packages/rest_framework/views.py", line 407, in dispatch
    response = self.handle_exception(exc)
  File "/usr/local/lib/python2.7/dist-packages/rest_framework/views.py", line 404, in dispatch
    response = handler(request, *args, **kwargs)
  File "/usr/local/lib/python2.7/dist-packages/rest_framework/generics.py", line 357, in put
    return self.update(request, *args, **kwargs)
  File "/home/camilo/Documents/BackEnd/sitios/views.py", line 70, in update
    print request.PUT
  File "/usr/local/lib/python2.7/dist-packages/rest_framework/request.py", line 501, in __getattribute__
    six.reraise(info[0], info[1], info[2].tb_next)
  File "<string>", line 2, in reraise
AttributeError: 'Request' object has no attribute 'PUT'
Internal Server Error: /sitio/detail/1
Traceback (most recent call last):
  File "/usr/local/lib/python2.7/dist-packages/django/core/handlers/base.py", line 132, in get_response
    response = wrapped_callback(request, *callback_args, **callback_kwargs)
  File "/usr/local/lib/python2.7/dist-packages/django/views/decorators/csrf.py", line 58, in wrapped_view
    return view_func(*args, **kwargs)
  File "/usr/local/lib/python2.7/dist-packages/django/views/generic/base.py", line 71, in view
    return self.dispatch(request, *args, **kwargs)
  File "/usr/local/lib/python2.7/dist-packages/rest_framework/views.py", line 407, in dispatch
    response = self.handle_exception(exc)
  File "/usr/local/lib/python2.7/dist-packages/rest_framework/views.py", line 404, in dispatch
    response = handler(request, *args, **kwargs)
  File "/usr/local/lib/python2.7/dist-packages/rest_framework/generics.py", line 357, in put
    return self.update(request, *args, **kwargs)
  File "/home/camilo/Documents/BackEnd/sitios/views.py", line 70, in update
    print request.PUT
  File "/usr/local/lib/python2.7/dist-packages/rest_framework/request.py", line 501, in __getattribute__
    six.reraise(info[0], info[1], info[2].tb_next)
  File "<string>", line 2, in reraise
AttributeError: 'Request' object has no attribute 'PUT'
Internal Server Error: /sitio/detail/1
Traceback (most recent call last):
  File "/usr/local/lib/python2.7/dist-packages/django/core/handlers/base.py", line 132, in get_response
    response = wrapped_callback(request, *callback_args, **callback_kwargs)
  File "/usr/local/lib/python2.7/dist-packages/django/views/decorators/csrf.py", line 58, in wrapped_view
    return view_func(*args, **kwargs)
  File "/usr/local/lib/python2.7/dist-packages/django/views/generic/base.py", line 71, in view
    return self.dispatch(request, *args, **kwargs)
  File "/usr/local/lib/python2.7/dist-packages/rest_framework/views.py", line 407, in dispatch
    response = self.handle_exception(exc)
  File "/usr/local/lib/python2.7/dist-packages/rest_framework/views.py", line 404, in dispatch
    response = handler(request, *args, **kwargs)
  File "/usr/local/lib/python2.7/dist-packages/rest_framework/generics.py", line 357, in put
    return self.update(request, *args, **kwargs)
  File "/home/camilo/Documents/BackEnd/sitios/views.py", line 76, in update
    self.get_object().objects.fotos.delete()
  File "/usr/local/lib/python2.7/dist-packages/django/db/models/manager.py", line 252, in __get__
    raise AttributeError("Manager isn't accessible via %s instances" % type.__name__)
AttributeError: Manager isn't accessible via Sitio instances
Internal Server Error: /sitio/detail/1
Traceback (most recent call last):
  File "/usr/local/lib/python2.7/dist-packages/django/core/handlers/base.py", line 132, in get_response
    response = wrapped_callback(request, *callback_args, **callback_kwargs)
  File "/usr/local/lib/python2.7/dist-packages/django/views/decorators/csrf.py", line 58, in wrapped_view
    return view_func(*args, **kwargs)
  File "/usr/local/lib/python2.7/dist-packages/django/views/generic/base.py", line 71, in view
    return self.dispatch(request, *args, **kwargs)
  File "/usr/local/lib/python2.7/dist-packages/rest_framework/views.py", line 407, in dispatch
    response = self.handle_exception(exc)
  File "/usr/local/lib/python2.7/dist-packages/rest_framework/views.py", line 404, in dispatch
    response = handler(request, *args, **kwargs)
  File "/usr/local/lib/python2.7/dist-packages/rest_framework/generics.py", line 357, in put
    return self.update(request, *args, **kwargs)
  File "/home/camilo/Documents/BackEnd/sitios/views.py", line 76, in update
    self.get_object().objects.fotos.delete()
  File "/usr/local/lib/python2.7/dist-packages/django/db/models/manager.py", line 252, in __get__
    raise AttributeError("Manager isn't accessible via %s instances" % type.__name__)
AttributeError: Manager isn't accessible via Sitio instances
Internal Server Error: /sitio/detail/1
Traceback (most recent call last):
  File "/usr/local/lib/python2.7/dist-packages/django/core/handlers/base.py", line 132, in get_response
    response = wrapped_callback(request, *callback_args, **callback_kwargs)
  File "/usr/local/lib/python2.7/dist-packages/django/views/decorators/csrf.py", line 58, in wrapped_view
    return view_func(*args, **kwargs)
  File "/usr/local/lib/python2.7/dist-packages/django/views/generic/base.py", line 71, in view
    return self.dispatch(request, *args, **kwargs)
  File "/usr/local/lib/python2.7/dist-packages/rest_framework/views.py", line 407, in dispatch
    response = self.handle_exception(exc)
  File "/usr/local/lib/python2.7/dist-packages/rest_framework/views.py", line 404, in dispatch
    response = handler(request, *args, **kwargs)
  File "/usr/local/lib/python2.7/dist-packages/rest_framework/generics.py", line 357, in put
    return self.update(request, *args, **kwargs)
  File "/home/camilo/Documents/BackEnd/sitios/views.py", line 76, in update
    self.get_object().objects.fotos.delete()
  File "/usr/local/lib/python2.7/dist-packages/django/db/models/manager.py", line 252, in __get__
    raise AttributeError("Manager isn't accessible via %s instances" % type.__name__)
AttributeError: Manager isn't accessible via Sitio instances
Internal Server Error: /rest-auth/login
Traceback (most recent call last):
  File "/usr/local/lib/python2.7/dist-packages/django/core/handlers/base.py", line 108, in get_response
    response = middleware_method(request)
  File "/usr/local/lib/python2.7/dist-packages/django/middleware/common.py", line 74, in process_request
    if (not urlresolvers.is_valid_path(request.path_info, urlconf) and
  File "/usr/local/lib/python2.7/dist-packages/django/core/urlresolvers.py", line 647, in is_valid_path
    resolve(path, urlconf)
  File "/usr/local/lib/python2.7/dist-packages/django/core/urlresolvers.py", line 522, in resolve
    return get_resolver(urlconf).resolve(path)
  File "/usr/local/lib/python2.7/dist-packages/django/core/urlresolvers.py", line 366, in resolve
    for pattern in self.url_patterns:
  File "/usr/local/lib/python2.7/dist-packages/django/core/urlresolvers.py", line 402, in url_patterns
    patterns = getattr(self.urlconf_module, "urlpatterns", self.urlconf_module)
  File "/usr/local/lib/python2.7/dist-packages/django/core/urlresolvers.py", line 396, in urlconf_module
    self._urlconf_module = import_module(self.urlconf_name)
  File "/usr/lib/python2.7/importlib/__init__.py", line 37, in import_module
    __import__(name)
  File "/home/camilo/Documents/BackEnd/turismo/urls.py", line 4, in <module>
    from plataforma import views
  File "/home/camilo/Documents/BackEnd/plataforma/views.py", line 5, in <module>
    from plataforma.serializers import *
  File "/home/camilo/Documents/BackEnd/plataforma/serializers.py", line 9, in <module>
    from sitios.serializers import SitioSerializer
  File "/home/camilo/Documents/BackEnd/sitios/serializers.py", line 18, in <module>
    class CategoriaSerializer(serializers.ModelSerializer):
  File "/home/camilo/Documents/BackEnd/sitios/serializers.py", line 19, in CategoriaSerializer
    class Meta:
  File "/home/camilo/Documents/BackEnd/sitios/serializers.py", line 20, in Meta
    model = Categoria
NameError: name 'Categoria' is not defined
Internal Server Error: /rest-auth/login
Traceback (most recent call last):
  File "/usr/local/lib/python2.7/dist-packages/django/core/handlers/base.py", line 108, in get_response
    response = middleware_method(request)
  File "/usr/local/lib/python2.7/dist-packages/django/middleware/common.py", line 74, in process_request
    if (not urlresolvers.is_valid_path(request.path_info, urlconf) and
  File "/usr/local/lib/python2.7/dist-packages/django/core/urlresolvers.py", line 647, in is_valid_path
    resolve(path, urlconf)
  File "/usr/local/lib/python2.7/dist-packages/django/core/urlresolvers.py", line 522, in resolve
    return get_resolver(urlconf).resolve(path)
  File "/usr/local/lib/python2.7/dist-packages/django/core/urlresolvers.py", line 366, in resolve
    for pattern in self.url_patterns:
  File "/usr/local/lib/python2.7/dist-packages/django/core/urlresolvers.py", line 402, in url_patterns
    patterns = getattr(self.urlconf_module, "urlpatterns", self.urlconf_module)
  File "/usr/local/lib/python2.7/dist-packages/django/core/urlresolvers.py", line 396, in urlconf_module
    self._urlconf_module = import_module(self.urlconf_name)
  File "/usr/lib/python2.7/importlib/__init__.py", line 37, in import_module
    __import__(name)
  File "/home/camilo/Documents/BackEnd/turismo/urls.py", line 4, in <module>
    from plataforma import views
  File "/home/camilo/Documents/BackEnd/plataforma/views.py", line 5, in <module>
    from plataforma.serializers import *
  File "/home/camilo/Documents/BackEnd/plataforma/serializers.py", line 9, in <module>
    from sitios.serializers import SitioSerializer
  File "/home/camilo/Documents/BackEnd/sitios/serializers.py", line 18, in <module>
    class CategoriaSerializer(serializers.ModelSerializer):
  File "/home/camilo/Documents/BackEnd/sitios/serializers.py", line 19, in CategoriaSerializer
    class Meta:
  File "/home/camilo/Documents/BackEnd/sitios/serializers.py", line 20, in Meta
    model = Categoria
NameError: name 'Categoria' is not defined
Internal Server Error: /rest-auth/login
Traceback (most recent call last):
  File "/usr/local/lib/python2.7/dist-packages/django/core/handlers/base.py", line 108, in get_response
    response = middleware_method(request)
  File "/usr/local/lib/python2.7/dist-packages/django/middleware/common.py", line 74, in process_request
    if (not urlresolvers.is_valid_path(request.path_info, urlconf) and
  File "/usr/local/lib/python2.7/dist-packages/django/core/urlresolvers.py", line 647, in is_valid_path
    resolve(path, urlconf)
  File "/usr/local/lib/python2.7/dist-packages/django/core/urlresolvers.py", line 522, in resolve
    return get_resolver(urlconf).resolve(path)
  File "/usr/local/lib/python2.7/dist-packages/django/core/urlresolvers.py", line 366, in resolve
    for pattern in self.url_patterns:
  File "/usr/local/lib/python2.7/dist-packages/django/core/urlresolvers.py", line 402, in url_patterns
    patterns = getattr(self.urlconf_module, "urlpatterns", self.urlconf_module)
  File "/usr/local/lib/python2.7/dist-packages/django/core/urlresolvers.py", line 396, in urlconf_module
    self._urlconf_module = import_module(self.urlconf_name)
  File "/usr/lib/python2.7/importlib/__init__.py", line 37, in import_module
    __import__(name)
  File "/home/camilo/Documents/BackEnd/turismo/urls.py", line 4, in <module>
    from plataforma import views
  File "/home/camilo/Documents/BackEnd/plataforma/views.py", line 5, in <module>
    from plataforma.serializers import *
  File "/home/camilo/Documents/BackEnd/plataforma/serializers.py", line 9, in <module>
    from sitios.serializers import SitioSerializer
  File "/home/camilo/Documents/BackEnd/sitios/serializers.py", line 18, in <module>
    class CategoriaSerializer(serializers.ModelSerializer):
  File "/home/camilo/Documents/BackEnd/sitios/serializers.py", line 19, in CategoriaSerializer
    class Meta:
  File "/home/camilo/Documents/BackEnd/sitios/serializers.py", line 20, in Meta
    model = Categoria
NameError: name 'Categoria' is not defined
Internal Server Error: /rest-auth/login
Traceback (most recent call last):
  File "/usr/local/lib/python2.7/dist-packages/django/core/handlers/base.py", line 108, in get_response
    response = middleware_method(request)
  File "/usr/local/lib/python2.7/dist-packages/django/middleware/common.py", line 74, in process_request
    if (not urlresolvers.is_valid_path(request.path_info, urlconf) and
  File "/usr/local/lib/python2.7/dist-packages/django/core/urlresolvers.py", line 647, in is_valid_path
    resolve(path, urlconf)
  File "/usr/local/lib/python2.7/dist-packages/django/core/urlresolvers.py", line 522, in resolve
    return get_resolver(urlconf).resolve(path)
  File "/usr/local/lib/python2.7/dist-packages/django/core/urlresolvers.py", line 366, in resolve
    for pattern in self.url_patterns:
  File "/usr/local/lib/python2.7/dist-packages/django/core/urlresolvers.py", line 402, in url_patterns
    patterns = getattr(self.urlconf_module, "urlpatterns", self.urlconf_module)
  File "/usr/local/lib/python2.7/dist-packages/django/core/urlresolvers.py", line 396, in urlconf_module
    self._urlconf_module = import_module(self.urlconf_name)
  File "/usr/lib/python2.7/importlib/__init__.py", line 37, in import_module
    __import__(name)
  File "/home/camilo/Documents/BackEnd/turismo/urls.py", line 4, in <module>
    from plataforma import views
  File "/home/camilo/Documents/BackEnd/plataforma/views.py", line 5, in <module>
    from plataforma.serializers import *
  File "/home/camilo/Documents/BackEnd/plataforma/serializers.py", line 9, in <module>
    from sitios.serializers import SitioSerializer
  File "/home/camilo/Documents/BackEnd/sitios/serializers.py", line 18, in <module>
    class CategoriaSerializer(serializers.ModelSerializer):
  File "/home/camilo/Documents/BackEnd/sitios/serializers.py", line 19, in CategoriaSerializer
    class Meta:
  File "/home/camilo/Documents/BackEnd/sitios/serializers.py", line 20, in Meta
    model = Categoria
NameError: name 'Categoria' is not defined
Internal Server Error: /buscar/
Traceback (most recent call last):
  File "/usr/local/lib/python2.7/dist-packages/django/core/handlers/base.py", line 132, in get_response
    response = wrapped_callback(request, *callback_args, **callback_kwargs)
  File "/usr/local/lib/python2.7/dist-packages/django/views/decorators/csrf.py", line 58, in wrapped_view
    return view_func(*args, **kwargs)
  File "/usr/local/lib/python2.7/dist-packages/django/views/generic/base.py", line 71, in view
    return self.dispatch(request, *args, **kwargs)
  File "/usr/local/lib/python2.7/dist-packages/rest_framework/views.py", line 407, in dispatch
    response = self.handle_exception(exc)
  File "/usr/local/lib/python2.7/dist-packages/rest_framework/views.py", line 404, in dispatch
    response = handler(request, *args, **kwargs)
  File "/usr/local/lib/python2.7/dist-packages/rest_framework/generics.py", line 311, in get
    return self.list(request, *args, **kwargs)
  File "/usr/local/lib/python2.7/dist-packages/rest_framework/mixins.py", line 46, in list
    return Response(serializer.data)
  File "/usr/local/lib/python2.7/dist-packages/rest_framework/serializers.py", line 615, in data
    ret = super(ListSerializer, self).data
  File "/usr/local/lib/python2.7/dist-packages/rest_framework/serializers.py", line 212, in data
    self._data = self.to_representation(self.instance)
  File "/usr/local/lib/python2.7/dist-packages/rest_framework/serializers.py", line 565, in to_representation
    self.child.to_representation(item) for item in iterable
  File "/usr/local/lib/python2.7/dist-packages/rest_framework/serializers.py", line 423, in to_representation
    attribute = field.get_attribute(instance)
  File "/usr/local/lib/python2.7/dist-packages/rest_framework/fields.py", line 307, in get_attribute
    raise type(exc)(msg)
AttributeError: Got AttributeError when attempting to get a value for field `categorias_ids` on serializer `SitioSerializer`.
The serializer field might be named incorrectly and not match any attribute or key on the `Sitio` instance.
Original exception text was: 'Sitio' object has no attribute 'categorias_ids'.
Internal Server Error: /buscar/
Traceback (most recent call last):
  File "/usr/local/lib/python2.7/dist-packages/django/core/handlers/base.py", line 132, in get_response
    response = wrapped_callback(request, *callback_args, **callback_kwargs)
  File "/usr/local/lib/python2.7/dist-packages/django/views/decorators/csrf.py", line 58, in wrapped_view
    return view_func(*args, **kwargs)
  File "/usr/local/lib/python2.7/dist-packages/django/views/generic/base.py", line 71, in view
    return self.dispatch(request, *args, **kwargs)
  File "/usr/local/lib/python2.7/dist-packages/rest_framework/views.py", line 407, in dispatch
    response = self.handle_exception(exc)
  File "/usr/local/lib/python2.7/dist-packages/rest_framework/views.py", line 404, in dispatch
    response = handler(request, *args, **kwargs)
  File "/usr/local/lib/python2.7/dist-packages/rest_framework/generics.py", line 311, in get
    return self.list(request, *args, **kwargs)
  File "/usr/local/lib/python2.7/dist-packages/rest_framework/mixins.py", line 46, in list
    return Response(serializer.data)
  File "/usr/local/lib/python2.7/dist-packages/rest_framework/serializers.py", line 615, in data
    ret = super(ListSerializer, self).data
  File "/usr/local/lib/python2.7/dist-packages/rest_framework/serializers.py", line 212, in data
    self._data = self.to_representation(self.instance)
  File "/usr/local/lib/python2.7/dist-packages/rest_framework/serializers.py", line 565, in to_representation
    self.child.to_representation(item) for item in iterable
  File "/usr/local/lib/python2.7/dist-packages/rest_framework/serializers.py", line 423, in to_representation
    attribute = field.get_attribute(instance)
  File "/usr/local/lib/python2.7/dist-packages/rest_framework/fields.py", line 307, in get_attribute
    raise type(exc)(msg)
AttributeError: Got AttributeError when attempting to get a value for field `categorias_ids` on serializer `SitioSerializer`.
The serializer field might be named incorrectly and not match any attribute or key on the `Sitio` instance.
Original exception text was: 'Sitio' object has no attribute 'categorias_ids'.
Internal Server Error: /buscar/
Traceback (most recent call last):
  File "/usr/local/lib/python2.7/dist-packages/django/core/handlers/base.py", line 132, in get_response
    response = wrapped_callback(request, *callback_args, **callback_kwargs)
  File "/usr/local/lib/python2.7/dist-packages/django/views/decorators/csrf.py", line 58, in wrapped_view
    return view_func(*args, **kwargs)
  File "/usr/local/lib/python2.7/dist-packages/django/views/generic/base.py", line 71, in view
    return self.dispatch(request, *args, **kwargs)
  File "/usr/local/lib/python2.7/dist-packages/rest_framework/views.py", line 407, in dispatch
    response = self.handle_exception(exc)
  File "/usr/local/lib/python2.7/dist-packages/rest_framework/views.py", line 404, in dispatch
    response = handler(request, *args, **kwargs)
  File "/usr/local/lib/python2.7/dist-packages/rest_framework/generics.py", line 311, in get
    return self.list(request, *args, **kwargs)
  File "/usr/local/lib/python2.7/dist-packages/rest_framework/mixins.py", line 46, in list
    return Response(serializer.data)
  File "/usr/local/lib/python2.7/dist-packages/rest_framework/serializers.py", line 615, in data
    ret = super(ListSerializer, self).data
  File "/usr/local/lib/python2.7/dist-packages/rest_framework/serializers.py", line 212, in data
    self._data = self.to_representation(self.instance)
  File "/usr/local/lib/python2.7/dist-packages/rest_framework/serializers.py", line 565, in to_representation
    self.child.to_representation(item) for item in iterable
  File "/usr/local/lib/python2.7/dist-packages/rest_framework/serializers.py", line 423, in to_representation
    attribute = field.get_attribute(instance)
  File "/usr/local/lib/python2.7/dist-packages/rest_framework/fields.py", line 307, in get_attribute
    raise type(exc)(msg)
AttributeError: Got AttributeError when attempting to get a value for field `categorias_ids` on serializer `SitioSerializer`.
The serializer field might be named incorrectly and not match any attribute or key on the `Sitio` instance.
Original exception text was: 'Sitio' object has no attribute 'categorias_ids'.
Internal Server Error: /buscar/
Traceback (most recent call last):
  File "/usr/local/lib/python2.7/dist-packages/django/core/handlers/base.py", line 132, in get_response
    response = wrapped_callback(request, *callback_args, **callback_kwargs)
  File "/usr/local/lib/python2.7/dist-packages/django/views/decorators/csrf.py", line 58, in wrapped_view
    return view_func(*args, **kwargs)
  File "/usr/local/lib/python2.7/dist-packages/django/views/generic/base.py", line 71, in view
    return self.dispatch(request, *args, **kwargs)
  File "/usr/local/lib/python2.7/dist-packages/rest_framework/views.py", line 407, in dispatch
    response = self.handle_exception(exc)
  File "/usr/local/lib/python2.7/dist-packages/rest_framework/views.py", line 404, in dispatch
    response = handler(request, *args, **kwargs)
  File "/usr/local/lib/python2.7/dist-packages/rest_framework/generics.py", line 311, in get
    return self.list(request, *args, **kwargs)
  File "/usr/local/lib/python2.7/dist-packages/rest_framework/mixins.py", line 46, in list
    return Response(serializer.data)
  File "/usr/local/lib/python2.7/dist-packages/rest_framework/serializers.py", line 615, in data
    ret = super(ListSerializer, self).data
  File "/usr/local/lib/python2.7/dist-packages/rest_framework/serializers.py", line 212, in data
    self._data = self.to_representation(self.instance)
  File "/usr/local/lib/python2.7/dist-packages/rest_framework/serializers.py", line 565, in to_representation
    self.child.to_representation(item) for item in iterable
  File "/usr/local/lib/python2.7/dist-packages/rest_framework/serializers.py", line 423, in to_representation
    attribute = field.get_attribute(instance)
  File "/usr/local/lib/python2.7/dist-packages/rest_framework/fields.py", line 307, in get_attribute
    raise type(exc)(msg)
AttributeError: Got AttributeError when attempting to get a value for field `categorias_ids` on serializer `SitioSerializer`.
The serializer field might be named incorrectly and not match any attribute or key on the `Sitio` instance.
Original exception text was: 'Sitio' object has no attribute 'categorias_ids'.
Internal Server Error: /buscar/
Traceback (most recent call last):
  File "/usr/local/lib/python2.7/dist-packages/django/core/handlers/base.py", line 132, in get_response
    response = wrapped_callback(request, *callback_args, **callback_kwargs)
  File "/usr/local/lib/python2.7/dist-packages/django/views/decorators/csrf.py", line 58, in wrapped_view
    return view_func(*args, **kwargs)
  File "/usr/local/lib/python2.7/dist-packages/django/views/generic/base.py", line 71, in view
    return self.dispatch(request, *args, **kwargs)
  File "/usr/local/lib/python2.7/dist-packages/rest_framework/views.py", line 407, in dispatch
    response = self.handle_exception(exc)
  File "/usr/local/lib/python2.7/dist-packages/rest_framework/views.py", line 404, in dispatch
    response = handler(request, *args, **kwargs)
  File "/usr/local/lib/python2.7/dist-packages/rest_framework/generics.py", line 311, in get
    return self.list(request, *args, **kwargs)
  File "/usr/local/lib/python2.7/dist-packages/rest_framework/mixins.py", line 46, in list
    return Response(serializer.data)
  File "/usr/local/lib/python2.7/dist-packages/rest_framework/serializers.py", line 615, in data
    ret = super(ListSerializer, self).data
  File "/usr/local/lib/python2.7/dist-packages/rest_framework/serializers.py", line 212, in data
    self._data = self.to_representation(self.instance)
  File "/usr/local/lib/python2.7/dist-packages/rest_framework/serializers.py", line 565, in to_representation
    self.child.to_representation(item) for item in iterable
  File "/usr/local/lib/python2.7/dist-packages/rest_framework/serializers.py", line 423, in to_representation
    attribute = field.get_attribute(instance)
  File "/usr/local/lib/python2.7/dist-packages/rest_framework/fields.py", line 307, in get_attribute
    raise type(exc)(msg)
AttributeError: Got AttributeError when attempting to get a value for field `categorias_ids` on serializer `SitioSerializer`.
The serializer field might be named incorrectly and not match any attribute or key on the `Sitio` instance.
Original exception text was: 'Sitio' object has no attribute 'categorias_ids'.
Internal Server Error: /buscar/
Traceback (most recent call last):
  File "/usr/local/lib/python2.7/dist-packages/django/core/handlers/base.py", line 132, in get_response
    response = wrapped_callback(request, *callback_args, **callback_kwargs)
  File "/usr/local/lib/python2.7/dist-packages/django/views/decorators/csrf.py", line 58, in wrapped_view
    return view_func(*args, **kwargs)
  File "/usr/local/lib/python2.7/dist-packages/django/views/generic/base.py", line 71, in view
    return self.dispatch(request, *args, **kwargs)
  File "/usr/local/lib/python2.7/dist-packages/rest_framework/views.py", line 407, in dispatch
    response = self.handle_exception(exc)
  File "/usr/local/lib/python2.7/dist-packages/rest_framework/views.py", line 404, in dispatch
    response = handler(request, *args, **kwargs)
  File "/usr/local/lib/python2.7/dist-packages/rest_framework/generics.py", line 311, in get
    return self.list(request, *args, **kwargs)
  File "/usr/local/lib/python2.7/dist-packages/rest_framework/mixins.py", line 46, in list
    return Response(serializer.data)
  File "/usr/local/lib/python2.7/dist-packages/rest_framework/serializers.py", line 615, in data
    ret = super(ListSerializer, self).data
  File "/usr/local/lib/python2.7/dist-packages/rest_framework/serializers.py", line 212, in data
    self._data = self.to_representation(self.instance)
  File "/usr/local/lib/python2.7/dist-packages/rest_framework/serializers.py", line 565, in to_representation
    self.child.to_representation(item) for item in iterable
  File "/usr/local/lib/python2.7/dist-packages/rest_framework/serializers.py", line 423, in to_representation
    attribute = field.get_attribute(instance)
  File "/usr/local/lib/python2.7/dist-packages/rest_framework/fields.py", line 307, in get_attribute
    raise type(exc)(msg)
AttributeError: Got AttributeError when attempting to get a value for field `categorias_ids` on serializer `SitioSerializer`.
The serializer field might be named incorrectly and not match any attribute or key on the `Sitio` instance.
Original exception text was: 'Sitio' object has no attribute 'categorias_ids'.
Internal Server Error: /buscar/
Traceback (most recent call last):
  File "/usr/local/lib/python2.7/dist-packages/django/core/handlers/base.py", line 132, in get_response
    response = wrapped_callback(request, *callback_args, **callback_kwargs)
  File "/usr/local/lib/python2.7/dist-packages/django/views/decorators/csrf.py", line 58, in wrapped_view
    return view_func(*args, **kwargs)
  File "/usr/local/lib/python2.7/dist-packages/django/views/generic/base.py", line 71, in view
    return self.dispatch(request, *args, **kwargs)
  File "/usr/local/lib/python2.7/dist-packages/rest_framework/views.py", line 407, in dispatch
    response = self.handle_exception(exc)
  File "/usr/local/lib/python2.7/dist-packages/rest_framework/views.py", line 404, in dispatch
    response = handler(request, *args, **kwargs)
  File "/usr/local/lib/python2.7/dist-packages/rest_framework/generics.py", line 311, in get
    return self.list(request, *args, **kwargs)
  File "/usr/local/lib/python2.7/dist-packages/rest_framework/mixins.py", line 46, in list
    return Response(serializer.data)
  File "/usr/local/lib/python2.7/dist-packages/rest_framework/serializers.py", line 615, in data
    ret = super(ListSerializer, self).data
  File "/usr/local/lib/python2.7/dist-packages/rest_framework/serializers.py", line 212, in data
    self._data = self.to_representation(self.instance)
  File "/usr/local/lib/python2.7/dist-packages/rest_framework/serializers.py", line 565, in to_representation
    self.child.to_representation(item) for item in iterable
  File "/usr/local/lib/python2.7/dist-packages/rest_framework/serializers.py", line 423, in to_representation
    attribute = field.get_attribute(instance)
  File "/usr/local/lib/python2.7/dist-packages/rest_framework/fields.py", line 307, in get_attribute
    raise type(exc)(msg)
AttributeError: Got AttributeError when attempting to get a value for field `categorias_ids` on serializer `SitioSerializer`.
The serializer field might be named incorrectly and not match any attribute or key on the `Sitio` instance.
Original exception text was: 'Sitio' object has no attribute 'categorias_ids'.
Internal Server Error: /sitio/detail/1
Traceback (most recent call last):
  File "/usr/local/lib/python2.7/dist-packages/django/core/handlers/base.py", line 132, in get_response
    response = wrapped_callback(request, *callback_args, **callback_kwargs)
  File "/usr/local/lib/python2.7/dist-packages/django/views/decorators/csrf.py", line 58, in wrapped_view
    return view_func(*args, **kwargs)
  File "/usr/local/lib/python2.7/dist-packages/django/views/generic/base.py", line 71, in view
    return self.dispatch(request, *args, **kwargs)
  File "/usr/local/lib/python2.7/dist-packages/rest_framework/views.py", line 407, in dispatch
    response = self.handle_exception(exc)
  File "/usr/local/lib/python2.7/dist-packages/rest_framework/views.py", line 404, in dispatch
    response = handler(request, *args, **kwargs)
  File "/usr/local/lib/python2.7/dist-packages/rest_framework/generics.py", line 357, in put
    return self.update(request, *args, **kwargs)
  File "/home/camilo/Documents/BackEnd/sitios/views.py", line 75, in update
    self.perform_update(serializer)
  File "/usr/local/lib/python2.7/dist-packages/rest_framework/mixins.py", line 72, in perform_update
    serializer.save()
  File "/usr/local/lib/python2.7/dist-packages/rest_framework/serializers.py", line 159, in save
    self.instance = self.update(self.instance, validated_data)
  File "/usr/local/lib/python2.7/dist-packages/rest_framework/serializers.py", line 794, in update
    raise_errors_on_nested_writes('update', self, validated_data)
  File "/usr/local/lib/python2.7/dist-packages/rest_framework/serializers.py", line 664, in raise_errors_on_nested_writes
    class_name=serializer.__class__.__name__
AssertionError: The `.update()` method does not support writable nestedfields by default.
Write an explicit `.update()` method for serializer `sitios.serializers.SitioSerializer`, or set `read_only=True` on nested serializer fields.
Internal Server Error: /sitio/detail/1
Traceback (most recent call last):
  File "/usr/local/lib/python2.7/dist-packages/django/core/handlers/base.py", line 132, in get_response
    response = wrapped_callback(request, *callback_args, **callback_kwargs)
  File "/usr/local/lib/python2.7/dist-packages/django/views/decorators/csrf.py", line 58, in wrapped_view
    return view_func(*args, **kwargs)
  File "/usr/local/lib/python2.7/dist-packages/django/views/generic/base.py", line 71, in view
    return self.dispatch(request, *args, **kwargs)
  File "/usr/local/lib/python2.7/dist-packages/rest_framework/views.py", line 407, in dispatch
    response = self.handle_exception(exc)
  File "/usr/local/lib/python2.7/dist-packages/rest_framework/views.py", line 404, in dispatch
    response = handler(request, *args, **kwargs)
  File "/usr/local/lib/python2.7/dist-packages/rest_framework/generics.py", line 357, in put
    return self.update(request, *args, **kwargs)
  File "/home/camilo/Documents/BackEnd/sitios/views.py", line 75, in update
    self.perform_update(serializer)
  File "/usr/local/lib/python2.7/dist-packages/rest_framework/mixins.py", line 72, in perform_update
    serializer.save()
  File "/usr/local/lib/python2.7/dist-packages/rest_framework/serializers.py", line 159, in save
    self.instance = self.update(self.instance, validated_data)
  File "/usr/local/lib/python2.7/dist-packages/rest_framework/serializers.py", line 794, in update
    raise_errors_on_nested_writes('update', self, validated_data)
  File "/usr/local/lib/python2.7/dist-packages/rest_framework/serializers.py", line 664, in raise_errors_on_nested_writes
    class_name=serializer.__class__.__name__
AssertionError: The `.update()` method does not support writable nestedfields by default.
Write an explicit `.update()` method for serializer `sitios.serializers.SitioSerializer`, or set `read_only=True` on nested serializer fields.
Internal Server Error: /sitio/detail/1
Traceback (most recent call last):
  File "/usr/local/lib/python2.7/dist-packages/django/core/handlers/base.py", line 132, in get_response
    response = wrapped_callback(request, *callback_args, **callback_kwargs)
  File "/usr/local/lib/python2.7/dist-packages/django/views/decorators/csrf.py", line 58, in wrapped_view
    return view_func(*args, **kwargs)
  File "/usr/local/lib/python2.7/dist-packages/django/views/generic/base.py", line 71, in view
    return self.dispatch(request, *args, **kwargs)
  File "/usr/local/lib/python2.7/dist-packages/rest_framework/views.py", line 407, in dispatch
    response = self.handle_exception(exc)
  File "/usr/local/lib/python2.7/dist-packages/rest_framework/views.py", line 404, in dispatch
    response = handler(request, *args, **kwargs)
  File "/usr/local/lib/python2.7/dist-packages/rest_framework/generics.py", line 357, in put
    return self.update(request, *args, **kwargs)
  File "/home/camilo/Documents/BackEnd/sitios/views.py", line 75, in update
    self.perform_update(serializer)
  File "/usr/local/lib/python2.7/dist-packages/rest_framework/mixins.py", line 72, in perform_update
    serializer.save()
  File "/usr/local/lib/python2.7/dist-packages/rest_framework/serializers.py", line 159, in save
    self.instance = self.update(self.instance, validated_data)
  File "/usr/local/lib/python2.7/dist-packages/rest_framework/serializers.py", line 794, in update
    raise_errors_on_nested_writes('update', self, validated_data)
  File "/usr/local/lib/python2.7/dist-packages/rest_framework/serializers.py", line 664, in raise_errors_on_nested_writes
    class_name=serializer.__class__.__name__
AssertionError: The `.update()` method does not support writable nestedfields by default.
Write an explicit `.update()` method for serializer `sitios.serializers.SitioSerializer`, or set `read_only=True` on nested serializer fields.
Internal Server Error: /rest-auth/login
Traceback (most recent call last):
  File "/usr/local/lib/python2.7/dist-packages/django/core/handlers/base.py", line 108, in get_response
    response = middleware_method(request)
  File "/usr/local/lib/python2.7/dist-packages/django/middleware/common.py", line 74, in process_request
    if (not urlresolvers.is_valid_path(request.path_info, urlconf) and
  File "/usr/local/lib/python2.7/dist-packages/django/core/urlresolvers.py", line 647, in is_valid_path
    resolve(path, urlconf)
  File "/usr/local/lib/python2.7/dist-packages/django/core/urlresolvers.py", line 522, in resolve
    return get_resolver(urlconf).resolve(path)
  File "/usr/local/lib/python2.7/dist-packages/django/core/urlresolvers.py", line 366, in resolve
    for pattern in self.url_patterns:
  File "/usr/local/lib/python2.7/dist-packages/django/core/urlresolvers.py", line 402, in url_patterns
    patterns = getattr(self.urlconf_module, "urlpatterns", self.urlconf_module)
  File "/usr/local/lib/python2.7/dist-packages/django/core/urlresolvers.py", line 396, in urlconf_module
    self._urlconf_module = import_module(self.urlconf_name)
  File "/usr/lib/python2.7/importlib/__init__.py", line 37, in import_module
    __import__(name)
  File "/home/camilo/Documents/BackEnd/turismo/urls.py", line 4, in <module>
    from plataforma import views
  File "/home/camilo/Documents/BackEnd/plataforma/views.py", line 5, in <module>
    from plataforma.serializers import *
  File "/home/camilo/Documents/BackEnd/plataforma/serializers.py", line 9, in <module>
    from sitios.serializers import SitioSerializer
  File "/home/camilo/Documents/BackEnd/sitios/serializers.py", line 28
    categorias_ids = CategoriaSerializer(many=True, source('categorias'))
SyntaxError: non-keyword arg after keyword arg
Internal Server Error: /rest-auth/login
Traceback (most recent call last):
  File "/usr/local/lib/python2.7/dist-packages/django/core/handlers/base.py", line 108, in get_response
    response = middleware_method(request)
  File "/usr/local/lib/python2.7/dist-packages/django/middleware/common.py", line 74, in process_request
    if (not urlresolvers.is_valid_path(request.path_info, urlconf) and
  File "/usr/local/lib/python2.7/dist-packages/django/core/urlresolvers.py", line 647, in is_valid_path
    resolve(path, urlconf)
  File "/usr/local/lib/python2.7/dist-packages/django/core/urlresolvers.py", line 522, in resolve
    return get_resolver(urlconf).resolve(path)
  File "/usr/local/lib/python2.7/dist-packages/django/core/urlresolvers.py", line 366, in resolve
    for pattern in self.url_patterns:
  File "/usr/local/lib/python2.7/dist-packages/django/core/urlresolvers.py", line 402, in url_patterns
    patterns = getattr(self.urlconf_module, "urlpatterns", self.urlconf_module)
  File "/usr/local/lib/python2.7/dist-packages/django/core/urlresolvers.py", line 396, in urlconf_module
    self._urlconf_module = import_module(self.urlconf_name)
  File "/usr/lib/python2.7/importlib/__init__.py", line 37, in import_module
    __import__(name)
  File "/home/camilo/Documents/BackEnd/turismo/urls.py", line 4, in <module>
    from plataforma import views
  File "/home/camilo/Documents/BackEnd/plataforma/views.py", line 5, in <module>
    from plataforma.serializers import *
  File "/home/camilo/Documents/BackEnd/plataforma/serializers.py", line 9, in <module>
    from sitios.serializers import SitioSerializer
  File "/home/camilo/Documents/BackEnd/sitios/serializers.py", line 28
    categorias_ids = CategoriaSerializer(many=True, source('categorias'))
SyntaxError: non-keyword arg after keyword arg
Internal Server Error: /buscar/
Traceback (most recent call last):
  File "/usr/local/lib/python2.7/dist-packages/django/core/handlers/base.py", line 132, in get_response
    response = wrapped_callback(request, *callback_args, **callback_kwargs)
  File "/usr/local/lib/python2.7/dist-packages/django/views/decorators/csrf.py", line 58, in wrapped_view
    return view_func(*args, **kwargs)
  File "/usr/local/lib/python2.7/dist-packages/django/views/generic/base.py", line 71, in view
    return self.dispatch(request, *args, **kwargs)
  File "/usr/local/lib/python2.7/dist-packages/rest_framework/views.py", line 407, in dispatch
    response = self.handle_exception(exc)
  File "/usr/local/lib/python2.7/dist-packages/rest_framework/views.py", line 404, in dispatch
    response = handler(request, *args, **kwargs)
  File "/usr/local/lib/python2.7/dist-packages/rest_framework/generics.py", line 311, in get
    return self.list(request, *args, **kwargs)
  File "/usr/local/lib/python2.7/dist-packages/rest_framework/mixins.py", line 46, in list
    return Response(serializer.data)
  File "/usr/local/lib/python2.7/dist-packages/rest_framework/serializers.py", line 615, in data
    ret = super(ListSerializer, self).data
  File "/usr/local/lib/python2.7/dist-packages/rest_framework/serializers.py", line 212, in data
    self._data = self.to_representation(self.instance)
  File "/usr/local/lib/python2.7/dist-packages/rest_framework/serializers.py", line 565, in to_representation
    self.child.to_representation(item) for item in iterable
  File "/usr/local/lib/python2.7/dist-packages/rest_framework/serializers.py", line 423, in to_representation
    attribute = field.get_attribute(instance)
  File "/usr/local/lib/python2.7/dist-packages/rest_framework/relations.py", line 103, in get_attribute
    return get_attribute(instance, self.source_attrs)
  File "/usr/local/lib/python2.7/dist-packages/rest_framework/fields.py", line 70, in get_attribute
    instance = getattr(instance, attr)
AttributeError: 'Sitio' object has no attribute 'categorias_ids'
Internal Server Error: /buscar/
Traceback (most recent call last):
  File "/usr/local/lib/python2.7/dist-packages/django/core/handlers/base.py", line 132, in get_response
    response = wrapped_callback(request, *callback_args, **callback_kwargs)
  File "/usr/local/lib/python2.7/dist-packages/django/views/decorators/csrf.py", line 58, in wrapped_view
    return view_func(*args, **kwargs)
  File "/usr/local/lib/python2.7/dist-packages/django/views/generic/base.py", line 71, in view
    return self.dispatch(request, *args, **kwargs)
  File "/usr/local/lib/python2.7/dist-packages/rest_framework/views.py", line 407, in dispatch
    response = self.handle_exception(exc)
  File "/usr/local/lib/python2.7/dist-packages/rest_framework/views.py", line 404, in dispatch
    response = handler(request, *args, **kwargs)
  File "/usr/local/lib/python2.7/dist-packages/rest_framework/generics.py", line 311, in get
    return self.list(request, *args, **kwargs)
  File "/usr/local/lib/python2.7/dist-packages/rest_framework/mixins.py", line 46, in list
    return Response(serializer.data)
  File "/usr/local/lib/python2.7/dist-packages/rest_framework/serializers.py", line 615, in data
    ret = super(ListSerializer, self).data
  File "/usr/local/lib/python2.7/dist-packages/rest_framework/serializers.py", line 212, in data
    self._data = self.to_representation(self.instance)
  File "/usr/local/lib/python2.7/dist-packages/rest_framework/serializers.py", line 565, in to_representation
    self.child.to_representation(item) for item in iterable
  File "/usr/local/lib/python2.7/dist-packages/rest_framework/serializers.py", line 423, in to_representation
    attribute = field.get_attribute(instance)
  File "/usr/local/lib/python2.7/dist-packages/rest_framework/relations.py", line 103, in get_attribute
    return get_attribute(instance, self.source_attrs)
  File "/usr/local/lib/python2.7/dist-packages/rest_framework/fields.py", line 70, in get_attribute
    instance = getattr(instance, attr)
AttributeError: 'Sitio' object has no attribute 'categorias_ids'
Internal Server Error: /buscar/
Traceback (most recent call last):
  File "/usr/local/lib/python2.7/dist-packages/django/core/handlers/base.py", line 132, in get_response
    response = wrapped_callback(request, *callback_args, **callback_kwargs)
  File "/usr/local/lib/python2.7/dist-packages/django/views/decorators/csrf.py", line 58, in wrapped_view
    return view_func(*args, **kwargs)
  File "/usr/local/lib/python2.7/dist-packages/django/views/generic/base.py", line 71, in view
    return self.dispatch(request, *args, **kwargs)
  File "/usr/local/lib/python2.7/dist-packages/rest_framework/views.py", line 407, in dispatch
    response = self.handle_exception(exc)
  File "/usr/local/lib/python2.7/dist-packages/rest_framework/views.py", line 404, in dispatch
    response = handler(request, *args, **kwargs)
  File "/usr/local/lib/python2.7/dist-packages/rest_framework/generics.py", line 311, in get
    return self.list(request, *args, **kwargs)
  File "/usr/local/lib/python2.7/dist-packages/rest_framework/mixins.py", line 46, in list
    return Response(serializer.data)
  File "/usr/local/lib/python2.7/dist-packages/rest_framework/serializers.py", line 615, in data
    ret = super(ListSerializer, self).data
  File "/usr/local/lib/python2.7/dist-packages/rest_framework/serializers.py", line 212, in data
    self._data = self.to_representation(self.instance)
  File "/usr/local/lib/python2.7/dist-packages/rest_framework/serializers.py", line 565, in to_representation
    self.child.to_representation(item) for item in iterable
  File "/usr/local/lib/python2.7/dist-packages/rest_framework/serializers.py", line 423, in to_representation
    attribute = field.get_attribute(instance)
  File "/usr/local/lib/python2.7/dist-packages/rest_framework/relations.py", line 103, in get_attribute
    return get_attribute(instance, self.source_attrs)
  File "/usr/local/lib/python2.7/dist-packages/rest_framework/fields.py", line 70, in get_attribute
    instance = getattr(instance, attr)
AttributeError: 'Sitio' object has no attribute 'categorias_ids'
Internal Server Error: /buscar/
Traceback (most recent call last):
  File "/usr/local/lib/python2.7/dist-packages/django/core/handlers/base.py", line 132, in get_response
    response = wrapped_callback(request, *callback_args, **callback_kwargs)
  File "/usr/local/lib/python2.7/dist-packages/django/views/decorators/csrf.py", line 58, in wrapped_view
    return view_func(*args, **kwargs)
  File "/usr/local/lib/python2.7/dist-packages/django/views/generic/base.py", line 71, in view
    return self.dispatch(request, *args, **kwargs)
  File "/usr/local/lib/python2.7/dist-packages/rest_framework/views.py", line 407, in dispatch
    response = self.handle_exception(exc)
  File "/usr/local/lib/python2.7/dist-packages/rest_framework/views.py", line 404, in dispatch
    response = handler(request, *args, **kwargs)
  File "/usr/local/lib/python2.7/dist-packages/rest_framework/generics.py", line 311, in get
    return self.list(request, *args, **kwargs)
  File "/usr/local/lib/python2.7/dist-packages/rest_framework/mixins.py", line 46, in list
    return Response(serializer.data)
  File "/usr/local/lib/python2.7/dist-packages/rest_framework/serializers.py", line 615, in data
    ret = super(ListSerializer, self).data
  File "/usr/local/lib/python2.7/dist-packages/rest_framework/serializers.py", line 212, in data
    self._data = self.to_representation(self.instance)
  File "/usr/local/lib/python2.7/dist-packages/rest_framework/serializers.py", line 565, in to_representation
    self.child.to_representation(item) for item in iterable
  File "/usr/local/lib/python2.7/dist-packages/rest_framework/serializers.py", line 423, in to_representation
    attribute = field.get_attribute(instance)
  File "/usr/local/lib/python2.7/dist-packages/rest_framework/relations.py", line 103, in get_attribute
    return get_attribute(instance, self.source_attrs)
  File "/usr/local/lib/python2.7/dist-packages/rest_framework/fields.py", line 70, in get_attribute
    instance = getattr(instance, attr)
AttributeError: 'Sitio' object has no attribute 'categorias_ids'
Internal Server Error: /buscar/
Traceback (most recent call last):
  File "/usr/local/lib/python2.7/dist-packages/django/core/handlers/base.py", line 132, in get_response
    response = wrapped_callback(request, *callback_args, **callback_kwargs)
  File "/usr/local/lib/python2.7/dist-packages/django/views/decorators/csrf.py", line 58, in wrapped_view
    return view_func(*args, **kwargs)
  File "/usr/local/lib/python2.7/dist-packages/django/views/generic/base.py", line 71, in view
    return self.dispatch(request, *args, **kwargs)
  File "/usr/local/lib/python2.7/dist-packages/rest_framework/views.py", line 407, in dispatch
    response = self.handle_exception(exc)
  File "/usr/local/lib/python2.7/dist-packages/rest_framework/views.py", line 404, in dispatch
    response = handler(request, *args, **kwargs)
  File "/usr/local/lib/python2.7/dist-packages/rest_framework/generics.py", line 311, in get
    return self.list(request, *args, **kwargs)
  File "/usr/local/lib/python2.7/dist-packages/rest_framework/mixins.py", line 46, in list
    return Response(serializer.data)
  File "/usr/local/lib/python2.7/dist-packages/rest_framework/serializers.py", line 615, in data
    ret = super(ListSerializer, self).data
  File "/usr/local/lib/python2.7/dist-packages/rest_framework/serializers.py", line 212, in data
    self._data = self.to_representation(self.instance)
  File "/usr/local/lib/python2.7/dist-packages/rest_framework/serializers.py", line 565, in to_representation
    self.child.to_representation(item) for item in iterable
  File "/usr/local/lib/python2.7/dist-packages/rest_framework/serializers.py", line 423, in to_representation
    attribute = field.get_attribute(instance)
  File "/usr/local/lib/python2.7/dist-packages/rest_framework/relations.py", line 103, in get_attribute
    return get_attribute(instance, self.source_attrs)
  File "/usr/local/lib/python2.7/dist-packages/rest_framework/fields.py", line 70, in get_attribute
    instance = getattr(instance, attr)
AttributeError: 'Sitio' object has no attribute 'categorias_ids'
Internal Server Error: /buscar/
Traceback (most recent call last):
  File "/usr/local/lib/python2.7/dist-packages/django/core/handlers/base.py", line 132, in get_response
    response = wrapped_callback(request, *callback_args, **callback_kwargs)
  File "/usr/local/lib/python2.7/dist-packages/django/views/decorators/csrf.py", line 58, in wrapped_view
    return view_func(*args, **kwargs)
  File "/usr/local/lib/python2.7/dist-packages/django/views/generic/base.py", line 71, in view
    return self.dispatch(request, *args, **kwargs)
  File "/usr/local/lib/python2.7/dist-packages/rest_framework/views.py", line 407, in dispatch
    response = self.handle_exception(exc)
  File "/usr/local/lib/python2.7/dist-packages/rest_framework/views.py", line 404, in dispatch
    response = handler(request, *args, **kwargs)
  File "/usr/local/lib/python2.7/dist-packages/rest_framework/generics.py", line 311, in get
    return self.list(request, *args, **kwargs)
  File "/usr/local/lib/python2.7/dist-packages/rest_framework/mixins.py", line 46, in list
    return Response(serializer.data)
  File "/usr/local/lib/python2.7/dist-packages/rest_framework/serializers.py", line 615, in data
    ret = super(ListSerializer, self).data
  File "/usr/local/lib/python2.7/dist-packages/rest_framework/serializers.py", line 212, in data
    self._data = self.to_representation(self.instance)
  File "/usr/local/lib/python2.7/dist-packages/rest_framework/serializers.py", line 565, in to_representation
    self.child.to_representation(item) for item in iterable
  File "/usr/local/lib/python2.7/dist-packages/rest_framework/serializers.py", line 423, in to_representation
    attribute = field.get_attribute(instance)
  File "/usr/local/lib/python2.7/dist-packages/rest_framework/relations.py", line 103, in get_attribute
    return get_attribute(instance, self.source_attrs)
  File "/usr/local/lib/python2.7/dist-packages/rest_framework/fields.py", line 70, in get_attribute
    instance = getattr(instance, attr)
AttributeError: 'Sitio' object has no attribute 'categorias_ids'
Internal Server Error: /buscar/
Traceback (most recent call last):
  File "/usr/local/lib/python2.7/dist-packages/django/core/handlers/base.py", line 132, in get_response
    response = wrapped_callback(request, *callback_args, **callback_kwargs)
  File "/usr/local/lib/python2.7/dist-packages/django/views/decorators/csrf.py", line 58, in wrapped_view
    return view_func(*args, **kwargs)
  File "/usr/local/lib/python2.7/dist-packages/django/views/generic/base.py", line 71, in view
    return self.dispatch(request, *args, **kwargs)
  File "/usr/local/lib/python2.7/dist-packages/rest_framework/views.py", line 407, in dispatch
    response = self.handle_exception(exc)
  File "/usr/local/lib/python2.7/dist-packages/rest_framework/views.py", line 404, in dispatch
    response = handler(request, *args, **kwargs)
  File "/usr/local/lib/python2.7/dist-packages/rest_framework/generics.py", line 311, in get
    return self.list(request, *args, **kwargs)
  File "/usr/local/lib/python2.7/dist-packages/rest_framework/mixins.py", line 46, in list
    return Response(serializer.data)
  File "/usr/local/lib/python2.7/dist-packages/rest_framework/serializers.py", line 615, in data
    ret = super(ListSerializer, self).data
  File "/usr/local/lib/python2.7/dist-packages/rest_framework/serializers.py", line 212, in data
    self._data = self.to_representation(self.instance)
  File "/usr/local/lib/python2.7/dist-packages/rest_framework/serializers.py", line 565, in to_representation
    self.child.to_representation(item) for item in iterable
  File "/usr/local/lib/python2.7/dist-packages/rest_framework/serializers.py", line 423, in to_representation
    attribute = field.get_attribute(instance)
  File "/usr/local/lib/python2.7/dist-packages/rest_framework/relations.py", line 103, in get_attribute
    return get_attribute(instance, self.source_attrs)
  File "/usr/local/lib/python2.7/dist-packages/rest_framework/fields.py", line 70, in get_attribute
    instance = getattr(instance, attr)
AttributeError: 'Sitio' object has no attribute 'categorias_ids'
Internal Server Error: /buscar/
Traceback (most recent call last):
  File "/usr/local/lib/python2.7/dist-packages/django/core/handlers/base.py", line 132, in get_response
    response = wrapped_callback(request, *callback_args, **callback_kwargs)
  File "/usr/local/lib/python2.7/dist-packages/django/views/decorators/csrf.py", line 58, in wrapped_view
    return view_func(*args, **kwargs)
  File "/usr/local/lib/python2.7/dist-packages/django/views/generic/base.py", line 71, in view
    return self.dispatch(request, *args, **kwargs)
  File "/usr/local/lib/python2.7/dist-packages/rest_framework/views.py", line 407, in dispatch
    response = self.handle_exception(exc)
  File "/usr/local/lib/python2.7/dist-packages/rest_framework/views.py", line 404, in dispatch
    response = handler(request, *args, **kwargs)
  File "/usr/local/lib/python2.7/dist-packages/rest_framework/generics.py", line 311, in get
    return self.list(request, *args, **kwargs)
  File "/usr/local/lib/python2.7/dist-packages/rest_framework/mixins.py", line 46, in list
    return Response(serializer.data)
  File "/usr/local/lib/python2.7/dist-packages/rest_framework/serializers.py", line 615, in data
    ret = super(ListSerializer, self).data
  File "/usr/local/lib/python2.7/dist-packages/rest_framework/serializers.py", line 212, in data
    self._data = self.to_representation(self.instance)
  File "/usr/local/lib/python2.7/dist-packages/rest_framework/serializers.py", line 565, in to_representation
    self.child.to_representation(item) for item in iterable
  File "/usr/local/lib/python2.7/dist-packages/rest_framework/serializers.py", line 423, in to_representation
    attribute = field.get_attribute(instance)
  File "/usr/local/lib/python2.7/dist-packages/rest_framework/relations.py", line 103, in get_attribute
    return get_attribute(instance, self.source_attrs)
  File "/usr/local/lib/python2.7/dist-packages/rest_framework/fields.py", line 70, in get_attribute
    instance = getattr(instance, attr)
AttributeError: 'Sitio' object has no attribute 'categorias_ids'
Internal Server Error: /buscar/
Traceback (most recent call last):
  File "/usr/local/lib/python2.7/dist-packages/django/core/handlers/base.py", line 132, in get_response
    response = wrapped_callback(request, *callback_args, **callback_kwargs)
  File "/usr/local/lib/python2.7/dist-packages/django/views/decorators/csrf.py", line 58, in wrapped_view
    return view_func(*args, **kwargs)
  File "/usr/local/lib/python2.7/dist-packages/django/views/generic/base.py", line 71, in view
    return self.dispatch(request, *args, **kwargs)
  File "/usr/local/lib/python2.7/dist-packages/rest_framework/views.py", line 407, in dispatch
    response = self.handle_exception(exc)
  File "/usr/local/lib/python2.7/dist-packages/rest_framework/views.py", line 404, in dispatch
    response = handler(request, *args, **kwargs)
  File "/usr/local/lib/python2.7/dist-packages/rest_framework/generics.py", line 311, in get
    return self.list(request, *args, **kwargs)
  File "/usr/local/lib/python2.7/dist-packages/rest_framework/mixins.py", line 46, in list
    return Response(serializer.data)
  File "/usr/local/lib/python2.7/dist-packages/rest_framework/serializers.py", line 615, in data
    ret = super(ListSerializer, self).data
  File "/usr/local/lib/python2.7/dist-packages/rest_framework/serializers.py", line 212, in data
    self._data = self.to_representation(self.instance)
  File "/usr/local/lib/python2.7/dist-packages/rest_framework/serializers.py", line 565, in to_representation
    self.child.to_representation(item) for item in iterable
  File "/usr/local/lib/python2.7/dist-packages/rest_framework/serializers.py", line 423, in to_representation
    attribute = field.get_attribute(instance)
  File "/usr/local/lib/python2.7/dist-packages/rest_framework/relations.py", line 103, in get_attribute
    return get_attribute(instance, self.source_attrs)
  File "/usr/local/lib/python2.7/dist-packages/rest_framework/fields.py", line 70, in get_attribute
    instance = getattr(instance, attr)
AttributeError: 'Sitio' object has no attribute 'categorias_ids'
Internal Server Error: /buscar/
Traceback (most recent call last):
  File "/usr/local/lib/python2.7/dist-packages/django/core/handlers/base.py", line 132, in get_response
    response = wrapped_callback(request, *callback_args, **callback_kwargs)
  File "/usr/local/lib/python2.7/dist-packages/django/views/decorators/csrf.py", line 58, in wrapped_view
    return view_func(*args, **kwargs)
  File "/usr/local/lib/python2.7/dist-packages/django/views/generic/base.py", line 71, in view
    return self.dispatch(request, *args, **kwargs)
  File "/usr/local/lib/python2.7/dist-packages/rest_framework/views.py", line 407, in dispatch
    response = self.handle_exception(exc)
  File "/usr/local/lib/python2.7/dist-packages/rest_framework/views.py", line 404, in dispatch
    response = handler(request, *args, **kwargs)
  File "/usr/local/lib/python2.7/dist-packages/rest_framework/generics.py", line 311, in get
    return self.list(request, *args, **kwargs)
  File "/usr/local/lib/python2.7/dist-packages/rest_framework/mixins.py", line 46, in list
    return Response(serializer.data)
  File "/usr/local/lib/python2.7/dist-packages/rest_framework/serializers.py", line 615, in data
    ret = super(ListSerializer, self).data
  File "/usr/local/lib/python2.7/dist-packages/rest_framework/serializers.py", line 212, in data
    self._data = self.to_representation(self.instance)
  File "/usr/local/lib/python2.7/dist-packages/rest_framework/serializers.py", line 565, in to_representation
    self.child.to_representation(item) for item in iterable
  File "/usr/local/lib/python2.7/dist-packages/rest_framework/serializers.py", line 423, in to_representation
    attribute = field.get_attribute(instance)
  File "/usr/local/lib/python2.7/dist-packages/rest_framework/relations.py", line 103, in get_attribute
    return get_attribute(instance, self.source_attrs)
  File "/usr/local/lib/python2.7/dist-packages/rest_framework/fields.py", line 70, in get_attribute
    instance = getattr(instance, attr)
AttributeError: 'Sitio' object has no attribute 'categorias_ids'
Internal Server Error: /buscar/
Traceback (most recent call last):
  File "/usr/local/lib/python2.7/dist-packages/django/core/handlers/base.py", line 132, in get_response
    response = wrapped_callback(request, *callback_args, **callback_kwargs)
  File "/usr/local/lib/python2.7/dist-packages/django/views/decorators/csrf.py", line 58, in wrapped_view
    return view_func(*args, **kwargs)
  File "/usr/local/lib/python2.7/dist-packages/django/views/generic/base.py", line 71, in view
    return self.dispatch(request, *args, **kwargs)
  File "/usr/local/lib/python2.7/dist-packages/rest_framework/views.py", line 407, in dispatch
    response = self.handle_exception(exc)
  File "/usr/local/lib/python2.7/dist-packages/rest_framework/views.py", line 404, in dispatch
    response = handler(request, *args, **kwargs)
  File "/usr/local/lib/python2.7/dist-packages/rest_framework/generics.py", line 311, in get
    return self.list(request, *args, **kwargs)
  File "/usr/local/lib/python2.7/dist-packages/rest_framework/mixins.py", line 46, in list
    return Response(serializer.data)
  File "/usr/local/lib/python2.7/dist-packages/rest_framework/serializers.py", line 615, in data
    ret = super(ListSerializer, self).data
  File "/usr/local/lib/python2.7/dist-packages/rest_framework/serializers.py", line 212, in data
    self._data = self.to_representation(self.instance)
  File "/usr/local/lib/python2.7/dist-packages/rest_framework/serializers.py", line 565, in to_representation
    self.child.to_representation(item) for item in iterable
  File "/usr/local/lib/python2.7/dist-packages/rest_framework/serializers.py", line 423, in to_representation
    attribute = field.get_attribute(instance)
  File "/usr/local/lib/python2.7/dist-packages/rest_framework/relations.py", line 103, in get_attribute
    return get_attribute(instance, self.source_attrs)
  File "/usr/local/lib/python2.7/dist-packages/rest_framework/fields.py", line 70, in get_attribute
    instance = getattr(instance, attr)
AttributeError: 'Sitio' object has no attribute 'categorias_ids'
Internal Server Error: /buscar/
Traceback (most recent call last):
  File "/usr/local/lib/python2.7/dist-packages/django/core/handlers/base.py", line 132, in get_response
    response = wrapped_callback(request, *callback_args, **callback_kwargs)
  File "/usr/local/lib/python2.7/dist-packages/django/views/decorators/csrf.py", line 58, in wrapped_view
    return view_func(*args, **kwargs)
  File "/usr/local/lib/python2.7/dist-packages/django/views/generic/base.py", line 71, in view
    return self.dispatch(request, *args, **kwargs)
  File "/usr/local/lib/python2.7/dist-packages/rest_framework/views.py", line 407, in dispatch
    response = self.handle_exception(exc)
  File "/usr/local/lib/python2.7/dist-packages/rest_framework/views.py", line 404, in dispatch
    response = handler(request, *args, **kwargs)
  File "/usr/local/lib/python2.7/dist-packages/rest_framework/generics.py", line 311, in get
    return self.list(request, *args, **kwargs)
  File "/usr/local/lib/python2.7/dist-packages/rest_framework/mixins.py", line 46, in list
    return Response(serializer.data)
  File "/usr/local/lib/python2.7/dist-packages/rest_framework/serializers.py", line 615, in data
    ret = super(ListSerializer, self).data
  File "/usr/local/lib/python2.7/dist-packages/rest_framework/serializers.py", line 212, in data
    self._data = self.to_representation(self.instance)
  File "/usr/local/lib/python2.7/dist-packages/rest_framework/serializers.py", line 565, in to_representation
    self.child.to_representation(item) for item in iterable
  File "/usr/local/lib/python2.7/dist-packages/rest_framework/serializers.py", line 423, in to_representation
    attribute = field.get_attribute(instance)
  File "/usr/local/lib/python2.7/dist-packages/rest_framework/relations.py", line 103, in get_attribute
    return get_attribute(instance, self.source_attrs)
  File "/usr/local/lib/python2.7/dist-packages/rest_framework/fields.py", line 70, in get_attribute
    instance = getattr(instance, attr)
AttributeError: 'Sitio' object has no attribute 'categorias_ids'
Internal Server Error: /buscar/
Traceback (most recent call last):
  File "/usr/local/lib/python2.7/dist-packages/django/core/handlers/base.py", line 132, in get_response
    response = wrapped_callback(request, *callback_args, **callback_kwargs)
  File "/usr/local/lib/python2.7/dist-packages/django/views/decorators/csrf.py", line 58, in wrapped_view
    return view_func(*args, **kwargs)
  File "/usr/local/lib/python2.7/dist-packages/django/views/generic/base.py", line 71, in view
    return self.dispatch(request, *args, **kwargs)
  File "/usr/local/lib/python2.7/dist-packages/rest_framework/views.py", line 407, in dispatch
    response = self.handle_exception(exc)
  File "/usr/local/lib/python2.7/dist-packages/rest_framework/views.py", line 404, in dispatch
    response = handler(request, *args, **kwargs)
  File "/usr/local/lib/python2.7/dist-packages/rest_framework/generics.py", line 311, in get
    return self.list(request, *args, **kwargs)
  File "/usr/local/lib/python2.7/dist-packages/rest_framework/mixins.py", line 46, in list
    return Response(serializer.data)
  File "/usr/local/lib/python2.7/dist-packages/rest_framework/serializers.py", line 615, in data
    ret = super(ListSerializer, self).data
  File "/usr/local/lib/python2.7/dist-packages/rest_framework/serializers.py", line 212, in data
    self._data = self.to_representation(self.instance)
  File "/usr/local/lib/python2.7/dist-packages/rest_framework/serializers.py", line 565, in to_representation
    self.child.to_representation(item) for item in iterable
  File "/usr/local/lib/python2.7/dist-packages/rest_framework/serializers.py", line 423, in to_representation
    attribute = field.get_attribute(instance)
  File "/usr/local/lib/python2.7/dist-packages/rest_framework/relations.py", line 103, in get_attribute
    return get_attribute(instance, self.source_attrs)
  File "/usr/local/lib/python2.7/dist-packages/rest_framework/fields.py", line 70, in get_attribute
    instance = getattr(instance, attr)
AttributeError: 'Sitio' object has no attribute 'categorias_ids'
Internal Server Error: /buscar/
Traceback (most recent call last):
  File "/usr/local/lib/python2.7/dist-packages/django/core/handlers/base.py", line 132, in get_response
    response = wrapped_callback(request, *callback_args, **callback_kwargs)
  File "/usr/local/lib/python2.7/dist-packages/django/views/decorators/csrf.py", line 58, in wrapped_view
    return view_func(*args, **kwargs)
  File "/usr/local/lib/python2.7/dist-packages/django/views/generic/base.py", line 71, in view
    return self.dispatch(request, *args, **kwargs)
  File "/usr/local/lib/python2.7/dist-packages/rest_framework/views.py", line 407, in dispatch
    response = self.handle_exception(exc)
  File "/usr/local/lib/python2.7/dist-packages/rest_framework/views.py", line 404, in dispatch
    response = handler(request, *args, **kwargs)
  File "/usr/local/lib/python2.7/dist-packages/rest_framework/generics.py", line 311, in get
    return self.list(request, *args, **kwargs)
  File "/usr/local/lib/python2.7/dist-packages/rest_framework/mixins.py", line 46, in list
    return Response(serializer.data)
  File "/usr/local/lib/python2.7/dist-packages/rest_framework/serializers.py", line 615, in data
    ret = super(ListSerializer, self).data
  File "/usr/local/lib/python2.7/dist-packages/rest_framework/serializers.py", line 212, in data
    self._data = self.to_representation(self.instance)
  File "/usr/local/lib/python2.7/dist-packages/rest_framework/serializers.py", line 565, in to_representation
    self.child.to_representation(item) for item in iterable
  File "/usr/local/lib/python2.7/dist-packages/rest_framework/serializers.py", line 423, in to_representation
    attribute = field.get_attribute(instance)
  File "/usr/local/lib/python2.7/dist-packages/rest_framework/relations.py", line 103, in get_attribute
    return get_attribute(instance, self.source_attrs)
  File "/usr/local/lib/python2.7/dist-packages/rest_framework/fields.py", line 70, in get_attribute
    instance = getattr(instance, attr)
AttributeError: 'Sitio' object has no attribute 'categorias_ids'
Internal Server Error: /sitio
Traceback (most recent call last):
  File "/usr/local/lib/python2.7/dist-packages/django/core/handlers/base.py", line 132, in get_response
    response = wrapped_callback(request, *callback_args, **callback_kwargs)
  File "/usr/local/lib/python2.7/dist-packages/django/views/decorators/csrf.py", line 58, in wrapped_view
    return view_func(*args, **kwargs)
  File "/usr/local/lib/python2.7/dist-packages/django/views/generic/base.py", line 71, in view
    return self.dispatch(request, *args, **kwargs)
  File "/usr/local/lib/python2.7/dist-packages/rest_framework/views.py", line 407, in dispatch
    response = self.handle_exception(exc)
  File "/usr/local/lib/python2.7/dist-packages/rest_framework/views.py", line 404, in dispatch
    response = handler(request, *args, **kwargs)
  File "/usr/local/lib/python2.7/dist-packages/rest_framework/generics.py", line 314, in post
    return self.create(request, *args, **kwargs)
  File "/home/camilo/Documents/BackEnd/sitios/views.py", line 58, in create
    serializer.add_photos_with_abbreviations(photos)
  File "/home/camilo/Documents/BackEnd/sitios/serializers.py", line 79, in add_photos_with_abbreviations
    sitio_id=self.data["id"],
  File "/usr/local/lib/python2.7/dist-packages/rest_framework/serializers.py", line 463, in data
    ret = super(Serializer, self).data
  File "/usr/local/lib/python2.7/dist-packages/rest_framework/serializers.py", line 212, in data
    self._data = self.to_representation(self.instance)
  File "/usr/local/lib/python2.7/dist-packages/rest_framework/serializers.py", line 423, in to_representation
    attribute = field.get_attribute(instance)
  File "/usr/local/lib/python2.7/dist-packages/rest_framework/relations.py", line 103, in get_attribute
    return get_attribute(instance, self.source_attrs)
  File "/usr/local/lib/python2.7/dist-packages/rest_framework/fields.py", line 70, in get_attribute
    instance = getattr(instance, attr)
AttributeError: 'Sitio' object has no attribute 'categorias_ids'
Internal Server Error: /sitio/detail/1
Traceback (most recent call last):
  File "/usr/local/lib/python2.7/dist-packages/django/core/handlers/base.py", line 132, in get_response
    response = wrapped_callback(request, *callback_args, **callback_kwargs)
  File "/usr/local/lib/python2.7/dist-packages/django/views/decorators/csrf.py", line 58, in wrapped_view
    return view_func(*args, **kwargs)
  File "/usr/local/lib/python2.7/dist-packages/django/views/generic/base.py", line 71, in view
    return self.dispatch(request, *args, **kwargs)
  File "/usr/local/lib/python2.7/dist-packages/rest_framework/views.py", line 407, in dispatch
    response = self.handle_exception(exc)
  File "/usr/local/lib/python2.7/dist-packages/rest_framework/views.py", line 404, in dispatch
    response = handler(request, *args, **kwargs)
  File "/usr/local/lib/python2.7/dist-packages/rest_framework/generics.py", line 357, in put
    return self.update(request, *args, **kwargs)
  File "/home/camilo/Documents/BackEnd/sitios/views.py", line 80, in update
    return Response(serializer.data)
  File "/usr/local/lib/python2.7/dist-packages/rest_framework/serializers.py", line 463, in data
    ret = super(Serializer, self).data
  File "/usr/local/lib/python2.7/dist-packages/rest_framework/serializers.py", line 212, in data
    self._data = self.to_representation(self.instance)
  File "/usr/local/lib/python2.7/dist-packages/rest_framework/serializers.py", line 423, in to_representation
    attribute = field.get_attribute(instance)
  File "/usr/local/lib/python2.7/dist-packages/rest_framework/relations.py", line 103, in get_attribute
    return get_attribute(instance, self.source_attrs)
  File "/usr/local/lib/python2.7/dist-packages/rest_framework/fields.py", line 70, in get_attribute
    instance = getattr(instance, attr)
AttributeError: 'Sitio' object has no attribute 'categorias_ids'
Internal Server Error: /sitio/detail/1
Traceback (most recent call last):
  File "/usr/local/lib/python2.7/dist-packages/django/core/handlers/base.py", line 132, in get_response
    response = wrapped_callback(request, *callback_args, **callback_kwargs)
  File "/usr/local/lib/python2.7/dist-packages/django/views/decorators/csrf.py", line 58, in wrapped_view
    return view_func(*args, **kwargs)
  File "/usr/local/lib/python2.7/dist-packages/django/views/generic/base.py", line 71, in view
    return self.dispatch(request, *args, **kwargs)
  File "/usr/local/lib/python2.7/dist-packages/rest_framework/views.py", line 407, in dispatch
    response = self.handle_exception(exc)
  File "/usr/local/lib/python2.7/dist-packages/rest_framework/views.py", line 404, in dispatch
    response = handler(request, *args, **kwargs)
  File "/usr/local/lib/python2.7/dist-packages/rest_framework/generics.py", line 357, in put
    return self.update(request, *args, **kwargs)
  File "/home/camilo/Documents/BackEnd/sitios/views.py", line 77, in update
    serializer.add_photos_with_abbreviations(photos)
  File "/home/camilo/Documents/BackEnd/sitios/serializers.py", line 79, in add_photos_with_abbreviations
    sitio_id=self.data["id"],
  File "/usr/local/lib/python2.7/dist-packages/rest_framework/serializers.py", line 463, in data
    ret = super(Serializer, self).data
  File "/usr/local/lib/python2.7/dist-packages/rest_framework/serializers.py", line 212, in data
    self._data = self.to_representation(self.instance)
  File "/usr/local/lib/python2.7/dist-packages/rest_framework/serializers.py", line 423, in to_representation
    attribute = field.get_attribute(instance)
  File "/usr/local/lib/python2.7/dist-packages/rest_framework/relations.py", line 103, in get_attribute
    return get_attribute(instance, self.source_attrs)
  File "/usr/local/lib/python2.7/dist-packages/rest_framework/fields.py", line 70, in get_attribute
    instance = getattr(instance, attr)
AttributeError: 'Sitio' object has no attribute 'categorias_ids'
Internal Server Error: /sitio/detail/1
Traceback (most recent call last):
  File "/usr/local/lib/python2.7/dist-packages/django/core/handlers/base.py", line 132, in get_response
    response = wrapped_callback(request, *callback_args, **callback_kwargs)
  File "/usr/local/lib/python2.7/dist-packages/django/views/decorators/csrf.py", line 58, in wrapped_view
    return view_func(*args, **kwargs)
  File "/usr/local/lib/python2.7/dist-packages/django/views/generic/base.py", line 71, in view
    return self.dispatch(request, *args, **kwargs)
  File "/usr/local/lib/python2.7/dist-packages/rest_framework/views.py", line 407, in dispatch
    response = self.handle_exception(exc)
  File "/usr/local/lib/python2.7/dist-packages/rest_framework/views.py", line 404, in dispatch
    response = handler(request, *args, **kwargs)
  File "/usr/local/lib/python2.7/dist-packages/rest_framework/generics.py", line 357, in put
    return self.update(request, *args, **kwargs)
  File "/home/camilo/Documents/BackEnd/sitios/views.py", line 77, in update
    serializer.add_photos_with_abbreviations(photos)
  File "/home/camilo/Documents/BackEnd/sitios/serializers.py", line 79, in add_photos_with_abbreviations
    sitio_id=self.data["id"],
  File "/usr/local/lib/python2.7/dist-packages/rest_framework/serializers.py", line 463, in data
    ret = super(Serializer, self).data
  File "/usr/local/lib/python2.7/dist-packages/rest_framework/serializers.py", line 212, in data
    self._data = self.to_representation(self.instance)
  File "/usr/local/lib/python2.7/dist-packages/rest_framework/serializers.py", line 423, in to_representation
    attribute = field.get_attribute(instance)
  File "/usr/local/lib/python2.7/dist-packages/rest_framework/relations.py", line 103, in get_attribute
    return get_attribute(instance, self.source_attrs)
  File "/usr/local/lib/python2.7/dist-packages/rest_framework/fields.py", line 70, in get_attribute
    instance = getattr(instance, attr)
AttributeError: 'Sitio' object has no attribute 'categorias_ids'
Internal Server Error: /rest-auth/login
Traceback (most recent call last):
  File "/usr/local/lib/python2.7/dist-packages/django/core/handlers/base.py", line 108, in get_response
    response = middleware_method(request)
  File "/usr/local/lib/python2.7/dist-packages/django/middleware/common.py", line 74, in process_request
    if (not urlresolvers.is_valid_path(request.path_info, urlconf) and
  File "/usr/local/lib/python2.7/dist-packages/django/core/urlresolvers.py", line 647, in is_valid_path
    resolve(path, urlconf)
  File "/usr/local/lib/python2.7/dist-packages/django/core/urlresolvers.py", line 522, in resolve
    return get_resolver(urlconf).resolve(path)
  File "/usr/local/lib/python2.7/dist-packages/django/core/urlresolvers.py", line 366, in resolve
    for pattern in self.url_patterns:
  File "/usr/local/lib/python2.7/dist-packages/django/core/urlresolvers.py", line 402, in url_patterns
    patterns = getattr(self.urlconf_module, "urlpatterns", self.urlconf_module)
  File "/usr/local/lib/python2.7/dist-packages/django/core/urlresolvers.py", line 396, in urlconf_module
    self._urlconf_module = import_module(self.urlconf_name)
  File "/usr/lib/python2.7/importlib/__init__.py", line 37, in import_module
    __import__(name)
  File "/home/camilo/Documents/BackEnd/turismo/urls.py", line 4, in <module>
    from plataforma import views
  File "/home/camilo/Documents/BackEnd/plataforma/views.py", line 5, in <module>
    from plataforma.serializers import *
  File "/home/camilo/Documents/BackEnd/plataforma/serializers.py", line 9, in <module>
    from sitios.serializers import SitioSerializer
  File "/home/camilo/Documents/BackEnd/sitios/serializers.py", line 23, in <module>
    class SitioSerializer(serializers.ModelSerializer):
  File "/home/camilo/Documents/BackEnd/sitios/serializers.py", line 29, in SitioSerializer
    queryset=Categoria.objects.all(), required=False)
  File "/usr/local/lib/python2.7/dist-packages/rest_framework/fields.py", line 667, in __init__
    super(IntegerField, self).__init__(**kwargs)
TypeError: __init__() got an unexpected keyword argument 'queryset'
Internal Server Error: /rest-auth/login
Traceback (most recent call last):
  File "/usr/local/lib/python2.7/dist-packages/django/core/handlers/base.py", line 108, in get_response
    response = middleware_method(request)
  File "/usr/local/lib/python2.7/dist-packages/django/middleware/common.py", line 74, in process_request
    if (not urlresolvers.is_valid_path(request.path_info, urlconf) and
  File "/usr/local/lib/python2.7/dist-packages/django/core/urlresolvers.py", line 647, in is_valid_path
    resolve(path, urlconf)
  File "/usr/local/lib/python2.7/dist-packages/django/core/urlresolvers.py", line 522, in resolve
    return get_resolver(urlconf).resolve(path)
  File "/usr/local/lib/python2.7/dist-packages/django/core/urlresolvers.py", line 366, in resolve
    for pattern in self.url_patterns:
  File "/usr/local/lib/python2.7/dist-packages/django/core/urlresolvers.py", line 402, in url_patterns
    patterns = getattr(self.urlconf_module, "urlpatterns", self.urlconf_module)
  File "/usr/local/lib/python2.7/dist-packages/django/core/urlresolvers.py", line 396, in urlconf_module
    self._urlconf_module = import_module(self.urlconf_name)
  File "/usr/lib/python2.7/importlib/__init__.py", line 37, in import_module
    __import__(name)
  File "/home/camilo/Documents/BackEnd/turismo/urls.py", line 4, in <module>
    from plataforma import views
  File "/home/camilo/Documents/BackEnd/plataforma/views.py", line 5, in <module>
    from plataforma.serializers import *
  File "/home/camilo/Documents/BackEnd/plataforma/serializers.py", line 9, in <module>
    from sitios.serializers import SitioSerializer
  File "/home/camilo/Documents/BackEnd/sitios/serializers.py", line 23, in <module>
    class SitioSerializer(serializers.ModelSerializer):
  File "/home/camilo/Documents/BackEnd/sitios/serializers.py", line 29, in SitioSerializer
    queryset=Categoria.objects.all(), required=False)
  File "/usr/local/lib/python2.7/dist-packages/rest_framework/fields.py", line 667, in __init__
    super(IntegerField, self).__init__(**kwargs)
TypeError: __init__() got an unexpected keyword argument 'queryset'
Internal Server Error: /buscar/
Traceback (most recent call last):
  File "/usr/local/lib/python2.7/dist-packages/django/core/handlers/base.py", line 132, in get_response
    response = wrapped_callback(request, *callback_args, **callback_kwargs)
  File "/usr/local/lib/python2.7/dist-packages/django/views/decorators/csrf.py", line 58, in wrapped_view
    return view_func(*args, **kwargs)
  File "/usr/local/lib/python2.7/dist-packages/django/views/generic/base.py", line 71, in view
    return self.dispatch(request, *args, **kwargs)
  File "/usr/local/lib/python2.7/dist-packages/rest_framework/views.py", line 407, in dispatch
    response = self.handle_exception(exc)
  File "/usr/local/lib/python2.7/dist-packages/rest_framework/views.py", line 404, in dispatch
    response = handler(request, *args, **kwargs)
  File "/usr/local/lib/python2.7/dist-packages/rest_framework/generics.py", line 311, in get
    return self.list(request, *args, **kwargs)
  File "/usr/local/lib/python2.7/dist-packages/rest_framework/mixins.py", line 46, in list
    return Response(serializer.data)
  File "/usr/local/lib/python2.7/dist-packages/rest_framework/serializers.py", line 615, in data
    ret = super(ListSerializer, self).data
  File "/usr/local/lib/python2.7/dist-packages/rest_framework/serializers.py", line 212, in data
    self._data = self.to_representation(self.instance)
  File "/usr/local/lib/python2.7/dist-packages/rest_framework/serializers.py", line 565, in to_representation
    self.child.to_representation(item) for item in iterable
  File "/usr/local/lib/python2.7/dist-packages/rest_framework/serializers.py", line 432, in to_representation
    ret[field.field_name] = field.to_representation(attribute)
  File "/usr/local/lib/python2.7/dist-packages/rest_framework/fields.py", line 686, in to_representation
    return int(value)
TypeError: int() argument must be a string or a number, not 'ManyRelatedManager'
Internal Server Error: /buscar/
Traceback (most recent call last):
  File "/usr/local/lib/python2.7/dist-packages/django/core/handlers/base.py", line 132, in get_response
    response = wrapped_callback(request, *callback_args, **callback_kwargs)
  File "/usr/local/lib/python2.7/dist-packages/django/views/decorators/csrf.py", line 58, in wrapped_view
    return view_func(*args, **kwargs)
  File "/usr/local/lib/python2.7/dist-packages/django/views/generic/base.py", line 71, in view
    return self.dispatch(request, *args, **kwargs)
  File "/usr/local/lib/python2.7/dist-packages/rest_framework/views.py", line 407, in dispatch
    response = self.handle_exception(exc)
  File "/usr/local/lib/python2.7/dist-packages/rest_framework/views.py", line 404, in dispatch
    response = handler(request, *args, **kwargs)
  File "/usr/local/lib/python2.7/dist-packages/rest_framework/generics.py", line 311, in get
    return self.list(request, *args, **kwargs)
  File "/usr/local/lib/python2.7/dist-packages/rest_framework/mixins.py", line 46, in list
    return Response(serializer.data)
  File "/usr/local/lib/python2.7/dist-packages/rest_framework/serializers.py", line 615, in data
    ret = super(ListSerializer, self).data
  File "/usr/local/lib/python2.7/dist-packages/rest_framework/serializers.py", line 212, in data
    self._data = self.to_representation(self.instance)
  File "/usr/local/lib/python2.7/dist-packages/rest_framework/serializers.py", line 565, in to_representation
    self.child.to_representation(item) for item in iterable
  File "/usr/local/lib/python2.7/dist-packages/rest_framework/serializers.py", line 432, in to_representation
    ret[field.field_name] = field.to_representation(attribute)
  File "/usr/local/lib/python2.7/dist-packages/rest_framework/fields.py", line 686, in to_representation
    return int(value)
TypeError: int() argument must be a string or a number, not 'ManyRelatedManager'
Internal Server Error: /buscar/
Traceback (most recent call last):
  File "/usr/local/lib/python2.7/dist-packages/django/core/handlers/base.py", line 132, in get_response
    response = wrapped_callback(request, *callback_args, **callback_kwargs)
  File "/usr/local/lib/python2.7/dist-packages/django/views/decorators/csrf.py", line 58, in wrapped_view
    return view_func(*args, **kwargs)
  File "/usr/local/lib/python2.7/dist-packages/django/views/generic/base.py", line 71, in view
    return self.dispatch(request, *args, **kwargs)
  File "/usr/local/lib/python2.7/dist-packages/rest_framework/views.py", line 407, in dispatch
    response = self.handle_exception(exc)
  File "/usr/local/lib/python2.7/dist-packages/rest_framework/views.py", line 404, in dispatch
    response = handler(request, *args, **kwargs)
  File "/usr/local/lib/python2.7/dist-packages/rest_framework/generics.py", line 311, in get
    return self.list(request, *args, **kwargs)
  File "/usr/local/lib/python2.7/dist-packages/rest_framework/mixins.py", line 46, in list
    return Response(serializer.data)
  File "/usr/local/lib/python2.7/dist-packages/rest_framework/serializers.py", line 615, in data
    ret = super(ListSerializer, self).data
  File "/usr/local/lib/python2.7/dist-packages/rest_framework/serializers.py", line 212, in data
    self._data = self.to_representation(self.instance)
  File "/usr/local/lib/python2.7/dist-packages/rest_framework/serializers.py", line 565, in to_representation
    self.child.to_representation(item) for item in iterable
  File "/usr/local/lib/python2.7/dist-packages/rest_framework/serializers.py", line 432, in to_representation
    ret[field.field_name] = field.to_representation(attribute)
  File "/usr/local/lib/python2.7/dist-packages/rest_framework/fields.py", line 686, in to_representation
    return int(value)
TypeError: int() argument must be a string or a number, not 'ManyRelatedManager'
Internal Server Error: /buscar/
Traceback (most recent call last):
  File "/usr/local/lib/python2.7/dist-packages/django/core/handlers/base.py", line 132, in get_response
    response = wrapped_callback(request, *callback_args, **callback_kwargs)
  File "/usr/local/lib/python2.7/dist-packages/django/views/decorators/csrf.py", line 58, in wrapped_view
    return view_func(*args, **kwargs)
  File "/usr/local/lib/python2.7/dist-packages/django/views/generic/base.py", line 71, in view
    return self.dispatch(request, *args, **kwargs)
  File "/usr/local/lib/python2.7/dist-packages/rest_framework/views.py", line 407, in dispatch
    response = self.handle_exception(exc)
  File "/usr/local/lib/python2.7/dist-packages/rest_framework/views.py", line 404, in dispatch
    response = handler(request, *args, **kwargs)
  File "/usr/local/lib/python2.7/dist-packages/rest_framework/generics.py", line 311, in get
    return self.list(request, *args, **kwargs)
  File "/usr/local/lib/python2.7/dist-packages/rest_framework/mixins.py", line 46, in list
    return Response(serializer.data)
  File "/usr/local/lib/python2.7/dist-packages/rest_framework/serializers.py", line 615, in data
    ret = super(ListSerializer, self).data
  File "/usr/local/lib/python2.7/dist-packages/rest_framework/serializers.py", line 212, in data
    self._data = self.to_representation(self.instance)
  File "/usr/local/lib/python2.7/dist-packages/rest_framework/serializers.py", line 565, in to_representation
    self.child.to_representation(item) for item in iterable
  File "/usr/local/lib/python2.7/dist-packages/rest_framework/serializers.py", line 432, in to_representation
    ret[field.field_name] = field.to_representation(attribute)
  File "/usr/local/lib/python2.7/dist-packages/rest_framework/fields.py", line 686, in to_representation
    return int(value)
TypeError: int() argument must be a string or a number, not 'ManyRelatedManager'
Internal Server Error: /buscar/
Traceback (most recent call last):
  File "/usr/local/lib/python2.7/dist-packages/django/core/handlers/base.py", line 132, in get_response
    response = wrapped_callback(request, *callback_args, **callback_kwargs)
  File "/usr/local/lib/python2.7/dist-packages/django/views/decorators/csrf.py", line 58, in wrapped_view
    return view_func(*args, **kwargs)
  File "/usr/local/lib/python2.7/dist-packages/django/views/generic/base.py", line 71, in view
    return self.dispatch(request, *args, **kwargs)
  File "/usr/local/lib/python2.7/dist-packages/rest_framework/views.py", line 407, in dispatch
    response = self.handle_exception(exc)
  File "/usr/local/lib/python2.7/dist-packages/rest_framework/views.py", line 404, in dispatch
    response = handler(request, *args, **kwargs)
  File "/usr/local/lib/python2.7/dist-packages/rest_framework/generics.py", line 311, in get
    return self.list(request, *args, **kwargs)
  File "/usr/local/lib/python2.7/dist-packages/rest_framework/mixins.py", line 46, in list
    return Response(serializer.data)
  File "/usr/local/lib/python2.7/dist-packages/rest_framework/serializers.py", line 615, in data
    ret = super(ListSerializer, self).data
  File "/usr/local/lib/python2.7/dist-packages/rest_framework/serializers.py", line 212, in data
    self._data = self.to_representation(self.instance)
  File "/usr/local/lib/python2.7/dist-packages/rest_framework/serializers.py", line 565, in to_representation
    self.child.to_representation(item) for item in iterable
  File "/usr/local/lib/python2.7/dist-packages/rest_framework/serializers.py", line 432, in to_representation
    ret[field.field_name] = field.to_representation(attribute)
  File "/usr/local/lib/python2.7/dist-packages/rest_framework/fields.py", line 686, in to_representation
    return int(value)
TypeError: int() argument must be a string or a number, not 'ManyRelatedManager'
Internal Server Error: /buscar/
Traceback (most recent call last):
  File "/usr/local/lib/python2.7/dist-packages/django/core/handlers/base.py", line 132, in get_response
    response = wrapped_callback(request, *callback_args, **callback_kwargs)
  File "/usr/local/lib/python2.7/dist-packages/django/views/decorators/csrf.py", line 58, in wrapped_view
    return view_func(*args, **kwargs)
  File "/usr/local/lib/python2.7/dist-packages/django/views/generic/base.py", line 71, in view
    return self.dispatch(request, *args, **kwargs)
  File "/usr/local/lib/python2.7/dist-packages/rest_framework/views.py", line 407, in dispatch
    response = self.handle_exception(exc)
  File "/usr/local/lib/python2.7/dist-packages/rest_framework/views.py", line 404, in dispatch
    response = handler(request, *args, **kwargs)
  File "/usr/local/lib/python2.7/dist-packages/rest_framework/generics.py", line 311, in get
    return self.list(request, *args, **kwargs)
  File "/usr/local/lib/python2.7/dist-packages/rest_framework/mixins.py", line 46, in list
    return Response(serializer.data)
  File "/usr/local/lib/python2.7/dist-packages/rest_framework/serializers.py", line 615, in data
    ret = super(ListSerializer, self).data
  File "/usr/local/lib/python2.7/dist-packages/rest_framework/serializers.py", line 212, in data
    self._data = self.to_representation(self.instance)
  File "/usr/local/lib/python2.7/dist-packages/rest_framework/serializers.py", line 565, in to_representation
    self.child.to_representation(item) for item in iterable
  File "/usr/local/lib/python2.7/dist-packages/rest_framework/serializers.py", line 432, in to_representation
    ret[field.field_name] = field.to_representation(attribute)
  File "/usr/local/lib/python2.7/dist-packages/rest_framework/fields.py", line 686, in to_representation
    return int(value)
TypeError: int() argument must be a string or a number, not 'ManyRelatedManager'
Internal Server Error: /buscar/
Traceback (most recent call last):
  File "/usr/local/lib/python2.7/dist-packages/django/core/handlers/base.py", line 132, in get_response
    response = wrapped_callback(request, *callback_args, **callback_kwargs)
  File "/usr/local/lib/python2.7/dist-packages/django/views/decorators/csrf.py", line 58, in wrapped_view
    return view_func(*args, **kwargs)
  File "/usr/local/lib/python2.7/dist-packages/django/views/generic/base.py", line 71, in view
    return self.dispatch(request, *args, **kwargs)
  File "/usr/local/lib/python2.7/dist-packages/rest_framework/views.py", line 407, in dispatch
    response = self.handle_exception(exc)
  File "/usr/local/lib/python2.7/dist-packages/rest_framework/views.py", line 404, in dispatch
    response = handler(request, *args, **kwargs)
  File "/usr/local/lib/python2.7/dist-packages/rest_framework/generics.py", line 311, in get
    return self.list(request, *args, **kwargs)
  File "/usr/local/lib/python2.7/dist-packages/rest_framework/mixins.py", line 46, in list
    return Response(serializer.data)
  File "/usr/local/lib/python2.7/dist-packages/rest_framework/serializers.py", line 615, in data
    ret = super(ListSerializer, self).data
  File "/usr/local/lib/python2.7/dist-packages/rest_framework/serializers.py", line 212, in data
    self._data = self.to_representation(self.instance)
  File "/usr/local/lib/python2.7/dist-packages/rest_framework/serializers.py", line 565, in to_representation
    self.child.to_representation(item) for item in iterable
  File "/usr/local/lib/python2.7/dist-packages/rest_framework/serializers.py", line 432, in to_representation
    ret[field.field_name] = field.to_representation(attribute)
  File "/usr/local/lib/python2.7/dist-packages/rest_framework/fields.py", line 686, in to_representation
    return int(value)
TypeError: int() argument must be a string or a number, not 'ManyRelatedManager'
Internal Server Error: /sitio
Traceback (most recent call last):
  File "/usr/local/lib/python2.7/dist-packages/django/core/handlers/base.py", line 132, in get_response
    response = wrapped_callback(request, *callback_args, **callback_kwargs)
  File "/usr/local/lib/python2.7/dist-packages/django/views/decorators/csrf.py", line 58, in wrapped_view
    return view_func(*args, **kwargs)
  File "/usr/local/lib/python2.7/dist-packages/django/views/generic/base.py", line 71, in view
    return self.dispatch(request, *args, **kwargs)
  File "/usr/local/lib/python2.7/dist-packages/rest_framework/views.py", line 407, in dispatch
    response = self.handle_exception(exc)
  File "/usr/local/lib/python2.7/dist-packages/rest_framework/views.py", line 404, in dispatch
    response = handler(request, *args, **kwargs)
  File "/usr/local/lib/python2.7/dist-packages/rest_framework/generics.py", line 314, in post
    return self.create(request, *args, **kwargs)
  File "/home/camilo/Documents/BackEnd/sitios/views.py", line 58, in create
    serializer.add_photos_with_abbreviations(photos)
  File "/home/camilo/Documents/BackEnd/sitios/serializers.py", line 79, in add_photos_with_abbreviations
    sitio_id=self.data["id"],
  File "/usr/local/lib/python2.7/dist-packages/rest_framework/serializers.py", line 463, in data
    ret = super(Serializer, self).data
  File "/usr/local/lib/python2.7/dist-packages/rest_framework/serializers.py", line 212, in data
    self._data = self.to_representation(self.instance)
  File "/usr/local/lib/python2.7/dist-packages/rest_framework/serializers.py", line 432, in to_representation
    ret[field.field_name] = field.to_representation(attribute)
  File "/usr/local/lib/python2.7/dist-packages/rest_framework/fields.py", line 686, in to_representation
    return int(value)
TypeError: int() argument must be a string or a number, not 'ManyRelatedManager'
Internal Server Error: /sitio/detail/1
Traceback (most recent call last):
  File "/usr/local/lib/python2.7/dist-packages/django/core/handlers/base.py", line 132, in get_response
    response = wrapped_callback(request, *callback_args, **callback_kwargs)
  File "/usr/local/lib/python2.7/dist-packages/django/views/decorators/csrf.py", line 58, in wrapped_view
    return view_func(*args, **kwargs)
  File "/usr/local/lib/python2.7/dist-packages/django/views/generic/base.py", line 71, in view
    return self.dispatch(request, *args, **kwargs)
  File "/usr/local/lib/python2.7/dist-packages/rest_framework/views.py", line 407, in dispatch
    response = self.handle_exception(exc)
  File "/usr/local/lib/python2.7/dist-packages/rest_framework/views.py", line 404, in dispatch
    response = handler(request, *args, **kwargs)
  File "/usr/local/lib/python2.7/dist-packages/rest_framework/generics.py", line 357, in put
    return self.update(request, *args, **kwargs)
  File "/home/camilo/Documents/BackEnd/sitios/views.py", line 80, in update
    return Response(serializer.data)
  File "/usr/local/lib/python2.7/dist-packages/rest_framework/serializers.py", line 463, in data
    ret = super(Serializer, self).data
  File "/usr/local/lib/python2.7/dist-packages/rest_framework/serializers.py", line 212, in data
    self._data = self.to_representation(self.instance)
  File "/usr/local/lib/python2.7/dist-packages/rest_framework/serializers.py", line 432, in to_representation
    ret[field.field_name] = field.to_representation(attribute)
  File "/usr/local/lib/python2.7/dist-packages/rest_framework/fields.py", line 686, in to_representation
    return int(value)
TypeError: int() argument must be a string or a number, not 'ManyRelatedManager'
Internal Server Error: /sitio/detail/1
Traceback (most recent call last):
  File "/usr/local/lib/python2.7/dist-packages/django/core/handlers/base.py", line 132, in get_response
    response = wrapped_callback(request, *callback_args, **callback_kwargs)
  File "/usr/local/lib/python2.7/dist-packages/django/views/decorators/csrf.py", line 58, in wrapped_view
    return view_func(*args, **kwargs)
  File "/usr/local/lib/python2.7/dist-packages/django/views/generic/base.py", line 71, in view
    return self.dispatch(request, *args, **kwargs)
  File "/usr/local/lib/python2.7/dist-packages/rest_framework/views.py", line 407, in dispatch
    response = self.handle_exception(exc)
  File "/usr/local/lib/python2.7/dist-packages/rest_framework/views.py", line 404, in dispatch
    response = handler(request, *args, **kwargs)
  File "/usr/local/lib/python2.7/dist-packages/rest_framework/generics.py", line 357, in put
    return self.update(request, *args, **kwargs)
  File "/home/camilo/Documents/BackEnd/sitios/views.py", line 77, in update
    serializer.add_photos_with_abbreviations(photos)
  File "/home/camilo/Documents/BackEnd/sitios/serializers.py", line 79, in add_photos_with_abbreviations
    sitio_id=self.data["id"],
  File "/usr/local/lib/python2.7/dist-packages/rest_framework/serializers.py", line 463, in data
    ret = super(Serializer, self).data
  File "/usr/local/lib/python2.7/dist-packages/rest_framework/serializers.py", line 212, in data
    self._data = self.to_representation(self.instance)
  File "/usr/local/lib/python2.7/dist-packages/rest_framework/serializers.py", line 432, in to_representation
    ret[field.field_name] = field.to_representation(attribute)
  File "/usr/local/lib/python2.7/dist-packages/rest_framework/fields.py", line 686, in to_representation
    return int(value)
TypeError: int() argument must be a string or a number, not 'ManyRelatedManager'
Internal Server Error: /sitio/detail/1
Traceback (most recent call last):
  File "/usr/local/lib/python2.7/dist-packages/django/core/handlers/base.py", line 132, in get_response
    response = wrapped_callback(request, *callback_args, **callback_kwargs)
  File "/usr/local/lib/python2.7/dist-packages/django/views/decorators/csrf.py", line 58, in wrapped_view
    return view_func(*args, **kwargs)
  File "/usr/local/lib/python2.7/dist-packages/django/views/generic/base.py", line 71, in view
    return self.dispatch(request, *args, **kwargs)
  File "/usr/local/lib/python2.7/dist-packages/rest_framework/views.py", line 407, in dispatch
    response = self.handle_exception(exc)
  File "/usr/local/lib/python2.7/dist-packages/rest_framework/views.py", line 404, in dispatch
    response = handler(request, *args, **kwargs)
  File "/usr/local/lib/python2.7/dist-packages/rest_framework/generics.py", line 357, in put
    return self.update(request, *args, **kwargs)
  File "/home/camilo/Documents/BackEnd/sitios/views.py", line 77, in update
    serializer.add_photos_with_abbreviations(photos)
  File "/home/camilo/Documents/BackEnd/sitios/serializers.py", line 79, in add_photos_with_abbreviations
    sitio_id=self.data["id"],
  File "/usr/local/lib/python2.7/dist-packages/rest_framework/serializers.py", line 463, in data
    ret = super(Serializer, self).data
  File "/usr/local/lib/python2.7/dist-packages/rest_framework/serializers.py", line 212, in data
    self._data = self.to_representation(self.instance)
  File "/usr/local/lib/python2.7/dist-packages/rest_framework/serializers.py", line 432, in to_representation
    ret[field.field_name] = field.to_representation(attribute)
  File "/usr/local/lib/python2.7/dist-packages/rest_framework/fields.py", line 686, in to_representation
    return int(value)
TypeError: int() argument must be a string or a number, not 'ManyRelatedManager'
Internal Server Error: /sitio/detail/1
Traceback (most recent call last):
  File "/usr/local/lib/python2.7/dist-packages/django/core/handlers/base.py", line 132, in get_response
    response = wrapped_callback(request, *callback_args, **callback_kwargs)
  File "/usr/local/lib/python2.7/dist-packages/django/views/decorators/csrf.py", line 58, in wrapped_view
    return view_func(*args, **kwargs)
  File "/usr/local/lib/python2.7/dist-packages/django/views/generic/base.py", line 71, in view
    return self.dispatch(request, *args, **kwargs)
  File "/usr/local/lib/python2.7/dist-packages/rest_framework/views.py", line 407, in dispatch
    response = self.handle_exception(exc)
  File "/usr/local/lib/python2.7/dist-packages/rest_framework/views.py", line 404, in dispatch
    response = handler(request, *args, **kwargs)
  File "/usr/local/lib/python2.7/dist-packages/rest_framework/generics.py", line 357, in put
    return self.update(request, *args, **kwargs)
  File "/home/camilo/Documents/BackEnd/sitios/views.py", line 75, in update
    self.perform_update(serializer)
  File "/usr/local/lib/python2.7/dist-packages/rest_framework/mixins.py", line 72, in perform_update
    serializer.save()
  File "/usr/local/lib/python2.7/dist-packages/rest_framework/serializers.py", line 159, in save
    self.instance = self.update(self.instance, validated_data)
  File "/usr/local/lib/python2.7/dist-packages/rest_framework/serializers.py", line 794, in update
    raise_errors_on_nested_writes('update', self, validated_data)
  File "/usr/local/lib/python2.7/dist-packages/rest_framework/serializers.py", line 664, in raise_errors_on_nested_writes
    class_name=serializer.__class__.__name__
AssertionError: The `.update()` method does not support writable nestedfields by default.
Write an explicit `.update()` method for serializer `sitios.serializers.SitioSerializer`, or set `read_only=True` on nested serializer fields.
Internal Server Error: /sitio/detail/1
Traceback (most recent call last):
  File "/usr/local/lib/python2.7/dist-packages/django/core/handlers/base.py", line 132, in get_response
    response = wrapped_callback(request, *callback_args, **callback_kwargs)
  File "/usr/local/lib/python2.7/dist-packages/django/views/decorators/csrf.py", line 58, in wrapped_view
    return view_func(*args, **kwargs)
  File "/usr/local/lib/python2.7/dist-packages/django/views/generic/base.py", line 71, in view
    return self.dispatch(request, *args, **kwargs)
  File "/usr/local/lib/python2.7/dist-packages/rest_framework/views.py", line 407, in dispatch
    response = self.handle_exception(exc)
  File "/usr/local/lib/python2.7/dist-packages/rest_framework/views.py", line 404, in dispatch
    response = handler(request, *args, **kwargs)
  File "/usr/local/lib/python2.7/dist-packages/rest_framework/generics.py", line 357, in put
    return self.update(request, *args, **kwargs)
  File "/home/camilo/Documents/BackEnd/sitios/views.py", line 75, in update
    self.perform_update(serializer)
  File "/usr/local/lib/python2.7/dist-packages/rest_framework/mixins.py", line 72, in perform_update
    serializer.save()
  File "/usr/local/lib/python2.7/dist-packages/rest_framework/serializers.py", line 159, in save
    self.instance = self.update(self.instance, validated_data)
  File "/usr/local/lib/python2.7/dist-packages/rest_framework/serializers.py", line 794, in update
    raise_errors_on_nested_writes('update', self, validated_data)
  File "/usr/local/lib/python2.7/dist-packages/rest_framework/serializers.py", line 664, in raise_errors_on_nested_writes
    class_name=serializer.__class__.__name__
AssertionError: The `.update()` method does not support writable nestedfields by default.
Write an explicit `.update()` method for serializer `sitios.serializers.SitioSerializer`, or set `read_only=True` on nested serializer fields.
Internal Server Error: /sitio/detail/1
Traceback (most recent call last):
  File "/usr/local/lib/python2.7/dist-packages/django/core/handlers/base.py", line 132, in get_response
    response = wrapped_callback(request, *callback_args, **callback_kwargs)
  File "/usr/local/lib/python2.7/dist-packages/django/views/decorators/csrf.py", line 58, in wrapped_view
    return view_func(*args, **kwargs)
  File "/usr/local/lib/python2.7/dist-packages/django/views/generic/base.py", line 71, in view
    return self.dispatch(request, *args, **kwargs)
  File "/usr/local/lib/python2.7/dist-packages/rest_framework/views.py", line 407, in dispatch
    response = self.handle_exception(exc)
  File "/usr/local/lib/python2.7/dist-packages/rest_framework/views.py", line 404, in dispatch
    response = handler(request, *args, **kwargs)
  File "/usr/local/lib/python2.7/dist-packages/rest_framework/generics.py", line 357, in put
    return self.update(request, *args, **kwargs)
  File "/home/camilo/Documents/BackEnd/sitios/views.py", line 75, in update
    self.perform_update(serializer)
  File "/usr/local/lib/python2.7/dist-packages/rest_framework/mixins.py", line 72, in perform_update
    serializer.save()
  File "/usr/local/lib/python2.7/dist-packages/rest_framework/serializers.py", line 159, in save
    self.instance = self.update(self.instance, validated_data)
  File "/usr/local/lib/python2.7/dist-packages/rest_framework/serializers.py", line 794, in update
    raise_errors_on_nested_writes('update', self, validated_data)
  File "/usr/local/lib/python2.7/dist-packages/rest_framework/serializers.py", line 664, in raise_errors_on_nested_writes
    class_name=serializer.__class__.__name__
AssertionError: The `.update()` method does not support writable nestedfields by default.
Write an explicit `.update()` method for serializer `sitios.serializers.SitioSerializer`, or set `read_only=True` on nested serializer fields.
Internal Server Error: /sitio/detail/1
Traceback (most recent call last):
  File "/usr/local/lib/python2.7/dist-packages/django/core/handlers/base.py", line 132, in get_response
    response = wrapped_callback(request, *callback_args, **callback_kwargs)
  File "/usr/local/lib/python2.7/dist-packages/django/views/decorators/csrf.py", line 58, in wrapped_view
    return view_func(*args, **kwargs)
  File "/usr/local/lib/python2.7/dist-packages/django/views/generic/base.py", line 71, in view
    return self.dispatch(request, *args, **kwargs)
  File "/usr/local/lib/python2.7/dist-packages/rest_framework/views.py", line 407, in dispatch
    response = self.handle_exception(exc)
  File "/usr/local/lib/python2.7/dist-packages/rest_framework/views.py", line 404, in dispatch
    response = handler(request, *args, **kwargs)
  File "/usr/local/lib/python2.7/dist-packages/rest_framework/generics.py", line 357, in put
    return self.update(request, *args, **kwargs)
  File "/home/camilo/Documents/BackEnd/sitios/views.py", line 75, in update
    self.perform_update(serializer)
  File "/usr/local/lib/python2.7/dist-packages/rest_framework/mixins.py", line 72, in perform_update
    serializer.save()
  File "/usr/local/lib/python2.7/dist-packages/rest_framework/serializers.py", line 159, in save
    self.instance = self.update(self.instance, validated_data)
  File "/usr/local/lib/python2.7/dist-packages/rest_framework/serializers.py", line 794, in update
    raise_errors_on_nested_writes('update', self, validated_data)
  File "/usr/local/lib/python2.7/dist-packages/rest_framework/serializers.py", line 664, in raise_errors_on_nested_writes
    class_name=serializer.__class__.__name__
AssertionError: The `.update()` method does not support writable nestedfields by default.
Write an explicit `.update()` method for serializer `sitios.serializers.SitioSerializer`, or set `read_only=True` on nested serializer fields.
Internal Server Error: /sitio/detail/1
Traceback (most recent call last):
  File "/usr/local/lib/python2.7/dist-packages/django/core/handlers/base.py", line 132, in get_response
    response = wrapped_callback(request, *callback_args, **callback_kwargs)
  File "/usr/local/lib/python2.7/dist-packages/django/views/decorators/csrf.py", line 58, in wrapped_view
    return view_func(*args, **kwargs)
  File "/usr/local/lib/python2.7/dist-packages/django/views/generic/base.py", line 71, in view
    return self.dispatch(request, *args, **kwargs)
  File "/usr/local/lib/python2.7/dist-packages/rest_framework/views.py", line 407, in dispatch
    response = self.handle_exception(exc)
  File "/usr/local/lib/python2.7/dist-packages/rest_framework/views.py", line 404, in dispatch
    response = handler(request, *args, **kwargs)
  File "/usr/local/lib/python2.7/dist-packages/rest_framework/generics.py", line 357, in put
    return self.update(request, *args, **kwargs)
  File "/home/camilo/Documents/BackEnd/sitios/views.py", line 75, in update
    self.perform_update(serializer)
  File "/usr/local/lib/python2.7/dist-packages/rest_framework/mixins.py", line 72, in perform_update
    serializer.save()
  File "/usr/local/lib/python2.7/dist-packages/rest_framework/serializers.py", line 159, in save
    self.instance = self.update(self.instance, validated_data)
  File "/usr/local/lib/python2.7/dist-packages/rest_framework/serializers.py", line 794, in update
    raise_errors_on_nested_writes('update', self, validated_data)
  File "/usr/local/lib/python2.7/dist-packages/rest_framework/serializers.py", line 664, in raise_errors_on_nested_writes
    class_name=serializer.__class__.__name__
AssertionError: The `.update()` method does not support writable nestedfields by default.
Write an explicit `.update()` method for serializer `sitios.serializers.SitioSerializer`, or set `read_only=True` on nested serializer fields.
Internal Server Error: /sitio/detail/1
Traceback (most recent call last):
  File "/usr/local/lib/python2.7/dist-packages/django/core/handlers/base.py", line 132, in get_response
    response = wrapped_callback(request, *callback_args, **callback_kwargs)
  File "/usr/local/lib/python2.7/dist-packages/django/views/decorators/csrf.py", line 58, in wrapped_view
    return view_func(*args, **kwargs)
  File "/usr/local/lib/python2.7/dist-packages/django/views/generic/base.py", line 71, in view
    return self.dispatch(request, *args, **kwargs)
  File "/usr/local/lib/python2.7/dist-packages/rest_framework/views.py", line 407, in dispatch
    response = self.handle_exception(exc)
  File "/usr/local/lib/python2.7/dist-packages/rest_framework/views.py", line 404, in dispatch
    response = handler(request, *args, **kwargs)
  File "/usr/local/lib/python2.7/dist-packages/rest_framework/generics.py", line 357, in put
    return self.update(request, *args, **kwargs)
  File "/home/camilo/Documents/BackEnd/sitios/views.py", line 75, in update
    self.perform_update(serializer)
  File "/usr/local/lib/python2.7/dist-packages/rest_framework/mixins.py", line 72, in perform_update
    serializer.save()
  File "/usr/local/lib/python2.7/dist-packages/rest_framework/serializers.py", line 159, in save
    self.instance = self.update(self.instance, validated_data)
  File "/usr/local/lib/python2.7/dist-packages/rest_framework/serializers.py", line 794, in update
    raise_errors_on_nested_writes('update', self, validated_data)
  File "/usr/local/lib/python2.7/dist-packages/rest_framework/serializers.py", line 664, in raise_errors_on_nested_writes
    class_name=serializer.__class__.__name__
AssertionError: The `.update()` method does not support writable nestedfields by default.
Write an explicit `.update()` method for serializer `sitios.serializers.SitioSerializer`, or set `read_only=True` on nested serializer fields.
