Internal Server Error: /municipios
Traceback (most recent call last):
  File "/usr/local/lib/python2.7/dist-packages/django/core/handlers/base.py", line 108, in get_response
    response = middleware_method(request)
  File "/usr/local/lib/python2.7/dist-packages/django/middleware/common.py", line 74, in process_request
    if (not urlresolvers.is_valid_path(request.path_info, urlconf) and
  File "/usr/local/lib/python2.7/dist-packages/django/core/urlresolvers.py", line 647, in is_valid_path
    resolve(path, urlconf)
  File "/usr/local/lib/python2.7/dist-packages/django/core/urlresolvers.py", line 522, in resolve
    return get_resolver(urlconf).resolve(path)
  File "/usr/local/lib/python2.7/dist-packages/django/core/urlresolvers.py", line 366, in resolve
    for pattern in self.url_patterns:
  File "/usr/local/lib/python2.7/dist-packages/django/core/urlresolvers.py", line 402, in url_patterns
    patterns = getattr(self.urlconf_module, "urlpatterns", self.urlconf_module)
  File "/usr/local/lib/python2.7/dist-packages/django/core/urlresolvers.py", line 396, in urlconf_module
    self._urlconf_module = import_module(self.urlconf_name)
  File "/usr/lib/python2.7/importlib/__init__.py", line 37, in import_module
    __import__(name)
  File "/home/camilo/Documents/BackEnd/turismo/urls.py", line 5, in <module>
    from sitios import views as sitio_views
  File "/home/camilo/Documents/BackEnd/sitios/views.py", line 85
    class SitiosCercanosARuta(viewsets.ViewSet):
        ^
SyntaxError: invalid syntax
Internal Server Error: /municipios
Traceback (most recent call last):
  File "/usr/local/lib/python2.7/dist-packages/django/core/handlers/base.py", line 108, in get_response
    response = middleware_method(request)
  File "/usr/local/lib/python2.7/dist-packages/django/middleware/common.py", line 74, in process_request
    if (not urlresolvers.is_valid_path(request.path_info, urlconf) and
  File "/usr/local/lib/python2.7/dist-packages/django/core/urlresolvers.py", line 647, in is_valid_path
    resolve(path, urlconf)
  File "/usr/local/lib/python2.7/dist-packages/django/core/urlresolvers.py", line 522, in resolve
    return get_resolver(urlconf).resolve(path)
  File "/usr/local/lib/python2.7/dist-packages/django/core/urlresolvers.py", line 366, in resolve
    for pattern in self.url_patterns:
  File "/usr/local/lib/python2.7/dist-packages/django/core/urlresolvers.py", line 402, in url_patterns
    patterns = getattr(self.urlconf_module, "urlpatterns", self.urlconf_module)
  File "/usr/local/lib/python2.7/dist-packages/django/core/urlresolvers.py", line 396, in urlconf_module
    self._urlconf_module = import_module(self.urlconf_name)
  File "/usr/lib/python2.7/importlib/__init__.py", line 37, in import_module
    __import__(name)
  File "/home/camilo/Documents/BackEnd/turismo/urls.py", line 5, in <module>
    from sitios import views as sitio_views
  File "/home/camilo/Documents/BackEnd/sitios/views.py", line 85
    class SitiosCercanosARuta(viewsets.ViewSet):
        ^
SyntaxError: invalid syntax
Internal Server Error: /municipios
Traceback (most recent call last):
  File "/usr/local/lib/python2.7/dist-packages/django/core/handlers/base.py", line 108, in get_response
    response = middleware_method(request)
  File "/usr/local/lib/python2.7/dist-packages/django/middleware/common.py", line 74, in process_request
    if (not urlresolvers.is_valid_path(request.path_info, urlconf) and
  File "/usr/local/lib/python2.7/dist-packages/django/core/urlresolvers.py", line 647, in is_valid_path
    resolve(path, urlconf)
  File "/usr/local/lib/python2.7/dist-packages/django/core/urlresolvers.py", line 522, in resolve
    return get_resolver(urlconf).resolve(path)
  File "/usr/local/lib/python2.7/dist-packages/django/core/urlresolvers.py", line 366, in resolve
    for pattern in self.url_patterns:
  File "/usr/local/lib/python2.7/dist-packages/django/core/urlresolvers.py", line 402, in url_patterns
    patterns = getattr(self.urlconf_module, "urlpatterns", self.urlconf_module)
  File "/usr/local/lib/python2.7/dist-packages/django/core/urlresolvers.py", line 396, in urlconf_module
    self._urlconf_module = import_module(self.urlconf_name)
  File "/usr/lib/python2.7/importlib/__init__.py", line 37, in import_module
    __import__(name)
  File "/home/camilo/Documents/BackEnd/turismo/urls.py", line 5, in <module>
    from sitios import views as sitio_views
  File "/home/camilo/Documents/BackEnd/sitios/views.py", line 85
    class SitiosCercanosARuta(viewsets.ViewSet):
        ^
SyntaxError: invalid syntax
Internal Server Error: /categorias
Traceback (most recent call last):
  File "/usr/local/lib/python2.7/dist-packages/django/core/handlers/base.py", line 108, in get_response
    response = middleware_method(request)
  File "/usr/local/lib/python2.7/dist-packages/django/middleware/common.py", line 74, in process_request
    if (not urlresolvers.is_valid_path(request.path_info, urlconf) and
  File "/usr/local/lib/python2.7/dist-packages/django/core/urlresolvers.py", line 647, in is_valid_path
    resolve(path, urlconf)
  File "/usr/local/lib/python2.7/dist-packages/django/core/urlresolvers.py", line 522, in resolve
    return get_resolver(urlconf).resolve(path)
  File "/usr/local/lib/python2.7/dist-packages/django/core/urlresolvers.py", line 366, in resolve
    for pattern in self.url_patterns:
  File "/usr/local/lib/python2.7/dist-packages/django/core/urlresolvers.py", line 402, in url_patterns
    patterns = getattr(self.urlconf_module, "urlpatterns", self.urlconf_module)
  File "/usr/local/lib/python2.7/dist-packages/django/core/urlresolvers.py", line 396, in urlconf_module
    self._urlconf_module = import_module(self.urlconf_name)
  File "/usr/lib/python2.7/importlib/__init__.py", line 37, in import_module
    __import__(name)
  File "/home/camilo/Documents/BackEnd/turismo/urls.py", line 5, in <module>
    from sitios import views as sitio_views
  File "/home/camilo/Documents/BackEnd/sitios/views.py", line 85
    class SitiosCercanosARuta(viewsets.ViewSet):
        ^
SyntaxError: invalid syntax
Internal Server Error: /municipios
Traceback (most recent call last):
  File "/usr/local/lib/python2.7/dist-packages/django/core/handlers/base.py", line 108, in get_response
    response = middleware_method(request)
  File "/usr/local/lib/python2.7/dist-packages/django/middleware/common.py", line 74, in process_request
    if (not urlresolvers.is_valid_path(request.path_info, urlconf) and
  File "/usr/local/lib/python2.7/dist-packages/django/core/urlresolvers.py", line 647, in is_valid_path
    resolve(path, urlconf)
  File "/usr/local/lib/python2.7/dist-packages/django/core/urlresolvers.py", line 522, in resolve
    return get_resolver(urlconf).resolve(path)
  File "/usr/local/lib/python2.7/dist-packages/django/core/urlresolvers.py", line 366, in resolve
    for pattern in self.url_patterns:
  File "/usr/local/lib/python2.7/dist-packages/django/core/urlresolvers.py", line 402, in url_patterns
    patterns = getattr(self.urlconf_module, "urlpatterns", self.urlconf_module)
  File "/usr/local/lib/python2.7/dist-packages/django/core/urlresolvers.py", line 396, in urlconf_module
    self._urlconf_module = import_module(self.urlconf_name)
  File "/usr/lib/python2.7/importlib/__init__.py", line 37, in import_module
    __import__(name)
  File "/home/camilo/Documents/BackEnd/turismo/urls.py", line 5, in <module>
    from sitios import views as sitio_views
  File "/home/camilo/Documents/BackEnd/sitios/views.py", line 85
    class SitiosCercanosARuta(viewsets.ViewSet):
        ^
SyntaxError: invalid syntax
Internal Server Error: /sitio/detail/1877
Traceback (most recent call last):
  File "/usr/local/lib/python2.7/dist-packages/django/core/handlers/base.py", line 132, in get_response
    response = wrapped_callback(request, *callback_args, **callback_kwargs)
  File "/usr/local/lib/python2.7/dist-packages/django/views/decorators/csrf.py", line 58, in wrapped_view
    return view_func(*args, **kwargs)
  File "/usr/local/lib/python2.7/dist-packages/django/views/generic/base.py", line 71, in view
    return self.dispatch(request, *args, **kwargs)
  File "/usr/local/lib/python2.7/dist-packages/rest_framework/views.py", line 407, in dispatch
    response = self.handle_exception(exc)
  File "/usr/local/lib/python2.7/dist-packages/rest_framework/views.py", line 404, in dispatch
    response = handler(request, *args, **kwargs)
  File "/usr/local/lib/python2.7/dist-packages/rest_framework/generics.py", line 357, in put
    return self.update(request, *args, **kwargs)
  File "/home/camilo/Documents/BackEnd/sitios/views.py", line 84, in update
    return Response(serializer.data)
NameError: global name 'serializer' is not defined
Internal Server Error: /sitio/detail/1877
Traceback (most recent call last):
  File "/usr/local/lib/python2.7/dist-packages/django/core/handlers/base.py", line 132, in get_response
    response = wrapped_callback(request, *callback_args, **callback_kwargs)
  File "/usr/local/lib/python2.7/dist-packages/django/views/decorators/csrf.py", line 58, in wrapped_view
    return view_func(*args, **kwargs)
  File "/usr/local/lib/python2.7/dist-packages/django/views/generic/base.py", line 71, in view
    return self.dispatch(request, *args, **kwargs)
  File "/usr/local/lib/python2.7/dist-packages/rest_framework/views.py", line 407, in dispatch
    response = self.handle_exception(exc)
  File "/usr/local/lib/python2.7/dist-packages/rest_framework/views.py", line 404, in dispatch
    response = handler(request, *args, **kwargs)
  File "/usr/local/lib/python2.7/dist-packages/rest_framework/generics.py", line 357, in put
    return self.update(request, *args, **kwargs)
  File "/home/camilo/Documents/BackEnd/sitios/views.py", line 84, in update
    data = super().update(self, request, *args, **kwargs)
TypeError: super() takes at least 1 argument (0 given)
Internal Server Error: /sitio/detail/1877
Traceback (most recent call last):
  File "/usr/local/lib/python2.7/dist-packages/django/core/handlers/base.py", line 132, in get_response
    response = wrapped_callback(request, *callback_args, **callback_kwargs)
  File "/usr/local/lib/python2.7/dist-packages/django/views/decorators/csrf.py", line 58, in wrapped_view
    return view_func(*args, **kwargs)
  File "/usr/local/lib/python2.7/dist-packages/django/views/generic/base.py", line 71, in view
    return self.dispatch(request, *args, **kwargs)
  File "/usr/local/lib/python2.7/dist-packages/rest_framework/views.py", line 407, in dispatch
    response = self.handle_exception(exc)
  File "/usr/local/lib/python2.7/dist-packages/rest_framework/views.py", line 404, in dispatch
    response = handler(request, *args, **kwargs)
  File "/usr/local/lib/python2.7/dist-packages/rest_framework/generics.py", line 357, in put
    return self.update(request, *args, **kwargs)
  File "/home/camilo/Documents/BackEnd/sitios/views.py", line 84, in update
    data = super().update(request, *args, **kwargs)
TypeError: super() takes at least 1 argument (0 given)
Internal Server Error: /sitio/detail/1877
Traceback (most recent call last):
  File "/usr/local/lib/python2.7/dist-packages/django/core/handlers/base.py", line 164, in get_response
    response = response.render()
  File "/usr/local/lib/python2.7/dist-packages/django/template/response.py", line 158, in render
    self.content = self.rendered_content
  File "/usr/local/lib/python2.7/dist-packages/rest_framework/response.py", line 59, in rendered_content
    ret = renderer.render(self.data, media_type, context)
  File "/usr/local/lib/python2.7/dist-packages/rest_framework/renderers.py", line 98, in render
    separators=separators
  File "/usr/lib/python2.7/json/__init__.py", line 250, in dumps
    sort_keys=sort_keys, **kw).encode(obj)
  File "/usr/lib/python2.7/json/encoder.py", line 207, in encode
    chunks = self.iterencode(o, _one_shot=True)
  File "/usr/lib/python2.7/json/encoder.py", line 270, in iterencode
    return _iterencode(o, 0)
  File "/usr/local/lib/python2.7/dist-packages/rest_framework/utils/encoders.py", line 63, in default
    return super(JSONEncoder, self).default(obj)
  File "/usr/lib/python2.7/json/encoder.py", line 184, in default
    raise TypeError(repr(o) + " is not JSON serializable")
TypeError: <rest_framework.response.Response object at 0x7fc7202e8f90> is not JSON serializable
Internal Server Error: /sitio/detail/1877
Traceback (most recent call last):
  File "/usr/local/lib/python2.7/dist-packages/django/core/handlers/base.py", line 164, in get_response
    response = response.render()
  File "/usr/local/lib/python2.7/dist-packages/django/template/response.py", line 158, in render
    self.content = self.rendered_content
  File "/usr/local/lib/python2.7/dist-packages/rest_framework/response.py", line 59, in rendered_content
    ret = renderer.render(self.data, media_type, context)
  File "/usr/local/lib/python2.7/dist-packages/rest_framework/renderers.py", line 98, in render
    separators=separators
  File "/usr/lib/python2.7/json/__init__.py", line 250, in dumps
    sort_keys=sort_keys, **kw).encode(obj)
  File "/usr/lib/python2.7/json/encoder.py", line 207, in encode
    chunks = self.iterencode(o, _one_shot=True)
  File "/usr/lib/python2.7/json/encoder.py", line 270, in iterencode
    return _iterencode(o, 0)
  File "/usr/local/lib/python2.7/dist-packages/rest_framework/utils/encoders.py", line 63, in default
    return super(JSONEncoder, self).default(obj)
  File "/usr/lib/python2.7/json/encoder.py", line 184, in default
    raise TypeError(repr(o) + " is not JSON serializable")
TypeError: <rest_framework.response.Response object at 0x7f76626ddf90> is not JSON serializable
Internal Server Error: /usuario
Traceback (most recent call last):
  File "/usr/local/lib/python2.7/dist-packages/django/core/handlers/base.py", line 108, in get_response
    response = middleware_method(request)
  File "/usr/local/lib/python2.7/dist-packages/django/middleware/common.py", line 74, in process_request
    if (not urlresolvers.is_valid_path(request.path_info, urlconf) and
  File "/usr/local/lib/python2.7/dist-packages/django/core/urlresolvers.py", line 647, in is_valid_path
    resolve(path, urlconf)
  File "/usr/local/lib/python2.7/dist-packages/django/core/urlresolvers.py", line 522, in resolve
    return get_resolver(urlconf).resolve(path)
  File "/usr/local/lib/python2.7/dist-packages/django/core/urlresolvers.py", line 366, in resolve
    for pattern in self.url_patterns:
  File "/usr/local/lib/python2.7/dist-packages/django/core/urlresolvers.py", line 402, in url_patterns
    patterns = getattr(self.urlconf_module, "urlpatterns", self.urlconf_module)
  File "/usr/local/lib/python2.7/dist-packages/django/core/urlresolvers.py", line 396, in urlconf_module
    self._urlconf_module = import_module(self.urlconf_name)
  File "/usr/lib/python2.7/importlib/__init__.py", line 37, in import_module
    __import__(name)
  File "/home/camilo/Documents/BackEnd/turismo/urls.py", line 5, in <module>
    from sitios import views as sitio_views
  File "/home/camilo/Documents/BackEnd/sitios/views.py", line 79
    print *args
          ^
SyntaxError: invalid syntax
Internal Server Error: /municipios
Traceback (most recent call last):
  File "/usr/local/lib/python2.7/dist-packages/django/core/handlers/base.py", line 108, in get_response
    response = middleware_method(request)
  File "/usr/local/lib/python2.7/dist-packages/django/middleware/common.py", line 74, in process_request
    if (not urlresolvers.is_valid_path(request.path_info, urlconf) and
  File "/usr/local/lib/python2.7/dist-packages/django/core/urlresolvers.py", line 647, in is_valid_path
    resolve(path, urlconf)
  File "/usr/local/lib/python2.7/dist-packages/django/core/urlresolvers.py", line 522, in resolve
    return get_resolver(urlconf).resolve(path)
  File "/usr/local/lib/python2.7/dist-packages/django/core/urlresolvers.py", line 366, in resolve
    for pattern in self.url_patterns:
  File "/usr/local/lib/python2.7/dist-packages/django/core/urlresolvers.py", line 402, in url_patterns
    patterns = getattr(self.urlconf_module, "urlpatterns", self.urlconf_module)
  File "/usr/local/lib/python2.7/dist-packages/django/core/urlresolvers.py", line 396, in urlconf_module
    self._urlconf_module = import_module(self.urlconf_name)
  File "/usr/lib/python2.7/importlib/__init__.py", line 37, in import_module
    __import__(name)
  File "/home/camilo/Documents/BackEnd/turismo/urls.py", line 5, in <module>
    from sitios import views as sitio_views
  File "/home/camilo/Documents/BackEnd/sitios/views.py", line 79
    print *args
          ^
SyntaxError: invalid syntax
Internal Server Error: /categorias
Traceback (most recent call last):
  File "/usr/local/lib/python2.7/dist-packages/django/core/handlers/base.py", line 108, in get_response
    response = middleware_method(request)
  File "/usr/local/lib/python2.7/dist-packages/django/middleware/common.py", line 74, in process_request
    if (not urlresolvers.is_valid_path(request.path_info, urlconf) and
  File "/usr/local/lib/python2.7/dist-packages/django/core/urlresolvers.py", line 647, in is_valid_path
    resolve(path, urlconf)
  File "/usr/local/lib/python2.7/dist-packages/django/core/urlresolvers.py", line 522, in resolve
    return get_resolver(urlconf).resolve(path)
  File "/usr/local/lib/python2.7/dist-packages/django/core/urlresolvers.py", line 366, in resolve
    for pattern in self.url_patterns:
  File "/usr/local/lib/python2.7/dist-packages/django/core/urlresolvers.py", line 402, in url_patterns
    patterns = getattr(self.urlconf_module, "urlpatterns", self.urlconf_module)
  File "/usr/local/lib/python2.7/dist-packages/django/core/urlresolvers.py", line 396, in urlconf_module
    self._urlconf_module = import_module(self.urlconf_name)
  File "/usr/lib/python2.7/importlib/__init__.py", line 37, in import_module
    __import__(name)
  File "/home/camilo/Documents/BackEnd/turismo/urls.py", line 5, in <module>
    from sitios import views as sitio_views
  File "/home/camilo/Documents/BackEnd/sitios/views.py", line 79
    print *args
          ^
SyntaxError: invalid syntax
Internal Server Error: /api/login/social/token/facebook
Traceback (most recent call last):
  File "/usr/local/lib/python2.7/dist-packages/django/core/handlers/base.py", line 108, in get_response
    response = middleware_method(request)
  File "/usr/local/lib/python2.7/dist-packages/django/middleware/common.py", line 74, in process_request
    if (not urlresolvers.is_valid_path(request.path_info, urlconf) and
  File "/usr/local/lib/python2.7/dist-packages/django/core/urlresolvers.py", line 647, in is_valid_path
    resolve(path, urlconf)
  File "/usr/local/lib/python2.7/dist-packages/django/core/urlresolvers.py", line 522, in resolve
    return get_resolver(urlconf).resolve(path)
  File "/usr/local/lib/python2.7/dist-packages/django/core/urlresolvers.py", line 366, in resolve
    for pattern in self.url_patterns:
  File "/usr/local/lib/python2.7/dist-packages/django/core/urlresolvers.py", line 402, in url_patterns
    patterns = getattr(self.urlconf_module, "urlpatterns", self.urlconf_module)
  File "/usr/local/lib/python2.7/dist-packages/django/core/urlresolvers.py", line 396, in urlconf_module
    self._urlconf_module = import_module(self.urlconf_name)
  File "/usr/lib/python2.7/importlib/__init__.py", line 37, in import_module
    __import__(name)
  File "/home/camilo/Documents/BackEnd/turismo/urls.py", line 5, in <module>
    from sitios import views as sitio_views
  File "/home/camilo/Documents/BackEnd/sitios/views.py", line 79
    print *args
          ^
SyntaxError: invalid syntax
Internal Server Error: /api/login/social/token/facebook
Traceback (most recent call last):
  File "/usr/local/lib/python2.7/dist-packages/django/core/handlers/base.py", line 108, in get_response
    response = middleware_method(request)
  File "/usr/local/lib/python2.7/dist-packages/django/middleware/common.py", line 74, in process_request
    if (not urlresolvers.is_valid_path(request.path_info, urlconf) and
  File "/usr/local/lib/python2.7/dist-packages/django/core/urlresolvers.py", line 647, in is_valid_path
    resolve(path, urlconf)
  File "/usr/local/lib/python2.7/dist-packages/django/core/urlresolvers.py", line 522, in resolve
    return get_resolver(urlconf).resolve(path)
  File "/usr/local/lib/python2.7/dist-packages/django/core/urlresolvers.py", line 366, in resolve
    for pattern in self.url_patterns:
  File "/usr/local/lib/python2.7/dist-packages/django/core/urlresolvers.py", line 402, in url_patterns
    patterns = getattr(self.urlconf_module, "urlpatterns", self.urlconf_module)
  File "/usr/local/lib/python2.7/dist-packages/django/core/urlresolvers.py", line 396, in urlconf_module
    self._urlconf_module = import_module(self.urlconf_name)
  File "/usr/lib/python2.7/importlib/__init__.py", line 37, in import_module
    __import__(name)
  File "/home/camilo/Documents/BackEnd/turismo/urls.py", line 5, in <module>
    from sitios import views as sitio_views
  File "/home/camilo/Documents/BackEnd/sitios/views.py", line 79
    print *args
          ^
SyntaxError: invalid syntax
Internal Server Error: /sitio/detail/1
Traceback (most recent call last):
  File "/usr/local/lib/python2.7/dist-packages/django/core/handlers/base.py", line 108, in get_response
    response = middleware_method(request)
  File "/usr/local/lib/python2.7/dist-packages/django/middleware/common.py", line 74, in process_request
    if (not urlresolvers.is_valid_path(request.path_info, urlconf) and
  File "/usr/local/lib/python2.7/dist-packages/django/core/urlresolvers.py", line 647, in is_valid_path
    resolve(path, urlconf)
  File "/usr/local/lib/python2.7/dist-packages/django/core/urlresolvers.py", line 522, in resolve
    return get_resolver(urlconf).resolve(path)
  File "/usr/local/lib/python2.7/dist-packages/django/core/urlresolvers.py", line 366, in resolve
    for pattern in self.url_patterns:
  File "/usr/local/lib/python2.7/dist-packages/django/core/urlresolvers.py", line 402, in url_patterns
    patterns = getattr(self.urlconf_module, "urlpatterns", self.urlconf_module)
  File "/usr/local/lib/python2.7/dist-packages/django/core/urlresolvers.py", line 396, in urlconf_module
    self._urlconf_module = import_module(self.urlconf_name)
  File "/usr/lib/python2.7/importlib/__init__.py", line 37, in import_module
    __import__(name)
  File "/home/camilo/Documents/BackEnd/turismo/urls.py", line 5, in <module>
    from sitios import views as sitio_views
  File "/home/camilo/Documents/BackEnd/sitios/views.py", line 79
    print *args
          ^
SyntaxError: invalid syntax
Internal Server Error: /favicon.ico
Traceback (most recent call last):
  File "/usr/local/lib/python2.7/dist-packages/django/core/handlers/base.py", line 108, in get_response
    response = middleware_method(request)
  File "/usr/local/lib/python2.7/dist-packages/django/middleware/common.py", line 74, in process_request
    if (not urlresolvers.is_valid_path(request.path_info, urlconf) and
  File "/usr/local/lib/python2.7/dist-packages/django/core/urlresolvers.py", line 647, in is_valid_path
    resolve(path, urlconf)
  File "/usr/local/lib/python2.7/dist-packages/django/core/urlresolvers.py", line 522, in resolve
    return get_resolver(urlconf).resolve(path)
  File "/usr/local/lib/python2.7/dist-packages/django/core/urlresolvers.py", line 366, in resolve
    for pattern in self.url_patterns:
  File "/usr/local/lib/python2.7/dist-packages/django/core/urlresolvers.py", line 402, in url_patterns
    patterns = getattr(self.urlconf_module, "urlpatterns", self.urlconf_module)
  File "/usr/local/lib/python2.7/dist-packages/django/core/urlresolvers.py", line 396, in urlconf_module
    self._urlconf_module = import_module(self.urlconf_name)
  File "/usr/lib/python2.7/importlib/__init__.py", line 37, in import_module
    __import__(name)
  File "/home/camilo/Documents/BackEnd/turismo/urls.py", line 5, in <module>
    from sitios import views as sitio_views
  File "/home/camilo/Documents/BackEnd/sitios/views.py", line 79
    print *args
          ^
SyntaxError: invalid syntax
Internal Server Error: /rest-auth/login
Traceback (most recent call last):
  File "/usr/local/lib/python2.7/dist-packages/django/core/handlers/base.py", line 108, in get_response
    response = middleware_method(request)
  File "/usr/local/lib/python2.7/dist-packages/django/middleware/common.py", line 74, in process_request
    if (not urlresolvers.is_valid_path(request.path_info, urlconf) and
  File "/usr/local/lib/python2.7/dist-packages/django/core/urlresolvers.py", line 647, in is_valid_path
    resolve(path, urlconf)
  File "/usr/local/lib/python2.7/dist-packages/django/core/urlresolvers.py", line 522, in resolve
    return get_resolver(urlconf).resolve(path)
  File "/usr/local/lib/python2.7/dist-packages/django/core/urlresolvers.py", line 366, in resolve
    for pattern in self.url_patterns:
  File "/usr/local/lib/python2.7/dist-packages/django/core/urlresolvers.py", line 402, in url_patterns
    patterns = getattr(self.urlconf_module, "urlpatterns", self.urlconf_module)
  File "/usr/local/lib/python2.7/dist-packages/django/core/urlresolvers.py", line 396, in urlconf_module
    self._urlconf_module = import_module(self.urlconf_name)
  File "/usr/lib/python2.7/importlib/__init__.py", line 37, in import_module
    __import__(name)
  File "/home/camilo/Documents/BackEnd/turismo/urls.py", line 4, in <module>
    from plataforma import views
  File "/home/camilo/Documents/BackEnd/plataforma/views.py", line 5, in <module>
    from plataforma.serializers import *
  File "/home/camilo/Documents/BackEnd/plataforma/serializers.py", line 9, in <module>
    from sitios.serializers import SitioSerializer
  File "/home/camilo/Documents/BackEnd/sitios/serializers.py", line 56
    if 'PRINCIPAL' in nombre:
                            ^
IndentationError: unindent does not match any outer indentation level
Internal Server Error: /rest-auth/login
Traceback (most recent call last):
  File "/usr/local/lib/python2.7/dist-packages/django/core/handlers/base.py", line 108, in get_response
    response = middleware_method(request)
  File "/usr/local/lib/python2.7/dist-packages/django/middleware/common.py", line 74, in process_request
    if (not urlresolvers.is_valid_path(request.path_info, urlconf) and
  File "/usr/local/lib/python2.7/dist-packages/django/core/urlresolvers.py", line 647, in is_valid_path
    resolve(path, urlconf)
  File "/usr/local/lib/python2.7/dist-packages/django/core/urlresolvers.py", line 522, in resolve
    return get_resolver(urlconf).resolve(path)
  File "/usr/local/lib/python2.7/dist-packages/django/core/urlresolvers.py", line 366, in resolve
    for pattern in self.url_patterns:
  File "/usr/local/lib/python2.7/dist-packages/django/core/urlresolvers.py", line 402, in url_patterns
    patterns = getattr(self.urlconf_module, "urlpatterns", self.urlconf_module)
  File "/usr/local/lib/python2.7/dist-packages/django/core/urlresolvers.py", line 396, in urlconf_module
    self._urlconf_module = import_module(self.urlconf_name)
  File "/usr/lib/python2.7/importlib/__init__.py", line 37, in import_module
    __import__(name)
  File "/home/camilo/Documents/BackEnd/turismo/urls.py", line 4, in <module>
    from plataforma import views
  File "/home/camilo/Documents/BackEnd/plataforma/views.py", line 5, in <module>
    from plataforma.serializers import *
  File "/home/camilo/Documents/BackEnd/plataforma/serializers.py", line 9, in <module>
    from sitios.serializers import SitioSerializer
  File "/home/camilo/Documents/BackEnd/sitios/serializers.py", line 56
    if 'PRINCIPAL' in nombre:
                            ^
IndentationError: unindent does not match any outer indentation level
Internal Server Error: /sitio
Traceback (most recent call last):
  File "/usr/local/lib/python2.7/dist-packages/django/core/handlers/base.py", line 132, in get_response
    response = wrapped_callback(request, *callback_args, **callback_kwargs)
  File "/usr/local/lib/python2.7/dist-packages/django/views/decorators/csrf.py", line 58, in wrapped_view
    return view_func(*args, **kwargs)
  File "/usr/local/lib/python2.7/dist-packages/django/views/generic/base.py", line 71, in view
    return self.dispatch(request, *args, **kwargs)
  File "/usr/local/lib/python2.7/dist-packages/rest_framework/views.py", line 407, in dispatch
    response = self.handle_exception(exc)
  File "/usr/local/lib/python2.7/dist-packages/rest_framework/views.py", line 404, in dispatch
    response = handler(request, *args, **kwargs)
  File "/usr/local/lib/python2.7/dist-packages/rest_framework/generics.py", line 314, in post
    return self.create(request, *args, **kwargs)
  File "/home/camilo/Documents/BackEnd/sitios/views.py", line 52, in create
    site.add_photos_with_abbreviations(photos)
AttributeError: 'Sitio' object has no attribute 'add_photos_with_abbreviations'
Internal Server Error: /sitio
Traceback (most recent call last):
  File "/usr/local/lib/python2.7/dist-packages/django/core/handlers/base.py", line 132, in get_response
    response = wrapped_callback(request, *callback_args, **callback_kwargs)
  File "/usr/local/lib/python2.7/dist-packages/django/views/decorators/csrf.py", line 58, in wrapped_view
    return view_func(*args, **kwargs)
  File "/usr/local/lib/python2.7/dist-packages/django/views/generic/base.py", line 71, in view
    return self.dispatch(request, *args, **kwargs)
  File "/usr/local/lib/python2.7/dist-packages/rest_framework/views.py", line 407, in dispatch
    response = self.handle_exception(exc)
  File "/usr/local/lib/python2.7/dist-packages/rest_framework/views.py", line 404, in dispatch
    response = handler(request, *args, **kwargs)
  File "/usr/local/lib/python2.7/dist-packages/rest_framework/generics.py", line 314, in post
    return self.create(request, *args, **kwargs)
  File "/home/camilo/Documents/BackEnd/sitios/views.py", line 52, in create
    site.add_photos_with_abbreviations(photos)
AttributeError: 'Sitio' object has no attribute 'add_photos_with_abbreviations'
Internal Server Error: /sitio
Traceback (most recent call last):
  File "/usr/local/lib/python2.7/dist-packages/django/core/handlers/base.py", line 132, in get_response
    response = wrapped_callback(request, *callback_args, **callback_kwargs)
  File "/usr/local/lib/python2.7/dist-packages/django/views/decorators/csrf.py", line 58, in wrapped_view
    return view_func(*args, **kwargs)
  File "/usr/local/lib/python2.7/dist-packages/django/views/generic/base.py", line 71, in view
    return self.dispatch(request, *args, **kwargs)
  File "/usr/local/lib/python2.7/dist-packages/rest_framework/views.py", line 407, in dispatch
    response = self.handle_exception(exc)
  File "/usr/local/lib/python2.7/dist-packages/rest_framework/views.py", line 404, in dispatch
    response = handler(request, *args, **kwargs)
  File "/usr/local/lib/python2.7/dist-packages/rest_framework/generics.py", line 314, in post
    return self.create(request, *args, **kwargs)
  File "/home/camilo/Documents/BackEnd/sitios/views.py", line 52, in create
    serializer.add_photos_with_abbreviations(photos)
TypeError: add_photos_with_abbreviations() takes exactly 1 argument (2 given)
Internal Server Error: /sitio
Traceback (most recent call last):
  File "/usr/local/lib/python2.7/dist-packages/django/core/handlers/base.py", line 132, in get_response
    response = wrapped_callback(request, *callback_args, **callback_kwargs)
  File "/usr/local/lib/python2.7/dist-packages/django/views/decorators/csrf.py", line 58, in wrapped_view
    return view_func(*args, **kwargs)
  File "/usr/local/lib/python2.7/dist-packages/django/views/generic/base.py", line 71, in view
    return self.dispatch(request, *args, **kwargs)
  File "/usr/local/lib/python2.7/dist-packages/rest_framework/views.py", line 407, in dispatch
    response = self.handle_exception(exc)
  File "/usr/local/lib/python2.7/dist-packages/rest_framework/views.py", line 404, in dispatch
    response = handler(request, *args, **kwargs)
  File "/usr/local/lib/python2.7/dist-packages/rest_framework/generics.py", line 314, in post
    return self.create(request, *args, **kwargs)
  File "/home/camilo/Documents/BackEnd/sitios/views.py", line 52, in create
    serializer.add_photos_with_abbreviations(photos)
TypeError: add_photos_with_abbreviations() takes exactly 1 argument (2 given)
Internal Server Error: /buscar/
Traceback (most recent call last):
  File "/usr/local/lib/python2.7/dist-packages/django/core/handlers/base.py", line 119, in get_response
    resolver_match = resolver.resolve(request.path_info)
  File "/usr/local/lib/python2.7/dist-packages/django/core/urlresolvers.py", line 366, in resolve
    for pattern in self.url_patterns:
  File "/usr/local/lib/python2.7/dist-packages/django/core/urlresolvers.py", line 402, in url_patterns
    patterns = getattr(self.urlconf_module, "urlpatterns", self.urlconf_module)
  File "/usr/local/lib/python2.7/dist-packages/django/core/urlresolvers.py", line 396, in urlconf_module
    self._urlconf_module = import_module(self.urlconf_name)
  File "/usr/lib/python2.7/importlib/__init__.py", line 37, in import_module
    __import__(name)
  File "/home/camilo/Documents/BackEnd/turismo/urls.py", line 5, in <module>
    from sitios import views as sitio_views
  File "/home/camilo/Documents/BackEnd/sitios/views.py", line 38
SyntaxError: Non-ASCII character '\xc3' in file /home/camilo/Documents/BackEnd/sitios/views.py on line 38, but no encoding declared; see http://www.python.org/peps/pep-0263.html for details
Internal Server Error: /sitio
Traceback (most recent call last):
  File "/usr/local/lib/python2.7/dist-packages/django/core/handlers/base.py", line 132, in get_response
    response = wrapped_callback(request, *callback_args, **callback_kwargs)
  File "/usr/local/lib/python2.7/dist-packages/django/views/decorators/csrf.py", line 58, in wrapped_view
    return view_func(*args, **kwargs)
  File "/usr/local/lib/python2.7/dist-packages/django/views/generic/base.py", line 71, in view
    return self.dispatch(request, *args, **kwargs)
  File "/usr/local/lib/python2.7/dist-packages/rest_framework/views.py", line 407, in dispatch
    response = self.handle_exception(exc)
  File "/usr/local/lib/python2.7/dist-packages/rest_framework/views.py", line 404, in dispatch
    response = handler(request, *args, **kwargs)
  File "/usr/local/lib/python2.7/dist-packages/rest_framework/generics.py", line 314, in post
    return self.create(request, *args, **kwargs)
  File "/home/vagrant/django_shared/ecosistema/BackEnd/sitios/views.py", line 61, in create
    serializer.add_categories(data['categorias'])
  File "/home/vagrant/django_shared/ecosistema/BackEnd/sitios/serializers.py", line 63, in add_categories
    SitioCategoria.objects.create(sitio_id=self.data["id"],categoria_id=category);
  File "/usr/local/lib/python2.7/dist-packages/django/db/models/manager.py", line 127, in manager_method
    return getattr(self.get_queryset(), name)(*args, **kwargs)
  File "/usr/local/lib/python2.7/dist-packages/django/db/models/query.py", line 348, in create
    obj.save(force_insert=True, using=self.db)
  File "/usr/local/lib/python2.7/dist-packages/django/db/models/base.py", line 710, in save
    force_update=force_update, update_fields=update_fields)
  File "/usr/local/lib/python2.7/dist-packages/django/db/models/base.py", line 738, in save_base
    updated = self._save_table(raw, cls, force_insert, force_update, using, update_fields)
  File "/usr/local/lib/python2.7/dist-packages/django/db/models/base.py", line 822, in _save_table
    result = self._do_insert(cls._base_manager, using, fields, update_pk, raw)
  File "/usr/local/lib/python2.7/dist-packages/django/db/models/base.py", line 861, in _do_insert
    using=using, raw=raw)
  File "/usr/local/lib/python2.7/dist-packages/django/db/models/manager.py", line 127, in manager_method
    return getattr(self.get_queryset(), name)(*args, **kwargs)
  File "/usr/local/lib/python2.7/dist-packages/django/db/models/query.py", line 920, in _insert
    return query.get_compiler(using=using).execute_sql(return_id)
  File "/usr/local/lib/python2.7/dist-packages/django/db/models/sql/compiler.py", line 962, in execute_sql
    for sql, params in self.as_sql():
  File "/usr/local/lib/python2.7/dist-packages/django/db/models/sql/compiler.py", line 920, in as_sql
    for obj in self.query.objs
  File "/usr/local/lib/python2.7/dist-packages/django/db/models/fields/related.py", line 1940, in get_db_prep_save
    return self.related_field.get_db_prep_save(value, connection=connection)
  File "/usr/local/lib/python2.7/dist-packages/django/db/models/fields/__init__.py", line 710, in get_db_prep_save
    prepared=False)
  File "/usr/local/lib/python2.7/dist-packages/django/db/models/fields/__init__.py", line 977, in get_db_prep_value
    value = self.get_prep_value(value)
  File "/usr/local/lib/python2.7/dist-packages/django/db/models/fields/__init__.py", line 985, in get_prep_value
    return int(value)
ValueError: invalid literal for int() with base 10: '{'
Internal Server Error: /sitio
Traceback (most recent call last):
  File "/usr/local/lib/python2.7/dist-packages/django/core/handlers/base.py", line 132, in get_response
    response = wrapped_callback(request, *callback_args, **callback_kwargs)
  File "/usr/local/lib/python2.7/dist-packages/django/views/decorators/csrf.py", line 58, in wrapped_view
    return view_func(*args, **kwargs)
  File "/usr/local/lib/python2.7/dist-packages/django/views/generic/base.py", line 71, in view
    return self.dispatch(request, *args, **kwargs)
  File "/usr/local/lib/python2.7/dist-packages/rest_framework/views.py", line 407, in dispatch
    response = self.handle_exception(exc)
  File "/usr/local/lib/python2.7/dist-packages/rest_framework/views.py", line 404, in dispatch
    response = handler(request, *args, **kwargs)
  File "/usr/local/lib/python2.7/dist-packages/rest_framework/generics.py", line 314, in post
    return self.create(request, *args, **kwargs)
  File "/home/vagrant/django_shared/ecosistema/BackEnd/sitios/views.py", line 61, in create
    serializer.add_categories(data['categorias'])
  File "/home/vagrant/django_shared/ecosistema/BackEnd/sitios/serializers.py", line 63, in add_categories
    SitioCategoria.objects.create(sitio_id=self.data["id"],categoria_id=category);
  File "/usr/local/lib/python2.7/dist-packages/django/db/models/manager.py", line 127, in manager_method
    return getattr(self.get_queryset(), name)(*args, **kwargs)
  File "/usr/local/lib/python2.7/dist-packages/django/db/models/query.py", line 348, in create
    obj.save(force_insert=True, using=self.db)
  File "/usr/local/lib/python2.7/dist-packages/django/db/models/base.py", line 710, in save
    force_update=force_update, update_fields=update_fields)
  File "/usr/local/lib/python2.7/dist-packages/django/db/models/base.py", line 738, in save_base
    updated = self._save_table(raw, cls, force_insert, force_update, using, update_fields)
  File "/usr/local/lib/python2.7/dist-packages/django/db/models/base.py", line 822, in _save_table
    result = self._do_insert(cls._base_manager, using, fields, update_pk, raw)
  File "/usr/local/lib/python2.7/dist-packages/django/db/models/base.py", line 861, in _do_insert
    using=using, raw=raw)
  File "/usr/local/lib/python2.7/dist-packages/django/db/models/manager.py", line 127, in manager_method
    return getattr(self.get_queryset(), name)(*args, **kwargs)
  File "/usr/local/lib/python2.7/dist-packages/django/db/models/query.py", line 920, in _insert
    return query.get_compiler(using=using).execute_sql(return_id)
  File "/usr/local/lib/python2.7/dist-packages/django/db/models/sql/compiler.py", line 962, in execute_sql
    for sql, params in self.as_sql():
  File "/usr/local/lib/python2.7/dist-packages/django/db/models/sql/compiler.py", line 920, in as_sql
    for obj in self.query.objs
  File "/usr/local/lib/python2.7/dist-packages/django/db/models/fields/related.py", line 1940, in get_db_prep_save
    return self.related_field.get_db_prep_save(value, connection=connection)
  File "/usr/local/lib/python2.7/dist-packages/django/db/models/fields/__init__.py", line 710, in get_db_prep_save
    prepared=False)
  File "/usr/local/lib/python2.7/dist-packages/django/db/models/fields/__init__.py", line 977, in get_db_prep_value
    value = self.get_prep_value(value)
  File "/usr/local/lib/python2.7/dist-packages/django/db/models/fields/__init__.py", line 985, in get_prep_value
    return int(value)
ValueError: invalid literal for int() with base 10: '{'
Internal Server Error: /sitio/detail/1
Traceback (most recent call last):
  File "/usr/local/lib/python2.7/dist-packages/django/core/handlers/base.py", line 132, in get_response
    response = wrapped_callback(request, *callback_args, **callback_kwargs)
  File "/usr/local/lib/python2.7/dist-packages/django/views/decorators/csrf.py", line 58, in wrapped_view
    return view_func(*args, **kwargs)
  File "/usr/local/lib/python2.7/dist-packages/django/views/generic/base.py", line 71, in view
    return self.dispatch(request, *args, **kwargs)
  File "/usr/local/lib/python2.7/dist-packages/rest_framework/views.py", line 407, in dispatch
    response = self.handle_exception(exc)
  File "/usr/local/lib/python2.7/dist-packages/rest_framework/views.py", line 404, in dispatch
    response = handler(request, *args, **kwargs)
  File "/usr/local/lib/python2.7/dist-packages/rest_framework/generics.py", line 357, in put
    return self.update(request, *args, **kwargs)
  File "/home/vagrant/django_shared/ecosistema/BackEnd/sitios/views.py", line 85, in update
    serializer.add_categories(request.data['categorias'])
  File "/home/vagrant/django_shared/ecosistema/BackEnd/sitios/serializers.py", line 63, in add_categories
    SitioCategoria.objects.create(sitio_id=self.data["id"],categoria_id=category);
  File "/usr/local/lib/python2.7/dist-packages/django/db/models/manager.py", line 127, in manager_method
    return getattr(self.get_queryset(), name)(*args, **kwargs)
  File "/usr/local/lib/python2.7/dist-packages/django/db/models/query.py", line 348, in create
    obj.save(force_insert=True, using=self.db)
  File "/usr/local/lib/python2.7/dist-packages/django/db/models/base.py", line 710, in save
    force_update=force_update, update_fields=update_fields)
  File "/usr/local/lib/python2.7/dist-packages/django/db/models/base.py", line 738, in save_base
    updated = self._save_table(raw, cls, force_insert, force_update, using, update_fields)
  File "/usr/local/lib/python2.7/dist-packages/django/db/models/base.py", line 822, in _save_table
    result = self._do_insert(cls._base_manager, using, fields, update_pk, raw)
  File "/usr/local/lib/python2.7/dist-packages/django/db/models/base.py", line 861, in _do_insert
    using=using, raw=raw)
  File "/usr/local/lib/python2.7/dist-packages/django/db/models/manager.py", line 127, in manager_method
    return getattr(self.get_queryset(), name)(*args, **kwargs)
  File "/usr/local/lib/python2.7/dist-packages/django/db/models/query.py", line 920, in _insert
    return query.get_compiler(using=using).execute_sql(return_id)
  File "/usr/local/lib/python2.7/dist-packages/django/db/models/sql/compiler.py", line 962, in execute_sql
    for sql, params in self.as_sql():
  File "/usr/local/lib/python2.7/dist-packages/django/db/models/sql/compiler.py", line 920, in as_sql
    for obj in self.query.objs
  File "/usr/local/lib/python2.7/dist-packages/django/db/models/fields/related.py", line 1940, in get_db_prep_save
    return self.related_field.get_db_prep_save(value, connection=connection)
  File "/usr/local/lib/python2.7/dist-packages/django/db/models/fields/__init__.py", line 710, in get_db_prep_save
    prepared=False)
  File "/usr/local/lib/python2.7/dist-packages/django/db/models/fields/__init__.py", line 977, in get_db_prep_value
    value = self.get_prep_value(value)
  File "/usr/local/lib/python2.7/dist-packages/django/db/models/fields/__init__.py", line 985, in get_prep_value
    return int(value)
ValueError: invalid literal for int() with base 10: '{'
Internal Server Error: /sitio/detail/1
Traceback (most recent call last):
  File "/usr/local/lib/python2.7/dist-packages/django/core/handlers/base.py", line 132, in get_response
    response = wrapped_callback(request, *callback_args, **callback_kwargs)
  File "/usr/local/lib/python2.7/dist-packages/django/views/decorators/csrf.py", line 58, in wrapped_view
    return view_func(*args, **kwargs)
  File "/usr/local/lib/python2.7/dist-packages/django/views/generic/base.py", line 71, in view
    return self.dispatch(request, *args, **kwargs)
  File "/usr/local/lib/python2.7/dist-packages/rest_framework/views.py", line 407, in dispatch
    response = self.handle_exception(exc)
  File "/usr/local/lib/python2.7/dist-packages/rest_framework/views.py", line 404, in dispatch
    response = handler(request, *args, **kwargs)
  File "/usr/local/lib/python2.7/dist-packages/rest_framework/generics.py", line 357, in put
    return self.update(request, *args, **kwargs)
  File "/home/vagrant/django_shared/ecosistema/BackEnd/sitios/views.py", line 85, in update
    serializer.add_categories(request.data['categorias'])
  File "/home/vagrant/django_shared/ecosistema/BackEnd/sitios/serializers.py", line 63, in add_categories
    SitioCategoria.objects.create(sitio_id=self.data["id"],categoria_id=category);
  File "/usr/local/lib/python2.7/dist-packages/django/db/models/manager.py", line 127, in manager_method
    return getattr(self.get_queryset(), name)(*args, **kwargs)
  File "/usr/local/lib/python2.7/dist-packages/django/db/models/query.py", line 348, in create
    obj.save(force_insert=True, using=self.db)
  File "/usr/local/lib/python2.7/dist-packages/django/db/models/base.py", line 710, in save
    force_update=force_update, update_fields=update_fields)
  File "/usr/local/lib/python2.7/dist-packages/django/db/models/base.py", line 738, in save_base
    updated = self._save_table(raw, cls, force_insert, force_update, using, update_fields)
  File "/usr/local/lib/python2.7/dist-packages/django/db/models/base.py", line 822, in _save_table
    result = self._do_insert(cls._base_manager, using, fields, update_pk, raw)
  File "/usr/local/lib/python2.7/dist-packages/django/db/models/base.py", line 861, in _do_insert
    using=using, raw=raw)
  File "/usr/local/lib/python2.7/dist-packages/django/db/models/manager.py", line 127, in manager_method
    return getattr(self.get_queryset(), name)(*args, **kwargs)
  File "/usr/local/lib/python2.7/dist-packages/django/db/models/query.py", line 920, in _insert
    return query.get_compiler(using=using).execute_sql(return_id)
  File "/usr/local/lib/python2.7/dist-packages/django/db/models/sql/compiler.py", line 962, in execute_sql
    for sql, params in self.as_sql():
  File "/usr/local/lib/python2.7/dist-packages/django/db/models/sql/compiler.py", line 920, in as_sql
    for obj in self.query.objs
  File "/usr/local/lib/python2.7/dist-packages/django/db/models/fields/related.py", line 1940, in get_db_prep_save
    return self.related_field.get_db_prep_save(value, connection=connection)
  File "/usr/local/lib/python2.7/dist-packages/django/db/models/fields/__init__.py", line 710, in get_db_prep_save
    prepared=False)
  File "/usr/local/lib/python2.7/dist-packages/django/db/models/fields/__init__.py", line 977, in get_db_prep_value
    value = self.get_prep_value(value)
  File "/usr/local/lib/python2.7/dist-packages/django/db/models/fields/__init__.py", line 985, in get_prep_value
    return int(value)
ValueError: invalid literal for int() with base 10: '{'
Internal Server Error: /sitio/detail/1
Traceback (most recent call last):
  File "/usr/local/lib/python2.7/dist-packages/django/core/handlers/base.py", line 132, in get_response
    response = wrapped_callback(request, *callback_args, **callback_kwargs)
  File "/usr/local/lib/python2.7/dist-packages/django/views/decorators/csrf.py", line 58, in wrapped_view
    return view_func(*args, **kwargs)
  File "/usr/local/lib/python2.7/dist-packages/django/views/generic/base.py", line 71, in view
    return self.dispatch(request, *args, **kwargs)
  File "/usr/local/lib/python2.7/dist-packages/rest_framework/views.py", line 407, in dispatch
    response = self.handle_exception(exc)
  File "/usr/local/lib/python2.7/dist-packages/rest_framework/views.py", line 404, in dispatch
    response = handler(request, *args, **kwargs)
  File "/usr/local/lib/python2.7/dist-packages/rest_framework/generics.py", line 357, in put
    return self.update(request, *args, **kwargs)
  File "/home/vagrant/django_shared/ecosistema/BackEnd/sitios/views.py", line 85, in update
    serializer.add_categories(request.data['categorias'])
  File "/home/vagrant/django_shared/ecosistema/BackEnd/sitios/serializers.py", line 63, in add_categories
    SitioCategoria.objects.create(sitio_id=self.data["id"],categoria_id=category);
  File "/usr/local/lib/python2.7/dist-packages/django/db/models/manager.py", line 127, in manager_method
    return getattr(self.get_queryset(), name)(*args, **kwargs)
  File "/usr/local/lib/python2.7/dist-packages/django/db/models/query.py", line 348, in create
    obj.save(force_insert=True, using=self.db)
  File "/usr/local/lib/python2.7/dist-packages/django/db/models/base.py", line 710, in save
    force_update=force_update, update_fields=update_fields)
  File "/usr/local/lib/python2.7/dist-packages/django/db/models/base.py", line 738, in save_base
    updated = self._save_table(raw, cls, force_insert, force_update, using, update_fields)
  File "/usr/local/lib/python2.7/dist-packages/django/db/models/base.py", line 822, in _save_table
    result = self._do_insert(cls._base_manager, using, fields, update_pk, raw)
  File "/usr/local/lib/python2.7/dist-packages/django/db/models/base.py", line 861, in _do_insert
    using=using, raw=raw)
  File "/usr/local/lib/python2.7/dist-packages/django/db/models/manager.py", line 127, in manager_method
    return getattr(self.get_queryset(), name)(*args, **kwargs)
  File "/usr/local/lib/python2.7/dist-packages/django/db/models/query.py", line 920, in _insert
    return query.get_compiler(using=using).execute_sql(return_id)
  File "/usr/local/lib/python2.7/dist-packages/django/db/models/sql/compiler.py", line 962, in execute_sql
    for sql, params in self.as_sql():
  File "/usr/local/lib/python2.7/dist-packages/django/db/models/sql/compiler.py", line 920, in as_sql
    for obj in self.query.objs
  File "/usr/local/lib/python2.7/dist-packages/django/db/models/fields/related.py", line 1940, in get_db_prep_save
    return self.related_field.get_db_prep_save(value, connection=connection)
  File "/usr/local/lib/python2.7/dist-packages/django/db/models/fields/__init__.py", line 710, in get_db_prep_save
    prepared=False)
  File "/usr/local/lib/python2.7/dist-packages/django/db/models/fields/__init__.py", line 977, in get_db_prep_value
    value = self.get_prep_value(value)
  File "/usr/local/lib/python2.7/dist-packages/django/db/models/fields/__init__.py", line 985, in get_prep_value
    return int(value)
ValueError: invalid literal for int() with base 10: '{'
Internal Server Error: /sitio
Traceback (most recent call last):
  File "/usr/local/lib/python2.7/dist-packages/django/core/handlers/base.py", line 132, in get_response
    response = wrapped_callback(request, *callback_args, **callback_kwargs)
  File "/usr/local/lib/python2.7/dist-packages/django/views/decorators/csrf.py", line 58, in wrapped_view
    return view_func(*args, **kwargs)
  File "/usr/local/lib/python2.7/dist-packages/django/views/generic/base.py", line 71, in view
    return self.dispatch(request, *args, **kwargs)
  File "/usr/local/lib/python2.7/dist-packages/rest_framework/views.py", line 407, in dispatch
    response = self.handle_exception(exc)
  File "/usr/local/lib/python2.7/dist-packages/rest_framework/views.py", line 404, in dispatch
    response = handler(request, *args, **kwargs)
  File "/usr/local/lib/python2.7/dist-packages/rest_framework/generics.py", line 314, in post
    return self.create(request, *args, **kwargs)
  File "/home/vagrant/django_shared/ecosistema/BackEnd/sitios/views.py", line 61, in create
    serializer.add_categories(data['categorias'])
  File "/home/vagrant/django_shared/ecosistema/BackEnd/sitios/serializers.py", line 63, in add_categories
    SitioCategoria.objects.create(sitio_id=self.data["id"],categoria_id=category["categoria_id"],tipo=category["tipo"]);
TypeError: string indices must be integers
Internal Server Error: /sitio
Traceback (most recent call last):
  File "/usr/local/lib/python2.7/dist-packages/django/core/handlers/base.py", line 132, in get_response
    response = wrapped_callback(request, *callback_args, **callback_kwargs)
  File "/usr/local/lib/python2.7/dist-packages/django/views/decorators/csrf.py", line 58, in wrapped_view
    return view_func(*args, **kwargs)
  File "/usr/local/lib/python2.7/dist-packages/django/views/generic/base.py", line 71, in view
    return self.dispatch(request, *args, **kwargs)
  File "/usr/local/lib/python2.7/dist-packages/rest_framework/views.py", line 407, in dispatch
    response = self.handle_exception(exc)
  File "/usr/local/lib/python2.7/dist-packages/rest_framework/views.py", line 404, in dispatch
    response = handler(request, *args, **kwargs)
  File "/usr/local/lib/python2.7/dist-packages/rest_framework/generics.py", line 314, in post
    return self.create(request, *args, **kwargs)
  File "/home/vagrant/django_shared/ecosistema/BackEnd/sitios/views.py", line 61, in create
    serializer.add_categories(data['categorias'])
  File "/home/vagrant/django_shared/ecosistema/BackEnd/sitios/serializers.py", line 63, in add_categories
    SitioCategoria.objects.create(sitio_id=self.data["id"],categoria_id=category["categoria_id"],tipo=category["tipo"]);
TypeError: string indices must be integers
Internal Server Error: /sitio/detail/1
Traceback (most recent call last):
  File "/usr/local/lib/python2.7/dist-packages/django/core/handlers/base.py", line 132, in get_response
    response = wrapped_callback(request, *callback_args, **callback_kwargs)
  File "/usr/local/lib/python2.7/dist-packages/django/views/decorators/csrf.py", line 58, in wrapped_view
    return view_func(*args, **kwargs)
  File "/usr/local/lib/python2.7/dist-packages/django/views/generic/base.py", line 71, in view
    return self.dispatch(request, *args, **kwargs)
  File "/usr/local/lib/python2.7/dist-packages/rest_framework/views.py", line 407, in dispatch
    response = self.handle_exception(exc)
  File "/usr/local/lib/python2.7/dist-packages/rest_framework/views.py", line 404, in dispatch
    response = handler(request, *args, **kwargs)
  File "/usr/local/lib/python2.7/dist-packages/rest_framework/generics.py", line 357, in put
    return self.update(request, *args, **kwargs)
  File "/home/vagrant/django_shared/ecosistema/BackEnd/sitios/views.py", line 85, in update
    serializer.add_categories(request.data['categorias'])
  File "/home/vagrant/django_shared/ecosistema/BackEnd/sitios/serializers.py", line 63, in add_categories
    SitioCategoria.objects.create(sitio_id=self.data["id"],categoria_id=category["categoria_id"],tipo=category["tipo"]);
TypeError: string indices must be integers
Internal Server Error: /sitio/detail/1
Traceback (most recent call last):
  File "/usr/local/lib/python2.7/dist-packages/django/core/handlers/base.py", line 132, in get_response
    response = wrapped_callback(request, *callback_args, **callback_kwargs)
  File "/usr/local/lib/python2.7/dist-packages/django/views/decorators/csrf.py", line 58, in wrapped_view
    return view_func(*args, **kwargs)
  File "/usr/local/lib/python2.7/dist-packages/django/views/generic/base.py", line 71, in view
    return self.dispatch(request, *args, **kwargs)
  File "/usr/local/lib/python2.7/dist-packages/rest_framework/views.py", line 407, in dispatch
    response = self.handle_exception(exc)
  File "/usr/local/lib/python2.7/dist-packages/rest_framework/views.py", line 404, in dispatch
    response = handler(request, *args, **kwargs)
  File "/usr/local/lib/python2.7/dist-packages/rest_framework/generics.py", line 357, in put
    return self.update(request, *args, **kwargs)
  File "/home/vagrant/django_shared/ecosistema/BackEnd/sitios/views.py", line 85, in update
    serializer.add_categories(request.data['categorias'])
  File "/home/vagrant/django_shared/ecosistema/BackEnd/sitios/serializers.py", line 63, in add_categories
    SitioCategoria.objects.create(sitio_id=self.data["id"],categoria_id=category["categoria_id"],tipo=category["tipo"]);
TypeError: string indices must be integers
Internal Server Error: /sitio/detail/1
Traceback (most recent call last):
  File "/usr/local/lib/python2.7/dist-packages/django/core/handlers/base.py", line 132, in get_response
    response = wrapped_callback(request, *callback_args, **callback_kwargs)
  File "/usr/local/lib/python2.7/dist-packages/django/views/decorators/csrf.py", line 58, in wrapped_view
    return view_func(*args, **kwargs)
  File "/usr/local/lib/python2.7/dist-packages/django/views/generic/base.py", line 71, in view
    return self.dispatch(request, *args, **kwargs)
  File "/usr/local/lib/python2.7/dist-packages/rest_framework/views.py", line 407, in dispatch
    response = self.handle_exception(exc)
  File "/usr/local/lib/python2.7/dist-packages/rest_framework/views.py", line 404, in dispatch
    response = handler(request, *args, **kwargs)
  File "/usr/local/lib/python2.7/dist-packages/rest_framework/generics.py", line 357, in put
    return self.update(request, *args, **kwargs)
  File "/home/vagrant/django_shared/ecosistema/BackEnd/sitios/views.py", line 85, in update
    serializer.add_categories(request.data['categorias'])
  File "/home/vagrant/django_shared/ecosistema/BackEnd/sitios/serializers.py", line 63, in add_categories
    SitioCategoria.objects.create(sitio_id=self.data["id"],categoria_id=category["categoria_id"],tipo=category["tipo"]);
TypeError: string indices must be integers
Internal Server Error: /sitio
Traceback (most recent call last):
  File "/usr/local/lib/python2.7/dist-packages/django/core/handlers/base.py", line 132, in get_response
    response = wrapped_callback(request, *callback_args, **callback_kwargs)
  File "/usr/local/lib/python2.7/dist-packages/django/views/decorators/csrf.py", line 58, in wrapped_view
    return view_func(*args, **kwargs)
  File "/usr/local/lib/python2.7/dist-packages/django/views/generic/base.py", line 71, in view
    return self.dispatch(request, *args, **kwargs)
  File "/usr/local/lib/python2.7/dist-packages/rest_framework/views.py", line 407, in dispatch
    response = self.handle_exception(exc)
  File "/usr/local/lib/python2.7/dist-packages/rest_framework/views.py", line 404, in dispatch
    response = handler(request, *args, **kwargs)
  File "/usr/local/lib/python2.7/dist-packages/rest_framework/generics.py", line 314, in post
    return self.create(request, *args, **kwargs)
  File "/home/vagrant/django_shared/ecosistema/BackEnd/sitios/views.py", line 61, in create
    serializer.add_categories(data['categorias'])
  File "/home/vagrant/django_shared/ecosistema/BackEnd/sitios/serializers.py", line 64, in add_categories
    SitioCategoria.objects.create(sitio_id=self.data["id"],categoria_id=category["categoria_id"],tipo=category["tipo"]);
TypeError: string indices must be integers
Internal Server Error: /sitio
Traceback (most recent call last):
  File "/usr/local/lib/python2.7/dist-packages/django/core/handlers/base.py", line 132, in get_response
    response = wrapped_callback(request, *callback_args, **callback_kwargs)
  File "/usr/local/lib/python2.7/dist-packages/django/views/decorators/csrf.py", line 58, in wrapped_view
    return view_func(*args, **kwargs)
  File "/usr/local/lib/python2.7/dist-packages/django/views/generic/base.py", line 71, in view
    return self.dispatch(request, *args, **kwargs)
  File "/usr/local/lib/python2.7/dist-packages/rest_framework/views.py", line 407, in dispatch
    response = self.handle_exception(exc)
  File "/usr/local/lib/python2.7/dist-packages/rest_framework/views.py", line 404, in dispatch
    response = handler(request, *args, **kwargs)
  File "/usr/local/lib/python2.7/dist-packages/rest_framework/generics.py", line 314, in post
    return self.create(request, *args, **kwargs)
  File "/home/vagrant/django_shared/ecosistema/BackEnd/sitios/views.py", line 61, in create
    serializer.add_categories(data['categorias'])
  File "/home/vagrant/django_shared/ecosistema/BackEnd/sitios/serializers.py", line 64, in add_categories
    SitioCategoria.objects.create(sitio_id=self.data["id"],categoria_id=category["categoria_id"],tipo=category["tipo"]);
TypeError: string indices must be integers
Internal Server Error: /sitio/detail/1
Traceback (most recent call last):
  File "/usr/local/lib/python2.7/dist-packages/django/core/handlers/base.py", line 132, in get_response
    response = wrapped_callback(request, *callback_args, **callback_kwargs)
  File "/usr/local/lib/python2.7/dist-packages/django/views/decorators/csrf.py", line 58, in wrapped_view
    return view_func(*args, **kwargs)
  File "/usr/local/lib/python2.7/dist-packages/django/views/generic/base.py", line 71, in view
    return self.dispatch(request, *args, **kwargs)
  File "/usr/local/lib/python2.7/dist-packages/rest_framework/views.py", line 407, in dispatch
    response = self.handle_exception(exc)
  File "/usr/local/lib/python2.7/dist-packages/rest_framework/views.py", line 404, in dispatch
    response = handler(request, *args, **kwargs)
  File "/usr/local/lib/python2.7/dist-packages/rest_framework/generics.py", line 357, in put
    return self.update(request, *args, **kwargs)
  File "/home/vagrant/django_shared/ecosistema/BackEnd/sitios/views.py", line 85, in update
    serializer.add_categories(request.data['categorias'])
  File "/home/vagrant/django_shared/ecosistema/BackEnd/sitios/serializers.py", line 64, in add_categories
    SitioCategoria.objects.create(sitio_id=self.data["id"],categoria_id=category["categoria_id"],tipo=category["tipo"]);
TypeError: string indices must be integers
Internal Server Error: /sitio/detail/1
Traceback (most recent call last):
  File "/usr/local/lib/python2.7/dist-packages/django/core/handlers/base.py", line 132, in get_response
    response = wrapped_callback(request, *callback_args, **callback_kwargs)
  File "/usr/local/lib/python2.7/dist-packages/django/views/decorators/csrf.py", line 58, in wrapped_view
    return view_func(*args, **kwargs)
  File "/usr/local/lib/python2.7/dist-packages/django/views/generic/base.py", line 71, in view
    return self.dispatch(request, *args, **kwargs)
  File "/usr/local/lib/python2.7/dist-packages/rest_framework/views.py", line 407, in dispatch
    response = self.handle_exception(exc)
  File "/usr/local/lib/python2.7/dist-packages/rest_framework/views.py", line 404, in dispatch
    response = handler(request, *args, **kwargs)
  File "/usr/local/lib/python2.7/dist-packages/rest_framework/generics.py", line 357, in put
    return self.update(request, *args, **kwargs)
  File "/home/vagrant/django_shared/ecosistema/BackEnd/sitios/views.py", line 85, in update
    serializer.add_categories(request.data['categorias'])
  File "/home/vagrant/django_shared/ecosistema/BackEnd/sitios/serializers.py", line 64, in add_categories
    SitioCategoria.objects.create(sitio_id=self.data["id"],categoria_id=category["categoria_id"],tipo=category["tipo"]);
TypeError: string indices must be integers
Internal Server Error: /sitio/detail/1
Traceback (most recent call last):
  File "/usr/local/lib/python2.7/dist-packages/django/core/handlers/base.py", line 132, in get_response
    response = wrapped_callback(request, *callback_args, **callback_kwargs)
  File "/usr/local/lib/python2.7/dist-packages/django/views/decorators/csrf.py", line 58, in wrapped_view
    return view_func(*args, **kwargs)
  File "/usr/local/lib/python2.7/dist-packages/django/views/generic/base.py", line 71, in view
    return self.dispatch(request, *args, **kwargs)
  File "/usr/local/lib/python2.7/dist-packages/rest_framework/views.py", line 407, in dispatch
    response = self.handle_exception(exc)
  File "/usr/local/lib/python2.7/dist-packages/rest_framework/views.py", line 404, in dispatch
    response = handler(request, *args, **kwargs)
  File "/usr/local/lib/python2.7/dist-packages/rest_framework/generics.py", line 357, in put
    return self.update(request, *args, **kwargs)
  File "/home/vagrant/django_shared/ecosistema/BackEnd/sitios/views.py", line 85, in update
    serializer.add_categories(request.data['categorias'])
  File "/home/vagrant/django_shared/ecosistema/BackEnd/sitios/serializers.py", line 64, in add_categories
    SitioCategoria.objects.create(sitio_id=self.data["id"],categoria_id=category["categoria_id"],tipo=category["tipo"]);
TypeError: string indices must be integers
Internal Server Error: /sitio
Traceback (most recent call last):
  File "/usr/local/lib/python2.7/dist-packages/django/core/handlers/base.py", line 132, in get_response
    response = wrapped_callback(request, *callback_args, **callback_kwargs)
  File "/usr/local/lib/python2.7/dist-packages/django/views/decorators/csrf.py", line 58, in wrapped_view
    return view_func(*args, **kwargs)
  File "/usr/local/lib/python2.7/dist-packages/django/views/generic/base.py", line 71, in view
    return self.dispatch(request, *args, **kwargs)
  File "/usr/local/lib/python2.7/dist-packages/rest_framework/views.py", line 407, in dispatch
    response = self.handle_exception(exc)
  File "/usr/local/lib/python2.7/dist-packages/rest_framework/views.py", line 404, in dispatch
    response = handler(request, *args, **kwargs)
  File "/usr/local/lib/python2.7/dist-packages/rest_framework/generics.py", line 314, in post
    return self.create(request, *args, **kwargs)
  File "/home/vagrant/django_shared/ecosistema/BackEnd/sitios/views.py", line 61, in create
    serializer.add_categories(data['categorias'])
  File "/home/vagrant/django_shared/ecosistema/BackEnd/sitios/serializers.py", line 65, in add_categories
    SitioCategoria.objects.create(sitio_id=self.data["id"],categoria_id=category["categoria_id"],tipo=category["tipo"]);
TypeError: string indices must be integers
Internal Server Error: /sitio
Traceback (most recent call last):
  File "/usr/local/lib/python2.7/dist-packages/django/core/handlers/base.py", line 132, in get_response
    response = wrapped_callback(request, *callback_args, **callback_kwargs)
  File "/usr/local/lib/python2.7/dist-packages/django/views/decorators/csrf.py", line 58, in wrapped_view
    return view_func(*args, **kwargs)
  File "/usr/local/lib/python2.7/dist-packages/django/views/generic/base.py", line 71, in view
    return self.dispatch(request, *args, **kwargs)
  File "/usr/local/lib/python2.7/dist-packages/rest_framework/views.py", line 407, in dispatch
    response = self.handle_exception(exc)
  File "/usr/local/lib/python2.7/dist-packages/rest_framework/views.py", line 404, in dispatch
    response = handler(request, *args, **kwargs)
  File "/usr/local/lib/python2.7/dist-packages/rest_framework/generics.py", line 314, in post
    return self.create(request, *args, **kwargs)
  File "/home/vagrant/django_shared/ecosistema/BackEnd/sitios/views.py", line 61, in create
    serializer.add_categories(data['categorias'])
  File "/home/vagrant/django_shared/ecosistema/BackEnd/sitios/serializers.py", line 65, in add_categories
    SitioCategoria.objects.create(sitio_id=self.data["id"],categoria_id=category["categoria_id"],tipo=category["tipo"]);
TypeError: string indices must be integers
Internal Server Error: /sitio/detail/1
Traceback (most recent call last):
  File "/usr/local/lib/python2.7/dist-packages/django/core/handlers/base.py", line 132, in get_response
    response = wrapped_callback(request, *callback_args, **callback_kwargs)
  File "/usr/local/lib/python2.7/dist-packages/django/views/decorators/csrf.py", line 58, in wrapped_view
    return view_func(*args, **kwargs)
  File "/usr/local/lib/python2.7/dist-packages/django/views/generic/base.py", line 71, in view
    return self.dispatch(request, *args, **kwargs)
  File "/usr/local/lib/python2.7/dist-packages/rest_framework/views.py", line 407, in dispatch
    response = self.handle_exception(exc)
  File "/usr/local/lib/python2.7/dist-packages/rest_framework/views.py", line 404, in dispatch
    response = handler(request, *args, **kwargs)
  File "/usr/local/lib/python2.7/dist-packages/rest_framework/generics.py", line 357, in put
    return self.update(request, *args, **kwargs)
  File "/home/vagrant/django_shared/ecosistema/BackEnd/sitios/views.py", line 85, in update
    serializer.add_categories(request.data['categorias'])
  File "/home/vagrant/django_shared/ecosistema/BackEnd/sitios/serializers.py", line 65, in add_categories
    SitioCategoria.objects.create(sitio_id=self.data["id"],categoria_id=category["categoria_id"],tipo=category["tipo"]);
TypeError: string indices must be integers
Internal Server Error: /sitio/detail/1
Traceback (most recent call last):
  File "/usr/local/lib/python2.7/dist-packages/django/core/handlers/base.py", line 132, in get_response
    response = wrapped_callback(request, *callback_args, **callback_kwargs)
  File "/usr/local/lib/python2.7/dist-packages/django/views/decorators/csrf.py", line 58, in wrapped_view
    return view_func(*args, **kwargs)
  File "/usr/local/lib/python2.7/dist-packages/django/views/generic/base.py", line 71, in view
    return self.dispatch(request, *args, **kwargs)
  File "/usr/local/lib/python2.7/dist-packages/rest_framework/views.py", line 407, in dispatch
    response = self.handle_exception(exc)
  File "/usr/local/lib/python2.7/dist-packages/rest_framework/views.py", line 404, in dispatch
    response = handler(request, *args, **kwargs)
  File "/usr/local/lib/python2.7/dist-packages/rest_framework/generics.py", line 357, in put
    return self.update(request, *args, **kwargs)
  File "/home/vagrant/django_shared/ecosistema/BackEnd/sitios/views.py", line 85, in update
    serializer.add_categories(request.data['categorias'])
  File "/home/vagrant/django_shared/ecosistema/BackEnd/sitios/serializers.py", line 65, in add_categories
    SitioCategoria.objects.create(sitio_id=self.data["id"],categoria_id=category["categoria_id"],tipo=category["tipo"]);
TypeError: string indices must be integers
Internal Server Error: /sitio/detail/1
Traceback (most recent call last):
  File "/usr/local/lib/python2.7/dist-packages/django/core/handlers/base.py", line 132, in get_response
    response = wrapped_callback(request, *callback_args, **callback_kwargs)
  File "/usr/local/lib/python2.7/dist-packages/django/views/decorators/csrf.py", line 58, in wrapped_view
    return view_func(*args, **kwargs)
  File "/usr/local/lib/python2.7/dist-packages/django/views/generic/base.py", line 71, in view
    return self.dispatch(request, *args, **kwargs)
  File "/usr/local/lib/python2.7/dist-packages/rest_framework/views.py", line 407, in dispatch
    response = self.handle_exception(exc)
  File "/usr/local/lib/python2.7/dist-packages/rest_framework/views.py", line 404, in dispatch
    response = handler(request, *args, **kwargs)
  File "/usr/local/lib/python2.7/dist-packages/rest_framework/generics.py", line 357, in put
    return self.update(request, *args, **kwargs)
  File "/home/vagrant/django_shared/ecosistema/BackEnd/sitios/views.py", line 85, in update
    serializer.add_categories(request.data['categorias'])
  File "/home/vagrant/django_shared/ecosistema/BackEnd/sitios/serializers.py", line 65, in add_categories
    SitioCategoria.objects.create(sitio_id=self.data["id"],categoria_id=category["categoria_id"],tipo=category["tipo"]);
TypeError: string indices must be integers
Internal Server Error: /sitio
Traceback (most recent call last):
  File "/usr/local/lib/python2.7/dist-packages/django/core/handlers/base.py", line 132, in get_response
    response = wrapped_callback(request, *callback_args, **callback_kwargs)
  File "/usr/local/lib/python2.7/dist-packages/django/views/decorators/csrf.py", line 58, in wrapped_view
    return view_func(*args, **kwargs)
  File "/usr/local/lib/python2.7/dist-packages/django/views/generic/base.py", line 71, in view
    return self.dispatch(request, *args, **kwargs)
  File "/usr/local/lib/python2.7/dist-packages/rest_framework/views.py", line 407, in dispatch
    response = self.handle_exception(exc)
  File "/usr/local/lib/python2.7/dist-packages/rest_framework/views.py", line 404, in dispatch
    response = handler(request, *args, **kwargs)
  File "/usr/local/lib/python2.7/dist-packages/rest_framework/generics.py", line 314, in post
    return self.create(request, *args, **kwargs)
  File "/home/vagrant/django_shared/ecosistema/BackEnd/sitios/views.py", line 61, in create
    serializer.add_categories(data['categorias'])
  File "/home/vagrant/django_shared/ecosistema/BackEnd/sitios/serializers.py", line 65, in add_categories
    SitioCategoria.objects.create(sitio_id=self.data["id"],categoria_id=category["categoria_id"],tipo=category["tipo"]);
TypeError: string indices must be integers
Internal Server Error: /sitio
Traceback (most recent call last):
  File "/usr/local/lib/python2.7/dist-packages/django/core/handlers/base.py", line 132, in get_response
    response = wrapped_callback(request, *callback_args, **callback_kwargs)
  File "/usr/local/lib/python2.7/dist-packages/django/views/decorators/csrf.py", line 58, in wrapped_view
    return view_func(*args, **kwargs)
  File "/usr/local/lib/python2.7/dist-packages/django/views/generic/base.py", line 71, in view
    return self.dispatch(request, *args, **kwargs)
  File "/usr/local/lib/python2.7/dist-packages/rest_framework/views.py", line 407, in dispatch
    response = self.handle_exception(exc)
  File "/usr/local/lib/python2.7/dist-packages/rest_framework/views.py", line 404, in dispatch
    response = handler(request, *args, **kwargs)
  File "/usr/local/lib/python2.7/dist-packages/rest_framework/generics.py", line 314, in post
    return self.create(request, *args, **kwargs)
  File "/home/vagrant/django_shared/ecosistema/BackEnd/sitios/views.py", line 61, in create
    serializer.add_categories(data['categorias'])
  File "/home/vagrant/django_shared/ecosistema/BackEnd/sitios/serializers.py", line 65, in add_categories
    SitioCategoria.objects.create(sitio_id=self.data["id"],categoria_id=category["categoria_id"],tipo=category["tipo"]);
TypeError: string indices must be integers
Internal Server Error: /sitio/detail/1
Traceback (most recent call last):
  File "/usr/local/lib/python2.7/dist-packages/django/core/handlers/base.py", line 132, in get_response
    response = wrapped_callback(request, *callback_args, **callback_kwargs)
  File "/usr/local/lib/python2.7/dist-packages/django/views/decorators/csrf.py", line 58, in wrapped_view
    return view_func(*args, **kwargs)
  File "/usr/local/lib/python2.7/dist-packages/django/views/generic/base.py", line 71, in view
    return self.dispatch(request, *args, **kwargs)
  File "/usr/local/lib/python2.7/dist-packages/rest_framework/views.py", line 407, in dispatch
    response = self.handle_exception(exc)
  File "/usr/local/lib/python2.7/dist-packages/rest_framework/views.py", line 404, in dispatch
    response = handler(request, *args, **kwargs)
  File "/usr/local/lib/python2.7/dist-packages/rest_framework/generics.py", line 357, in put
    return self.update(request, *args, **kwargs)
  File "/home/vagrant/django_shared/ecosistema/BackEnd/sitios/views.py", line 85, in update
    serializer.add_categories(request.data['categorias'])
  File "/home/vagrant/django_shared/ecosistema/BackEnd/sitios/serializers.py", line 65, in add_categories
    SitioCategoria.objects.create(sitio_id=self.data["id"],categoria_id=category["categoria_id"],tipo=category["tipo"]);
TypeError: string indices must be integers
Internal Server Error: /sitio/detail/1
Traceback (most recent call last):
  File "/usr/local/lib/python2.7/dist-packages/django/core/handlers/base.py", line 132, in get_response
    response = wrapped_callback(request, *callback_args, **callback_kwargs)
  File "/usr/local/lib/python2.7/dist-packages/django/views/decorators/csrf.py", line 58, in wrapped_view
    return view_func(*args, **kwargs)
  File "/usr/local/lib/python2.7/dist-packages/django/views/generic/base.py", line 71, in view
    return self.dispatch(request, *args, **kwargs)
  File "/usr/local/lib/python2.7/dist-packages/rest_framework/views.py", line 407, in dispatch
    response = self.handle_exception(exc)
  File "/usr/local/lib/python2.7/dist-packages/rest_framework/views.py", line 404, in dispatch
    response = handler(request, *args, **kwargs)
  File "/usr/local/lib/python2.7/dist-packages/rest_framework/generics.py", line 357, in put
    return self.update(request, *args, **kwargs)
  File "/home/vagrant/django_shared/ecosistema/BackEnd/sitios/views.py", line 85, in update
    serializer.add_categories(request.data['categorias'])
  File "/home/vagrant/django_shared/ecosistema/BackEnd/sitios/serializers.py", line 65, in add_categories
    SitioCategoria.objects.create(sitio_id=self.data["id"],categoria_id=category["categoria_id"],tipo=category["tipo"]);
TypeError: string indices must be integers
Internal Server Error: /sitio/detail/1
Traceback (most recent call last):
  File "/usr/local/lib/python2.7/dist-packages/django/core/handlers/base.py", line 132, in get_response
    response = wrapped_callback(request, *callback_args, **callback_kwargs)
  File "/usr/local/lib/python2.7/dist-packages/django/views/decorators/csrf.py", line 58, in wrapped_view
    return view_func(*args, **kwargs)
  File "/usr/local/lib/python2.7/dist-packages/django/views/generic/base.py", line 71, in view
    return self.dispatch(request, *args, **kwargs)
  File "/usr/local/lib/python2.7/dist-packages/rest_framework/views.py", line 407, in dispatch
    response = self.handle_exception(exc)
  File "/usr/local/lib/python2.7/dist-packages/rest_framework/views.py", line 404, in dispatch
    response = handler(request, *args, **kwargs)
  File "/usr/local/lib/python2.7/dist-packages/rest_framework/generics.py", line 357, in put
    return self.update(request, *args, **kwargs)
  File "/home/vagrant/django_shared/ecosistema/BackEnd/sitios/views.py", line 85, in update
    serializer.add_categories(request.data['categorias'])
  File "/home/vagrant/django_shared/ecosistema/BackEnd/sitios/serializers.py", line 65, in add_categories
    SitioCategoria.objects.create(sitio_id=self.data["id"],categoria_id=category["categoria_id"],tipo=category["tipo"]);
TypeError: string indices must be integers
Internal Server Error: /sitio/detail/1
Traceback (most recent call last):
  File "/usr/local/lib/python2.7/dist-packages/django/core/handlers/base.py", line 132, in get_response
    response = wrapped_callback(request, *callback_args, **callback_kwargs)
  File "/usr/local/lib/python2.7/dist-packages/django/views/decorators/csrf.py", line 58, in wrapped_view
    return view_func(*args, **kwargs)
  File "/usr/local/lib/python2.7/dist-packages/django/views/generic/base.py", line 71, in view
    return self.dispatch(request, *args, **kwargs)
  File "/usr/local/lib/python2.7/dist-packages/rest_framework/views.py", line 407, in dispatch
    response = self.handle_exception(exc)
  File "/usr/local/lib/python2.7/dist-packages/rest_framework/views.py", line 404, in dispatch
    response = handler(request, *args, **kwargs)
  File "/usr/local/lib/python2.7/dist-packages/rest_framework/generics.py", line 357, in put
    return self.update(request, *args, **kwargs)
  File "/home/vagrant/django_shared/ecosistema/BackEnd/sitios/views.py", line 85, in update
    serializer.add_categories(request.data['categorias'])
  File "/home/vagrant/django_shared/ecosistema/BackEnd/sitios/serializers.py", line 65, in add_categories
    SitioCategoria.objects.create(sitio_id=self.data["id"],categoria_id=category["categoria_id"],tipo=category["tipo"]);
TypeError: string indices must be integers
Internal Server Error: /sitio/detail/1
Traceback (most recent call last):
  File "/usr/local/lib/python2.7/dist-packages/django/core/handlers/base.py", line 132, in get_response
    response = wrapped_callback(request, *callback_args, **callback_kwargs)
  File "/usr/local/lib/python2.7/dist-packages/django/views/decorators/csrf.py", line 58, in wrapped_view
    return view_func(*args, **kwargs)
  File "/usr/local/lib/python2.7/dist-packages/django/views/generic/base.py", line 71, in view
    return self.dispatch(request, *args, **kwargs)
  File "/usr/local/lib/python2.7/dist-packages/rest_framework/views.py", line 407, in dispatch
    response = self.handle_exception(exc)
  File "/usr/local/lib/python2.7/dist-packages/rest_framework/views.py", line 404, in dispatch
    response = handler(request, *args, **kwargs)
  File "/usr/local/lib/python2.7/dist-packages/rest_framework/generics.py", line 357, in put
    return self.update(request, *args, **kwargs)
  File "/home/vagrant/django_shared/ecosistema/BackEnd/sitios/views.py", line 85, in update
    serializer.add_categories(request.data['categorias'])
  File "/home/vagrant/django_shared/ecosistema/BackEnd/sitios/serializers.py", line 65, in add_categories
    SitioCategoria.objects.create(sitio_id=self.data["id"],categoria_id=category["categoria_id"],tipo=category["tipo"]);
TypeError: string indices must be integers
Internal Server Error: /sitio/detail/1
Traceback (most recent call last):
  File "/usr/local/lib/python2.7/dist-packages/django/core/handlers/base.py", line 132, in get_response
    response = wrapped_callback(request, *callback_args, **callback_kwargs)
  File "/usr/local/lib/python2.7/dist-packages/django/views/decorators/csrf.py", line 58, in wrapped_view
    return view_func(*args, **kwargs)
  File "/usr/local/lib/python2.7/dist-packages/django/views/generic/base.py", line 71, in view
    return self.dispatch(request, *args, **kwargs)
  File "/usr/local/lib/python2.7/dist-packages/rest_framework/views.py", line 407, in dispatch
    response = self.handle_exception(exc)
  File "/usr/local/lib/python2.7/dist-packages/rest_framework/views.py", line 404, in dispatch
    response = handler(request, *args, **kwargs)
  File "/usr/local/lib/python2.7/dist-packages/rest_framework/generics.py", line 357, in put
    return self.update(request, *args, **kwargs)
  File "/home/vagrant/django_shared/ecosistema/BackEnd/sitios/views.py", line 85, in update
    serializer.add_categories(request.data['categorias'])
  File "/home/vagrant/django_shared/ecosistema/BackEnd/sitios/serializers.py", line 65, in add_categories
    SitioCategoria.objects.create(sitio_id=self.data["id"],categoria_id=category["categoria_id"],tipo=category["tipo"]);
TypeError: string indices must be integers
Internal Server Error: /sitio/detail/1
Traceback (most recent call last):
  File "/usr/local/lib/python2.7/dist-packages/django/core/handlers/base.py", line 132, in get_response
    response = wrapped_callback(request, *callback_args, **callback_kwargs)
  File "/usr/local/lib/python2.7/dist-packages/django/views/decorators/csrf.py", line 58, in wrapped_view
    return view_func(*args, **kwargs)
  File "/usr/local/lib/python2.7/dist-packages/django/views/generic/base.py", line 71, in view
    return self.dispatch(request, *args, **kwargs)
  File "/usr/local/lib/python2.7/dist-packages/rest_framework/views.py", line 407, in dispatch
    response = self.handle_exception(exc)
  File "/usr/local/lib/python2.7/dist-packages/rest_framework/views.py", line 404, in dispatch
    response = handler(request, *args, **kwargs)
  File "/usr/local/lib/python2.7/dist-packages/rest_framework/generics.py", line 357, in put
    return self.update(request, *args, **kwargs)
  File "/home/vagrant/django_shared/ecosistema/BackEnd/sitios/views.py", line 85, in update
    serializer.add_categories(request.data['categorias'])
  File "/home/vagrant/django_shared/ecosistema/BackEnd/sitios/serializers.py", line 67, in add_categories
    SitioCategoria.objects.create(sitio_id=self.data["id"],categoria_id=category["categoria_id"],tipo=category["tipo"]);
TypeError: string indices must be integers
Internal Server Error: /sitio/detail/1
Traceback (most recent call last):
  File "/usr/local/lib/python2.7/dist-packages/django/core/handlers/base.py", line 132, in get_response
    response = wrapped_callback(request, *callback_args, **callback_kwargs)
  File "/usr/local/lib/python2.7/dist-packages/django/views/decorators/csrf.py", line 58, in wrapped_view
    return view_func(*args, **kwargs)
  File "/usr/local/lib/python2.7/dist-packages/django/views/generic/base.py", line 71, in view
    return self.dispatch(request, *args, **kwargs)
  File "/usr/local/lib/python2.7/dist-packages/rest_framework/views.py", line 407, in dispatch
    response = self.handle_exception(exc)
  File "/usr/local/lib/python2.7/dist-packages/rest_framework/views.py", line 404, in dispatch
    response = handler(request, *args, **kwargs)
  File "/usr/local/lib/python2.7/dist-packages/rest_framework/generics.py", line 357, in put
    return self.update(request, *args, **kwargs)
  File "/home/vagrant/django_shared/ecosistema/BackEnd/sitios/views.py", line 85, in update
    serializer.add_categories(request.data['categorias'])
  File "/home/vagrant/django_shared/ecosistema/BackEnd/sitios/serializers.py", line 67, in add_categories
    SitioCategoria.objects.create(sitio_id=self.data["id"],categoria_id=category["categoria_id"],tipo=category["tipo"]);
TypeError: string indices must be integers
Internal Server Error: /sitio/detail/1
Traceback (most recent call last):
  File "/usr/local/lib/python2.7/dist-packages/django/core/handlers/base.py", line 132, in get_response
    response = wrapped_callback(request, *callback_args, **callback_kwargs)
  File "/usr/local/lib/python2.7/dist-packages/django/views/decorators/csrf.py", line 58, in wrapped_view
    return view_func(*args, **kwargs)
  File "/usr/local/lib/python2.7/dist-packages/django/views/generic/base.py", line 71, in view
    return self.dispatch(request, *args, **kwargs)
  File "/usr/local/lib/python2.7/dist-packages/rest_framework/views.py", line 407, in dispatch
    response = self.handle_exception(exc)
  File "/usr/local/lib/python2.7/dist-packages/rest_framework/views.py", line 404, in dispatch
    response = handler(request, *args, **kwargs)
  File "/usr/local/lib/python2.7/dist-packages/rest_framework/generics.py", line 357, in put
    return self.update(request, *args, **kwargs)
  File "/home/vagrant/django_shared/ecosistema/BackEnd/sitios/views.py", line 85, in update
    serializer.add_categories(request.data['categorias'])
  File "/home/vagrant/django_shared/ecosistema/BackEnd/sitios/serializers.py", line 67, in add_categories
    SitioCategoria.objects.create(sitio_id=self.data["id"],categoria_id=category["categoria_id"],tipo=category["tipo"]);
TypeError: string indices must be integers
Internal Server Error: /sitio/detail/1
Traceback (most recent call last):
  File "/usr/local/lib/python2.7/dist-packages/django/core/handlers/base.py", line 132, in get_response
    response = wrapped_callback(request, *callback_args, **callback_kwargs)
  File "/usr/local/lib/python2.7/dist-packages/django/views/decorators/csrf.py", line 58, in wrapped_view
    return view_func(*args, **kwargs)
  File "/usr/local/lib/python2.7/dist-packages/django/views/generic/base.py", line 71, in view
    return self.dispatch(request, *args, **kwargs)
  File "/usr/local/lib/python2.7/dist-packages/rest_framework/views.py", line 407, in dispatch
    response = self.handle_exception(exc)
  File "/usr/local/lib/python2.7/dist-packages/rest_framework/views.py", line 404, in dispatch
    response = handler(request, *args, **kwargs)
  File "/usr/local/lib/python2.7/dist-packages/rest_framework/generics.py", line 357, in put
    return self.update(request, *args, **kwargs)
  File "/home/vagrant/django_shared/ecosistema/BackEnd/sitios/views.py", line 85, in update
    serializer.add_categories(request.data['categorias'])
  File "/home/vagrant/django_shared/ecosistema/BackEnd/sitios/serializers.py", line 69, in add_categories
    s.save()
  File "/usr/local/lib/python2.7/dist-packages/rest_framework/serializers.py", line 150, in save
    'You cannot call `.save()` on a serializer with invalid data.'
AssertionError: You cannot call `.save()` on a serializer with invalid data.
Internal Server Error: /sitio/detail/1
Traceback (most recent call last):
  File "/usr/local/lib/python2.7/dist-packages/django/core/handlers/base.py", line 132, in get_response
    response = wrapped_callback(request, *callback_args, **callback_kwargs)
  File "/usr/local/lib/python2.7/dist-packages/django/views/decorators/csrf.py", line 58, in wrapped_view
    return view_func(*args, **kwargs)
  File "/usr/local/lib/python2.7/dist-packages/django/views/generic/base.py", line 71, in view
    return self.dispatch(request, *args, **kwargs)
  File "/usr/local/lib/python2.7/dist-packages/rest_framework/views.py", line 407, in dispatch
    response = self.handle_exception(exc)
  File "/usr/local/lib/python2.7/dist-packages/rest_framework/views.py", line 404, in dispatch
    response = handler(request, *args, **kwargs)
  File "/usr/local/lib/python2.7/dist-packages/rest_framework/generics.py", line 357, in put
    return self.update(request, *args, **kwargs)
  File "/home/vagrant/django_shared/ecosistema/BackEnd/sitios/views.py", line 85, in update
    serializer.add_categories(request.data['categorias'])
  File "/home/vagrant/django_shared/ecosistema/BackEnd/sitios/serializers.py", line 69, in add_categories
    s.save()
  File "/usr/local/lib/python2.7/dist-packages/rest_framework/serializers.py", line 150, in save
    'You cannot call `.save()` on a serializer with invalid data.'
AssertionError: You cannot call `.save()` on a serializer with invalid data.
Internal Server Error: /sitio/detail/1
Traceback (most recent call last):
  File "/usr/local/lib/python2.7/dist-packages/django/core/handlers/base.py", line 132, in get_response
    response = wrapped_callback(request, *callback_args, **callback_kwargs)
  File "/usr/local/lib/python2.7/dist-packages/django/views/decorators/csrf.py", line 58, in wrapped_view
    return view_func(*args, **kwargs)
  File "/usr/local/lib/python2.7/dist-packages/django/views/generic/base.py", line 71, in view
    return self.dispatch(request, *args, **kwargs)
  File "/usr/local/lib/python2.7/dist-packages/rest_framework/views.py", line 407, in dispatch
    response = self.handle_exception(exc)
  File "/usr/local/lib/python2.7/dist-packages/rest_framework/views.py", line 404, in dispatch
    response = handler(request, *args, **kwargs)
  File "/usr/local/lib/python2.7/dist-packages/rest_framework/generics.py", line 357, in put
    return self.update(request, *args, **kwargs)
  File "/home/vagrant/django_shared/ecosistema/BackEnd/sitios/views.py", line 85, in update
    serializer.add_categories(request.data['categorias'])
  File "/home/vagrant/django_shared/ecosistema/BackEnd/sitios/serializers.py", line 69, in add_categories
    s.save()
  File "/usr/local/lib/python2.7/dist-packages/rest_framework/serializers.py", line 150, in save
    'You cannot call `.save()` on a serializer with invalid data.'
AssertionError: You cannot call `.save()` on a serializer with invalid data.
Internal Server Error: /sitio/detail/1
Traceback (most recent call last):
  File "/usr/local/lib/python2.7/dist-packages/django/core/handlers/base.py", line 132, in get_response
    response = wrapped_callback(request, *callback_args, **callback_kwargs)
  File "/usr/local/lib/python2.7/dist-packages/django/views/decorators/csrf.py", line 58, in wrapped_view
    return view_func(*args, **kwargs)
  File "/usr/local/lib/python2.7/dist-packages/django/views/generic/base.py", line 71, in view
    return self.dispatch(request, *args, **kwargs)
  File "/usr/local/lib/python2.7/dist-packages/rest_framework/views.py", line 407, in dispatch
    response = self.handle_exception(exc)
  File "/usr/local/lib/python2.7/dist-packages/rest_framework/views.py", line 404, in dispatch
    response = handler(request, *args, **kwargs)
  File "/usr/local/lib/python2.7/dist-packages/rest_framework/generics.py", line 357, in put
    return self.update(request, *args, **kwargs)
  File "/home/vagrant/django_shared/ecosistema/BackEnd/sitios/views.py", line 85, in update
    serializer.add_categories(eval(request.data['categorias']))
  File "/home/vagrant/django_shared/ecosistema/BackEnd/sitios/serializers.py", line 65, in add_categories
    SitioCategoria.objects.create(sitio_id=self.data["id"],categoria_id=category["categoria_id"],tipo=category["tipo"]);
TypeError: string indices must be integers, not str
Internal Server Error: /sitio/detail/1
Traceback (most recent call last):
  File "/usr/local/lib/python2.7/dist-packages/django/core/handlers/base.py", line 132, in get_response
    response = wrapped_callback(request, *callback_args, **callback_kwargs)
  File "/usr/local/lib/python2.7/dist-packages/django/views/decorators/csrf.py", line 58, in wrapped_view
    return view_func(*args, **kwargs)
  File "/usr/local/lib/python2.7/dist-packages/django/views/generic/base.py", line 71, in view
    return self.dispatch(request, *args, **kwargs)
  File "/usr/local/lib/python2.7/dist-packages/rest_framework/views.py", line 407, in dispatch
    response = self.handle_exception(exc)
  File "/usr/local/lib/python2.7/dist-packages/rest_framework/views.py", line 404, in dispatch
    response = handler(request, *args, **kwargs)
  File "/usr/local/lib/python2.7/dist-packages/rest_framework/generics.py", line 357, in put
    return self.update(request, *args, **kwargs)
  File "/home/vagrant/django_shared/ecosistema/BackEnd/sitios/views.py", line 85, in update
    serializer.add_categories(eval(request.data['categorias']))
  File "/home/vagrant/django_shared/ecosistema/BackEnd/sitios/serializers.py", line 65, in add_categories
    SitioCategoria.objects.create(sitio_id=self.data["id"],categoria_id=category["categoria_id"],tipo=category["tipo"]);
TypeError: string indices must be integers, not str
Internal Server Error: /sitio/detail/1
Traceback (most recent call last):
  File "/usr/local/lib/python2.7/dist-packages/django/core/handlers/base.py", line 132, in get_response
    response = wrapped_callback(request, *callback_args, **callback_kwargs)
  File "/usr/local/lib/python2.7/dist-packages/django/views/decorators/csrf.py", line 58, in wrapped_view
    return view_func(*args, **kwargs)
  File "/usr/local/lib/python2.7/dist-packages/django/views/generic/base.py", line 71, in view
    return self.dispatch(request, *args, **kwargs)
  File "/usr/local/lib/python2.7/dist-packages/rest_framework/views.py", line 407, in dispatch
    response = self.handle_exception(exc)
  File "/usr/local/lib/python2.7/dist-packages/rest_framework/views.py", line 404, in dispatch
    response = handler(request, *args, **kwargs)
  File "/usr/local/lib/python2.7/dist-packages/rest_framework/generics.py", line 357, in put
    return self.update(request, *args, **kwargs)
  File "/home/vagrant/django_shared/ecosistema/BackEnd/sitios/views.py", line 85, in update
    serializer.add_categories(eval(request.data['categorias']))
  File "/home/vagrant/django_shared/ecosistema/BackEnd/sitios/serializers.py", line 65, in add_categories
    SitioCategoria.objects.create(sitio_id=self.data["id"],categoria_id=category["categoria_id"],tipo=category["tipo"]);
TypeError: string indices must be integers, not str
Internal Server Error: /sitio
Traceback (most recent call last):
  File "/usr/local/lib/python2.7/dist-packages/django/core/handlers/base.py", line 132, in get_response
    response = wrapped_callback(request, *callback_args, **callback_kwargs)
  File "/usr/local/lib/python2.7/dist-packages/django/views/decorators/csrf.py", line 58, in wrapped_view
    return view_func(*args, **kwargs)
  File "/usr/local/lib/python2.7/dist-packages/django/views/generic/base.py", line 71, in view
    return self.dispatch(request, *args, **kwargs)
  File "/usr/local/lib/python2.7/dist-packages/rest_framework/views.py", line 407, in dispatch
    response = self.handle_exception(exc)
  File "/usr/local/lib/python2.7/dist-packages/rest_framework/views.py", line 404, in dispatch
    response = handler(request, *args, **kwargs)
  File "/usr/local/lib/python2.7/dist-packages/rest_framework/generics.py", line 314, in post
    return self.create(request, *args, **kwargs)
  File "/home/vagrant/django_shared/ecosistema/BackEnd/sitios/views.py", line 61, in create
    serializer.add_categories(data['categorias'])
  File "/home/vagrant/django_shared/ecosistema/BackEnd/sitios/serializers.py", line 66, in add_categories
    SitioCategoria.objects.create(sitio_id=self.data["id"],categoria_id=category["categoria_id"],tipo=category["tipo"]);
TypeError: string indices must be integers
Internal Server Error: /sitio
Traceback (most recent call last):
  File "/usr/local/lib/python2.7/dist-packages/django/core/handlers/base.py", line 132, in get_response
    response = wrapped_callback(request, *callback_args, **callback_kwargs)
  File "/usr/local/lib/python2.7/dist-packages/django/views/decorators/csrf.py", line 58, in wrapped_view
    return view_func(*args, **kwargs)
  File "/usr/local/lib/python2.7/dist-packages/django/views/generic/base.py", line 71, in view
    return self.dispatch(request, *args, **kwargs)
  File "/usr/local/lib/python2.7/dist-packages/rest_framework/views.py", line 407, in dispatch
    response = self.handle_exception(exc)
  File "/usr/local/lib/python2.7/dist-packages/rest_framework/views.py", line 404, in dispatch
    response = handler(request, *args, **kwargs)
  File "/usr/local/lib/python2.7/dist-packages/rest_framework/generics.py", line 314, in post
    return self.create(request, *args, **kwargs)
  File "/home/vagrant/django_shared/ecosistema/BackEnd/sitios/views.py", line 62, in create
    serializer.add_categories(data['categorias'])
  File "/home/vagrant/django_shared/ecosistema/BackEnd/sitios/serializers.py", line 66, in add_categories
    SitioCategoria.objects.create(sitio_id=self.data["id"],categoria_id=category["categoria_id"],tipo=category["tipo"]);
TypeError: string indices must be integers
Internal Server Error: /sitio
Traceback (most recent call last):
  File "/usr/local/lib/python2.7/dist-packages/django/core/handlers/base.py", line 132, in get_response
    response = wrapped_callback(request, *callback_args, **callback_kwargs)
  File "/usr/local/lib/python2.7/dist-packages/django/views/decorators/csrf.py", line 58, in wrapped_view
    return view_func(*args, **kwargs)
  File "/usr/local/lib/python2.7/dist-packages/django/views/generic/base.py", line 71, in view
    return self.dispatch(request, *args, **kwargs)
  File "/usr/local/lib/python2.7/dist-packages/rest_framework/views.py", line 407, in dispatch
    response = self.handle_exception(exc)
  File "/usr/local/lib/python2.7/dist-packages/rest_framework/views.py", line 404, in dispatch
    response = handler(request, *args, **kwargs)
  File "/usr/local/lib/python2.7/dist-packages/rest_framework/generics.py", line 314, in post
    return self.create(request, *args, **kwargs)
  File "/home/vagrant/django_shared/ecosistema/BackEnd/sitios/views.py", line 62, in create
    print json.loads(data['categorias'])
  File "/usr/lib/python2.7/json/__init__.py", line 338, in loads
    return _default_decoder.decode(s)
  File "/usr/lib/python2.7/json/decoder.py", line 366, in decode
    obj, end = self.raw_decode(s, idx=_w(s, 0).end())
  File "/usr/lib/python2.7/json/decoder.py", line 382, in raw_decode
    obj, end = self.scan_once(s, idx)
ValueError: Expecting property name enclosed in double quotes: line 1 column 2 (char 1)
Internal Server Error: /sitio
Traceback (most recent call last):
  File "/usr/local/lib/python2.7/dist-packages/django/core/handlers/base.py", line 132, in get_response
    response = wrapped_callback(request, *callback_args, **callback_kwargs)
  File "/usr/local/lib/python2.7/dist-packages/django/views/decorators/csrf.py", line 58, in wrapped_view
    return view_func(*args, **kwargs)
  File "/usr/local/lib/python2.7/dist-packages/django/views/generic/base.py", line 71, in view
    return self.dispatch(request, *args, **kwargs)
  File "/usr/local/lib/python2.7/dist-packages/rest_framework/views.py", line 407, in dispatch
    response = self.handle_exception(exc)
  File "/usr/local/lib/python2.7/dist-packages/rest_framework/views.py", line 404, in dispatch
    response = handler(request, *args, **kwargs)
  File "/usr/local/lib/python2.7/dist-packages/rest_framework/generics.py", line 314, in post
    return self.create(request, *args, **kwargs)
  File "/home/vagrant/django_shared/ecosistema/BackEnd/sitios/views.py", line 63, in create
    print json.loads(data['categorias'])
  File "/usr/lib/python2.7/json/__init__.py", line 338, in loads
    return _default_decoder.decode(s)
  File "/usr/lib/python2.7/json/decoder.py", line 366, in decode
    obj, end = self.raw_decode(s, idx=_w(s, 0).end())
  File "/usr/lib/python2.7/json/decoder.py", line 382, in raw_decode
    obj, end = self.scan_once(s, idx)
ValueError: Expecting property name enclosed in double quotes: line 1 column 2 (char 1)
Internal Server Error: /sitio
Traceback (most recent call last):
  File "/usr/local/lib/python2.7/dist-packages/django/core/handlers/base.py", line 132, in get_response
    response = wrapped_callback(request, *callback_args, **callback_kwargs)
  File "/usr/local/lib/python2.7/dist-packages/django/views/decorators/csrf.py", line 58, in wrapped_view
    return view_func(*args, **kwargs)
  File "/usr/local/lib/python2.7/dist-packages/django/views/generic/base.py", line 71, in view
    return self.dispatch(request, *args, **kwargs)
  File "/usr/local/lib/python2.7/dist-packages/rest_framework/views.py", line 407, in dispatch
    response = self.handle_exception(exc)
  File "/usr/local/lib/python2.7/dist-packages/rest_framework/views.py", line 404, in dispatch
    response = handler(request, *args, **kwargs)
  File "/usr/local/lib/python2.7/dist-packages/rest_framework/generics.py", line 314, in post
    return self.create(request, *args, **kwargs)
  File "/home/vagrant/django_shared/ecosistema/BackEnd/sitios/views.py", line 65, in create
    serializer.add_categories(json.loads(data['categorias']))
  File "/usr/lib/python2.7/json/__init__.py", line 338, in loads
    return _default_decoder.decode(s)
  File "/usr/lib/python2.7/json/decoder.py", line 366, in decode
    obj, end = self.raw_decode(s, idx=_w(s, 0).end())
  File "/usr/lib/python2.7/json/decoder.py", line 382, in raw_decode
    obj, end = self.scan_once(s, idx)
ValueError: Expecting property name enclosed in double quotes: line 1 column 2 (char 1)
Internal Server Error: /sitio
Traceback (most recent call last):
  File "/usr/local/lib/python2.7/dist-packages/django/core/handlers/base.py", line 132, in get_response
    response = wrapped_callback(request, *callback_args, **callback_kwargs)
  File "/usr/local/lib/python2.7/dist-packages/django/views/decorators/csrf.py", line 58, in wrapped_view
    return view_func(*args, **kwargs)
  File "/usr/local/lib/python2.7/dist-packages/django/views/generic/base.py", line 71, in view
    return self.dispatch(request, *args, **kwargs)
  File "/usr/local/lib/python2.7/dist-packages/rest_framework/views.py", line 407, in dispatch
    response = self.handle_exception(exc)
  File "/usr/local/lib/python2.7/dist-packages/rest_framework/views.py", line 404, in dispatch
    response = handler(request, *args, **kwargs)
  File "/usr/local/lib/python2.7/dist-packages/rest_framework/generics.py", line 314, in post
    return self.create(request, *args, **kwargs)
  File "/home/vagrant/django_shared/ecosistema/BackEnd/sitios/views.py", line 65, in create
    serializer.add_categories(json.loads(data['categorias']))
  File "/usr/lib/python2.7/json/__init__.py", line 338, in loads
    return _default_decoder.decode(s)
  File "/usr/lib/python2.7/json/decoder.py", line 366, in decode
    obj, end = self.raw_decode(s, idx=_w(s, 0).end())
  File "/usr/lib/python2.7/json/decoder.py", line 382, in raw_decode
    obj, end = self.scan_once(s, idx)
ValueError: Expecting property name enclosed in double quotes: line 1 column 2 (char 1)
Internal Server Error: /sitio
Traceback (most recent call last):
  File "/usr/local/lib/python2.7/dist-packages/django/core/handlers/base.py", line 132, in get_response
    response = wrapped_callback(request, *callback_args, **callback_kwargs)
  File "/usr/local/lib/python2.7/dist-packages/django/views/decorators/csrf.py", line 58, in wrapped_view
    return view_func(*args, **kwargs)
  File "/usr/local/lib/python2.7/dist-packages/django/views/generic/base.py", line 71, in view
    return self.dispatch(request, *args, **kwargs)
  File "/usr/local/lib/python2.7/dist-packages/rest_framework/views.py", line 407, in dispatch
    response = self.handle_exception(exc)
  File "/usr/local/lib/python2.7/dist-packages/rest_framework/views.py", line 404, in dispatch
    response = handler(request, *args, **kwargs)
  File "/usr/local/lib/python2.7/dist-packages/rest_framework/generics.py", line 314, in post
    return self.create(request, *args, **kwargs)
  File "/home/vagrant/django_shared/ecosistema/BackEnd/sitios/views.py", line 65, in create
    serializer.add_categories(json.loads(data['categorias']))
  File "/usr/lib/python2.7/json/__init__.py", line 338, in loads
    return _default_decoder.decode(s)
  File "/usr/lib/python2.7/json/decoder.py", line 366, in decode
    obj, end = self.raw_decode(s, idx=_w(s, 0).end())
  File "/usr/lib/python2.7/json/decoder.py", line 382, in raw_decode
    obj, end = self.scan_once(s, idx)
ValueError: Expecting property name enclosed in double quotes: line 1 column 2 (char 1)
Internal Server Error: /sitio
Traceback (most recent call last):
  File "/usr/local/lib/python2.7/dist-packages/django/core/handlers/base.py", line 132, in get_response
    response = wrapped_callback(request, *callback_args, **callback_kwargs)
  File "/usr/local/lib/python2.7/dist-packages/django/views/decorators/csrf.py", line 58, in wrapped_view
    return view_func(*args, **kwargs)
  File "/usr/local/lib/python2.7/dist-packages/django/views/generic/base.py", line 71, in view
    return self.dispatch(request, *args, **kwargs)
  File "/usr/local/lib/python2.7/dist-packages/rest_framework/views.py", line 407, in dispatch
    response = self.handle_exception(exc)
  File "/usr/local/lib/python2.7/dist-packages/rest_framework/views.py", line 404, in dispatch
    response = handler(request, *args, **kwargs)
  File "/usr/local/lib/python2.7/dist-packages/rest_framework/generics.py", line 314, in post
    return self.create(request, *args, **kwargs)
  File "/home/vagrant/django_shared/ecosistema/BackEnd/sitios/views.py", line 65, in create
    serializer.add_categories(json.loads(data['categorias']))
  File "/usr/lib/python2.7/json/__init__.py", line 338, in loads
    return _default_decoder.decode(s)
  File "/usr/lib/python2.7/json/decoder.py", line 366, in decode
    obj, end = self.raw_decode(s, idx=_w(s, 0).end())
  File "/usr/lib/python2.7/json/decoder.py", line 382, in raw_decode
    obj, end = self.scan_once(s, idx)
ValueError: Expecting property name enclosed in double quotes: line 1 column 2 (char 1)
Internal Server Error: /sitio
Traceback (most recent call last):
  File "/usr/local/lib/python2.7/dist-packages/django/core/handlers/base.py", line 132, in get_response
    response = wrapped_callback(request, *callback_args, **callback_kwargs)
  File "/usr/local/lib/python2.7/dist-packages/django/views/decorators/csrf.py", line 58, in wrapped_view
    return view_func(*args, **kwargs)
  File "/usr/local/lib/python2.7/dist-packages/django/views/generic/base.py", line 71, in view
    return self.dispatch(request, *args, **kwargs)
  File "/usr/local/lib/python2.7/dist-packages/rest_framework/views.py", line 407, in dispatch
    response = self.handle_exception(exc)
  File "/usr/local/lib/python2.7/dist-packages/rest_framework/views.py", line 404, in dispatch
    response = handler(request, *args, **kwargs)
  File "/usr/local/lib/python2.7/dist-packages/rest_framework/generics.py", line 314, in post
    return self.create(request, *args, **kwargs)
  File "/home/vagrant/django_shared/ecosistema/BackEnd/sitios/views.py", line 65, in create
    serializer.add_categories(json.loads(data['categorias']))
  File "/usr/lib/python2.7/json/__init__.py", line 338, in loads
    return _default_decoder.decode(s)
  File "/usr/lib/python2.7/json/decoder.py", line 366, in decode
    obj, end = self.raw_decode(s, idx=_w(s, 0).end())
  File "/usr/lib/python2.7/json/decoder.py", line 382, in raw_decode
    obj, end = self.scan_once(s, idx)
ValueError: Expecting property name enclosed in double quotes: line 1 column 2 (char 1)
Internal Server Error: /sitio
Traceback (most recent call last):
  File "/usr/local/lib/python2.7/dist-packages/django/core/handlers/base.py", line 132, in get_response
    response = wrapped_callback(request, *callback_args, **callback_kwargs)
  File "/usr/local/lib/python2.7/dist-packages/django/views/decorators/csrf.py", line 58, in wrapped_view
    return view_func(*args, **kwargs)
  File "/usr/local/lib/python2.7/dist-packages/django/views/generic/base.py", line 71, in view
    return self.dispatch(request, *args, **kwargs)
  File "/usr/local/lib/python2.7/dist-packages/rest_framework/views.py", line 407, in dispatch
    response = self.handle_exception(exc)
  File "/usr/local/lib/python2.7/dist-packages/rest_framework/views.py", line 404, in dispatch
    response = handler(request, *args, **kwargs)
  File "/usr/local/lib/python2.7/dist-packages/rest_framework/generics.py", line 314, in post
    return self.create(request, *args, **kwargs)
  File "/home/vagrant/django_shared/ecosistema/BackEnd/sitios/views.py", line 65, in create
    serializer.add_categories(json.loads(data['categorias']))
  File "/usr/lib/python2.7/json/__init__.py", line 338, in loads
    return _default_decoder.decode(s)
  File "/usr/lib/python2.7/json/decoder.py", line 366, in decode
    obj, end = self.raw_decode(s, idx=_w(s, 0).end())
  File "/usr/lib/python2.7/json/decoder.py", line 382, in raw_decode
    obj, end = self.scan_once(s, idx)
ValueError: Expecting property name enclosed in double quotes: line 1 column 2 (char 1)
Internal Server Error: /sitio
Traceback (most recent call last):
  File "/usr/local/lib/python2.7/dist-packages/django/core/handlers/base.py", line 132, in get_response
    response = wrapped_callback(request, *callback_args, **callback_kwargs)
  File "/usr/local/lib/python2.7/dist-packages/django/views/decorators/csrf.py", line 58, in wrapped_view
    return view_func(*args, **kwargs)
  File "/usr/local/lib/python2.7/dist-packages/django/views/generic/base.py", line 71, in view
    return self.dispatch(request, *args, **kwargs)
  File "/usr/local/lib/python2.7/dist-packages/rest_framework/views.py", line 407, in dispatch
    response = self.handle_exception(exc)
  File "/usr/local/lib/python2.7/dist-packages/rest_framework/views.py", line 404, in dispatch
    response = handler(request, *args, **kwargs)
  File "/usr/local/lib/python2.7/dist-packages/rest_framework/generics.py", line 314, in post
    return self.create(request, *args, **kwargs)
  File "/home/vagrant/django_shared/ecosistema/BackEnd/sitios/views.py", line 65, in create
    serializer.add_categories(request.POST['categorias'])
  File "/home/vagrant/django_shared/ecosistema/BackEnd/sitios/serializers.py", line 67, in add_categories
    SitioCategoria.objects.create(sitio_id=self.data["id"],categoria_id=category["categoria_id"],tipo=category["tipo"]);
TypeError: string indices must be integers
Internal Server Error: /sitio
Traceback (most recent call last):
  File "/usr/local/lib/python2.7/dist-packages/django/core/handlers/base.py", line 132, in get_response
    response = wrapped_callback(request, *callback_args, **callback_kwargs)
  File "/usr/local/lib/python2.7/dist-packages/django/views/decorators/csrf.py", line 58, in wrapped_view
    return view_func(*args, **kwargs)
  File "/usr/local/lib/python2.7/dist-packages/django/views/generic/base.py", line 71, in view
    return self.dispatch(request, *args, **kwargs)
  File "/usr/local/lib/python2.7/dist-packages/rest_framework/views.py", line 407, in dispatch
    response = self.handle_exception(exc)
  File "/usr/local/lib/python2.7/dist-packages/rest_framework/views.py", line 404, in dispatch
    response = handler(request, *args, **kwargs)
  File "/usr/local/lib/python2.7/dist-packages/rest_framework/generics.py", line 314, in post
    return self.create(request, *args, **kwargs)
  File "/home/vagrant/django_shared/ecosistema/BackEnd/sitios/views.py", line 65, in create
    serializer.add_categories(request.POST['categorias'])
  File "/home/vagrant/django_shared/ecosistema/BackEnd/sitios/serializers.py", line 67, in add_categories
    SitioCategoria.objects.create(sitio_id=self.data["id"],categoria_id=category["categoria_id"],tipo=category["tipo"]);
TypeError: string indices must be integers
Internal Server Error: /sitio
Traceback (most recent call last):
  File "/usr/local/lib/python2.7/dist-packages/django/core/handlers/base.py", line 132, in get_response
    response = wrapped_callback(request, *callback_args, **callback_kwargs)
  File "/usr/local/lib/python2.7/dist-packages/django/views/decorators/csrf.py", line 58, in wrapped_view
    return view_func(*args, **kwargs)
  File "/usr/local/lib/python2.7/dist-packages/django/views/generic/base.py", line 71, in view
    return self.dispatch(request, *args, **kwargs)
  File "/usr/local/lib/python2.7/dist-packages/rest_framework/views.py", line 407, in dispatch
    response = self.handle_exception(exc)
  File "/usr/local/lib/python2.7/dist-packages/rest_framework/views.py", line 404, in dispatch
    response = handler(request, *args, **kwargs)
  File "/usr/local/lib/python2.7/dist-packages/rest_framework/generics.py", line 314, in post
    return self.create(request, *args, **kwargs)
  File "/home/vagrant/django_shared/ecosistema/BackEnd/sitios/views.py", line 65, in create
    serializer.add_categories(eval(request.POST['categorias']))
  File "/home/vagrant/django_shared/ecosistema/BackEnd/sitios/serializers.py", line 67, in add_categories
    SitioCategoria.objects.create(sitio_id=self.data["id"],categoria_id=category["categoria_id"],tipo=category["tipo"]);
TypeError: string indices must be integers, not str
Internal Server Error: /sitio
Traceback (most recent call last):
  File "/usr/local/lib/python2.7/dist-packages/django/core/handlers/base.py", line 132, in get_response
    response = wrapped_callback(request, *callback_args, **callback_kwargs)
  File "/usr/local/lib/python2.7/dist-packages/django/views/decorators/csrf.py", line 58, in wrapped_view
    return view_func(*args, **kwargs)
  File "/usr/local/lib/python2.7/dist-packages/django/views/generic/base.py", line 71, in view
    return self.dispatch(request, *args, **kwargs)
  File "/usr/local/lib/python2.7/dist-packages/rest_framework/views.py", line 407, in dispatch
    response = self.handle_exception(exc)
  File "/usr/local/lib/python2.7/dist-packages/rest_framework/views.py", line 404, in dispatch
    response = handler(request, *args, **kwargs)
  File "/usr/local/lib/python2.7/dist-packages/rest_framework/generics.py", line 314, in post
    return self.create(request, *args, **kwargs)
  File "/home/vagrant/django_shared/ecosistema/BackEnd/sitios/views.py", line 65, in create
    serializer.add_categories(json.loads(request.POST['categorias']))
  File "/usr/lib/python2.7/json/__init__.py", line 338, in loads
    return _default_decoder.decode(s)
  File "/usr/lib/python2.7/json/decoder.py", line 366, in decode
    obj, end = self.raw_decode(s, idx=_w(s, 0).end())
  File "/usr/lib/python2.7/json/decoder.py", line 382, in raw_decode
    obj, end = self.scan_once(s, idx)
ValueError: Expecting property name enclosed in double quotes: line 1 column 2 (char 1)
