Internal Server Error: /
Traceback (most recent call last):
  File "/usr/local/lib/python2.7/dist-packages/django/core/handlers/base.py", line 119, in get_response
    resolver_match = resolver.resolve(request.path_info)
  File "/usr/local/lib/python2.7/dist-packages/django/core/urlresolvers.py", line 366, in resolve
    for pattern in self.url_patterns:
  File "/usr/local/lib/python2.7/dist-packages/django/core/urlresolvers.py", line 402, in url_patterns
    patterns = getattr(self.urlconf_module, "urlpatterns", self.urlconf_module)
  File "/usr/local/lib/python2.7/dist-packages/django/core/urlresolvers.py", line 396, in urlconf_module
    self._urlconf_module = import_module(self.urlconf_name)
  File "/usr/lib/python2.7/importlib/__init__.py", line 37, in import_module
    __import__(name)
  File "/home/camilo/Documents/django_projects/BackEnd/turismo/urls.py", line 5, in <module>
    from sitios import views as sitio_views
  File "/home/camilo/Documents/django_projects/BackEnd/sitios/views.py", line 18, in <module>
    from sitios.photo_processing import *
  File "/home/camilo/Documents/django_projects/BackEnd/sitios/photo_processing.py", line 1, in <module>
    from PIL import Image, ExifTags
ImportError: No module named PIL
Internal Server Error: /favicon.ico
Traceback (most recent call last):
  File "/usr/local/lib/python2.7/dist-packages/django/core/handlers/base.py", line 108, in get_response
    response = middleware_method(request)
  File "/usr/local/lib/python2.7/dist-packages/django/middleware/common.py", line 74, in process_request
    if (not urlresolvers.is_valid_path(request.path_info, urlconf) and
  File "/usr/local/lib/python2.7/dist-packages/django/core/urlresolvers.py", line 647, in is_valid_path
    resolve(path, urlconf)
  File "/usr/local/lib/python2.7/dist-packages/django/core/urlresolvers.py", line 522, in resolve
    return get_resolver(urlconf).resolve(path)
  File "/usr/local/lib/python2.7/dist-packages/django/core/urlresolvers.py", line 366, in resolve
    for pattern in self.url_patterns:
  File "/usr/local/lib/python2.7/dist-packages/django/core/urlresolvers.py", line 402, in url_patterns
    patterns = getattr(self.urlconf_module, "urlpatterns", self.urlconf_module)
  File "/usr/local/lib/python2.7/dist-packages/django/core/urlresolvers.py", line 396, in urlconf_module
    self._urlconf_module = import_module(self.urlconf_name)
  File "/usr/lib/python2.7/importlib/__init__.py", line 37, in import_module
    __import__(name)
  File "/home/camilo/Documents/django_projects/BackEnd/turismo/urls.py", line 5, in <module>
    from sitios import views as sitio_views
  File "/home/camilo/Documents/django_projects/BackEnd/sitios/views.py", line 18, in <module>
    from sitios.photo_processing import *
  File "/home/camilo/Documents/django_projects/BackEnd/sitios/photo_processing.py", line 1, in <module>
    from PIL import Image, ExifTags
ImportError: No module named PIL
Internal Server Error: /
Traceback (most recent call last):
  File "/usr/local/lib/python2.7/dist-packages/django/core/handlers/base.py", line 119, in get_response
    resolver_match = resolver.resolve(request.path_info)
  File "/usr/local/lib/python2.7/dist-packages/django/core/urlresolvers.py", line 366, in resolve
    for pattern in self.url_patterns:
  File "/usr/local/lib/python2.7/dist-packages/django/core/urlresolvers.py", line 402, in url_patterns
    patterns = getattr(self.urlconf_module, "urlpatterns", self.urlconf_module)
  File "/usr/local/lib/python2.7/dist-packages/django/core/urlresolvers.py", line 396, in urlconf_module
    self._urlconf_module = import_module(self.urlconf_name)
  File "/usr/lib/python2.7/importlib/__init__.py", line 37, in import_module
    __import__(name)
  File "/home/camilo/Documents/django_projects/BackEnd/turismo/urls.py", line 5, in <module>
    from sitios import views as sitio_views
  File "/home/camilo/Documents/django_projects/BackEnd/sitios/views.py", line 18, in <module>
    from sitios.photo_processing import *
  File "/home/camilo/Documents/django_projects/BackEnd/sitios/photo_processing.py", line 1, in <module>
    from PIL import Image, ExifTags
ImportError: No module named PIL
Internal Server Error: /favicon.ico
Traceback (most recent call last):
  File "/usr/local/lib/python2.7/dist-packages/django/core/handlers/base.py", line 108, in get_response
    response = middleware_method(request)
  File "/usr/local/lib/python2.7/dist-packages/django/middleware/common.py", line 74, in process_request
    if (not urlresolvers.is_valid_path(request.path_info, urlconf) and
  File "/usr/local/lib/python2.7/dist-packages/django/core/urlresolvers.py", line 647, in is_valid_path
    resolve(path, urlconf)
  File "/usr/local/lib/python2.7/dist-packages/django/core/urlresolvers.py", line 522, in resolve
    return get_resolver(urlconf).resolve(path)
  File "/usr/local/lib/python2.7/dist-packages/django/core/urlresolvers.py", line 366, in resolve
    for pattern in self.url_patterns:
  File "/usr/local/lib/python2.7/dist-packages/django/core/urlresolvers.py", line 402, in url_patterns
    patterns = getattr(self.urlconf_module, "urlpatterns", self.urlconf_module)
  File "/usr/local/lib/python2.7/dist-packages/django/core/urlresolvers.py", line 396, in urlconf_module
    self._urlconf_module = import_module(self.urlconf_name)
  File "/usr/lib/python2.7/importlib/__init__.py", line 37, in import_module
    __import__(name)
  File "/home/camilo/Documents/django_projects/BackEnd/turismo/urls.py", line 5, in <module>
    from sitios import views as sitio_views
  File "/home/camilo/Documents/django_projects/BackEnd/sitios/views.py", line 18, in <module>
    from sitios.photo_processing import *
  File "/home/camilo/Documents/django_projects/BackEnd/sitios/photo_processing.py", line 1, in <module>
    from PIL import Image, ExifTags
ImportError: No module named PIL
Internal Server Error: /buscar/
Traceback (most recent call last):
  File "/usr/local/lib/python2.7/dist-packages/django/core/handlers/base.py", line 132, in get_response
    response = wrapped_callback(request, *callback_args, **callback_kwargs)
  File "/usr/local/lib/python2.7/dist-packages/django/views/decorators/csrf.py", line 58, in wrapped_view
    return view_func(*args, **kwargs)
  File "/usr/local/lib/python2.7/dist-packages/django/views/generic/base.py", line 71, in view
    return self.dispatch(request, *args, **kwargs)
  File "/usr/local/lib/python2.7/dist-packages/rest_framework/views.py", line 452, in dispatch
    response = self.handle_exception(exc)
  File "/usr/local/lib/python2.7/dist-packages/rest_framework/views.py", line 449, in dispatch
    response = handler(request, *args, **kwargs)
  File "/usr/local/lib/python2.7/dist-packages/rest_framework/generics.py", line 199, in get
    return self.list(request, *args, **kwargs)
  File "/usr/local/lib/python2.7/dist-packages/rest_framework/mixins.py", line 47, in list
    return Response(serializer.data)
  File "/usr/local/lib/python2.7/dist-packages/rest_framework/serializers.py", line 618, in data
    ret = super(ListSerializer, self).data
  File "/usr/local/lib/python2.7/dist-packages/rest_framework/serializers.py", line 213, in data
    self._data = self.to_representation(self.instance)
  File "/usr/local/lib/python2.7/dist-packages/rest_framework/serializers.py", line 568, in to_representation
    self.child.to_representation(item) for item in iterable
  File "/usr/local/lib/python2.7/dist-packages/django/db/models/query.py", line 1284, in __iter__
    query = iter(self.query)
  File "/usr/local/lib/python2.7/dist-packages/django/db/models/sql/query.py", line 78, in __iter__
    self._execute_query()
  File "/usr/local/lib/python2.7/dist-packages/django/db/models/sql/query.py", line 96, in _execute_query
    self.cursor.execute(self.sql, self.params)
  File "/usr/local/lib/python2.7/dist-packages/django/db/backends/utils.py", line 79, in execute
    return super(CursorDebugWrapper, self).execute(sql, params)
  File "/usr/local/lib/python2.7/dist-packages/django/db/backends/utils.py", line 64, in execute
    return self.cursor.execute(sql, params)
  File "/usr/local/lib/python2.7/dist-packages/django/db/utils.py", line 97, in __exit__
    six.reraise(dj_exc_type, dj_exc_value, traceback)
  File "/usr/local/lib/python2.7/dist-packages/django/db/backends/utils.py", line 64, in execute
    return self.cursor.execute(sql, params)
  File "/usr/local/lib/python2.7/dist-packages/django/db/backends/mysql/base.py", line 124, in execute
    return self.cursor.execute(query, args)
  File "/usr/lib/python2.7/dist-packages/MySQLdb/cursors.py", line 174, in execute
    self.errorhandler(self, exc, value)
  File "/usr/lib/python2.7/dist-packages/MySQLdb/connections.py", line 36, in defaulterrorhandler
    raise errorclass, errorvalue
ProgrammingError: (1064, "You have an error in your SQL syntax; check the manual that corresponds to your MySQL server version for the right syntax to use near '(authentication_module_customuser.id=sitios_sitio.usuario_id) LEFT OUTER JOIN si' at line 1")
