Internal Server Error: /admin/sitios/foto/
Traceback (most recent call last):
  File "/usr/local/lib/python2.7/dist-packages/django/core/handlers/base.py", line 164, in get_response
    response = response.render()
  File "/usr/local/lib/python2.7/dist-packages/django/template/response.py", line 158, in render
    self.content = self.rendered_content
  File "/usr/local/lib/python2.7/dist-packages/django/template/response.py", line 135, in rendered_content
    content = template.render(context, self._request)
  File "/usr/local/lib/python2.7/dist-packages/django/template/backends/django.py", line 74, in render
    return self.template.render(context)
  File "/usr/local/lib/python2.7/dist-packages/django/template/base.py", line 209, in render
    return self._render(context)
  File "/usr/local/lib/python2.7/dist-packages/django/template/base.py", line 201, in _render
    return self.nodelist.render(context)
  File "/usr/local/lib/python2.7/dist-packages/django/template/base.py", line 903, in render
    bit = self.render_node(node, context)
  File "/usr/local/lib/python2.7/dist-packages/django/template/debug.py", line 79, in render_node
    return node.render(context)
  File "/usr/local/lib/python2.7/dist-packages/django/template/loader_tags.py", line 135, in render
    return compiled_parent._render(context)
  File "/usr/local/lib/python2.7/dist-packages/django/template/base.py", line 201, in _render
    return self.nodelist.render(context)
  File "/usr/local/lib/python2.7/dist-packages/django/template/base.py", line 903, in render
    bit = self.render_node(node, context)
  File "/usr/local/lib/python2.7/dist-packages/django/template/debug.py", line 79, in render_node
    return node.render(context)
  File "/usr/local/lib/python2.7/dist-packages/django/template/loader_tags.py", line 135, in render
    return compiled_parent._render(context)
  File "/usr/local/lib/python2.7/dist-packages/django/template/base.py", line 201, in _render
    return self.nodelist.render(context)
  File "/usr/local/lib/python2.7/dist-packages/django/template/base.py", line 903, in render
    bit = self.render_node(node, context)
  File "/usr/local/lib/python2.7/dist-packages/django/template/debug.py", line 79, in render_node
    return node.render(context)
  File "/usr/local/lib/python2.7/dist-packages/django/template/loader_tags.py", line 65, in render
    result = block.nodelist.render(context)
  File "/usr/local/lib/python2.7/dist-packages/django/template/base.py", line 903, in render
    bit = self.render_node(node, context)
  File "/usr/local/lib/python2.7/dist-packages/django/template/debug.py", line 79, in render_node
    return node.render(context)
  File "/usr/local/lib/python2.7/dist-packages/django/template/loader_tags.py", line 65, in render
    result = block.nodelist.render(context)
  File "/usr/local/lib/python2.7/dist-packages/django/template/base.py", line 903, in render
    bit = self.render_node(node, context)
  File "/usr/local/lib/python2.7/dist-packages/django/template/debug.py", line 79, in render_node
    return node.render(context)
  File "/usr/local/lib/python2.7/dist-packages/django/template/loader_tags.py", line 65, in render
    result = block.nodelist.render(context)
  File "/usr/local/lib/python2.7/dist-packages/django/template/base.py", line 903, in render
    bit = self.render_node(node, context)
  File "/usr/local/lib/python2.7/dist-packages/django/template/debug.py", line 79, in render_node
    return node.render(context)
  File "/usr/local/lib/python2.7/dist-packages/django/template/loader_tags.py", line 65, in render
    result = block.nodelist.render(context)
  File "/usr/local/lib/python2.7/dist-packages/django/template/base.py", line 903, in render
    bit = self.render_node(node, context)
  File "/usr/local/lib/python2.7/dist-packages/django/template/debug.py", line 79, in render_node
    return node.render(context)
  File "/usr/local/lib/python2.7/dist-packages/django/template/defaulttags.py", line 329, in render
    return nodelist.render(context)
  File "/usr/local/lib/python2.7/dist-packages/django/template/base.py", line 903, in render
    bit = self.render_node(node, context)
  File "/usr/local/lib/python2.7/dist-packages/django/template/debug.py", line 79, in render_node
    return node.render(context)
  File "/usr/local/lib/python2.7/dist-packages/django/template/base.py", line 1271, in render
    _dict = func(*resolved_args, **resolved_kwargs)
  File "/usr/local/lib/python2.7/dist-packages/suit/templatetags/suit_list.py", line 189, in result_list_with_context
    res = result_list(cl)
  File "/usr/local/lib/python2.7/dist-packages/django/contrib/admin/templatetags/admin_list.py", line 320, in result_list
    'results': list(results(cl))}
  File "/usr/local/lib/python2.7/dist-packages/django/contrib/admin/templatetags/admin_list.py", line 296, in results
    yield ResultList(None, items_for_result(cl, res, None))
  File "/usr/local/lib/python2.7/dist-packages/django/contrib/admin/templatetags/admin_list.py", line 287, in __init__
    super(ResultList, self).__init__(*items)
  File "/usr/local/lib/python2.7/dist-packages/django/contrib/admin/templatetags/admin_list.py", line 199, in items_for_result
    f, attr, value = lookup_field(field_name, result, cl.model_admin)
  File "/usr/local/lib/python2.7/dist-packages/django/contrib/admin/utils.py", line 282, in lookup_field
    value = attr()
  File "/usr/local/lib/python2.7/dist-packages/django/db/models/base.py", line 503, in __str__
    return force_text(self).encode('utf-8')
  File "/usr/local/lib/python2.7/dist-packages/django/utils/encoding.py", line 92, in force_text
    s = six.text_type(s)
TypeError: coercing to Unicode: need string or buffer, Sitio found
Internal Server Error: /admin/sitios/sitio/1920/
Traceback (most recent call last):
  File "/usr/local/lib/python2.7/dist-packages/django/core/handlers/base.py", line 164, in get_response
    response = response.render()
  File "/usr/local/lib/python2.7/dist-packages/django/template/response.py", line 158, in render
    self.content = self.rendered_content
  File "/usr/local/lib/python2.7/dist-packages/django/template/response.py", line 135, in rendered_content
    content = template.render(context, self._request)
  File "/usr/local/lib/python2.7/dist-packages/django/template/backends/django.py", line 74, in render
    return self.template.render(context)
  File "/usr/local/lib/python2.7/dist-packages/django/template/base.py", line 209, in render
    return self._render(context)
  File "/usr/local/lib/python2.7/dist-packages/django/template/base.py", line 201, in _render
    return self.nodelist.render(context)
  File "/usr/local/lib/python2.7/dist-packages/django/template/base.py", line 903, in render
    bit = self.render_node(node, context)
  File "/usr/local/lib/python2.7/dist-packages/django/template/debug.py", line 79, in render_node
    return node.render(context)
  File "/usr/local/lib/python2.7/dist-packages/django/template/loader_tags.py", line 135, in render
    return compiled_parent._render(context)
  File "/usr/local/lib/python2.7/dist-packages/django/template/base.py", line 201, in _render
    return self.nodelist.render(context)
  File "/usr/local/lib/python2.7/dist-packages/django/template/base.py", line 903, in render
    bit = self.render_node(node, context)
  File "/usr/local/lib/python2.7/dist-packages/django/template/debug.py", line 79, in render_node
    return node.render(context)
  File "/usr/local/lib/python2.7/dist-packages/django/template/loader_tags.py", line 135, in render
    return compiled_parent._render(context)
  File "/usr/local/lib/python2.7/dist-packages/django/template/base.py", line 201, in _render
    return self.nodelist.render(context)
  File "/usr/local/lib/python2.7/dist-packages/django/template/base.py", line 903, in render
    bit = self.render_node(node, context)
  File "/usr/local/lib/python2.7/dist-packages/django/template/debug.py", line 79, in render_node
    return node.render(context)
  File "/usr/local/lib/python2.7/dist-packages/django/template/loader_tags.py", line 65, in render
    result = block.nodelist.render(context)
  File "/usr/local/lib/python2.7/dist-packages/django/template/base.py", line 903, in render
    bit = self.render_node(node, context)
  File "/usr/local/lib/python2.7/dist-packages/django/template/debug.py", line 79, in render_node
    return node.render(context)
  File "/usr/local/lib/python2.7/dist-packages/django/template/loader_tags.py", line 65, in render
    result = block.nodelist.render(context)
  File "/usr/local/lib/python2.7/dist-packages/django/template/base.py", line 903, in render
    bit = self.render_node(node, context)
  File "/usr/local/lib/python2.7/dist-packages/django/template/debug.py", line 79, in render_node
    return node.render(context)
  File "/usr/local/lib/python2.7/dist-packages/django/template/loader_tags.py", line 65, in render
    result = block.nodelist.render(context)
  File "/usr/local/lib/python2.7/dist-packages/django/template/base.py", line 903, in render
    bit = self.render_node(node, context)
  File "/usr/local/lib/python2.7/dist-packages/django/template/debug.py", line 79, in render_node
    return node.render(context)
  File "/usr/local/lib/python2.7/dist-packages/django/template/loader_tags.py", line 65, in render
    result = block.nodelist.render(context)
  File "/usr/local/lib/python2.7/dist-packages/django/template/base.py", line 903, in render
    bit = self.render_node(node, context)
  File "/usr/local/lib/python2.7/dist-packages/django/template/debug.py", line 79, in render_node
    return node.render(context)
  File "/usr/local/lib/python2.7/dist-packages/django/template/defaulttags.py", line 217, in render
    nodelist.append(node.render(context))
  File "/usr/local/lib/python2.7/dist-packages/django/template/loader_tags.py", line 159, in render
    return template.render(context)
  File "/usr/local/lib/python2.7/dist-packages/django/template/base.py", line 211, in render
    return self._render(context)
  File "/usr/local/lib/python2.7/dist-packages/django/template/base.py", line 201, in _render
    return self.nodelist.render(context)
  File "/usr/local/lib/python2.7/dist-packages/django/template/base.py", line 903, in render
    bit = self.render_node(node, context)
  File "/usr/local/lib/python2.7/dist-packages/django/template/debug.py", line 79, in render_node
    return node.render(context)
  File "/usr/local/lib/python2.7/dist-packages/django/template/defaulttags.py", line 217, in render
    nodelist.append(node.render(context))
  File "/usr/local/lib/python2.7/dist-packages/django/template/defaulttags.py", line 576, in render
    return self.nodelist.render(context)
  File "/usr/local/lib/python2.7/dist-packages/django/template/base.py", line 903, in render
    bit = self.render_node(node, context)
  File "/usr/local/lib/python2.7/dist-packages/django/template/debug.py", line 79, in render_node
    return node.render(context)
  File "/usr/local/lib/python2.7/dist-packages/django/template/defaulttags.py", line 217, in render
    nodelist.append(node.render(context))
  File "/usr/local/lib/python2.7/dist-packages/django/template/defaulttags.py", line 444, in render
    return strip_spaces_between_tags(self.nodelist.render(context).strip())
  File "/usr/local/lib/python2.7/dist-packages/django/template/base.py", line 903, in render
    bit = self.render_node(node, context)
  File "/usr/local/lib/python2.7/dist-packages/django/template/debug.py", line 79, in render_node
    return node.render(context)
  File "/usr/local/lib/python2.7/dist-packages/django/template/defaulttags.py", line 329, in render
    return nodelist.render(context)
  File "/usr/local/lib/python2.7/dist-packages/django/template/base.py", line 903, in render
    bit = self.render_node(node, context)
  File "/usr/local/lib/python2.7/dist-packages/django/template/debug.py", line 79, in render_node
    return node.render(context)
  File "/usr/local/lib/python2.7/dist-packages/django/template/debug.py", line 92, in render
    output = force_text(output)
  File "/usr/local/lib/python2.7/dist-packages/django/utils/encoding.py", line 92, in force_text
    s = six.text_type(s)
  File "/usr/local/lib/python2.7/dist-packages/django/utils/html.py", line 390, in <lambda>
    klass.__unicode__ = lambda self: mark_safe(klass_unicode(self))
  File "/usr/local/lib/python2.7/dist-packages/django/forms/forms.py", line 537, in __str__
    return self.as_widget()
  File "/usr/local/lib/python2.7/dist-packages/django/forms/forms.py", line 593, in as_widget
    return force_text(widget.render(name, self.value(), attrs=attrs))
  File "/usr/local/lib/python2.7/dist-packages/django/contrib/admin/widgets.py", line 292, in render
    'widget': self.widget.render(name, value, *args, **kwargs),
  File "/usr/local/lib/python2.7/dist-packages/django/forms/widgets.py", line 513, in render
    options = self.render_options(choices, [value])
  File "/usr/local/lib/python2.7/dist-packages/django/forms/widgets.py", line 539, in render_options
    for option_value, option_label in chain(self.choices, choices):
  File "/usr/local/lib/python2.7/dist-packages/django/forms/models.py", line 1104, in __iter__
    yield self.choice(obj)
  File "/usr/local/lib/python2.7/dist-packages/django/forms/models.py", line 1111, in choice
    return (self.field.prepare_value(obj), self.field.label_from_instance(obj))
  File "/usr/local/lib/python2.7/dist-packages/django/forms/models.py", line 1182, in label_from_instance
    return smart_text(obj)
  File "/usr/local/lib/python2.7/dist-packages/django/utils/encoding.py", line 56, in smart_text
    return force_text(s, encoding, strings_only, errors)
  File "/usr/local/lib/python2.7/dist-packages/django/utils/encoding.py", line 92, in force_text
    s = six.text_type(s)
TypeError: coercing to Unicode: need string or buffer, NoneType found
Internal Server Error: /categorias
Traceback (most recent call last):
  File "/usr/local/lib/python2.7/dist-packages/django/core/handlers/base.py", line 108, in get_response
    response = middleware_method(request)
  File "/usr/local/lib/python2.7/dist-packages/django/middleware/common.py", line 74, in process_request
    if (not urlresolvers.is_valid_path(request.path_info, urlconf) and
  File "/usr/local/lib/python2.7/dist-packages/django/core/urlresolvers.py", line 646, in is_valid_path
    resolve(path, urlconf)
  File "/usr/local/lib/python2.7/dist-packages/django/core/urlresolvers.py", line 521, in resolve
    return get_resolver(urlconf).resolve(path)
  File "/usr/local/lib/python2.7/dist-packages/django/core/urlresolvers.py", line 365, in resolve
    for pattern in self.url_patterns:
  File "/usr/local/lib/python2.7/dist-packages/django/core/urlresolvers.py", line 401, in url_patterns
    patterns = getattr(self.urlconf_module, "urlpatterns", self.urlconf_module)
  File "/usr/local/lib/python2.7/dist-packages/django/core/urlresolvers.py", line 395, in urlconf_module
    self._urlconf_module = import_module(self.urlconf_name)
  File "/usr/lib/python2.7/importlib/__init__.py", line 37, in import_module
    __import__(name)
  File "/home/camilo/Documentos/djangoprojects/plataforma/turismo/urls.py", line 28, in <module>
    url(r'^rest-auth/registration/', include('rest_auth.registration.urls')),
  File "/usr/local/lib/python2.7/dist-packages/django/conf/urls/__init__.py", line 33, in include
    urlconf_module = import_module(urlconf_module)
  File "/usr/lib/python2.7/importlib/__init__.py", line 37, in import_module
    __import__(name)
  File "/home/camilo/Documentos/djangoprojects/plataforma/rest_auth/registration/urls.py", line 4, in <module>
    from .views import RegisterView, VerifyEmailView
  File "/home/camilo/Documentos/djangoprojects/plataforma/rest_auth/registration/views.py", line 18, in <module>
    from rest_auth.registration.serializers import (SocialLoginSerializer,
  File "/home/camilo/Documentos/djangoprojects/plataforma/rest_auth/registration/serializers.py", line 157
SyntaxError: Non-ASCII character '\xc3' in file /home/camilo/Documentos/djangoprojects/plataforma/rest_auth/registration/serializers.py on line 157, but no encoding declared; see http://www.python.org/peps/pep-0263.html for details
Internal Server Error: /municipios
Traceback (most recent call last):
  File "/usr/local/lib/python2.7/dist-packages/django/core/handlers/base.py", line 108, in get_response
    response = middleware_method(request)
  File "/usr/local/lib/python2.7/dist-packages/django/middleware/common.py", line 74, in process_request
    if (not urlresolvers.is_valid_path(request.path_info, urlconf) and
  File "/usr/local/lib/python2.7/dist-packages/django/core/urlresolvers.py", line 646, in is_valid_path
    resolve(path, urlconf)
  File "/usr/local/lib/python2.7/dist-packages/django/core/urlresolvers.py", line 521, in resolve
    return get_resolver(urlconf).resolve(path)
  File "/usr/local/lib/python2.7/dist-packages/django/core/urlresolvers.py", line 365, in resolve
    for pattern in self.url_patterns:
  File "/usr/local/lib/python2.7/dist-packages/django/core/urlresolvers.py", line 401, in url_patterns
    patterns = getattr(self.urlconf_module, "urlpatterns", self.urlconf_module)
  File "/usr/local/lib/python2.7/dist-packages/django/core/urlresolvers.py", line 395, in urlconf_module
    self._urlconf_module = import_module(self.urlconf_name)
  File "/usr/lib/python2.7/importlib/__init__.py", line 37, in import_module
    __import__(name)
  File "/home/camilo/Documentos/djangoprojects/plataforma/turismo/urls.py", line 28, in <module>
    url(r'^rest-auth/registration/', include('rest_auth.registration.urls')),
  File "/usr/local/lib/python2.7/dist-packages/django/conf/urls/__init__.py", line 33, in include
    urlconf_module = import_module(urlconf_module)
  File "/usr/lib/python2.7/importlib/__init__.py", line 37, in import_module
    __import__(name)
  File "/home/camilo/Documentos/djangoprojects/plataforma/rest_auth/registration/urls.py", line 4, in <module>
    from .views import RegisterView, VerifyEmailView
  File "/home/camilo/Documentos/djangoprojects/plataforma/rest_auth/registration/views.py", line 18, in <module>
    from rest_auth.registration.serializers import (SocialLoginSerializer,
  File "/home/camilo/Documentos/djangoprojects/plataforma/rest_auth/registration/serializers.py", line 157
SyntaxError: Non-ASCII character '\xc3' in file /home/camilo/Documentos/djangoprojects/plataforma/rest_auth/registration/serializers.py on line 157, but no encoding declared; see http://www.python.org/peps/pep-0263.html for details
Internal Server Error: /municipios
Traceback (most recent call last):
  File "/usr/local/lib/python2.7/dist-packages/django/core/handlers/base.py", line 108, in get_response
    response = middleware_method(request)
  File "/usr/local/lib/python2.7/dist-packages/django/middleware/common.py", line 74, in process_request
    if (not urlresolvers.is_valid_path(request.path_info, urlconf) and
  File "/usr/local/lib/python2.7/dist-packages/django/core/urlresolvers.py", line 646, in is_valid_path
    resolve(path, urlconf)
  File "/usr/local/lib/python2.7/dist-packages/django/core/urlresolvers.py", line 521, in resolve
    return get_resolver(urlconf).resolve(path)
  File "/usr/local/lib/python2.7/dist-packages/django/core/urlresolvers.py", line 365, in resolve
    for pattern in self.url_patterns:
  File "/usr/local/lib/python2.7/dist-packages/django/core/urlresolvers.py", line 401, in url_patterns
    patterns = getattr(self.urlconf_module, "urlpatterns", self.urlconf_module)
  File "/usr/local/lib/python2.7/dist-packages/django/core/urlresolvers.py", line 395, in urlconf_module
    self._urlconf_module = import_module(self.urlconf_name)
  File "/usr/lib/python2.7/importlib/__init__.py", line 37, in import_module
    __import__(name)
  File "/home/camilo/Documentos/djangoprojects/plataforma/turismo/urls.py", line 28, in <module>
    url(r'^rest-auth/registration/', include('rest_auth.registration.urls')),
  File "/usr/local/lib/python2.7/dist-packages/django/conf/urls/__init__.py", line 33, in include
    urlconf_module = import_module(urlconf_module)
  File "/usr/lib/python2.7/importlib/__init__.py", line 37, in import_module
    __import__(name)
  File "/home/camilo/Documentos/djangoprojects/plataforma/rest_auth/registration/urls.py", line 4, in <module>
    from .views import RegisterView, VerifyEmailView
  File "/home/camilo/Documentos/djangoprojects/plataforma/rest_auth/registration/views.py", line 18, in <module>
    from rest_auth.registration.serializers import (SocialLoginSerializer,
  File "/home/camilo/Documentos/djangoprojects/plataforma/rest_auth/registration/serializers.py", line 157
SyntaxError: Non-ASCII character '\xc3' in file /home/camilo/Documentos/djangoprojects/plataforma/rest_auth/registration/serializers.py on line 157, but no encoding declared; see http://www.python.org/peps/pep-0263.html for details
Internal Server Error: /municipios
Traceback (most recent call last):
  File "/usr/local/lib/python2.7/dist-packages/django/core/handlers/base.py", line 108, in get_response
    response = middleware_method(request)
  File "/usr/local/lib/python2.7/dist-packages/django/middleware/common.py", line 74, in process_request
    if (not urlresolvers.is_valid_path(request.path_info, urlconf) and
  File "/usr/local/lib/python2.7/dist-packages/django/core/urlresolvers.py", line 646, in is_valid_path
    resolve(path, urlconf)
  File "/usr/local/lib/python2.7/dist-packages/django/core/urlresolvers.py", line 521, in resolve
    return get_resolver(urlconf).resolve(path)
  File "/usr/local/lib/python2.7/dist-packages/django/core/urlresolvers.py", line 365, in resolve
    for pattern in self.url_patterns:
  File "/usr/local/lib/python2.7/dist-packages/django/core/urlresolvers.py", line 401, in url_patterns
    patterns = getattr(self.urlconf_module, "urlpatterns", self.urlconf_module)
  File "/usr/local/lib/python2.7/dist-packages/django/core/urlresolvers.py", line 395, in urlconf_module
    self._urlconf_module = import_module(self.urlconf_name)
  File "/usr/lib/python2.7/importlib/__init__.py", line 37, in import_module
    __import__(name)
  File "/home/camilo/Documentos/djangoprojects/plataforma/turismo/urls.py", line 28, in <module>
    url(r'^rest-auth/registration/', include('rest_auth.registration.urls')),
  File "/usr/local/lib/python2.7/dist-packages/django/conf/urls/__init__.py", line 33, in include
    urlconf_module = import_module(urlconf_module)
  File "/usr/lib/python2.7/importlib/__init__.py", line 37, in import_module
    __import__(name)
  File "/home/camilo/Documentos/djangoprojects/plataforma/rest_auth/registration/urls.py", line 4, in <module>
    from .views import RegisterView, VerifyEmailView
  File "/home/camilo/Documentos/djangoprojects/plataforma/rest_auth/registration/views.py", line 18, in <module>
    from rest_auth.registration.serializers import (SocialLoginSerializer,
  File "/home/camilo/Documentos/djangoprojects/plataforma/rest_auth/registration/serializers.py", line 157
SyntaxError: Non-ASCII character '\xc3' in file /home/camilo/Documentos/djangoprojects/plataforma/rest_auth/registration/serializers.py on line 157, but no encoding declared; see http://www.python.org/peps/pep-0263.html for details
Internal Server Error: /categorias
Traceback (most recent call last):
  File "/usr/local/lib/python2.7/dist-packages/django/core/handlers/base.py", line 108, in get_response
    response = middleware_method(request)
  File "/usr/local/lib/python2.7/dist-packages/django/middleware/common.py", line 74, in process_request
    if (not urlresolvers.is_valid_path(request.path_info, urlconf) and
  File "/usr/local/lib/python2.7/dist-packages/django/core/urlresolvers.py", line 646, in is_valid_path
    resolve(path, urlconf)
  File "/usr/local/lib/python2.7/dist-packages/django/core/urlresolvers.py", line 521, in resolve
    return get_resolver(urlconf).resolve(path)
  File "/usr/local/lib/python2.7/dist-packages/django/core/urlresolvers.py", line 365, in resolve
    for pattern in self.url_patterns:
  File "/usr/local/lib/python2.7/dist-packages/django/core/urlresolvers.py", line 401, in url_patterns
    patterns = getattr(self.urlconf_module, "urlpatterns", self.urlconf_module)
  File "/usr/local/lib/python2.7/dist-packages/django/core/urlresolvers.py", line 395, in urlconf_module
    self._urlconf_module = import_module(self.urlconf_name)
  File "/usr/lib/python2.7/importlib/__init__.py", line 37, in import_module
    __import__(name)
  File "/home/camilo/Documentos/djangoprojects/plataforma/turismo/urls.py", line 28, in <module>
    url(r'^rest-auth/registration/', include('rest_auth.registration.urls')),
  File "/usr/local/lib/python2.7/dist-packages/django/conf/urls/__init__.py", line 33, in include
    urlconf_module = import_module(urlconf_module)
  File "/usr/lib/python2.7/importlib/__init__.py", line 37, in import_module
    __import__(name)
  File "/home/camilo/Documentos/djangoprojects/plataforma/rest_auth/registration/urls.py", line 4, in <module>
    from .views import RegisterView, VerifyEmailView
  File "/home/camilo/Documentos/djangoprojects/plataforma/rest_auth/registration/views.py", line 18, in <module>
    from rest_auth.registration.serializers import (SocialLoginSerializer,
  File "/home/camilo/Documentos/djangoprojects/plataforma/rest_auth/registration/serializers.py", line 157
SyntaxError: Non-ASCII character '\xc3' in file /home/camilo/Documentos/djangoprojects/plataforma/rest_auth/registration/serializers.py on line 157, but no encoding declared; see http://www.python.org/peps/pep-0263.html for details
Internal Server Error: /municipios
Traceback (most recent call last):
  File "/usr/local/lib/python2.7/dist-packages/django/core/handlers/base.py", line 108, in get_response
    response = middleware_method(request)
  File "/usr/local/lib/python2.7/dist-packages/django/middleware/common.py", line 74, in process_request
    if (not urlresolvers.is_valid_path(request.path_info, urlconf) and
  File "/usr/local/lib/python2.7/dist-packages/django/core/urlresolvers.py", line 646, in is_valid_path
    resolve(path, urlconf)
  File "/usr/local/lib/python2.7/dist-packages/django/core/urlresolvers.py", line 521, in resolve
    return get_resolver(urlconf).resolve(path)
  File "/usr/local/lib/python2.7/dist-packages/django/core/urlresolvers.py", line 365, in resolve
    for pattern in self.url_patterns:
  File "/usr/local/lib/python2.7/dist-packages/django/core/urlresolvers.py", line 401, in url_patterns
    patterns = getattr(self.urlconf_module, "urlpatterns", self.urlconf_module)
  File "/usr/local/lib/python2.7/dist-packages/django/core/urlresolvers.py", line 395, in urlconf_module
    self._urlconf_module = import_module(self.urlconf_name)
  File "/usr/lib/python2.7/importlib/__init__.py", line 37, in import_module
    __import__(name)
  File "/home/camilo/Documentos/djangoprojects/plataforma/turismo/urls.py", line 28, in <module>
    url(r'^rest-auth/registration/', include('rest_auth.registration.urls')),
  File "/usr/local/lib/python2.7/dist-packages/django/conf/urls/__init__.py", line 33, in include
    urlconf_module = import_module(urlconf_module)
  File "/usr/lib/python2.7/importlib/__init__.py", line 37, in import_module
    __import__(name)
  File "/home/camilo/Documentos/djangoprojects/plataforma/rest_auth/registration/urls.py", line 4, in <module>
    from .views import RegisterView, VerifyEmailView
  File "/home/camilo/Documentos/djangoprojects/plataforma/rest_auth/registration/views.py", line 18, in <module>
    from rest_auth.registration.serializers import (SocialLoginSerializer,
  File "/home/camilo/Documentos/djangoprojects/plataforma/rest_auth/registration/serializers.py", line 157
SyntaxError: Non-ASCII character '\xc3' in file /home/camilo/Documentos/djangoprojects/plataforma/rest_auth/registration/serializers.py on line 157, but no encoding declared; see http://www.python.org/peps/pep-0263.html for details
Internal Server Error: /municipios
Traceback (most recent call last):
  File "/usr/local/lib/python2.7/dist-packages/django/core/handlers/base.py", line 108, in get_response
    response = middleware_method(request)
  File "/usr/local/lib/python2.7/dist-packages/django/middleware/common.py", line 74, in process_request
    if (not urlresolvers.is_valid_path(request.path_info, urlconf) and
  File "/usr/local/lib/python2.7/dist-packages/django/core/urlresolvers.py", line 646, in is_valid_path
    resolve(path, urlconf)
  File "/usr/local/lib/python2.7/dist-packages/django/core/urlresolvers.py", line 521, in resolve
    return get_resolver(urlconf).resolve(path)
  File "/usr/local/lib/python2.7/dist-packages/django/core/urlresolvers.py", line 365, in resolve
    for pattern in self.url_patterns:
  File "/usr/local/lib/python2.7/dist-packages/django/core/urlresolvers.py", line 401, in url_patterns
    patterns = getattr(self.urlconf_module, "urlpatterns", self.urlconf_module)
  File "/usr/local/lib/python2.7/dist-packages/django/core/urlresolvers.py", line 395, in urlconf_module
    self._urlconf_module = import_module(self.urlconf_name)
  File "/usr/lib/python2.7/importlib/__init__.py", line 37, in import_module
    __import__(name)
  File "/home/camilo/Documentos/djangoprojects/plataforma/turismo/urls.py", line 28, in <module>
    url(r'^rest-auth/registration/', include('rest_auth.registration.urls')),
  File "/usr/local/lib/python2.7/dist-packages/django/conf/urls/__init__.py", line 33, in include
    urlconf_module = import_module(urlconf_module)
  File "/usr/lib/python2.7/importlib/__init__.py", line 37, in import_module
    __import__(name)
  File "/home/camilo/Documentos/djangoprojects/plataforma/rest_auth/registration/urls.py", line 4, in <module>
    from .views import RegisterView, VerifyEmailView
  File "/home/camilo/Documentos/djangoprojects/plataforma/rest_auth/registration/views.py", line 18, in <module>
    from rest_auth.registration.serializers import (SocialLoginSerializer,
  File "/home/camilo/Documentos/djangoprojects/plataforma/rest_auth/registration/serializers.py", line 157
SyntaxError: Non-ASCII character '\xc3' in file /home/camilo/Documentos/djangoprojects/plataforma/rest_auth/registration/serializers.py on line 157, but no encoding declared; see http://www.python.org/peps/pep-0263.html for details
Internal Server Error: /municipios
Traceback (most recent call last):
  File "/usr/local/lib/python2.7/dist-packages/django/core/handlers/base.py", line 108, in get_response
    response = middleware_method(request)
  File "/usr/local/lib/python2.7/dist-packages/django/middleware/common.py", line 74, in process_request
    if (not urlresolvers.is_valid_path(request.path_info, urlconf) and
  File "/usr/local/lib/python2.7/dist-packages/django/core/urlresolvers.py", line 646, in is_valid_path
    resolve(path, urlconf)
  File "/usr/local/lib/python2.7/dist-packages/django/core/urlresolvers.py", line 521, in resolve
    return get_resolver(urlconf).resolve(path)
  File "/usr/local/lib/python2.7/dist-packages/django/core/urlresolvers.py", line 365, in resolve
    for pattern in self.url_patterns:
  File "/usr/local/lib/python2.7/dist-packages/django/core/urlresolvers.py", line 401, in url_patterns
    patterns = getattr(self.urlconf_module, "urlpatterns", self.urlconf_module)
  File "/usr/local/lib/python2.7/dist-packages/django/core/urlresolvers.py", line 395, in urlconf_module
    self._urlconf_module = import_module(self.urlconf_name)
  File "/usr/lib/python2.7/importlib/__init__.py", line 37, in import_module
    __import__(name)
  File "/home/camilo/Documentos/djangoprojects/plataforma/turismo/urls.py", line 28, in <module>
    url(r'^rest-auth/registration/', include('rest_auth.registration.urls')),
  File "/usr/local/lib/python2.7/dist-packages/django/conf/urls/__init__.py", line 33, in include
    urlconf_module = import_module(urlconf_module)
  File "/usr/lib/python2.7/importlib/__init__.py", line 37, in import_module
    __import__(name)
  File "/home/camilo/Documentos/djangoprojects/plataforma/rest_auth/registration/urls.py", line 4, in <module>
    from .views import RegisterView, VerifyEmailView
  File "/home/camilo/Documentos/djangoprojects/plataforma/rest_auth/registration/views.py", line 18, in <module>
    from rest_auth.registration.serializers import (SocialLoginSerializer,
  File "/home/camilo/Documentos/djangoprojects/plataforma/rest_auth/registration/serializers.py", line 157
SyntaxError: Non-ASCII character '\xc3' in file /home/camilo/Documentos/djangoprojects/plataforma/rest_auth/registration/serializers.py on line 157, but no encoding declared; see http://www.python.org/peps/pep-0263.html for details
Internal Server Error: /categorias
Traceback (most recent call last):
  File "/usr/local/lib/python2.7/dist-packages/django/core/handlers/base.py", line 108, in get_response
    response = middleware_method(request)
  File "/usr/local/lib/python2.7/dist-packages/django/middleware/common.py", line 74, in process_request
    if (not urlresolvers.is_valid_path(request.path_info, urlconf) and
  File "/usr/local/lib/python2.7/dist-packages/django/core/urlresolvers.py", line 646, in is_valid_path
    resolve(path, urlconf)
  File "/usr/local/lib/python2.7/dist-packages/django/core/urlresolvers.py", line 521, in resolve
    return get_resolver(urlconf).resolve(path)
  File "/usr/local/lib/python2.7/dist-packages/django/core/urlresolvers.py", line 365, in resolve
    for pattern in self.url_patterns:
  File "/usr/local/lib/python2.7/dist-packages/django/core/urlresolvers.py", line 401, in url_patterns
    patterns = getattr(self.urlconf_module, "urlpatterns", self.urlconf_module)
  File "/usr/local/lib/python2.7/dist-packages/django/core/urlresolvers.py", line 395, in urlconf_module
    self._urlconf_module = import_module(self.urlconf_name)
  File "/usr/lib/python2.7/importlib/__init__.py", line 37, in import_module
    __import__(name)
  File "/home/camilo/Documentos/djangoprojects/plataforma/turismo/urls.py", line 28, in <module>
    url(r'^rest-auth/registration/', include('rest_auth.registration.urls')),
  File "/usr/local/lib/python2.7/dist-packages/django/conf/urls/__init__.py", line 33, in include
    urlconf_module = import_module(urlconf_module)
  File "/usr/lib/python2.7/importlib/__init__.py", line 37, in import_module
    __import__(name)
  File "/home/camilo/Documentos/djangoprojects/plataforma/rest_auth/registration/urls.py", line 4, in <module>
    from .views import RegisterView, VerifyEmailView
  File "/home/camilo/Documentos/djangoprojects/plataforma/rest_auth/registration/views.py", line 18, in <module>
    from rest_auth.registration.serializers import (SocialLoginSerializer,
  File "/home/camilo/Documentos/djangoprojects/plataforma/rest_auth/registration/serializers.py", line 157
SyntaxError: Non-ASCII character '\xc3' in file /home/camilo/Documentos/djangoprojects/plataforma/rest_auth/registration/serializers.py on line 157, but no encoding declared; see http://www.python.org/peps/pep-0263.html for details
Internal Server Error: /municipios
Traceback (most recent call last):
  File "/usr/local/lib/python2.7/dist-packages/django/core/handlers/base.py", line 108, in get_response
    response = middleware_method(request)
  File "/usr/local/lib/python2.7/dist-packages/django/middleware/common.py", line 74, in process_request
    if (not urlresolvers.is_valid_path(request.path_info, urlconf) and
  File "/usr/local/lib/python2.7/dist-packages/django/core/urlresolvers.py", line 646, in is_valid_path
    resolve(path, urlconf)
  File "/usr/local/lib/python2.7/dist-packages/django/core/urlresolvers.py", line 521, in resolve
    return get_resolver(urlconf).resolve(path)
  File "/usr/local/lib/python2.7/dist-packages/django/core/urlresolvers.py", line 365, in resolve
    for pattern in self.url_patterns:
  File "/usr/local/lib/python2.7/dist-packages/django/core/urlresolvers.py", line 401, in url_patterns
    patterns = getattr(self.urlconf_module, "urlpatterns", self.urlconf_module)
  File "/usr/local/lib/python2.7/dist-packages/django/core/urlresolvers.py", line 395, in urlconf_module
    self._urlconf_module = import_module(self.urlconf_name)
  File "/usr/lib/python2.7/importlib/__init__.py", line 37, in import_module
    __import__(name)
  File "/home/camilo/Documentos/djangoprojects/plataforma/turismo/urls.py", line 28, in <module>
    url(r'^rest-auth/registration/', include('rest_auth.registration.urls')),
  File "/usr/local/lib/python2.7/dist-packages/django/conf/urls/__init__.py", line 33, in include
    urlconf_module = import_module(urlconf_module)
  File "/usr/lib/python2.7/importlib/__init__.py", line 37, in import_module
    __import__(name)
  File "/home/camilo/Documentos/djangoprojects/plataforma/rest_auth/registration/urls.py", line 4, in <module>
    from .views import RegisterView, VerifyEmailView
  File "/home/camilo/Documentos/djangoprojects/plataforma/rest_auth/registration/views.py", line 18, in <module>
    from rest_auth.registration.serializers import (SocialLoginSerializer,
  File "/home/camilo/Documentos/djangoprojects/plataforma/rest_auth/registration/serializers.py", line 157
SyntaxError: Non-ASCII character '\xc3' in file /home/camilo/Documentos/djangoprojects/plataforma/rest_auth/registration/serializers.py on line 157, but no encoding declared; see http://www.python.org/peps/pep-0263.html for details
Internal Server Error: /municipios
Traceback (most recent call last):
  File "/usr/local/lib/python2.7/dist-packages/django/core/handlers/base.py", line 108, in get_response
    response = middleware_method(request)
  File "/usr/local/lib/python2.7/dist-packages/django/middleware/common.py", line 74, in process_request
    if (not urlresolvers.is_valid_path(request.path_info, urlconf) and
  File "/usr/local/lib/python2.7/dist-packages/django/core/urlresolvers.py", line 646, in is_valid_path
    resolve(path, urlconf)
  File "/usr/local/lib/python2.7/dist-packages/django/core/urlresolvers.py", line 521, in resolve
    return get_resolver(urlconf).resolve(path)
  File "/usr/local/lib/python2.7/dist-packages/django/core/urlresolvers.py", line 365, in resolve
    for pattern in self.url_patterns:
  File "/usr/local/lib/python2.7/dist-packages/django/core/urlresolvers.py", line 401, in url_patterns
    patterns = getattr(self.urlconf_module, "urlpatterns", self.urlconf_module)
  File "/usr/local/lib/python2.7/dist-packages/django/core/urlresolvers.py", line 395, in urlconf_module
    self._urlconf_module = import_module(self.urlconf_name)
  File "/usr/lib/python2.7/importlib/__init__.py", line 37, in import_module
    __import__(name)
  File "/home/camilo/Documentos/djangoprojects/plataforma/turismo/urls.py", line 28, in <module>
    url(r'^rest-auth/registration/', include('rest_auth.registration.urls')),
  File "/usr/local/lib/python2.7/dist-packages/django/conf/urls/__init__.py", line 33, in include
    urlconf_module = import_module(urlconf_module)
  File "/usr/lib/python2.7/importlib/__init__.py", line 37, in import_module
    __import__(name)
  File "/home/camilo/Documentos/djangoprojects/plataforma/rest_auth/registration/urls.py", line 4, in <module>
    from .views import RegisterView, VerifyEmailView
  File "/home/camilo/Documentos/djangoprojects/plataforma/rest_auth/registration/views.py", line 18, in <module>
    from rest_auth.registration.serializers import (SocialLoginSerializer,
  File "/home/camilo/Documentos/djangoprojects/plataforma/rest_auth/registration/serializers.py", line 157
SyntaxError: Non-ASCII character '\xc3' in file /home/camilo/Documentos/djangoprojects/plataforma/rest_auth/registration/serializers.py on line 157, but no encoding declared; see http://www.python.org/peps/pep-0263.html for details
Internal Server Error: /municipios
Traceback (most recent call last):
  File "/usr/local/lib/python2.7/dist-packages/django/core/handlers/base.py", line 108, in get_response
    response = middleware_method(request)
  File "/usr/local/lib/python2.7/dist-packages/django/middleware/common.py", line 74, in process_request
    if (not urlresolvers.is_valid_path(request.path_info, urlconf) and
  File "/usr/local/lib/python2.7/dist-packages/django/core/urlresolvers.py", line 646, in is_valid_path
    resolve(path, urlconf)
  File "/usr/local/lib/python2.7/dist-packages/django/core/urlresolvers.py", line 521, in resolve
    return get_resolver(urlconf).resolve(path)
  File "/usr/local/lib/python2.7/dist-packages/django/core/urlresolvers.py", line 365, in resolve
    for pattern in self.url_patterns:
  File "/usr/local/lib/python2.7/dist-packages/django/core/urlresolvers.py", line 401, in url_patterns
    patterns = getattr(self.urlconf_module, "urlpatterns", self.urlconf_module)
  File "/usr/local/lib/python2.7/dist-packages/django/core/urlresolvers.py", line 395, in urlconf_module
    self._urlconf_module = import_module(self.urlconf_name)
  File "/usr/lib/python2.7/importlib/__init__.py", line 37, in import_module
    __import__(name)
  File "/home/camilo/Documentos/djangoprojects/plataforma/turismo/urls.py", line 28, in <module>
    url(r'^rest-auth/registration/', include('rest_auth.registration.urls')),
  File "/usr/local/lib/python2.7/dist-packages/django/conf/urls/__init__.py", line 33, in include
    urlconf_module = import_module(urlconf_module)
  File "/usr/lib/python2.7/importlib/__init__.py", line 37, in import_module
    __import__(name)
  File "/home/camilo/Documentos/djangoprojects/plataforma/rest_auth/registration/urls.py", line 4, in <module>
    from .views import RegisterView, VerifyEmailView
  File "/home/camilo/Documentos/djangoprojects/plataforma/rest_auth/registration/views.py", line 18, in <module>
    from rest_auth.registration.serializers import (SocialLoginSerializer,
  File "/home/camilo/Documentos/djangoprojects/plataforma/rest_auth/registration/serializers.py", line 157
SyntaxError: Non-ASCII character '\xc3' in file /home/camilo/Documentos/djangoprojects/plataforma/rest_auth/registration/serializers.py on line 157, but no encoding declared; see http://www.python.org/peps/pep-0263.html for details
Internal Server Error: /admin/sitios/sitio/1917/
Traceback (most recent call last):
  File "/usr/local/lib/python2.7/dist-packages/django/core/handlers/base.py", line 132, in get_response
    response = wrapped_callback(request, *callback_args, **callback_kwargs)
  File "/usr/local/lib/python2.7/dist-packages/django/contrib/admin/options.py", line 616, in wrapper
    return self.admin_site.admin_view(view)(*args, **kwargs)
  File "/usr/local/lib/python2.7/dist-packages/django/utils/decorators.py", line 110, in _wrapped_view
    response = view_func(request, *args, **kwargs)
  File "/usr/local/lib/python2.7/dist-packages/django/views/decorators/cache.py", line 57, in _wrapped_view_func
    response = view_func(request, *args, **kwargs)
  File "/usr/local/lib/python2.7/dist-packages/django/contrib/admin/sites.py", line 233, in inner
    return view(request, *args, **kwargs)
  File "/usr/local/lib/python2.7/dist-packages/django/contrib/admin/options.py", line 1519, in change_view
    return self.changeform_view(request, object_id, form_url, extra_context)
  File "/usr/local/lib/python2.7/dist-packages/django/utils/decorators.py", line 34, in _wrapper
    return bound_func(*args, **kwargs)
  File "/usr/local/lib/python2.7/dist-packages/django/utils/decorators.py", line 110, in _wrapped_view
    response = view_func(request, *args, **kwargs)
  File "/usr/local/lib/python2.7/dist-packages/django/utils/decorators.py", line 30, in bound_func
    return func.__get__(self, type(self))(*args2, **kwargs2)
  File "/usr/local/lib/python2.7/dist-packages/django/utils/decorators.py", line 145, in inner
    return func(*args, **kwargs)
  File "/usr/local/lib/python2.7/dist-packages/django/contrib/admin/options.py", line 1456, in changeform_view
    ModelForm = self.get_form(request, obj)
  File "/usr/local/lib/python2.7/dist-packages/django/contrib/admin/options.py", line 703, in get_form
    % (e, self.__class__.__name__))
FieldError: Unknown field(s) (fotos) specified for Sitio. Check fields/fieldsets/exclude attributes of class SiteAdmin.
Internal Server Error: /admin/sitios/sitio/1917/
Traceback (most recent call last):
  File "/usr/local/lib/python2.7/dist-packages/django/core/handlers/base.py", line 132, in get_response
    response = wrapped_callback(request, *callback_args, **callback_kwargs)
  File "/usr/local/lib/python2.7/dist-packages/django/contrib/admin/options.py", line 616, in wrapper
    return self.admin_site.admin_view(view)(*args, **kwargs)
  File "/usr/local/lib/python2.7/dist-packages/django/utils/decorators.py", line 110, in _wrapped_view
    response = view_func(request, *args, **kwargs)
  File "/usr/local/lib/python2.7/dist-packages/django/views/decorators/cache.py", line 57, in _wrapped_view_func
    response = view_func(request, *args, **kwargs)
  File "/usr/local/lib/python2.7/dist-packages/django/contrib/admin/sites.py", line 233, in inner
    return view(request, *args, **kwargs)
  File "/usr/local/lib/python2.7/dist-packages/django/contrib/admin/options.py", line 1519, in change_view
    return self.changeform_view(request, object_id, form_url, extra_context)
  File "/usr/local/lib/python2.7/dist-packages/django/utils/decorators.py", line 34, in _wrapper
    return bound_func(*args, **kwargs)
  File "/usr/local/lib/python2.7/dist-packages/django/utils/decorators.py", line 110, in _wrapped_view
    response = view_func(request, *args, **kwargs)
  File "/usr/local/lib/python2.7/dist-packages/django/utils/decorators.py", line 30, in bound_func
    return func.__get__(self, type(self))(*args2, **kwargs2)
  File "/usr/local/lib/python2.7/dist-packages/django/utils/decorators.py", line 145, in inner
    return func(*args, **kwargs)
  File "/usr/local/lib/python2.7/dist-packages/django/contrib/admin/options.py", line 1456, in changeform_view
    ModelForm = self.get_form(request, obj)
  File "/usr/local/lib/python2.7/dist-packages/django/contrib/admin/options.py", line 703, in get_form
    % (e, self.__class__.__name__))
FieldError: Unknown field(s) (fotos) specified for Sitio. Check fields/fieldsets/exclude attributes of class SiteAdmin.
Internal Server Error: /admin/sitios/sitio/1917/
Traceback (most recent call last):
  File "/usr/local/lib/python2.7/dist-packages/django/core/handlers/base.py", line 164, in get_response
    response = response.render()
  File "/usr/local/lib/python2.7/dist-packages/django/template/response.py", line 158, in render
    self.content = self.rendered_content
  File "/usr/local/lib/python2.7/dist-packages/django/template/response.py", line 135, in rendered_content
    content = template.render(context, self._request)
  File "/usr/local/lib/python2.7/dist-packages/django/template/backends/django.py", line 74, in render
    return self.template.render(context)
  File "/usr/local/lib/python2.7/dist-packages/django/template/base.py", line 209, in render
    return self._render(context)
  File "/usr/local/lib/python2.7/dist-packages/django/template/base.py", line 201, in _render
    return self.nodelist.render(context)
  File "/usr/local/lib/python2.7/dist-packages/django/template/base.py", line 903, in render
    bit = self.render_node(node, context)
  File "/usr/local/lib/python2.7/dist-packages/django/template/debug.py", line 79, in render_node
    return node.render(context)
  File "/usr/local/lib/python2.7/dist-packages/django/template/loader_tags.py", line 135, in render
    return compiled_parent._render(context)
  File "/usr/local/lib/python2.7/dist-packages/django/template/base.py", line 201, in _render
    return self.nodelist.render(context)
  File "/usr/local/lib/python2.7/dist-packages/django/template/base.py", line 903, in render
    bit = self.render_node(node, context)
  File "/usr/local/lib/python2.7/dist-packages/django/template/debug.py", line 79, in render_node
    return node.render(context)
  File "/usr/local/lib/python2.7/dist-packages/django/template/loader_tags.py", line 135, in render
    return compiled_parent._render(context)
  File "/usr/local/lib/python2.7/dist-packages/django/template/base.py", line 201, in _render
    return self.nodelist.render(context)
  File "/usr/local/lib/python2.7/dist-packages/django/template/base.py", line 903, in render
    bit = self.render_node(node, context)
  File "/usr/local/lib/python2.7/dist-packages/django/template/debug.py", line 79, in render_node
    return node.render(context)
  File "/usr/local/lib/python2.7/dist-packages/django/template/loader_tags.py", line 65, in render
    result = block.nodelist.render(context)
  File "/usr/local/lib/python2.7/dist-packages/django/template/base.py", line 903, in render
    bit = self.render_node(node, context)
  File "/usr/local/lib/python2.7/dist-packages/django/template/debug.py", line 79, in render_node
    return node.render(context)
  File "/usr/local/lib/python2.7/dist-packages/django/template/loader_tags.py", line 65, in render
    result = block.nodelist.render(context)
  File "/usr/local/lib/python2.7/dist-packages/django/template/base.py", line 903, in render
    bit = self.render_node(node, context)
  File "/usr/local/lib/python2.7/dist-packages/django/template/debug.py", line 79, in render_node
    return node.render(context)
  File "/usr/local/lib/python2.7/dist-packages/django/template/loader_tags.py", line 65, in render
    result = block.nodelist.render(context)
  File "/usr/local/lib/python2.7/dist-packages/django/template/base.py", line 903, in render
    bit = self.render_node(node, context)
  File "/usr/local/lib/python2.7/dist-packages/django/template/debug.py", line 79, in render_node
    return node.render(context)
  File "/usr/local/lib/python2.7/dist-packages/django/template/loader_tags.py", line 65, in render
    result = block.nodelist.render(context)
  File "/usr/local/lib/python2.7/dist-packages/django/template/base.py", line 903, in render
    bit = self.render_node(node, context)
  File "/usr/local/lib/python2.7/dist-packages/django/template/debug.py", line 79, in render_node
    return node.render(context)
  File "/usr/local/lib/python2.7/dist-packages/django/template/defaulttags.py", line 217, in render
    nodelist.append(node.render(context))
  File "/usr/local/lib/python2.7/dist-packages/django/template/loader_tags.py", line 159, in render
    return template.render(context)
  File "/usr/local/lib/python2.7/dist-packages/django/template/base.py", line 211, in render
    return self._render(context)
  File "/usr/local/lib/python2.7/dist-packages/django/template/base.py", line 201, in _render
    return self.nodelist.render(context)
  File "/usr/local/lib/python2.7/dist-packages/django/template/base.py", line 903, in render
    bit = self.render_node(node, context)
  File "/usr/local/lib/python2.7/dist-packages/django/template/debug.py", line 79, in render_node
    return node.render(context)
  File "/usr/local/lib/python2.7/dist-packages/django/template/defaulttags.py", line 217, in render
    nodelist.append(node.render(context))
  File "/usr/local/lib/python2.7/dist-packages/django/template/defaulttags.py", line 217, in render
    nodelist.append(node.render(context))
  File "/usr/local/lib/python2.7/dist-packages/django/template/defaulttags.py", line 217, in render
    nodelist.append(node.render(context))
  File "/usr/local/lib/python2.7/dist-packages/django/template/defaulttags.py", line 217, in render
    nodelist.append(node.render(context))
  File "/usr/local/lib/python2.7/dist-packages/django/template/loader_tags.py", line 56, in render
    result = self.nodelist.render(context)
  File "/usr/local/lib/python2.7/dist-packages/django/template/base.py", line 903, in render
    bit = self.render_node(node, context)
  File "/usr/local/lib/python2.7/dist-packages/django/template/debug.py", line 79, in render_node
    return node.render(context)
  File "/usr/local/lib/python2.7/dist-packages/django/template/defaulttags.py", line 329, in render
    return nodelist.render(context)
  File "/usr/local/lib/python2.7/dist-packages/django/template/base.py", line 903, in render
    bit = self.render_node(node, context)
  File "/usr/local/lib/python2.7/dist-packages/django/template/debug.py", line 79, in render_node
    return node.render(context)
  File "/usr/local/lib/python2.7/dist-packages/django/template/debug.py", line 92, in render
    output = force_text(output)
  File "/usr/local/lib/python2.7/dist-packages/django/utils/encoding.py", line 92, in force_text
    s = six.text_type(s)
  File "/usr/local/lib/python2.7/dist-packages/django/utils/html.py", line 390, in <lambda>
    klass.__unicode__ = lambda self: mark_safe(klass_unicode(self))
  File "/usr/local/lib/python2.7/dist-packages/django/forms/forms.py", line 537, in __str__
    return self.as_widget()
  File "/usr/local/lib/python2.7/dist-packages/django/forms/forms.py", line 593, in as_widget
    return force_text(widget.render(name, self.value(), attrs=attrs))
  File "/usr/local/lib/python2.7/dist-packages/django/contrib/admin/widgets.py", line 292, in render
    'widget': self.widget.render(name, value, *args, **kwargs),
  File "/usr/local/lib/python2.7/dist-packages/django/forms/widgets.py", line 513, in render
    options = self.render_options(choices, [value])
  File "/usr/local/lib/python2.7/dist-packages/django/forms/widgets.py", line 539, in render_options
    for option_value, option_label in chain(self.choices, choices):
  File "/usr/local/lib/python2.7/dist-packages/django/forms/models.py", line 1104, in __iter__
    yield self.choice(obj)
  File "/usr/local/lib/python2.7/dist-packages/django/forms/models.py", line 1111, in choice
    return (self.field.prepare_value(obj), self.field.label_from_instance(obj))
  File "/usr/local/lib/python2.7/dist-packages/django/forms/models.py", line 1182, in label_from_instance
    return smart_text(obj)
  File "/usr/local/lib/python2.7/dist-packages/django/utils/encoding.py", line 56, in smart_text
    return force_text(s, encoding, strings_only, errors)
  File "/usr/local/lib/python2.7/dist-packages/django/utils/encoding.py", line 92, in force_text
    s = six.text_type(s)
  File "/home/camilo/Documentos/djangoprojects/plataforma/plataforma/models.py", line 23, in __unicode__
    return nombre
NameError: global name 'nombre' is not defined
Internal Server Error: /categorias
Traceback (most recent call last):
  File "/usr/local/lib/python2.7/dist-packages/django/core/handlers/base.py", line 108, in get_response
    response = middleware_method(request)
  File "/usr/local/lib/python2.7/dist-packages/django/middleware/common.py", line 74, in process_request
    if (not urlresolvers.is_valid_path(request.path_info, urlconf) and
  File "/usr/local/lib/python2.7/dist-packages/django/core/urlresolvers.py", line 646, in is_valid_path
    resolve(path, urlconf)
  File "/usr/local/lib/python2.7/dist-packages/django/core/urlresolvers.py", line 521, in resolve
    return get_resolver(urlconf).resolve(path)
  File "/usr/local/lib/python2.7/dist-packages/django/core/urlresolvers.py", line 365, in resolve
    for pattern in self.url_patterns:
  File "/usr/local/lib/python2.7/dist-packages/django/core/urlresolvers.py", line 401, in url_patterns
    patterns = getattr(self.urlconf_module, "urlpatterns", self.urlconf_module)
  File "/usr/local/lib/python2.7/dist-packages/django/core/urlresolvers.py", line 395, in urlconf_module
    self._urlconf_module = import_module(self.urlconf_name)
  File "/usr/lib/python2.7/importlib/__init__.py", line 37, in import_module
    __import__(name)
  File "/home/camilo/Documentos/djangoprojects/plataforma/turismo/urls.py", line 5, in <module>
    from sitios import views as sitio_views
  File "/home/camilo/Documentos/djangoprojects/plataforma/sitios/views.py", line 156, in <module>
    class SitioList(generics.ListAPIView):
  File "/home/camilo/Documentos/djangoprojects/plataforma/sitios/views.py", line 157, in SitioList
    queryset = Sitio.objects.filter(tipo='M')
  File "/usr/local/lib/python2.7/dist-packages/django/db/models/manager.py", line 127, in manager_method
    return getattr(self.get_queryset(), name)(*args, **kwargs)
  File "/usr/local/lib/python2.7/dist-packages/django/db/models/query.py", line 679, in filter
    return self._filter_or_exclude(False, *args, **kwargs)
  File "/usr/local/lib/python2.7/dist-packages/django/db/models/query.py", line 697, in _filter_or_exclude
    clone.query.add_q(Q(*args, **kwargs))
  File "/usr/local/lib/python2.7/dist-packages/django/db/models/sql/query.py", line 1310, in add_q
    clause, require_inner = self._add_q(where_part, self.used_aliases)
  File "/usr/local/lib/python2.7/dist-packages/django/db/models/sql/query.py", line 1338, in _add_q
    allow_joins=allow_joins, split_subq=split_subq,
  File "/usr/local/lib/python2.7/dist-packages/django/db/models/sql/query.py", line 1150, in build_filter
    lookups, parts, reffed_expression = self.solve_lookup_type(arg)
  File "/usr/local/lib/python2.7/dist-packages/django/db/models/sql/query.py", line 1036, in solve_lookup_type
    _, field, _, lookup_parts = self.names_to_path(lookup_splitted, self.get_meta())
  File "/usr/local/lib/python2.7/dist-packages/django/db/models/sql/query.py", line 1397, in names_to_path
    "Choices are: %s" % (name, ", ".join(available)))
FieldError: Cannot resolve keyword 'tipo' into field. Choices are: categorias, correolocal, descripcion, fotos, horariolocal, id, latitud, longitud, municipio, municipio_id, nombre, sitiocategoria, tags, telefono, tipo_sitio, ubicacionlocal, usuario, usuario_id, web, whatsapp
Internal Server Error: /municipios
Traceback (most recent call last):
  File "/usr/local/lib/python2.7/dist-packages/django/core/handlers/base.py", line 108, in get_response
    response = middleware_method(request)
  File "/usr/local/lib/python2.7/dist-packages/django/middleware/common.py", line 74, in process_request
    if (not urlresolvers.is_valid_path(request.path_info, urlconf) and
  File "/usr/local/lib/python2.7/dist-packages/django/core/urlresolvers.py", line 646, in is_valid_path
    resolve(path, urlconf)
  File "/usr/local/lib/python2.7/dist-packages/django/core/urlresolvers.py", line 521, in resolve
    return get_resolver(urlconf).resolve(path)
  File "/usr/local/lib/python2.7/dist-packages/django/core/urlresolvers.py", line 365, in resolve
    for pattern in self.url_patterns:
  File "/usr/local/lib/python2.7/dist-packages/django/core/urlresolvers.py", line 401, in url_patterns
    patterns = getattr(self.urlconf_module, "urlpatterns", self.urlconf_module)
  File "/usr/local/lib/python2.7/dist-packages/django/core/urlresolvers.py", line 395, in urlconf_module
    self._urlconf_module = import_module(self.urlconf_name)
  File "/usr/lib/python2.7/importlib/__init__.py", line 37, in import_module
    __import__(name)
  File "/home/camilo/Documentos/djangoprojects/plataforma/turismo/urls.py", line 5, in <module>
    from sitios import views as sitio_views
  File "/home/camilo/Documentos/djangoprojects/plataforma/sitios/views.py", line 156, in <module>
    class SitioList(generics.ListAPIView):
  File "/home/camilo/Documentos/djangoprojects/plataforma/sitios/views.py", line 157, in SitioList
    queryset = Sitio.objects.filter(tipo='M')
  File "/usr/local/lib/python2.7/dist-packages/django/db/models/manager.py", line 127, in manager_method
    return getattr(self.get_queryset(), name)(*args, **kwargs)
  File "/usr/local/lib/python2.7/dist-packages/django/db/models/query.py", line 679, in filter
    return self._filter_or_exclude(False, *args, **kwargs)
  File "/usr/local/lib/python2.7/dist-packages/django/db/models/query.py", line 697, in _filter_or_exclude
    clone.query.add_q(Q(*args, **kwargs))
  File "/usr/local/lib/python2.7/dist-packages/django/db/models/sql/query.py", line 1310, in add_q
    clause, require_inner = self._add_q(where_part, self.used_aliases)
  File "/usr/local/lib/python2.7/dist-packages/django/db/models/sql/query.py", line 1338, in _add_q
    allow_joins=allow_joins, split_subq=split_subq,
  File "/usr/local/lib/python2.7/dist-packages/django/db/models/sql/query.py", line 1150, in build_filter
    lookups, parts, reffed_expression = self.solve_lookup_type(arg)
  File "/usr/local/lib/python2.7/dist-packages/django/db/models/sql/query.py", line 1036, in solve_lookup_type
    _, field, _, lookup_parts = self.names_to_path(lookup_splitted, self.get_meta())
  File "/usr/local/lib/python2.7/dist-packages/django/db/models/sql/query.py", line 1397, in names_to_path
    "Choices are: %s" % (name, ", ".join(available)))
FieldError: Cannot resolve keyword 'tipo' into field. Choices are: categorias, correolocal, descripcion, fotos, horariolocal, id, latitud, longitud, municipio, municipio_id, nombre, sitiocategoria, tags, telefono, tipo_sitio, ubicacionlocal, usuario, usuario_id, web, whatsapp
Internal Server Error: /municipios
Traceback (most recent call last):
  File "/usr/local/lib/python2.7/dist-packages/django/core/handlers/base.py", line 108, in get_response
    response = middleware_method(request)
  File "/usr/local/lib/python2.7/dist-packages/django/middleware/common.py", line 74, in process_request
    if (not urlresolvers.is_valid_path(request.path_info, urlconf) and
  File "/usr/local/lib/python2.7/dist-packages/django/core/urlresolvers.py", line 646, in is_valid_path
    resolve(path, urlconf)
  File "/usr/local/lib/python2.7/dist-packages/django/core/urlresolvers.py", line 521, in resolve
    return get_resolver(urlconf).resolve(path)
  File "/usr/local/lib/python2.7/dist-packages/django/core/urlresolvers.py", line 365, in resolve
    for pattern in self.url_patterns:
  File "/usr/local/lib/python2.7/dist-packages/django/core/urlresolvers.py", line 401, in url_patterns
    patterns = getattr(self.urlconf_module, "urlpatterns", self.urlconf_module)
  File "/usr/local/lib/python2.7/dist-packages/django/core/urlresolvers.py", line 395, in urlconf_module
    self._urlconf_module = import_module(self.urlconf_name)
  File "/usr/lib/python2.7/importlib/__init__.py", line 37, in import_module
    __import__(name)
  File "/home/camilo/Documentos/djangoprojects/plataforma/turismo/urls.py", line 5, in <module>
    from sitios import views as sitio_views
  File "/home/camilo/Documentos/djangoprojects/plataforma/sitios/views.py", line 156, in <module>
    class SitioList(generics.ListAPIView):
  File "/home/camilo/Documentos/djangoprojects/plataforma/sitios/views.py", line 157, in SitioList
    queryset = Sitio.objects.filter(tipo='M')
  File "/usr/local/lib/python2.7/dist-packages/django/db/models/manager.py", line 127, in manager_method
    return getattr(self.get_queryset(), name)(*args, **kwargs)
  File "/usr/local/lib/python2.7/dist-packages/django/db/models/query.py", line 679, in filter
    return self._filter_or_exclude(False, *args, **kwargs)
  File "/usr/local/lib/python2.7/dist-packages/django/db/models/query.py", line 697, in _filter_or_exclude
    clone.query.add_q(Q(*args, **kwargs))
  File "/usr/local/lib/python2.7/dist-packages/django/db/models/sql/query.py", line 1310, in add_q
    clause, require_inner = self._add_q(where_part, self.used_aliases)
  File "/usr/local/lib/python2.7/dist-packages/django/db/models/sql/query.py", line 1338, in _add_q
    allow_joins=allow_joins, split_subq=split_subq,
  File "/usr/local/lib/python2.7/dist-packages/django/db/models/sql/query.py", line 1150, in build_filter
    lookups, parts, reffed_expression = self.solve_lookup_type(arg)
  File "/usr/local/lib/python2.7/dist-packages/django/db/models/sql/query.py", line 1036, in solve_lookup_type
    _, field, _, lookup_parts = self.names_to_path(lookup_splitted, self.get_meta())
  File "/usr/local/lib/python2.7/dist-packages/django/db/models/sql/query.py", line 1397, in names_to_path
    "Choices are: %s" % (name, ", ".join(available)))
FieldError: Cannot resolve keyword 'tipo' into field. Choices are: categorias, correolocal, descripcion, fotos, horariolocal, id, latitud, longitud, municipio, municipio_id, nombre, sitiocategoria, tags, telefono, tipo_sitio, ubicacionlocal, usuario, usuario_id, web, whatsapp
Internal Server Error: /municipios
Traceback (most recent call last):
  File "/usr/local/lib/python2.7/dist-packages/django/core/handlers/base.py", line 108, in get_response
    response = middleware_method(request)
  File "/usr/local/lib/python2.7/dist-packages/django/middleware/common.py", line 74, in process_request
    if (not urlresolvers.is_valid_path(request.path_info, urlconf) and
  File "/usr/local/lib/python2.7/dist-packages/django/core/urlresolvers.py", line 646, in is_valid_path
    resolve(path, urlconf)
  File "/usr/local/lib/python2.7/dist-packages/django/core/urlresolvers.py", line 521, in resolve
    return get_resolver(urlconf).resolve(path)
  File "/usr/local/lib/python2.7/dist-packages/django/core/urlresolvers.py", line 365, in resolve
    for pattern in self.url_patterns:
  File "/usr/local/lib/python2.7/dist-packages/django/core/urlresolvers.py", line 401, in url_patterns
    patterns = getattr(self.urlconf_module, "urlpatterns", self.urlconf_module)
  File "/usr/local/lib/python2.7/dist-packages/django/core/urlresolvers.py", line 395, in urlconf_module
    self._urlconf_module = import_module(self.urlconf_name)
  File "/usr/lib/python2.7/importlib/__init__.py", line 37, in import_module
    __import__(name)
  File "/home/camilo/Documentos/djangoprojects/plataforma/turismo/urls.py", line 5, in <module>
    from sitios import views as sitio_views
  File "/home/camilo/Documentos/djangoprojects/plataforma/sitios/views.py", line 156, in <module>
    class SitioList(generics.ListAPIView):
  File "/home/camilo/Documentos/djangoprojects/plataforma/sitios/views.py", line 157, in SitioList
    queryset = Sitio.objects.filter(tipo='M')
  File "/usr/local/lib/python2.7/dist-packages/django/db/models/manager.py", line 127, in manager_method
    return getattr(self.get_queryset(), name)(*args, **kwargs)
  File "/usr/local/lib/python2.7/dist-packages/django/db/models/query.py", line 679, in filter
    return self._filter_or_exclude(False, *args, **kwargs)
  File "/usr/local/lib/python2.7/dist-packages/django/db/models/query.py", line 697, in _filter_or_exclude
    clone.query.add_q(Q(*args, **kwargs))
  File "/usr/local/lib/python2.7/dist-packages/django/db/models/sql/query.py", line 1310, in add_q
    clause, require_inner = self._add_q(where_part, self.used_aliases)
  File "/usr/local/lib/python2.7/dist-packages/django/db/models/sql/query.py", line 1338, in _add_q
    allow_joins=allow_joins, split_subq=split_subq,
  File "/usr/local/lib/python2.7/dist-packages/django/db/models/sql/query.py", line 1150, in build_filter
    lookups, parts, reffed_expression = self.solve_lookup_type(arg)
  File "/usr/local/lib/python2.7/dist-packages/django/db/models/sql/query.py", line 1036, in solve_lookup_type
    _, field, _, lookup_parts = self.names_to_path(lookup_splitted, self.get_meta())
  File "/usr/local/lib/python2.7/dist-packages/django/db/models/sql/query.py", line 1397, in names_to_path
    "Choices are: %s" % (name, ", ".join(available)))
FieldError: Cannot resolve keyword 'tipo' into field. Choices are: categorias, correolocal, descripcion, fotos, horariolocal, id, latitud, longitud, municipio, municipio_id, nombre, sitiocategoria, tags, telefono, tipo_sitio, ubicacionlocal, usuario, usuario_id, web, whatsapp
Internal Server Error: /
Traceback (most recent call last):
  File "/usr/local/lib/python2.7/dist-packages/django/core/handlers/base.py", line 119, in get_response
    resolver_match = resolver.resolve(request.path_info)
  File "/usr/local/lib/python2.7/dist-packages/django/core/urlresolvers.py", line 365, in resolve
    for pattern in self.url_patterns:
  File "/usr/local/lib/python2.7/dist-packages/django/core/urlresolvers.py", line 401, in url_patterns
    patterns = getattr(self.urlconf_module, "urlpatterns", self.urlconf_module)
  File "/usr/local/lib/python2.7/dist-packages/django/core/urlresolvers.py", line 395, in urlconf_module
    self._urlconf_module = import_module(self.urlconf_name)
  File "/usr/lib/python2.7/importlib/__init__.py", line 37, in import_module
    __import__(name)
  File "/home/camilo/Documentos/djangoprojects/plataforma/turismo/urls.py", line 5, in <module>
    from sitios import views as sitio_views
  File "/home/camilo/Documentos/djangoprojects/plataforma/sitios/views.py", line 156, in <module>
    class SitioMunicipioList(generics.ListAPIView):
  File "/home/camilo/Documentos/djangoprojects/plataforma/sitios/views.py", line 157, in SitioMunicipioList
    queryset = Sitio.objects.filter(tipo='M')
  File "/usr/local/lib/python2.7/dist-packages/django/db/models/manager.py", line 127, in manager_method
    return getattr(self.get_queryset(), name)(*args, **kwargs)
  File "/usr/local/lib/python2.7/dist-packages/django/db/models/query.py", line 679, in filter
    return self._filter_or_exclude(False, *args, **kwargs)
  File "/usr/local/lib/python2.7/dist-packages/django/db/models/query.py", line 697, in _filter_or_exclude
    clone.query.add_q(Q(*args, **kwargs))
  File "/usr/local/lib/python2.7/dist-packages/django/db/models/sql/query.py", line 1310, in add_q
    clause, require_inner = self._add_q(where_part, self.used_aliases)
  File "/usr/local/lib/python2.7/dist-packages/django/db/models/sql/query.py", line 1338, in _add_q
    allow_joins=allow_joins, split_subq=split_subq,
  File "/usr/local/lib/python2.7/dist-packages/django/db/models/sql/query.py", line 1150, in build_filter
    lookups, parts, reffed_expression = self.solve_lookup_type(arg)
  File "/usr/local/lib/python2.7/dist-packages/django/db/models/sql/query.py", line 1036, in solve_lookup_type
    _, field, _, lookup_parts = self.names_to_path(lookup_splitted, self.get_meta())
  File "/usr/local/lib/python2.7/dist-packages/django/db/models/sql/query.py", line 1397, in names_to_path
    "Choices are: %s" % (name, ", ".join(available)))
FieldError: Cannot resolve keyword 'tipo' into field. Choices are: categorias, correolocal, descripcion, fotos, horariolocal, id, latitud, longitud, municipio, municipio_id, nombre, sitiocategoria, tags, telefono, tipo_sitio, ubicacionlocal, usuario, usuario_id, web, whatsapp
Internal Server Error: /favicon.ico
Traceback (most recent call last):
  File "/usr/local/lib/python2.7/dist-packages/django/core/handlers/base.py", line 108, in get_response
    response = middleware_method(request)
  File "/usr/local/lib/python2.7/dist-packages/django/middleware/common.py", line 74, in process_request
    if (not urlresolvers.is_valid_path(request.path_info, urlconf) and
  File "/usr/local/lib/python2.7/dist-packages/django/core/urlresolvers.py", line 646, in is_valid_path
    resolve(path, urlconf)
  File "/usr/local/lib/python2.7/dist-packages/django/core/urlresolvers.py", line 521, in resolve
    return get_resolver(urlconf).resolve(path)
  File "/usr/local/lib/python2.7/dist-packages/django/core/urlresolvers.py", line 365, in resolve
    for pattern in self.url_patterns:
  File "/usr/local/lib/python2.7/dist-packages/django/core/urlresolvers.py", line 401, in url_patterns
    patterns = getattr(self.urlconf_module, "urlpatterns", self.urlconf_module)
  File "/usr/local/lib/python2.7/dist-packages/django/core/urlresolvers.py", line 395, in urlconf_module
    self._urlconf_module = import_module(self.urlconf_name)
  File "/usr/lib/python2.7/importlib/__init__.py", line 37, in import_module
    __import__(name)
  File "/home/camilo/Documentos/djangoprojects/plataforma/turismo/urls.py", line 5, in <module>
    from sitios import views as sitio_views
  File "/home/camilo/Documentos/djangoprojects/plataforma/sitios/views.py", line 156, in <module>
    class SitioMunicipioList(generics.ListAPIView):
  File "/home/camilo/Documentos/djangoprojects/plataforma/sitios/views.py", line 157, in SitioMunicipioList
    queryset = Sitio.objects.filter(tipo='M')
  File "/usr/local/lib/python2.7/dist-packages/django/db/models/manager.py", line 127, in manager_method
    return getattr(self.get_queryset(), name)(*args, **kwargs)
  File "/usr/local/lib/python2.7/dist-packages/django/db/models/query.py", line 679, in filter
    return self._filter_or_exclude(False, *args, **kwargs)
  File "/usr/local/lib/python2.7/dist-packages/django/db/models/query.py", line 697, in _filter_or_exclude
    clone.query.add_q(Q(*args, **kwargs))
  File "/usr/local/lib/python2.7/dist-packages/django/db/models/sql/query.py", line 1310, in add_q
    clause, require_inner = self._add_q(where_part, self.used_aliases)
  File "/usr/local/lib/python2.7/dist-packages/django/db/models/sql/query.py", line 1338, in _add_q
    allow_joins=allow_joins, split_subq=split_subq,
  File "/usr/local/lib/python2.7/dist-packages/django/db/models/sql/query.py", line 1150, in build_filter
    lookups, parts, reffed_expression = self.solve_lookup_type(arg)
  File "/usr/local/lib/python2.7/dist-packages/django/db/models/sql/query.py", line 1036, in solve_lookup_type
    _, field, _, lookup_parts = self.names_to_path(lookup_splitted, self.get_meta())
  File "/usr/local/lib/python2.7/dist-packages/django/db/models/sql/query.py", line 1397, in names_to_path
    "Choices are: %s" % (name, ", ".join(available)))
FieldError: Cannot resolve keyword 'tipo' into field. Choices are: categorias, correolocal, descripcion, fotos, horariolocal, id, latitud, longitud, municipio, municipio_id, nombre, sitiocategoria, tags, telefono, tipo_sitio, ubicacionlocal, usuario, usuario_id, web, whatsapp
Internal Server Error: /sitio
Traceback (most recent call last):
  File "/usr/local/lib/python2.7/dist-packages/django/core/handlers/base.py", line 132, in get_response
    response = wrapped_callback(request, *callback_args, **callback_kwargs)
  File "/usr/local/lib/python2.7/dist-packages/django/views/decorators/csrf.py", line 58, in wrapped_view
    return view_func(*args, **kwargs)
  File "/usr/local/lib/python2.7/dist-packages/django/views/generic/base.py", line 71, in view
    return self.dispatch(request, *args, **kwargs)
  File "/usr/local/lib/python2.7/dist-packages/rest_framework/views.py", line 407, in dispatch
    response = self.handle_exception(exc)
  File "/usr/local/lib/python2.7/dist-packages/rest_framework/views.py", line 404, in dispatch
    response = handler(request, *args, **kwargs)
  File "/usr/local/lib/python2.7/dist-packages/rest_framework/generics.py", line 260, in post
    return self.create(request, *args, **kwargs)
  File "/home/camilo/Documentos/djangoprojects/plataforma/sitios/views.py", line 80, in create
    reduce_site_photos(dir,site_photos)
  File "/home/camilo/Documentos/djangoprojects/plataforma/sitios/photo_processing.py", line 46, in reduce_site_photos
    photo.URLfoto.name = reduce_photo_size(dir,photo.URLfoto.name,photo.URLfoto.size)
  File "/home/camilo/Documentos/djangoprojects/plataforma/sitios/photo_processing.py", line 39, in reduce_photo_size
    file.close()
  File "/usr/lib/python2.7/dist-packages/PIL/Image.py", line 528, in __getattr__
    raise AttributeError(name)
AttributeError: close
Internal Server Error: /sitio
Traceback (most recent call last):
  File "/usr/local/lib/python2.7/dist-packages/django/core/handlers/base.py", line 132, in get_response
    response = wrapped_callback(request, *callback_args, **callback_kwargs)
  File "/usr/local/lib/python2.7/dist-packages/django/views/decorators/csrf.py", line 58, in wrapped_view
    return view_func(*args, **kwargs)
  File "/usr/local/lib/python2.7/dist-packages/django/views/generic/base.py", line 71, in view
    return self.dispatch(request, *args, **kwargs)
  File "/usr/local/lib/python2.7/dist-packages/rest_framework/views.py", line 407, in dispatch
    response = self.handle_exception(exc)
  File "/usr/local/lib/python2.7/dist-packages/rest_framework/views.py", line 404, in dispatch
    response = handler(request, *args, **kwargs)
  File "/usr/local/lib/python2.7/dist-packages/rest_framework/generics.py", line 260, in post
    return self.create(request, *args, **kwargs)
  File "/home/camilo/Documentos/djangoprojects/plataforma/sitios/views.py", line 80, in create
    reduce_site_photos(dir,site_photos)
  File "/home/camilo/Documentos/djangoprojects/plataforma/sitios/photo_processing.py", line 46, in reduce_site_photos
    photo.URLfoto.name = reduce_photo_size(dir,photo.URLfoto.name,photo.URLfoto.size)
  File "/home/camilo/Documentos/djangoprojects/plataforma/sitios/photo_processing.py", line 24, in reduce_photo_size
    file.close()
  File "/usr/lib/python2.7/dist-packages/PIL/Image.py", line 528, in __getattr__
    raise AttributeError(name)
AttributeError: close
Internal Server Error: /sitio/detail/1
Traceback (most recent call last):
  File "/usr/local/lib/python2.7/dist-packages/django/core/handlers/base.py", line 132, in get_response
    response = wrapped_callback(request, *callback_args, **callback_kwargs)
  File "/usr/local/lib/python2.7/dist-packages/django/views/decorators/csrf.py", line 58, in wrapped_view
    return view_func(*args, **kwargs)
  File "/usr/local/lib/python2.7/dist-packages/django/views/generic/base.py", line 71, in view
    return self.dispatch(request, *args, **kwargs)
  File "/usr/local/lib/python2.7/dist-packages/rest_framework/views.py", line 407, in dispatch
    response = self.handle_exception(exc)
  File "/usr/local/lib/python2.7/dist-packages/rest_framework/views.py", line 404, in dispatch
    response = handler(request, *args, **kwargs)
  File "/usr/local/lib/python2.7/dist-packages/rest_framework/generics.py", line 357, in put
    return self.update(request, *args, **kwargs)
  File "/home/camilo/Documentos/djangoprojects/plataforma/sitios/views.py", line 115, in update
    reduce_site_photos(dir,site_photos)
  File "/home/camilo/Documentos/djangoprojects/plataforma/sitios/photo_processing.py", line 46, in reduce_site_photos
    photo.URLfoto.name = reduce_photo_size(dir,photo.URLfoto.name,photo.URLfoto.size)
  File "/home/camilo/Documentos/djangoprojects/plataforma/sitios/photo_processing.py", line 39, in reduce_photo_size
    file.close()
  File "/usr/lib/python2.7/dist-packages/PIL/Image.py", line 528, in __getattr__
    raise AttributeError(name)
AttributeError: close
Internal Server Error: /sitio/detail/1
Traceback (most recent call last):
  File "/usr/local/lib/python2.7/dist-packages/django/core/handlers/base.py", line 132, in get_response
    response = wrapped_callback(request, *callback_args, **callback_kwargs)
  File "/usr/local/lib/python2.7/dist-packages/django/views/decorators/csrf.py", line 58, in wrapped_view
    return view_func(*args, **kwargs)
  File "/usr/local/lib/python2.7/dist-packages/django/views/generic/base.py", line 71, in view
    return self.dispatch(request, *args, **kwargs)
  File "/usr/local/lib/python2.7/dist-packages/rest_framework/views.py", line 407, in dispatch
    response = self.handle_exception(exc)
  File "/usr/local/lib/python2.7/dist-packages/rest_framework/views.py", line 404, in dispatch
    response = handler(request, *args, **kwargs)
  File "/usr/local/lib/python2.7/dist-packages/rest_framework/generics.py", line 357, in put
    return self.update(request, *args, **kwargs)
  File "/home/camilo/Documentos/djangoprojects/plataforma/sitios/views.py", line 115, in update
    reduce_site_photos(dir,site_photos)
  File "/home/camilo/Documentos/djangoprojects/plataforma/sitios/photo_processing.py", line 46, in reduce_site_photos
    photo.URLfoto.name = reduce_photo_size(dir,photo.URLfoto.name,photo.URLfoto.size)
  File "/home/camilo/Documentos/djangoprojects/plataforma/sitios/photo_processing.py", line 39, in reduce_photo_size
    file.close()
  File "/usr/lib/python2.7/dist-packages/PIL/Image.py", line 528, in __getattr__
    raise AttributeError(name)
AttributeError: close
Internal Server Error: /sitio
Traceback (most recent call last):
  File "/usr/local/lib/python2.7/dist-packages/django/core/handlers/base.py", line 132, in get_response
    response = wrapped_callback(request, *callback_args, **callback_kwargs)
  File "/usr/local/lib/python2.7/dist-packages/django/views/decorators/csrf.py", line 58, in wrapped_view
    return view_func(*args, **kwargs)
  File "/usr/local/lib/python2.7/dist-packages/django/views/generic/base.py", line 71, in view
    return self.dispatch(request, *args, **kwargs)
  File "/usr/local/lib/python2.7/dist-packages/rest_framework/views.py", line 407, in dispatch
    response = self.handle_exception(exc)
  File "/usr/local/lib/python2.7/dist-packages/rest_framework/views.py", line 404, in dispatch
    response = handler(request, *args, **kwargs)
  File "/usr/local/lib/python2.7/dist-packages/rest_framework/generics.py", line 260, in post
    return self.create(request, *args, **kwargs)
  File "/home/camilo/Documentos/djangoprojects/plataforma/sitios/views.py", line 80, in create
    reduce_site_photos(dir,site_photos)
  File "/home/camilo/Documentos/djangoprojects/plataforma/sitios/photo_processing.py", line 46, in reduce_site_photos
    photo.URLfoto.name = reduce_photo_size(dir,photo.URLfoto.name,photo.URLfoto.size)
  File "/home/camilo/Documentos/djangoprojects/plataforma/sitios/photo_processing.py", line 24, in reduce_photo_size
    file.close()
  File "/usr/lib/python2.7/dist-packages/PIL/Image.py", line 528, in __getattr__
    raise AttributeError(name)
AttributeError: close
Internal Server Error: /sitio
Traceback (most recent call last):
  File "/usr/local/lib/python2.7/dist-packages/django/core/handlers/base.py", line 132, in get_response
    response = wrapped_callback(request, *callback_args, **callback_kwargs)
  File "/usr/local/lib/python2.7/dist-packages/django/views/decorators/csrf.py", line 58, in wrapped_view
    return view_func(*args, **kwargs)
  File "/usr/local/lib/python2.7/dist-packages/django/views/generic/base.py", line 71, in view
    return self.dispatch(request, *args, **kwargs)
  File "/usr/local/lib/python2.7/dist-packages/rest_framework/views.py", line 407, in dispatch
    response = self.handle_exception(exc)
  File "/usr/local/lib/python2.7/dist-packages/rest_framework/views.py", line 404, in dispatch
    response = handler(request, *args, **kwargs)
  File "/usr/local/lib/python2.7/dist-packages/rest_framework/generics.py", line 260, in post
    return self.create(request, *args, **kwargs)
  File "/home/camilo/Documentos/djangoprojects/plataforma/sitios/views.py", line 80, in create
    reduce_site_photos(dir,site_photos)
  File "/home/camilo/Documentos/djangoprojects/plataforma/sitios/photo_processing.py", line 46, in reduce_site_photos
    photo.URLfoto.name = reduce_photo_size(dir,photo.URLfoto.name,photo.URLfoto.size)
  File "/home/camilo/Documentos/djangoprojects/plataforma/sitios/photo_processing.py", line 24, in reduce_photo_size
    file.close()
  File "/usr/lib/python2.7/dist-packages/PIL/Image.py", line 528, in __getattr__
    raise AttributeError(name)
AttributeError: close
Internal Server Error: /
Traceback (most recent call last):
  File "/usr/local/lib/python2.7/dist-packages/django/core/handlers/base.py", line 119, in get_response
    resolver_match = resolver.resolve(request.path_info)
  File "/usr/local/lib/python2.7/dist-packages/django/core/urlresolvers.py", line 365, in resolve
    for pattern in self.url_patterns:
  File "/usr/local/lib/python2.7/dist-packages/django/core/urlresolvers.py", line 401, in url_patterns
    patterns = getattr(self.urlconf_module, "urlpatterns", self.urlconf_module)
  File "/usr/local/lib/python2.7/dist-packages/django/core/urlresolvers.py", line 395, in urlconf_module
    self._urlconf_module = import_module(self.urlconf_name)
  File "/usr/lib/python2.7/importlib/__init__.py", line 37, in import_module
    __import__(name)
  File "/home/camilo/Documentos/djangoprojects/plataforma/turismo/urls.py", line 38, in <module>
    url(r'^rutas', sitio_views.RutaCreate.as_view()),
AttributeError: 'module' object has no attribute 'RutaCreate'
Internal Server Error: /favicon.ico
Traceback (most recent call last):
  File "/usr/local/lib/python2.7/dist-packages/django/core/handlers/base.py", line 108, in get_response
    response = middleware_method(request)
  File "/usr/local/lib/python2.7/dist-packages/django/middleware/common.py", line 74, in process_request
    if (not urlresolvers.is_valid_path(request.path_info, urlconf) and
  File "/usr/local/lib/python2.7/dist-packages/django/core/urlresolvers.py", line 646, in is_valid_path
    resolve(path, urlconf)
  File "/usr/local/lib/python2.7/dist-packages/django/core/urlresolvers.py", line 521, in resolve
    return get_resolver(urlconf).resolve(path)
  File "/usr/local/lib/python2.7/dist-packages/django/core/urlresolvers.py", line 365, in resolve
    for pattern in self.url_patterns:
  File "/usr/local/lib/python2.7/dist-packages/django/core/urlresolvers.py", line 401, in url_patterns
    patterns = getattr(self.urlconf_module, "urlpatterns", self.urlconf_module)
  File "/usr/local/lib/python2.7/dist-packages/django/core/urlresolvers.py", line 395, in urlconf_module
    self._urlconf_module = import_module(self.urlconf_name)
  File "/usr/lib/python2.7/importlib/__init__.py", line 37, in import_module
    __import__(name)
  File "/home/camilo/Documentos/djangoprojects/plataforma/turismo/urls.py", line 38, in <module>
    url(r'^rutas', sitio_views.RutaCreate.as_view()),
AttributeError: 'module' object has no attribute 'RutaCreate'
Internal Server Error: /
Traceback (most recent call last):
  File "/usr/local/lib/python2.7/dist-packages/django/core/handlers/base.py", line 119, in get_response
    resolver_match = resolver.resolve(request.path_info)
  File "/usr/local/lib/python2.7/dist-packages/django/core/urlresolvers.py", line 365, in resolve
    for pattern in self.url_patterns:
  File "/usr/local/lib/python2.7/dist-packages/django/core/urlresolvers.py", line 401, in url_patterns
    patterns = getattr(self.urlconf_module, "urlpatterns", self.urlconf_module)
  File "/usr/local/lib/python2.7/dist-packages/django/core/urlresolvers.py", line 395, in urlconf_module
    self._urlconf_module = import_module(self.urlconf_name)
  File "/usr/lib/python2.7/importlib/__init__.py", line 37, in import_module
    __import__(name)
  File "/home/camilo/Documentos/djangoprojects/plataforma/turismo/urls.py", line 6, in <module>
    from rutas import views
  File "/home/camilo/Documentos/djangoprojects/plataforma/rutas/views.py", line 6, in <module>
    class RutaCreate(generics.CreateAPIView):
NameError: name 'generics' is not defined
Internal Server Error: /favicon.ico
Traceback (most recent call last):
  File "/usr/local/lib/python2.7/dist-packages/django/core/handlers/base.py", line 108, in get_response
    response = middleware_method(request)
  File "/usr/local/lib/python2.7/dist-packages/django/middleware/common.py", line 74, in process_request
    if (not urlresolvers.is_valid_path(request.path_info, urlconf) and
  File "/usr/local/lib/python2.7/dist-packages/django/core/urlresolvers.py", line 646, in is_valid_path
    resolve(path, urlconf)
  File "/usr/local/lib/python2.7/dist-packages/django/core/urlresolvers.py", line 521, in resolve
    return get_resolver(urlconf).resolve(path)
  File "/usr/local/lib/python2.7/dist-packages/django/core/urlresolvers.py", line 365, in resolve
    for pattern in self.url_patterns:
  File "/usr/local/lib/python2.7/dist-packages/django/core/urlresolvers.py", line 401, in url_patterns
    patterns = getattr(self.urlconf_module, "urlpatterns", self.urlconf_module)
  File "/usr/local/lib/python2.7/dist-packages/django/core/urlresolvers.py", line 395, in urlconf_module
    self._urlconf_module = import_module(self.urlconf_name)
  File "/usr/lib/python2.7/importlib/__init__.py", line 37, in import_module
    __import__(name)
  File "/home/camilo/Documentos/djangoprojects/plataforma/turismo/urls.py", line 6, in <module>
    from rutas import views
  File "/home/camilo/Documentos/djangoprojects/plataforma/rutas/views.py", line 6, in <module>
    class RutaCreate(generics.CreateAPIView):
NameError: name 'generics' is not defined
Internal Server Error: /
Traceback (most recent call last):
  File "/usr/local/lib/python2.7/dist-packages/django/core/handlers/base.py", line 119, in get_response
    resolver_match = resolver.resolve(request.path_info)
  File "/usr/local/lib/python2.7/dist-packages/django/core/urlresolvers.py", line 365, in resolve
    for pattern in self.url_patterns:
  File "/usr/local/lib/python2.7/dist-packages/django/core/urlresolvers.py", line 401, in url_patterns
    patterns = getattr(self.urlconf_module, "urlpatterns", self.urlconf_module)
  File "/usr/local/lib/python2.7/dist-packages/django/core/urlresolvers.py", line 395, in urlconf_module
    self._urlconf_module = import_module(self.urlconf_name)
  File "/usr/lib/python2.7/importlib/__init__.py", line 37, in import_module
    __import__(name)
  File "/home/camilo/Documentos/djangoprojects/plataforma/turismo/urls.py", line 21, in <module>
    url(r'^municipios', views.MunicipiosListCreate.as_view()),
AttributeError: 'module' object has no attribute 'MunicipiosListCreate'
Internal Server Error: /favicon.ico
Traceback (most recent call last):
  File "/usr/local/lib/python2.7/dist-packages/django/core/handlers/base.py", line 108, in get_response
    response = middleware_method(request)
  File "/usr/local/lib/python2.7/dist-packages/django/middleware/common.py", line 74, in process_request
    if (not urlresolvers.is_valid_path(request.path_info, urlconf) and
  File "/usr/local/lib/python2.7/dist-packages/django/core/urlresolvers.py", line 646, in is_valid_path
    resolve(path, urlconf)
  File "/usr/local/lib/python2.7/dist-packages/django/core/urlresolvers.py", line 521, in resolve
    return get_resolver(urlconf).resolve(path)
  File "/usr/local/lib/python2.7/dist-packages/django/core/urlresolvers.py", line 365, in resolve
    for pattern in self.url_patterns:
  File "/usr/local/lib/python2.7/dist-packages/django/core/urlresolvers.py", line 401, in url_patterns
    patterns = getattr(self.urlconf_module, "urlpatterns", self.urlconf_module)
  File "/usr/local/lib/python2.7/dist-packages/django/core/urlresolvers.py", line 395, in urlconf_module
    self._urlconf_module = import_module(self.urlconf_name)
  File "/usr/lib/python2.7/importlib/__init__.py", line 37, in import_module
    __import__(name)
  File "/home/camilo/Documentos/djangoprojects/plataforma/turismo/urls.py", line 21, in <module>
    url(r'^municipios', views.MunicipiosListCreate.as_view()),
AttributeError: 'module' object has no attribute 'MunicipiosListCreate'
Internal Server Error: /rutas
Traceback (most recent call last):
  File "/usr/local/lib/python2.7/dist-packages/django/core/handlers/base.py", line 108, in get_response
    response = middleware_method(request)
  File "/usr/local/lib/python2.7/dist-packages/django/middleware/common.py", line 74, in process_request
    if (not urlresolvers.is_valid_path(request.path_info, urlconf) and
  File "/usr/local/lib/python2.7/dist-packages/django/core/urlresolvers.py", line 646, in is_valid_path
    resolve(path, urlconf)
  File "/usr/local/lib/python2.7/dist-packages/django/core/urlresolvers.py", line 521, in resolve
    return get_resolver(urlconf).resolve(path)
  File "/usr/local/lib/python2.7/dist-packages/django/core/urlresolvers.py", line 365, in resolve
    for pattern in self.url_patterns:
  File "/usr/local/lib/python2.7/dist-packages/django/core/urlresolvers.py", line 401, in url_patterns
    patterns = getattr(self.urlconf_module, "urlpatterns", self.urlconf_module)
  File "/usr/local/lib/python2.7/dist-packages/django/core/urlresolvers.py", line 395, in urlconf_module
    self._urlconf_module = import_module(self.urlconf_name)
  File "/usr/lib/python2.7/importlib/__init__.py", line 37, in import_module
    __import__(name)
  File "/home/camilo/Documentos/djangoprojects/plataforma/turismo/urls.py", line 40, in <module>
    url(r'^rutas', ruta_views.RutaList.as_view()),
AttributeError: 'module' object has no attribute 'RutaList'
Internal Server Error: /rutas
Traceback (most recent call last):
  File "/usr/local/lib/python2.7/dist-packages/django/core/handlers/base.py", line 108, in get_response
    response = middleware_method(request)
  File "/usr/local/lib/python2.7/dist-packages/django/middleware/common.py", line 74, in process_request
    if (not urlresolvers.is_valid_path(request.path_info, urlconf) and
  File "/usr/local/lib/python2.7/dist-packages/django/core/urlresolvers.py", line 646, in is_valid_path
    resolve(path, urlconf)
  File "/usr/local/lib/python2.7/dist-packages/django/core/urlresolvers.py", line 521, in resolve
    return get_resolver(urlconf).resolve(path)
  File "/usr/local/lib/python2.7/dist-packages/django/core/urlresolvers.py", line 367, in resolve
    sub_match = pattern.resolve(new_path)
  File "/usr/local/lib/python2.7/dist-packages/django/core/urlresolvers.py", line 237, in resolve
    kwargs.update(self.default_args)
TypeError: 'function' object is not iterable
Internal Server Error: /rutas
Traceback (most recent call last):
  File "/usr/local/lib/python2.7/dist-packages/django/core/handlers/base.py", line 108, in get_response
    response = middleware_method(request)
  File "/usr/local/lib/python2.7/dist-packages/django/middleware/common.py", line 74, in process_request
    if (not urlresolvers.is_valid_path(request.path_info, urlconf) and
  File "/usr/local/lib/python2.7/dist-packages/django/core/urlresolvers.py", line 646, in is_valid_path
    resolve(path, urlconf)
  File "/usr/local/lib/python2.7/dist-packages/django/core/urlresolvers.py", line 521, in resolve
    return get_resolver(urlconf).resolve(path)
  File "/usr/local/lib/python2.7/dist-packages/django/core/urlresolvers.py", line 365, in resolve
    for pattern in self.url_patterns:
  File "/usr/local/lib/python2.7/dist-packages/django/core/urlresolvers.py", line 401, in url_patterns
    patterns = getattr(self.urlconf_module, "urlpatterns", self.urlconf_module)
  File "/usr/local/lib/python2.7/dist-packages/django/core/urlresolvers.py", line 395, in urlconf_module
    self._urlconf_module = import_module(self.urlconf_name)
  File "/usr/lib/python2.7/importlib/__init__.py", line 37, in import_module
    __import__(name)
  File "/home/camilo/Documentos/djangoprojects/plataforma/turismo/urls.py", line 39, in <module>
    url(r'^rutas', ruta_views.RutaCreate.as_view({'post': 'create'})),
TypeError: as_view() takes exactly 1 argument (2 given)
Internal Server Error: /rutas
Traceback (most recent call last):
  File "/usr/local/lib/python2.7/dist-packages/django/core/handlers/base.py", line 108, in get_response
    response = middleware_method(request)
  File "/usr/local/lib/python2.7/dist-packages/django/middleware/common.py", line 74, in process_request
    if (not urlresolvers.is_valid_path(request.path_info, urlconf) and
  File "/usr/local/lib/python2.7/dist-packages/django/core/urlresolvers.py", line 646, in is_valid_path
    resolve(path, urlconf)
  File "/usr/local/lib/python2.7/dist-packages/django/core/urlresolvers.py", line 521, in resolve
    return get_resolver(urlconf).resolve(path)
  File "/usr/local/lib/python2.7/dist-packages/django/core/urlresolvers.py", line 365, in resolve
    for pattern in self.url_patterns:
  File "/usr/local/lib/python2.7/dist-packages/django/core/urlresolvers.py", line 401, in url_patterns
    patterns = getattr(self.urlconf_module, "urlpatterns", self.urlconf_module)
  File "/usr/local/lib/python2.7/dist-packages/django/core/urlresolvers.py", line 395, in urlconf_module
    self._urlconf_module = import_module(self.urlconf_name)
  File "/usr/lib/python2.7/importlib/__init__.py", line 37, in import_module
    __import__(name)
  File "/home/camilo/Documentos/djangoprojects/plataforma/turismo/urls.py", line 6, in <module>
    from rutas import views as ruta_views
  File "/home/camilo/Documentos/djangoprojects/plataforma/rutas/views.py", line 5, in <module>
    from rutas.serializers import RutaSerializer
  File "/home/camilo/Documentos/djangoprojects/plataforma/rutas/serializers.py", line 5, in <module>
    class RutaSerializer(serializers.ModelSerializer):
  File "/home/camilo/Documentos/djangoprojects/plataforma/rutas/serializers.py", line 6, in RutaSerializer
    sitios = RutaSitioSerializer(source='rutasitio_set', many=True)
NameError: name 'RutaSitioSerializer' is not defined
Internal Server Error: /rutas
Traceback (most recent call last):
  File "/usr/local/lib/python2.7/dist-packages/django/core/handlers/base.py", line 108, in get_response
    response = middleware_method(request)
  File "/usr/local/lib/python2.7/dist-packages/django/middleware/common.py", line 74, in process_request
    if (not urlresolvers.is_valid_path(request.path_info, urlconf) and
  File "/usr/local/lib/python2.7/dist-packages/django/core/urlresolvers.py", line 646, in is_valid_path
    resolve(path, urlconf)
  File "/usr/local/lib/python2.7/dist-packages/django/core/urlresolvers.py", line 521, in resolve
    return get_resolver(urlconf).resolve(path)
  File "/usr/local/lib/python2.7/dist-packages/django/core/urlresolvers.py", line 365, in resolve
    for pattern in self.url_patterns:
  File "/usr/local/lib/python2.7/dist-packages/django/core/urlresolvers.py", line 401, in url_patterns
    patterns = getattr(self.urlconf_module, "urlpatterns", self.urlconf_module)
  File "/usr/local/lib/python2.7/dist-packages/django/core/urlresolvers.py", line 395, in urlconf_module
    self._urlconf_module = import_module(self.urlconf_name)
  File "/usr/lib/python2.7/importlib/__init__.py", line 37, in import_module
    __import__(name)
  File "/home/camilo/Documentos/djangoprojects/plataforma/turismo/urls.py", line 6, in <module>
    from rutas import views as ruta_views
  File "/home/camilo/Documentos/djangoprojects/plataforma/rutas/views.py", line 5, in <module>
    from rutas.serializers import RutaSerializer
  File "/home/camilo/Documentos/djangoprojects/plataforma/rutas/serializers.py", line 3, in <module>
    from sitios.serializers import SitioSerializer, RutaSitioSerializer
ImportError: cannot import name RutaSitioSerializer
Internal Server Error: /buscar/
Traceback (most recent call last):
  File "/usr/local/lib/python2.7/dist-packages/django/core/handlers/base.py", line 119, in get_response
    resolver_match = resolver.resolve(request.path_info)
  File "/usr/local/lib/python2.7/dist-packages/django/core/urlresolvers.py", line 365, in resolve
    for pattern in self.url_patterns:
  File "/usr/local/lib/python2.7/dist-packages/django/core/urlresolvers.py", line 401, in url_patterns
    patterns = getattr(self.urlconf_module, "urlpatterns", self.urlconf_module)
  File "/usr/local/lib/python2.7/dist-packages/django/core/urlresolvers.py", line 395, in urlconf_module
    self._urlconf_module = import_module(self.urlconf_name)
  File "/usr/lib/python2.7/importlib/__init__.py", line 37, in import_module
    __import__(name)
  File "/home/camilo/Documentos/djangoprojects/plataforma/turismo/urls.py", line 4, in <module>
    from plataforma import views
  File "/home/camilo/Documentos/djangoprojects/plataforma/plataforma/views.py", line 6, in <module>
    from sitios.serializers import MunicipioSerializer
  File "/home/camilo/Documentos/djangoprojects/plataforma/sitios/serializers.py", line 10, in <module>
    from rutas.serializers import RutaSerializer
  File "/home/camilo/Documentos/djangoprojects/plataforma/rutas/serializers.py", line 3, in <module>
    from sitios.serializers import SitioSerializer
ImportError: cannot import name SitioSerializer
Internal Server Error: /buscar/
Traceback (most recent call last):
  File "/usr/local/lib/python2.7/dist-packages/django/core/handlers/base.py", line 119, in get_response
    resolver_match = resolver.resolve(request.path_info)
  File "/usr/local/lib/python2.7/dist-packages/django/core/urlresolvers.py", line 365, in resolve
    for pattern in self.url_patterns:
  File "/usr/local/lib/python2.7/dist-packages/django/core/urlresolvers.py", line 401, in url_patterns
    patterns = getattr(self.urlconf_module, "urlpatterns", self.urlconf_module)
  File "/usr/local/lib/python2.7/dist-packages/django/core/urlresolvers.py", line 395, in urlconf_module
    self._urlconf_module = import_module(self.urlconf_name)
  File "/usr/lib/python2.7/importlib/__init__.py", line 37, in import_module
    __import__(name)
  File "/home/camilo/Documentos/djangoprojects/plataforma/turismo/urls.py", line 4, in <module>
    from plataforma import views
  File "/home/camilo/Documentos/djangoprojects/plataforma/plataforma/views.py", line 6, in <module>
    from sitios.serializers import MunicipioSerializer
  File "/home/camilo/Documentos/djangoprojects/plataforma/sitios/serializers.py", line 10, in <module>
    from rutas.serializers import RutaSerializer
  File "/home/camilo/Documentos/djangoprojects/plataforma/rutas/serializers.py", line 8, in <module>
    class RutaSitioSerializer(serializers.ModelSerializer):
  File "/home/camilo/Documentos/djangoprojects/plataforma/rutas/serializers.py", line 9, in RutaSitioSerializer
    sitio = SitioSerializer(read_only=True)
NameError: name 'SitioSerializer' is not defined
Internal Server Error: /buscar/
Traceback (most recent call last):
  File "/usr/local/lib/python2.7/dist-packages/django/core/handlers/base.py", line 119, in get_response
    resolver_match = resolver.resolve(request.path_info)
  File "/usr/local/lib/python2.7/dist-packages/django/core/urlresolvers.py", line 365, in resolve
    for pattern in self.url_patterns:
  File "/usr/local/lib/python2.7/dist-packages/django/core/urlresolvers.py", line 401, in url_patterns
    patterns = getattr(self.urlconf_module, "urlpatterns", self.urlconf_module)
  File "/usr/local/lib/python2.7/dist-packages/django/core/urlresolvers.py", line 395, in urlconf_module
    self._urlconf_module = import_module(self.urlconf_name)
  File "/usr/lib/python2.7/importlib/__init__.py", line 37, in import_module
    __import__(name)
  File "/home/camilo/Documentos/djangoprojects/plataforma/turismo/urls.py", line 4, in <module>
    from plataforma import views
  File "/home/camilo/Documentos/djangoprojects/plataforma/plataforma/views.py", line 6, in <module>
    from sitios.serializers import MunicipioSerializer
  File "/home/camilo/Documentos/djangoprojects/plataforma/sitios/serializers.py", line 10, in <module>
    from rutas.serializers import RutaSerializer
  File "/home/camilo/Documentos/djangoprojects/plataforma/rutas/serializers.py", line 8, in <module>
    class RutaSerializer(serializers.ModelSerializer):
  File "/home/camilo/Documentos/djangoprojects/plataforma/rutas/serializers.py", line 9, in RutaSerializer
    sitios = RutaSitioSerializer(source='rutasitio_set', many=True)
NameError: name 'RutaSitioSerializer' is not defined
Internal Server Error: /buscar/
Traceback (most recent call last):
  File "/usr/local/lib/python2.7/dist-packages/django/core/handlers/base.py", line 119, in get_response
    resolver_match = resolver.resolve(request.path_info)
  File "/usr/local/lib/python2.7/dist-packages/django/core/urlresolvers.py", line 365, in resolve
    for pattern in self.url_patterns:
  File "/usr/local/lib/python2.7/dist-packages/django/core/urlresolvers.py", line 401, in url_patterns
    patterns = getattr(self.urlconf_module, "urlpatterns", self.urlconf_module)
  File "/usr/local/lib/python2.7/dist-packages/django/core/urlresolvers.py", line 395, in urlconf_module
    self._urlconf_module = import_module(self.urlconf_name)
  File "/usr/lib/python2.7/importlib/__init__.py", line 37, in import_module
    __import__(name)
  File "/home/camilo/Documentos/djangoprojects/plataforma/turismo/urls.py", line 4, in <module>
    from plataforma import views
  File "/home/camilo/Documentos/djangoprojects/plataforma/plataforma/views.py", line 6, in <module>
    from sitios.serializers import MunicipioSerializer
  File "/home/camilo/Documentos/djangoprojects/plataforma/sitios/serializers.py", line 10, in <module>
    from rutas.serializers import RutaSerializer
  File "/home/camilo/Documentos/djangoprojects/plataforma/rutas/serializers.py", line 3, in <module>
    from sitios.serializers import RutaSitioSerializer
ImportError: cannot import name RutaSitioSerializer
Internal Server Error: /buscar/
Traceback (most recent call last):
  File "/usr/local/lib/python2.7/dist-packages/django/core/handlers/base.py", line 119, in get_response
    resolver_match = resolver.resolve(request.path_info)
  File "/usr/local/lib/python2.7/dist-packages/django/core/urlresolvers.py", line 365, in resolve
    for pattern in self.url_patterns:
  File "/usr/local/lib/python2.7/dist-packages/django/core/urlresolvers.py", line 401, in url_patterns
    patterns = getattr(self.urlconf_module, "urlpatterns", self.urlconf_module)
  File "/usr/local/lib/python2.7/dist-packages/django/core/urlresolvers.py", line 395, in urlconf_module
    self._urlconf_module = import_module(self.urlconf_name)
  File "/usr/lib/python2.7/importlib/__init__.py", line 37, in import_module
    __import__(name)
  File "/home/camilo/Documentos/djangoprojects/plataforma/turismo/urls.py", line 4, in <module>
    from plataforma import views
  File "/home/camilo/Documentos/djangoprojects/plataforma/plataforma/views.py", line 6, in <module>
    from sitios.serializers import MunicipioSerializer
  File "/home/camilo/Documentos/djangoprojects/plataforma/sitios/serializers.py", line 10, in <module>
    from rutas.serializers import RutaSerializer
  File "/home/camilo/Documentos/djangoprojects/plataforma/rutas/serializers.py", line 3, in <module>
    from sitios.serializers import CategoriaSerializer
ImportError: cannot import name CategoriaSerializer
Internal Server Error: /buscar/
Traceback (most recent call last):
  File "/usr/local/lib/python2.7/dist-packages/django/core/handlers/base.py", line 119, in get_response
    resolver_match = resolver.resolve(request.path_info)
  File "/usr/local/lib/python2.7/dist-packages/django/core/urlresolvers.py", line 365, in resolve
    for pattern in self.url_patterns:
  File "/usr/local/lib/python2.7/dist-packages/django/core/urlresolvers.py", line 401, in url_patterns
    patterns = getattr(self.urlconf_module, "urlpatterns", self.urlconf_module)
  File "/usr/local/lib/python2.7/dist-packages/django/core/urlresolvers.py", line 395, in urlconf_module
    self._urlconf_module = import_module(self.urlconf_name)
  File "/usr/lib/python2.7/importlib/__init__.py", line 37, in import_module
    __import__(name)
  File "/home/camilo/Documentos/djangoprojects/plataforma/turismo/urls.py", line 4, in <module>
    from plataforma import views
  File "/home/camilo/Documentos/djangoprojects/plataforma/plataforma/views.py", line 6, in <module>
    from sitios.serializers import MunicipioSerializer
  File "/home/camilo/Documentos/djangoprojects/plataforma/sitios/serializers.py", line 32, in <module>
    class SitioSerializer(serializers.ModelSerializer):
  File "/home/camilo/Documentos/djangoprojects/plataforma/sitios/serializers.py", line 35, in SitioSerializer
    rutas=RutaSerializer(many=True, read_only=True)
NameError: name 'RutaSerializer' is not defined
Internal Server Error: /buscar/
Traceback (most recent call last):
  File "/usr/local/lib/python2.7/dist-packages/django/core/handlers/base.py", line 119, in get_response
    resolver_match = resolver.resolve(request.path_info)
  File "/usr/local/lib/python2.7/dist-packages/django/core/urlresolvers.py", line 365, in resolve
    for pattern in self.url_patterns:
  File "/usr/local/lib/python2.7/dist-packages/django/core/urlresolvers.py", line 401, in url_patterns
    patterns = getattr(self.urlconf_module, "urlpatterns", self.urlconf_module)
  File "/usr/local/lib/python2.7/dist-packages/django/core/urlresolvers.py", line 395, in urlconf_module
    self._urlconf_module = import_module(self.urlconf_name)
  File "/usr/lib/python2.7/importlib/__init__.py", line 37, in import_module
    __import__(name)
  File "/home/camilo/Documentos/djangoprojects/plataforma/turismo/urls.py", line 6, in <module>
    from rutas import views as ruta_views
  File "/home/camilo/Documentos/djangoprojects/plataforma/rutas/views.py", line 5, in <module>
    from rutas.serializers import RutaSerializer
  File "/home/camilo/Documentos/djangoprojects/plataforma/rutas/serializers.py", line 9, in <module>
    class RutaSerializer(serializers.ModelSerializer):
  File "/home/camilo/Documentos/djangoprojects/plataforma/rutas/serializers.py", line 10, in RutaSerializer
    sitios = RutaSitioSerializer(source='rutasitio_set', many=True)
NameError: name 'RutaSitioSerializer' is not defined
Internal Server Error: /buscar/
Traceback (most recent call last):
  File "/usr/local/lib/python2.7/dist-packages/django/core/handlers/base.py", line 119, in get_response
    resolver_match = resolver.resolve(request.path_info)
  File "/usr/local/lib/python2.7/dist-packages/django/core/urlresolvers.py", line 365, in resolve
    for pattern in self.url_patterns:
  File "/usr/local/lib/python2.7/dist-packages/django/core/urlresolvers.py", line 401, in url_patterns
    patterns = getattr(self.urlconf_module, "urlpatterns", self.urlconf_module)
  File "/usr/local/lib/python2.7/dist-packages/django/core/urlresolvers.py", line 395, in urlconf_module
    self._urlconf_module = import_module(self.urlconf_name)
  File "/usr/lib/python2.7/importlib/__init__.py", line 37, in import_module
    __import__(name)
  File "/home/camilo/Documentos/djangoprojects/plataforma/turismo/urls.py", line 4, in <module>
    from plataforma import views
  File "/home/camilo/Documentos/djangoprojects/plataforma/plataforma/views.py", line 6, in <module>
    from sitios.serializers import MunicipioSerializer
  File "/home/camilo/Documentos/djangoprojects/plataforma/sitios/serializers.py", line 10, in <module>
    from rutas.serializers import RutaSerializer
  File "/home/camilo/Documentos/djangoprojects/plataforma/rutas/serializers.py", line 3, in <module>
    from sitios.serializers import RutaSitioSerializer
ImportError: cannot import name RutaSitioSerializer
Internal Server Error: /buscar/
Traceback (most recent call last):
  File "/usr/local/lib/python2.7/dist-packages/django/core/handlers/base.py", line 119, in get_response
    resolver_match = resolver.resolve(request.path_info)
  File "/usr/local/lib/python2.7/dist-packages/django/core/urlresolvers.py", line 365, in resolve
    for pattern in self.url_patterns:
  File "/usr/local/lib/python2.7/dist-packages/django/core/urlresolvers.py", line 401, in url_patterns
    patterns = getattr(self.urlconf_module, "urlpatterns", self.urlconf_module)
  File "/usr/local/lib/python2.7/dist-packages/django/core/urlresolvers.py", line 395, in urlconf_module
    self._urlconf_module = import_module(self.urlconf_name)
  File "/usr/lib/python2.7/importlib/__init__.py", line 37, in import_module
    __import__(name)
  File "/home/camilo/Documentos/djangoprojects/plataforma/turismo/urls.py", line 4, in <module>
    from plataforma import views
  File "/home/camilo/Documentos/djangoprojects/plataforma/plataforma/views.py", line 6, in <module>
    from sitios.serializers import MunicipioSerializer
  File "/home/camilo/Documentos/djangoprojects/plataforma/sitios/serializers.py", line 10, in <module>
    from rutas.serializers import RutaSerializer
ImportError: cannot import name RutaSerializer
Internal Server Error: /buscar/
Traceback (most recent call last):
  File "/usr/local/lib/python2.7/dist-packages/django/core/handlers/base.py", line 119, in get_response
    resolver_match = resolver.resolve(request.path_info)
  File "/usr/local/lib/python2.7/dist-packages/django/core/urlresolvers.py", line 365, in resolve
    for pattern in self.url_patterns:
  File "/usr/local/lib/python2.7/dist-packages/django/core/urlresolvers.py", line 401, in url_patterns
    patterns = getattr(self.urlconf_module, "urlpatterns", self.urlconf_module)
  File "/usr/local/lib/python2.7/dist-packages/django/core/urlresolvers.py", line 395, in urlconf_module
    self._urlconf_module = import_module(self.urlconf_name)
  File "/usr/lib/python2.7/importlib/__init__.py", line 37, in import_module
    __import__(name)
  File "/home/camilo/Documentos/djangoprojects/plataforma/turismo/urls.py", line 4, in <module>
    from plataforma import views
  File "/home/camilo/Documentos/djangoprojects/plataforma/plataforma/views.py", line 6, in <module>
    from sitios.serializers import MunicipioSerializer
  File "/home/camilo/Documentos/djangoprojects/plataforma/sitios/serializers.py", line 31, in <module>
    class SitioSerializer(serializers.ModelSerializer):
  File "/home/camilo/Documentos/djangoprojects/plataforma/sitios/serializers.py", line 34, in SitioSerializer
    rutas=RutaSerializer(many=True, read_only=True)
NameError: name 'RutaSerializer' is not defined
Internal Server Error: /buscar/
Traceback (most recent call last):
  File "/usr/local/lib/python2.7/dist-packages/django/core/handlers/base.py", line 119, in get_response
    resolver_match = resolver.resolve(request.path_info)
  File "/usr/local/lib/python2.7/dist-packages/django/core/urlresolvers.py", line 365, in resolve
    for pattern in self.url_patterns:
  File "/usr/local/lib/python2.7/dist-packages/django/core/urlresolvers.py", line 401, in url_patterns
    patterns = getattr(self.urlconf_module, "urlpatterns", self.urlconf_module)
  File "/usr/local/lib/python2.7/dist-packages/django/core/urlresolvers.py", line 395, in urlconf_module
    self._urlconf_module = import_module(self.urlconf_name)
  File "/usr/lib/python2.7/importlib/__init__.py", line 37, in import_module
    __import__(name)
  File "/home/camilo/Documentos/djangoprojects/plataforma/turismo/urls.py", line 4, in <module>
    from plataforma import views
  File "/home/camilo/Documentos/djangoprojects/plataforma/plataforma/views.py", line 6, in <module>
    from sitios.serializers import MunicipioSerializer
  File "/home/camilo/Documentos/djangoprojects/plataforma/sitios/serializers.py", line 30, in <module>
    class RutaSerializer(serializers.ModelSerializer):
  File "/home/camilo/Documentos/djangoprojects/plataforma/sitios/serializers.py", line 31, in RutaSerializer
    sitios = RutaSitioSerializer(source='rutasitio_set', many=True)
NameError: name 'RutaSitioSerializer' is not defined
Internal Server Error: /buscar/
Traceback (most recent call last):
  File "/usr/local/lib/python2.7/dist-packages/django/core/handlers/base.py", line 119, in get_response
    resolver_match = resolver.resolve(request.path_info)
  File "/usr/local/lib/python2.7/dist-packages/django/core/urlresolvers.py", line 365, in resolve
    for pattern in self.url_patterns:
  File "/usr/local/lib/python2.7/dist-packages/django/core/urlresolvers.py", line 401, in url_patterns
    patterns = getattr(self.urlconf_module, "urlpatterns", self.urlconf_module)
  File "/usr/local/lib/python2.7/dist-packages/django/core/urlresolvers.py", line 395, in urlconf_module
    self._urlconf_module = import_module(self.urlconf_name)
  File "/usr/lib/python2.7/importlib/__init__.py", line 37, in import_module
    __import__(name)
  File "/home/camilo/Documentos/djangoprojects/plataforma/turismo/urls.py", line 4, in <module>
    from plataforma import views
  File "/home/camilo/Documentos/djangoprojects/plataforma/plataforma/views.py", line 6, in <module>
    from sitios.serializers import MunicipioSerializer
  File "/home/camilo/Documentos/djangoprojects/plataforma/sitios/serializers.py", line 30, in <module>
    class RutaSitioSerializer(serializers.ModelSerializer):
  File "/home/camilo/Documentos/djangoprojects/plataforma/sitios/serializers.py", line 31, in RutaSitioSerializer
    sitio = SitioSerializer(read_only=True)
NameError: name 'SitioSerializer' is not defined
Internal Server Error: /buscar/
Traceback (most recent call last):
  File "/usr/local/lib/python2.7/dist-packages/django/core/handlers/base.py", line 119, in get_response
    resolver_match = resolver.resolve(request.path_info)
  File "/usr/local/lib/python2.7/dist-packages/django/core/urlresolvers.py", line 365, in resolve
    for pattern in self.url_patterns:
  File "/usr/local/lib/python2.7/dist-packages/django/core/urlresolvers.py", line 401, in url_patterns
    patterns = getattr(self.urlconf_module, "urlpatterns", self.urlconf_module)
  File "/usr/local/lib/python2.7/dist-packages/django/core/urlresolvers.py", line 395, in urlconf_module
    self._urlconf_module = import_module(self.urlconf_name)
  File "/usr/lib/python2.7/importlib/__init__.py", line 37, in import_module
    __import__(name)
  File "/home/camilo/Documentos/djangoprojects/plataforma/turismo/urls.py", line 4, in <module>
    from plataforma import views
  File "/home/camilo/Documentos/djangoprojects/plataforma/plataforma/views.py", line 6, in <module>
    from sitios.serializers import MunicipioSerializer
  File "/home/camilo/Documentos/djangoprojects/plataforma/sitios/serializers.py", line 30, in <module>
    class RutaSitioSerializer(serializers.ModelSerializer):
  File "/home/camilo/Documentos/djangoprojects/plataforma/sitios/serializers.py", line 31, in RutaSitioSerializer
    sitio = SitioSerializer(read_only=True)
NameError: name 'SitioSerializer' is not defined
Internal Server Error: /buscar/
Traceback (most recent call last):
  File "/usr/local/lib/python2.7/dist-packages/django/core/handlers/base.py", line 119, in get_response
    resolver_match = resolver.resolve(request.path_info)
  File "/usr/local/lib/python2.7/dist-packages/django/core/urlresolvers.py", line 365, in resolve
    for pattern in self.url_patterns:
  File "/usr/local/lib/python2.7/dist-packages/django/core/urlresolvers.py", line 401, in url_patterns
    patterns = getattr(self.urlconf_module, "urlpatterns", self.urlconf_module)
  File "/usr/local/lib/python2.7/dist-packages/django/core/urlresolvers.py", line 395, in urlconf_module
    self._urlconf_module = import_module(self.urlconf_name)
  File "/usr/lib/python2.7/importlib/__init__.py", line 37, in import_module
    __import__(name)
  File "/home/camilo/Documentos/djangoprojects/plataforma/turismo/urls.py", line 4, in <module>
    from plataforma import views
  File "/home/camilo/Documentos/djangoprojects/plataforma/plataforma/views.py", line 6, in <module>
    from sitios.serializers import MunicipioSerializer
  File "/home/camilo/Documentos/djangoprojects/plataforma/sitios/serializers.py", line 33, in <module>
    class RutaSerializer(serializers.ModelSerializer):
  File "/home/camilo/Documentos/djangoprojects/plataforma/sitios/serializers.py", line 36, in RutaSerializer
    class Meta:
  File "/home/camilo/Documentos/djangoprojects/plataforma/sitios/serializers.py", line 37, in Meta
    model = Ruta
NameError: name 'Ruta' is not defined
Internal Server Error: /buscar/
Traceback (most recent call last):
  File "/usr/local/lib/python2.7/dist-packages/django/core/handlers/base.py", line 119, in get_response
    resolver_match = resolver.resolve(request.path_info)
  File "/usr/local/lib/python2.7/dist-packages/django/core/urlresolvers.py", line 365, in resolve
    for pattern in self.url_patterns:
  File "/usr/local/lib/python2.7/dist-packages/django/core/urlresolvers.py", line 401, in url_patterns
    patterns = getattr(self.urlconf_module, "urlpatterns", self.urlconf_module)
  File "/usr/local/lib/python2.7/dist-packages/django/core/urlresolvers.py", line 395, in urlconf_module
    self._urlconf_module = import_module(self.urlconf_name)
  File "/usr/lib/python2.7/importlib/__init__.py", line 37, in import_module
    __import__(name)
  File "/home/camilo/Documentos/djangoprojects/plataforma/turismo/urls.py", line 4, in <module>
    from plataforma import views
  File "/home/camilo/Documentos/djangoprojects/plataforma/plataforma/views.py", line 6, in <module>
    from sitios.serializers import MunicipioSerializer
  File "/home/camilo/Documentos/djangoprojects/plataforma/sitios/serializers.py", line 38, in <module>
    class RutaSitioSerializer(serializers.ModelSerializer):
  File "/home/camilo/Documentos/djangoprojects/plataforma/sitios/serializers.py", line 40, in RutaSitioSerializer
    class Meta:
  File "/home/camilo/Documentos/djangoprojects/plataforma/sitios/serializers.py", line 41, in Meta
    model = RutaSitio
NameError: name 'RutaSitio' is not defined
Internal Server Error: /buscar/
Traceback (most recent call last):
  File "/usr/local/lib/python2.7/dist-packages/django/core/handlers/base.py", line 119, in get_response
    resolver_match = resolver.resolve(request.path_info)
  File "/usr/local/lib/python2.7/dist-packages/django/core/urlresolvers.py", line 365, in resolve
    for pattern in self.url_patterns:
  File "/usr/local/lib/python2.7/dist-packages/django/core/urlresolvers.py", line 401, in url_patterns
    patterns = getattr(self.urlconf_module, "urlpatterns", self.urlconf_module)
  File "/usr/local/lib/python2.7/dist-packages/django/core/urlresolvers.py", line 395, in urlconf_module
    self._urlconf_module = import_module(self.urlconf_name)
  File "/usr/lib/python2.7/importlib/__init__.py", line 37, in import_module
    __import__(name)
  File "/home/camilo/Documentos/djangoprojects/plataforma/turismo/urls.py", line 6, in <module>
    from rutas import views as ruta_views
  File "/home/camilo/Documentos/djangoprojects/plataforma/rutas/views.py", line 5, in <module>
    from rutas.serializers import RutaSerializer
ImportError: cannot import name RutaSerializer
Internal Server Error: /buscar/
Traceback (most recent call last):
  File "/usr/local/lib/python2.7/dist-packages/django/core/handlers/base.py", line 132, in get_response
    response = wrapped_callback(request, *callback_args, **callback_kwargs)
  File "/usr/local/lib/python2.7/dist-packages/django/views/decorators/csrf.py", line 58, in wrapped_view
    return view_func(*args, **kwargs)
  File "/usr/local/lib/python2.7/dist-packages/django/views/generic/base.py", line 71, in view
    return self.dispatch(request, *args, **kwargs)
  File "/usr/local/lib/python2.7/dist-packages/rest_framework/views.py", line 407, in dispatch
    response = self.handle_exception(exc)
  File "/usr/local/lib/python2.7/dist-packages/rest_framework/views.py", line 404, in dispatch
    response = handler(request, *args, **kwargs)
  File "/usr/local/lib/python2.7/dist-packages/rest_framework/generics.py", line 269, in get
    return self.list(request, *args, **kwargs)
  File "/usr/local/lib/python2.7/dist-packages/rest_framework/mixins.py", line 46, in list
    return Response(serializer.data)
  File "/usr/local/lib/python2.7/dist-packages/rest_framework/serializers.py", line 615, in data
    ret = super(ListSerializer, self).data
  File "/usr/local/lib/python2.7/dist-packages/rest_framework/serializers.py", line 212, in data
    self._data = self.to_representation(self.instance)
  File "/usr/local/lib/python2.7/dist-packages/rest_framework/serializers.py", line 565, in to_representation
    self.child.to_representation(item) for item in iterable
  File "/usr/local/lib/python2.7/dist-packages/rest_framework/serializers.py", line 432, in to_representation
    ret[field.field_name] = field.to_representation(attribute)
  File "/usr/local/lib/python2.7/dist-packages/rest_framework/serializers.py", line 565, in to_representation
    self.child.to_representation(item) for item in iterable
  File "/usr/local/lib/python2.7/dist-packages/rest_framework/serializers.py", line 432, in to_representation
    ret[field.field_name] = field.to_representation(attribute)
  File "/usr/local/lib/python2.7/dist-packages/rest_framework/serializers.py", line 565, in to_representation
    self.child.to_representation(item) for item in iterable
  File "/usr/local/lib/python2.7/dist-packages/rest_framework/serializers.py", line 432, in to_representation
    ret[field.field_name] = field.to_representation(attribute)
  File "/usr/local/lib/python2.7/dist-packages/rest_framework/serializers.py", line 419, in to_representation
    fields = [field for field in self.fields.values() if not field.write_only]
  File "/usr/local/lib/python2.7/dist-packages/rest_framework/serializers.py", line 312, in fields
    for key, value in self.get_fields().items():
  File "/usr/local/lib/python2.7/dist-packages/rest_framework/serializers.py", line 860, in get_fields
    model = getattr(self.Meta, 'model')
AttributeError: 'SitioEnRutaSerializer' object has no attribute 'Meta'
Internal Server Error: /buscar/
Traceback (most recent call last):
  File "/usr/local/lib/python2.7/dist-packages/django/core/handlers/base.py", line 119, in get_response
    resolver_match = resolver.resolve(request.path_info)
  File "/usr/local/lib/python2.7/dist-packages/django/core/urlresolvers.py", line 365, in resolve
    for pattern in self.url_patterns:
  File "/usr/local/lib/python2.7/dist-packages/django/core/urlresolvers.py", line 401, in url_patterns
    patterns = getattr(self.urlconf_module, "urlpatterns", self.urlconf_module)
  File "/usr/local/lib/python2.7/dist-packages/django/core/urlresolvers.py", line 395, in urlconf_module
    self._urlconf_module = import_module(self.urlconf_name)
  File "/usr/lib/python2.7/importlib/__init__.py", line 37, in import_module
    __import__(name)
  File "/home/camilo/Documentos/djangoprojects/plataforma/turismo/urls.py", line 4, in <module>
    from plataforma import views
  File "/home/camilo/Documentos/djangoprojects/plataforma/plataforma/views.py", line 6, in <module>
    from sitios.serializers import MunicipioSerializer
  File "/home/camilo/Documentos/djangoprojects/plataforma/sitios/serializers.py", line 38
    model = Sitio
        ^
IndentationError: expected an indented block
Internal Server Error: /buscar/
Traceback (most recent call last):
  File "/usr/local/lib/python2.7/dist-packages/django/core/handlers/base.py", line 119, in get_response
    resolver_match = resolver.resolve(request.path_info)
  File "/usr/local/lib/python2.7/dist-packages/django/core/urlresolvers.py", line 365, in resolve
    for pattern in self.url_patterns:
  File "/usr/local/lib/python2.7/dist-packages/django/core/urlresolvers.py", line 401, in url_patterns
    patterns = getattr(self.urlconf_module, "urlpatterns", self.urlconf_module)
  File "/usr/local/lib/python2.7/dist-packages/django/core/urlresolvers.py", line 395, in urlconf_module
    self._urlconf_module = import_module(self.urlconf_name)
  File "/usr/lib/python2.7/importlib/__init__.py", line 37, in import_module
    __import__(name)
  File "/home/camilo/Documentos/djangoprojects/plataforma/turismo/urls.py", line 4, in <module>
    from plataforma import views
  File "/home/camilo/Documentos/djangoprojects/plataforma/plataforma/views.py", line 6, in <module>
    from sitios.serializers import MunicipioSerializer
  File "/home/camilo/Documentos/djangoprojects/plataforma/sitios/serializers.py", line 10, in <module>
    from rutas.serializers import *
  File "/home/camilo/Documentos/djangoprojects/plataforma/rutas/serializers.py", line 10, in <module>
    class SitioEnRutaSerializer(serializers.ModelSerializer):
  File "/home/camilo/Documentos/djangoprojects/plataforma/rutas/serializers.py", line 11, in SitioEnRutaSerializer
    categorias = SitioCategoriaSerializer(source='sitiocategoria_set', many=True)
NameError: name 'SitioCategoriaSerializer' is not defined
Internal Server Error: /buscar/
Traceback (most recent call last):
  File "/usr/local/lib/python2.7/dist-packages/django/core/handlers/base.py", line 119, in get_response
    resolver_match = resolver.resolve(request.path_info)
  File "/usr/local/lib/python2.7/dist-packages/django/core/urlresolvers.py", line 365, in resolve
    for pattern in self.url_patterns:
  File "/usr/local/lib/python2.7/dist-packages/django/core/urlresolvers.py", line 401, in url_patterns
    patterns = getattr(self.urlconf_module, "urlpatterns", self.urlconf_module)
  File "/usr/local/lib/python2.7/dist-packages/django/core/urlresolvers.py", line 395, in urlconf_module
    self._urlconf_module = import_module(self.urlconf_name)
  File "/usr/lib/python2.7/importlib/__init__.py", line 37, in import_module
    __import__(name)
  File "/home/camilo/Documentos/djangoprojects/plataforma/turismo/urls.py", line 4, in <module>
    from plataforma import views
  File "/home/camilo/Documentos/djangoprojects/plataforma/plataforma/views.py", line 6, in <module>
    from sitios.serializers import MunicipioSerializer
  File "/home/camilo/Documentos/djangoprojects/plataforma/sitios/serializers.py", line 10, in <module>
    from rutas.serializers import *
  File "/home/camilo/Documentos/djangoprojects/plataforma/rutas/serializers.py", line 8, in <module>
    from sitios.serializers import SitioCategoriaSerializer
ImportError: cannot import name SitioCategoriaSerializer
Internal Server Error: /buscar/
Traceback (most recent call last):
  File "/usr/local/lib/python2.7/dist-packages/django/core/handlers/base.py", line 119, in get_response
    resolver_match = resolver.resolve(request.path_info)
  File "/usr/local/lib/python2.7/dist-packages/django/core/urlresolvers.py", line 365, in resolve
    for pattern in self.url_patterns:
  File "/usr/local/lib/python2.7/dist-packages/django/core/urlresolvers.py", line 401, in url_patterns
    patterns = getattr(self.urlconf_module, "urlpatterns", self.urlconf_module)
  File "/usr/local/lib/python2.7/dist-packages/django/core/urlresolvers.py", line 395, in urlconf_module
    self._urlconf_module = import_module(self.urlconf_name)
  File "/usr/lib/python2.7/importlib/__init__.py", line 37, in import_module
    __import__(name)
  File "/home/camilo/Documentos/djangoprojects/plataforma/turismo/urls.py", line 4, in <module>
    from plataforma import views
  File "/home/camilo/Documentos/djangoprojects/plataforma/plataforma/views.py", line 6, in <module>
    from sitios.serializers import MunicipioSerializer
  File "/home/camilo/Documentos/djangoprojects/plataforma/sitios/serializers.py", line 10, in <module>
    from rutas.serializers import *
  File "/home/camilo/Documentos/djangoprojects/plataforma/rutas/serializers.py", line 8, in <module>
    from sitios.serializers import SitioEnRutaSerializer
ImportError: cannot import name SitioEnRutaSerializer
Internal Server Error: /buscar/
Traceback (most recent call last):
  File "/usr/local/lib/python2.7/dist-packages/django/core/handlers/base.py", line 119, in get_response
    resolver_match = resolver.resolve(request.path_info)
  File "/usr/local/lib/python2.7/dist-packages/django/core/urlresolvers.py", line 365, in resolve
    for pattern in self.url_patterns:
  File "/usr/local/lib/python2.7/dist-packages/django/core/urlresolvers.py", line 401, in url_patterns
    patterns = getattr(self.urlconf_module, "urlpatterns", self.urlconf_module)
  File "/usr/local/lib/python2.7/dist-packages/django/core/urlresolvers.py", line 395, in urlconf_module
    self._urlconf_module = import_module(self.urlconf_name)
  File "/usr/lib/python2.7/importlib/__init__.py", line 37, in import_module
    __import__(name)
  File "/home/camilo/Documentos/djangoprojects/plataforma/turismo/urls.py", line 4, in <module>
    from plataforma import views
  File "/home/camilo/Documentos/djangoprojects/plataforma/plataforma/views.py", line 6, in <module>
    from sitios.serializers import MunicipioSerializer
  File "/home/camilo/Documentos/djangoprojects/plataforma/sitios/serializers.py", line 40, in <module>
    class RutaSitioSerializer(serializers.ModelSerializer):
  File "/home/camilo/Documentos/djangoprojects/plataforma/sitios/serializers.py", line 42, in RutaSitioSerializer
    class Meta:
  File "/home/camilo/Documentos/djangoprojects/plataforma/sitios/serializers.py", line 43, in Meta
    model = RutaSitio
NameError: name 'RutaSitio' is not defined
