Internal Server Error: /sitio/detail/1
Traceback (most recent call last):
  File "/usr/local/lib/python2.7/dist-packages/django/core/handlers/base.py", line 132, in get_response
    response = wrapped_callback(request, *callback_args, **callback_kwargs)
  File "/usr/local/lib/python2.7/dist-packages/django/views/decorators/csrf.py", line 58, in wrapped_view
    return view_func(*args, **kwargs)
  File "/usr/local/lib/python2.7/dist-packages/django/views/generic/base.py", line 71, in view
    return self.dispatch(request, *args, **kwargs)
  File "/usr/local/lib/python2.7/dist-packages/rest_framework/views.py", line 407, in dispatch
    response = self.handle_exception(exc)
  File "/usr/local/lib/python2.7/dist-packages/rest_framework/views.py", line 404, in dispatch
    response = handler(request, *args, **kwargs)
  File "/usr/local/lib/python2.7/dist-packages/rest_framework/generics.py", line 357, in put
    return self.update(request, *args, **kwargs)
  File "/home/camilo/Documents/BackEnd/sitios/views.py", line 74, in update
    if serializer.is_valid():
NameError: global name 'serializer' is not defined
Internal Server Error: /sitio/detail/1
Traceback (most recent call last):
  File "/usr/local/lib/python2.7/dist-packages/django/core/handlers/base.py", line 132, in get_response
    response = wrapped_callback(request, *callback_args, **callback_kwargs)
  File "/usr/local/lib/python2.7/dist-packages/django/views/decorators/csrf.py", line 58, in wrapped_view
    return view_func(*args, **kwargs)
  File "/usr/local/lib/python2.7/dist-packages/django/views/generic/base.py", line 71, in view
    return self.dispatch(request, *args, **kwargs)
  File "/usr/local/lib/python2.7/dist-packages/rest_framework/views.py", line 407, in dispatch
    response = self.handle_exception(exc)
  File "/usr/local/lib/python2.7/dist-packages/rest_framework/views.py", line 404, in dispatch
    response = handler(request, *args, **kwargs)
  File "/usr/local/lib/python2.7/dist-packages/rest_framework/generics.py", line 357, in put
    return self.update(request, *args, **kwargs)
  File "/home/camilo/Documents/BackEnd/sitios/views.py", line 74, in update
    if serializer.is_valid():
NameError: global name 'serializer' is not defined
Internal Server Error: /sitio/detail/1
Traceback (most recent call last):
  File "/usr/local/lib/python2.7/dist-packages/django/core/handlers/base.py", line 132, in get_response
    response = wrapped_callback(request, *callback_args, **callback_kwargs)
  File "/usr/local/lib/python2.7/dist-packages/django/views/decorators/csrf.py", line 58, in wrapped_view
    return view_func(*args, **kwargs)
  File "/usr/local/lib/python2.7/dist-packages/django/views/generic/base.py", line 71, in view
    return self.dispatch(request, *args, **kwargs)
  File "/usr/local/lib/python2.7/dist-packages/rest_framework/views.py", line 407, in dispatch
    response = self.handle_exception(exc)
  File "/usr/local/lib/python2.7/dist-packages/rest_framework/views.py", line 404, in dispatch
    response = handler(request, *args, **kwargs)
  File "/usr/local/lib/python2.7/dist-packages/rest_framework/generics.py", line 357, in put
    return self.update(request, *args, **kwargs)
  File "/home/camilo/Documents/BackEnd/sitios/views.py", line 74, in update
    if serializer.is_valid():
NameError: global name 'serializer' is not defined
Internal Server Error: /sitio/detail/1
Traceback (most recent call last):
  File "/usr/local/lib/python2.7/dist-packages/django/core/handlers/base.py", line 132, in get_response
    response = wrapped_callback(request, *callback_args, **callback_kwargs)
  File "/usr/local/lib/python2.7/dist-packages/django/views/decorators/csrf.py", line 58, in wrapped_view
    return view_func(*args, **kwargs)
  File "/usr/local/lib/python2.7/dist-packages/django/views/generic/base.py", line 71, in view
    return self.dispatch(request, *args, **kwargs)
  File "/usr/local/lib/python2.7/dist-packages/rest_framework/views.py", line 407, in dispatch
    response = self.handle_exception(exc)
  File "/usr/local/lib/python2.7/dist-packages/rest_framework/views.py", line 404, in dispatch
    response = handler(request, *args, **kwargs)
  File "/usr/local/lib/python2.7/dist-packages/rest_framework/generics.py", line 357, in put
    return self.update(request, *args, **kwargs)
  File "/home/camilo/Documents/BackEnd/sitios/views.py", line 75, in update
    if serializer.is_valid():
  File "/usr/local/lib/python2.7/dist-packages/rest_framework/serializers.py", line 180, in is_valid
    'Cannot call `.is_valid()` as no `data=` keyword argument was '
AssertionError: Cannot call `.is_valid()` as no `data=` keyword argument was passed when instantiating the serializer instance.
Internal Server Error: /sitio/detail/1
Traceback (most recent call last):
  File "/usr/local/lib/python2.7/dist-packages/django/core/handlers/base.py", line 132, in get_response
    response = wrapped_callback(request, *callback_args, **callback_kwargs)
  File "/usr/local/lib/python2.7/dist-packages/django/views/decorators/csrf.py", line 58, in wrapped_view
    return view_func(*args, **kwargs)
  File "/usr/local/lib/python2.7/dist-packages/django/views/generic/base.py", line 71, in view
    return self.dispatch(request, *args, **kwargs)
  File "/usr/local/lib/python2.7/dist-packages/rest_framework/views.py", line 407, in dispatch
    response = self.handle_exception(exc)
  File "/usr/local/lib/python2.7/dist-packages/rest_framework/views.py", line 404, in dispatch
    response = handler(request, *args, **kwargs)
  File "/usr/local/lib/python2.7/dist-packages/rest_framework/generics.py", line 357, in put
    return self.update(request, *args, **kwargs)
  File "/home/camilo/Documents/BackEnd/sitios/views.py", line 75, in update
    if serializer.is_valid():
  File "/usr/local/lib/python2.7/dist-packages/rest_framework/serializers.py", line 180, in is_valid
    'Cannot call `.is_valid()` as no `data=` keyword argument was '
AssertionError: Cannot call `.is_valid()` as no `data=` keyword argument was passed when instantiating the serializer instance.
Internal Server Error: /sitio/detail/1
Traceback (most recent call last):
  File "/usr/local/lib/python2.7/dist-packages/django/core/handlers/base.py", line 132, in get_response
    response = wrapped_callback(request, *callback_args, **callback_kwargs)
  File "/usr/local/lib/python2.7/dist-packages/django/views/decorators/csrf.py", line 58, in wrapped_view
    return view_func(*args, **kwargs)
  File "/usr/local/lib/python2.7/dist-packages/django/views/generic/base.py", line 71, in view
    return self.dispatch(request, *args, **kwargs)
  File "/usr/local/lib/python2.7/dist-packages/rest_framework/views.py", line 407, in dispatch
    response = self.handle_exception(exc)
  File "/usr/local/lib/python2.7/dist-packages/rest_framework/views.py", line 404, in dispatch
    response = handler(request, *args, **kwargs)
  File "/usr/local/lib/python2.7/dist-packages/rest_framework/generics.py", line 357, in put
    return self.update(request, *args, **kwargs)
  File "/home/camilo/Documents/BackEnd/sitios/views.py", line 75, in update
    if serializer.is_valid():
  File "/usr/local/lib/python2.7/dist-packages/rest_framework/serializers.py", line 180, in is_valid
    'Cannot call `.is_valid()` as no `data=` keyword argument was '
AssertionError: Cannot call `.is_valid()` as no `data=` keyword argument was passed when instantiating the serializer instance.
Internal Server Error: /sitio/detail/1
Traceback (most recent call last):
  File "/usr/local/lib/python2.7/dist-packages/django/core/handlers/base.py", line 132, in get_response
    response = wrapped_callback(request, *callback_args, **callback_kwargs)
  File "/usr/local/lib/python2.7/dist-packages/django/views/decorators/csrf.py", line 58, in wrapped_view
    return view_func(*args, **kwargs)
  File "/usr/local/lib/python2.7/dist-packages/django/views/generic/base.py", line 71, in view
    return self.dispatch(request, *args, **kwargs)
  File "/usr/local/lib/python2.7/dist-packages/rest_framework/views.py", line 407, in dispatch
    response = self.handle_exception(exc)
  File "/usr/local/lib/python2.7/dist-packages/rest_framework/views.py", line 404, in dispatch
    response = handler(request, *args, **kwargs)
  File "/usr/local/lib/python2.7/dist-packages/rest_framework/generics.py", line 357, in put
    return self.update(request, *args, **kwargs)
  File "/home/camilo/Documents/BackEnd/sitios/views.py", line 75, in update
    if serializer.is_valid():
  File "/usr/local/lib/python2.7/dist-packages/rest_framework/serializers.py", line 180, in is_valid
    'Cannot call `.is_valid()` as no `data=` keyword argument was '
AssertionError: Cannot call `.is_valid()` as no `data=` keyword argument was passed when instantiating the serializer instance.
Internal Server Error: /sitio/detail/1
Traceback (most recent call last):
  File "/usr/local/lib/python2.7/dist-packages/django/core/handlers/base.py", line 132, in get_response
    response = wrapped_callback(request, *callback_args, **callback_kwargs)
  File "/usr/local/lib/python2.7/dist-packages/django/views/decorators/csrf.py", line 58, in wrapped_view
    return view_func(*args, **kwargs)
  File "/usr/local/lib/python2.7/dist-packages/django/views/generic/base.py", line 71, in view
    return self.dispatch(request, *args, **kwargs)
  File "/usr/local/lib/python2.7/dist-packages/rest_framework/views.py", line 407, in dispatch
    response = self.handle_exception(exc)
  File "/usr/local/lib/python2.7/dist-packages/rest_framework/views.py", line 404, in dispatch
    response = handler(request, *args, **kwargs)
  File "/usr/local/lib/python2.7/dist-packages/rest_framework/generics.py", line 357, in put
    return self.update(request, *args, **kwargs)
  File "/home/camilo/Documents/BackEnd/sitios/views.py", line 75, in update
    if serializer.is_valid():
  File "/usr/local/lib/python2.7/dist-packages/rest_framework/serializers.py", line 180, in is_valid
    'Cannot call `.is_valid()` as no `data=` keyword argument was '
AssertionError: Cannot call `.is_valid()` as no `data=` keyword argument was passed when instantiating the serializer instance.
Internal Server Error: /sitio/detail/1
Traceback (most recent call last):
  File "/usr/local/lib/python2.7/dist-packages/django/core/handlers/base.py", line 132, in get_response
    response = wrapped_callback(request, *callback_args, **callback_kwargs)
  File "/usr/local/lib/python2.7/dist-packages/django/views/decorators/csrf.py", line 58, in wrapped_view
    return view_func(*args, **kwargs)
  File "/usr/local/lib/python2.7/dist-packages/django/views/generic/base.py", line 71, in view
    return self.dispatch(request, *args, **kwargs)
  File "/usr/local/lib/python2.7/dist-packages/rest_framework/views.py", line 407, in dispatch
    response = self.handle_exception(exc)
  File "/usr/local/lib/python2.7/dist-packages/rest_framework/views.py", line 404, in dispatch
    response = handler(request, *args, **kwargs)
  File "/usr/local/lib/python2.7/dist-packages/rest_framework/generics.py", line 357, in put
    return self.update(request, *args, **kwargs)
  File "/home/camilo/Documents/BackEnd/sitios/views.py", line 75, in update
    if serializer.is_valid():
  File "/usr/local/lib/python2.7/dist-packages/rest_framework/serializers.py", line 180, in is_valid
    'Cannot call `.is_valid()` as no `data=` keyword argument was '
AssertionError: Cannot call `.is_valid()` as no `data=` keyword argument was passed when instantiating the serializer instance.
Internal Server Error: /sitio/detail/1
Traceback (most recent call last):
  File "/usr/local/lib/python2.7/dist-packages/django/core/handlers/base.py", line 132, in get_response
    response = wrapped_callback(request, *callback_args, **callback_kwargs)
  File "/usr/local/lib/python2.7/dist-packages/django/views/decorators/csrf.py", line 58, in wrapped_view
    return view_func(*args, **kwargs)
  File "/usr/local/lib/python2.7/dist-packages/django/views/generic/base.py", line 71, in view
    return self.dispatch(request, *args, **kwargs)
  File "/usr/local/lib/python2.7/dist-packages/rest_framework/views.py", line 407, in dispatch
    response = self.handle_exception(exc)
  File "/usr/local/lib/python2.7/dist-packages/rest_framework/views.py", line 404, in dispatch
    response = handler(request, *args, **kwargs)
  File "/usr/local/lib/python2.7/dist-packages/rest_framework/generics.py", line 357, in put
    return self.update(request, *args, **kwargs)
  File "/home/camilo/Documents/BackEnd/sitios/views.py", line 74, in update
    print data
NameError: global name 'data' is not defined
Internal Server Error: /sitio/detail/1
Traceback (most recent call last):
  File "/usr/local/lib/python2.7/dist-packages/django/core/handlers/base.py", line 132, in get_response
    response = wrapped_callback(request, *callback_args, **callback_kwargs)
  File "/usr/local/lib/python2.7/dist-packages/django/views/decorators/csrf.py", line 58, in wrapped_view
    return view_func(*args, **kwargs)
  File "/usr/local/lib/python2.7/dist-packages/django/views/generic/base.py", line 71, in view
    return self.dispatch(request, *args, **kwargs)
  File "/usr/local/lib/python2.7/dist-packages/rest_framework/views.py", line 407, in dispatch
    response = self.handle_exception(exc)
  File "/usr/local/lib/python2.7/dist-packages/rest_framework/views.py", line 404, in dispatch
    response = handler(request, *args, **kwargs)
  File "/usr/local/lib/python2.7/dist-packages/rest_framework/generics.py", line 357, in put
    return self.update(request, *args, **kwargs)
  File "/home/camilo/Documents/BackEnd/sitios/views.py", line 74, in update
    print data
NameError: global name 'data' is not defined
Internal Server Error: /sitio/detail/1
Traceback (most recent call last):
  File "/usr/local/lib/python2.7/dist-packages/django/core/handlers/base.py", line 132, in get_response
    response = wrapped_callback(request, *callback_args, **callback_kwargs)
  File "/usr/local/lib/python2.7/dist-packages/django/views/decorators/csrf.py", line 58, in wrapped_view
    return view_func(*args, **kwargs)
  File "/usr/local/lib/python2.7/dist-packages/django/views/generic/base.py", line 71, in view
    return self.dispatch(request, *args, **kwargs)
  File "/usr/local/lib/python2.7/dist-packages/rest_framework/views.py", line 407, in dispatch
    response = self.handle_exception(exc)
  File "/usr/local/lib/python2.7/dist-packages/rest_framework/views.py", line 404, in dispatch
    response = handler(request, *args, **kwargs)
  File "/usr/local/lib/python2.7/dist-packages/rest_framework/generics.py", line 357, in put
    return self.update(request, *args, **kwargs)
  File "/home/camilo/Documents/BackEnd/sitios/views.py", line 74, in update
    print data
NameError: global name 'data' is not defined
Internal Server Error: /sitio/detail/1
Traceback (most recent call last):
  File "/usr/local/lib/python2.7/dist-packages/django/core/handlers/base.py", line 132, in get_response
    response = wrapped_callback(request, *callback_args, **callback_kwargs)
  File "/usr/local/lib/python2.7/dist-packages/django/views/decorators/csrf.py", line 58, in wrapped_view
    return view_func(*args, **kwargs)
  File "/usr/local/lib/python2.7/dist-packages/django/views/generic/base.py", line 71, in view
    return self.dispatch(request, *args, **kwargs)
  File "/usr/local/lib/python2.7/dist-packages/rest_framework/views.py", line 407, in dispatch
    response = self.handle_exception(exc)
  File "/usr/local/lib/python2.7/dist-packages/rest_framework/views.py", line 404, in dispatch
    response = handler(request, *args, **kwargs)
  File "/usr/local/lib/python2.7/dist-packages/rest_framework/generics.py", line 357, in put
    return self.update(request, *args, **kwargs)
  File "/home/camilo/Documents/BackEnd/sitios/views.py", line 76, in update
    if serializer.is_valid():
  File "/usr/local/lib/python2.7/dist-packages/rest_framework/serializers.py", line 186, in is_valid
    self._validated_data = self.run_validation(self.initial_data)
  File "/usr/local/lib/python2.7/dist-packages/rest_framework/serializers.py", line 364, in run_validation
    value = self.to_internal_value(data)
  File "/home/camilo/Documents/BackEnd/sitios/serializers.py", line 40, in to_internal_value
    data["latitud"]=float(data.get("latitud")[0])
TypeError: 'float' object has no attribute '__getitem__'
Internal Server Error: /sitio/detail/1
Traceback (most recent call last):
  File "/usr/local/lib/python2.7/dist-packages/django/core/handlers/base.py", line 132, in get_response
    response = wrapped_callback(request, *callback_args, **callback_kwargs)
  File "/usr/local/lib/python2.7/dist-packages/django/views/decorators/csrf.py", line 58, in wrapped_view
    return view_func(*args, **kwargs)
  File "/usr/local/lib/python2.7/dist-packages/django/views/generic/base.py", line 71, in view
    return self.dispatch(request, *args, **kwargs)
  File "/usr/local/lib/python2.7/dist-packages/rest_framework/views.py", line 407, in dispatch
    response = self.handle_exception(exc)
  File "/usr/local/lib/python2.7/dist-packages/rest_framework/views.py", line 404, in dispatch
    response = handler(request, *args, **kwargs)
  File "/usr/local/lib/python2.7/dist-packages/rest_framework/generics.py", line 357, in put
    return self.update(request, *args, **kwargs)
  File "/home/camilo/Documents/BackEnd/sitios/views.py", line 70, in update
    print request.PUT
  File "/usr/local/lib/python2.7/dist-packages/rest_framework/request.py", line 501, in __getattribute__
    six.reraise(info[0], info[1], info[2].tb_next)
  File "<string>", line 2, in reraise
AttributeError: 'Request' object has no attribute 'PUT'
Internal Server Error: /sitio/detail/1
Traceback (most recent call last):
  File "/usr/local/lib/python2.7/dist-packages/django/core/handlers/base.py", line 132, in get_response
    response = wrapped_callback(request, *callback_args, **callback_kwargs)
  File "/usr/local/lib/python2.7/dist-packages/django/views/decorators/csrf.py", line 58, in wrapped_view
    return view_func(*args, **kwargs)
  File "/usr/local/lib/python2.7/dist-packages/django/views/generic/base.py", line 71, in view
    return self.dispatch(request, *args, **kwargs)
  File "/usr/local/lib/python2.7/dist-packages/rest_framework/views.py", line 407, in dispatch
    response = self.handle_exception(exc)
  File "/usr/local/lib/python2.7/dist-packages/rest_framework/views.py", line 404, in dispatch
    response = handler(request, *args, **kwargs)
  File "/usr/local/lib/python2.7/dist-packages/rest_framework/generics.py", line 357, in put
    return self.update(request, *args, **kwargs)
  File "/home/camilo/Documents/BackEnd/sitios/views.py", line 70, in update
    print request.PUT
  File "/usr/local/lib/python2.7/dist-packages/rest_framework/request.py", line 501, in __getattribute__
    six.reraise(info[0], info[1], info[2].tb_next)
  File "<string>", line 2, in reraise
AttributeError: 'Request' object has no attribute 'PUT'
Internal Server Error: /sitio/detail/1
Traceback (most recent call last):
  File "/usr/local/lib/python2.7/dist-packages/django/core/handlers/base.py", line 132, in get_response
    response = wrapped_callback(request, *callback_args, **callback_kwargs)
  File "/usr/local/lib/python2.7/dist-packages/django/views/decorators/csrf.py", line 58, in wrapped_view
    return view_func(*args, **kwargs)
  File "/usr/local/lib/python2.7/dist-packages/django/views/generic/base.py", line 71, in view
    return self.dispatch(request, *args, **kwargs)
  File "/usr/local/lib/python2.7/dist-packages/rest_framework/views.py", line 407, in dispatch
    response = self.handle_exception(exc)
  File "/usr/local/lib/python2.7/dist-packages/rest_framework/views.py", line 404, in dispatch
    response = handler(request, *args, **kwargs)
  File "/usr/local/lib/python2.7/dist-packages/rest_framework/generics.py", line 357, in put
    return self.update(request, *args, **kwargs)
  File "/home/camilo/Documents/BackEnd/sitios/views.py", line 70, in update
    print request.PUT
  File "/usr/local/lib/python2.7/dist-packages/rest_framework/request.py", line 501, in __getattribute__
    six.reraise(info[0], info[1], info[2].tb_next)
  File "<string>", line 2, in reraise
AttributeError: 'Request' object has no attribute 'PUT'
Internal Server Error: /sitio/detail/1
Traceback (most recent call last):
  File "/usr/local/lib/python2.7/dist-packages/django/core/handlers/base.py", line 132, in get_response
    response = wrapped_callback(request, *callback_args, **callback_kwargs)
  File "/usr/local/lib/python2.7/dist-packages/django/views/decorators/csrf.py", line 58, in wrapped_view
    return view_func(*args, **kwargs)
  File "/usr/local/lib/python2.7/dist-packages/django/views/generic/base.py", line 71, in view
    return self.dispatch(request, *args, **kwargs)
  File "/usr/local/lib/python2.7/dist-packages/rest_framework/views.py", line 407, in dispatch
    response = self.handle_exception(exc)
  File "/usr/local/lib/python2.7/dist-packages/rest_framework/views.py", line 404, in dispatch
    response = handler(request, *args, **kwargs)
  File "/usr/local/lib/python2.7/dist-packages/rest_framework/generics.py", line 357, in put
    return self.update(request, *args, **kwargs)
  File "/home/camilo/Documents/BackEnd/sitios/views.py", line 70, in update
    print request.PUT
  File "/usr/local/lib/python2.7/dist-packages/rest_framework/request.py", line 501, in __getattribute__
    six.reraise(info[0], info[1], info[2].tb_next)
  File "<string>", line 2, in reraise
AttributeError: 'Request' object has no attribute 'PUT'
Internal Server Error: /sitio/detail/1
Traceback (most recent call last):
  File "/usr/local/lib/python2.7/dist-packages/django/core/handlers/base.py", line 132, in get_response
    response = wrapped_callback(request, *callback_args, **callback_kwargs)
  File "/usr/local/lib/python2.7/dist-packages/django/views/decorators/csrf.py", line 58, in wrapped_view
    return view_func(*args, **kwargs)
  File "/usr/local/lib/python2.7/dist-packages/django/views/generic/base.py", line 71, in view
    return self.dispatch(request, *args, **kwargs)
  File "/usr/local/lib/python2.7/dist-packages/rest_framework/views.py", line 407, in dispatch
    response = self.handle_exception(exc)
  File "/usr/local/lib/python2.7/dist-packages/rest_framework/views.py", line 404, in dispatch
    response = handler(request, *args, **kwargs)
  File "/usr/local/lib/python2.7/dist-packages/rest_framework/generics.py", line 357, in put
    return self.update(request, *args, **kwargs)
  File "/home/camilo/Documents/BackEnd/sitios/views.py", line 70, in update
    print request.PUT
  File "/usr/local/lib/python2.7/dist-packages/rest_framework/request.py", line 501, in __getattribute__
    six.reraise(info[0], info[1], info[2].tb_next)
  File "<string>", line 2, in reraise
AttributeError: 'Request' object has no attribute 'PUT'
Internal Server Error: /sitio/detail/1
Traceback (most recent call last):
  File "/usr/local/lib/python2.7/dist-packages/django/core/handlers/base.py", line 132, in get_response
    response = wrapped_callback(request, *callback_args, **callback_kwargs)
  File "/usr/local/lib/python2.7/dist-packages/django/views/decorators/csrf.py", line 58, in wrapped_view
    return view_func(*args, **kwargs)
  File "/usr/local/lib/python2.7/dist-packages/django/views/generic/base.py", line 71, in view
    return self.dispatch(request, *args, **kwargs)
  File "/usr/local/lib/python2.7/dist-packages/rest_framework/views.py", line 407, in dispatch
    response = self.handle_exception(exc)
  File "/usr/local/lib/python2.7/dist-packages/rest_framework/views.py", line 404, in dispatch
    response = handler(request, *args, **kwargs)
  File "/usr/local/lib/python2.7/dist-packages/rest_framework/generics.py", line 357, in put
    return self.update(request, *args, **kwargs)
  File "/home/camilo/Documents/BackEnd/sitios/views.py", line 70, in update
    print request.PUT
  File "/usr/local/lib/python2.7/dist-packages/rest_framework/request.py", line 501, in __getattribute__
    six.reraise(info[0], info[1], info[2].tb_next)
  File "<string>", line 2, in reraise
AttributeError: 'Request' object has no attribute 'PUT'
Internal Server Error: /sitio/detail/1
Traceback (most recent call last):
  File "/usr/local/lib/python2.7/dist-packages/django/core/handlers/base.py", line 132, in get_response
    response = wrapped_callback(request, *callback_args, **callback_kwargs)
  File "/usr/local/lib/python2.7/dist-packages/django/views/decorators/csrf.py", line 58, in wrapped_view
    return view_func(*args, **kwargs)
  File "/usr/local/lib/python2.7/dist-packages/django/views/generic/base.py", line 71, in view
    return self.dispatch(request, *args, **kwargs)
  File "/usr/local/lib/python2.7/dist-packages/rest_framework/views.py", line 407, in dispatch
    response = self.handle_exception(exc)
  File "/usr/local/lib/python2.7/dist-packages/rest_framework/views.py", line 404, in dispatch
    response = handler(request, *args, **kwargs)
  File "/usr/local/lib/python2.7/dist-packages/rest_framework/generics.py", line 357, in put
    return self.update(request, *args, **kwargs)
  File "/home/camilo/Documents/BackEnd/sitios/views.py", line 76, in update
    self.get_object().objects.fotos.delete()
  File "/usr/local/lib/python2.7/dist-packages/django/db/models/manager.py", line 252, in __get__
    raise AttributeError("Manager isn't accessible via %s instances" % type.__name__)
AttributeError: Manager isn't accessible via Sitio instances
Internal Server Error: /sitio/detail/1
Traceback (most recent call last):
  File "/usr/local/lib/python2.7/dist-packages/django/core/handlers/base.py", line 132, in get_response
    response = wrapped_callback(request, *callback_args, **callback_kwargs)
  File "/usr/local/lib/python2.7/dist-packages/django/views/decorators/csrf.py", line 58, in wrapped_view
    return view_func(*args, **kwargs)
  File "/usr/local/lib/python2.7/dist-packages/django/views/generic/base.py", line 71, in view
    return self.dispatch(request, *args, **kwargs)
  File "/usr/local/lib/python2.7/dist-packages/rest_framework/views.py", line 407, in dispatch
    response = self.handle_exception(exc)
  File "/usr/local/lib/python2.7/dist-packages/rest_framework/views.py", line 404, in dispatch
    response = handler(request, *args, **kwargs)
  File "/usr/local/lib/python2.7/dist-packages/rest_framework/generics.py", line 357, in put
    return self.update(request, *args, **kwargs)
  File "/home/camilo/Documents/BackEnd/sitios/views.py", line 76, in update
    self.get_object().objects.fotos.delete()
  File "/usr/local/lib/python2.7/dist-packages/django/db/models/manager.py", line 252, in __get__
    raise AttributeError("Manager isn't accessible via %s instances" % type.__name__)
AttributeError: Manager isn't accessible via Sitio instances
Internal Server Error: /sitio/detail/1
Traceback (most recent call last):
  File "/usr/local/lib/python2.7/dist-packages/django/core/handlers/base.py", line 132, in get_response
    response = wrapped_callback(request, *callback_args, **callback_kwargs)
  File "/usr/local/lib/python2.7/dist-packages/django/views/decorators/csrf.py", line 58, in wrapped_view
    return view_func(*args, **kwargs)
  File "/usr/local/lib/python2.7/dist-packages/django/views/generic/base.py", line 71, in view
    return self.dispatch(request, *args, **kwargs)
  File "/usr/local/lib/python2.7/dist-packages/rest_framework/views.py", line 407, in dispatch
    response = self.handle_exception(exc)
  File "/usr/local/lib/python2.7/dist-packages/rest_framework/views.py", line 404, in dispatch
    response = handler(request, *args, **kwargs)
  File "/usr/local/lib/python2.7/dist-packages/rest_framework/generics.py", line 357, in put
    return self.update(request, *args, **kwargs)
  File "/home/camilo/Documents/BackEnd/sitios/views.py", line 76, in update
    self.get_object().objects.fotos.delete()
  File "/usr/local/lib/python2.7/dist-packages/django/db/models/manager.py", line 252, in __get__
    raise AttributeError("Manager isn't accessible via %s instances" % type.__name__)
AttributeError: Manager isn't accessible via Sitio instances
