Internal Server Error: /api/login/social/token/facebook
Traceback (most recent call last):
  File "/usr/local/lib/python2.7/dist-packages/django/core/handlers/base.py", line 132, in get_response
    response = wrapped_callback(request, *callback_args, **callback_kwargs)
  File "/usr/local/lib/python2.7/dist-packages/django/views/decorators/csrf.py", line 58, in wrapped_view
    return view_func(*args, **kwargs)
  File "/usr/local/lib/python2.7/dist-packages/django/views/generic/base.py", line 71, in view
    return self.dispatch(request, *args, **kwargs)
  File "/usr/local/lib/python2.7/dist-packages/rest_framework/views.py", line 407, in dispatch
    response = self.handle_exception(exc)
  File "/usr/local/lib/python2.7/dist-packages/rest_framework/views.py", line 404, in dispatch
    response = handler(request, *args, **kwargs)
  File "/usr/local/lib/python2.7/dist-packages/django/utils/decorators.py", line 34, in _wrapper
    return bound_func(*args, **kwargs)
  File "/usr/local/lib/python2.7/dist-packages/django/views/decorators/cache.py", line 57, in _wrapped_view_func
    response = view_func(request, *args, **kwargs)
  File "/usr/local/lib/python2.7/dist-packages/django/utils/decorators.py", line 30, in bound_func
    return func.__get__(self, type(self))(*args2, **kwargs2)
  File "/usr/local/lib/python2.7/dist-packages/rest_social_auth/views.py", line 108, in post
    user = self.get_object()
  File "/usr/local/lib/python2.7/dist-packages/rest_social_auth/views.py", line 144, in get_object
    print("usuario datos", user.last_name)
AttributeError: 'CustomUser' object has no attribute 'last_name'
Internal Server Error: /api/login/social/token/facebook
Traceback (most recent call last):
  File "/usr/local/lib/python2.7/dist-packages/django/core/handlers/base.py", line 132, in get_response
    response = wrapped_callback(request, *callback_args, **callback_kwargs)
  File "/usr/local/lib/python2.7/dist-packages/django/views/decorators/csrf.py", line 58, in wrapped_view
    return view_func(*args, **kwargs)
  File "/usr/local/lib/python2.7/dist-packages/django/views/generic/base.py", line 71, in view
    return self.dispatch(request, *args, **kwargs)
  File "/usr/local/lib/python2.7/dist-packages/rest_framework/views.py", line 407, in dispatch
    response = self.handle_exception(exc)
  File "/usr/local/lib/python2.7/dist-packages/rest_framework/views.py", line 404, in dispatch
    response = handler(request, *args, **kwargs)
  File "/usr/local/lib/python2.7/dist-packages/django/utils/decorators.py", line 34, in _wrapper
    return bound_func(*args, **kwargs)
  File "/usr/local/lib/python2.7/dist-packages/django/views/decorators/cache.py", line 57, in _wrapped_view_func
    response = view_func(request, *args, **kwargs)
  File "/usr/local/lib/python2.7/dist-packages/django/utils/decorators.py", line 30, in bound_func
    return func.__get__(self, type(self))(*args2, **kwargs2)
  File "/usr/local/lib/python2.7/dist-packages/rest_social_auth/views.py", line 108, in post
    user = self.get_object()
  File "/usr/local/lib/python2.7/dist-packages/rest_social_auth/views.py", line 143, in get_object
    user = self.request.backend.complete(user=user)
  File "/usr/local/lib/python2.7/dist-packages/social/backends/base.py", line 41, in complete
    return self.auth_complete(*args, **kwargs)
  File "/usr/local/lib/python2.7/dist-packages/social/utils.py", line 229, in wrapper
    return func(*args, **kwargs)
  File "/usr/local/lib/python2.7/dist-packages/social/backends/facebook.py", line 87, in auth_complete
    return self.do_auth(access_token, response, *args, **kwargs)
  File "/usr/local/lib/python2.7/dist-packages/social/backends/facebook.py", line 119, in do_auth
    return self.strategy.authenticate(*args, **kwargs)
  File "/usr/local/lib/python2.7/dist-packages/social/strategies/django_strategy.py", line 96, in authenticate
    return authenticate(*args, **kwargs)
  File "/usr/local/lib/python2.7/dist-packages/django/contrib/auth/__init__.py", line 74, in authenticate
    user = backend.authenticate(**credentials)
  File "/usr/local/lib/python2.7/dist-packages/social/backends/base.py", line 82, in authenticate
    return self.pipeline(pipeline, *args, **kwargs)
  File "/usr/local/lib/python2.7/dist-packages/social/backends/base.py", line 85, in pipeline
    out = self.run_pipeline(pipeline, pipeline_index, *args, **kwargs)
  File "/usr/local/lib/python2.7/dist-packages/social/backends/base.py", line 111, in run_pipeline
    func = module_member(name)
  File "/usr/local/lib/python2.7/dist-packages/social/utils.py", line 56, in module_member
    module = import_module(mod)
  File "/usr/local/lib/python2.7/dist-packages/social/utils.py", line 50, in import_module
    __import__(name)
ImportError: No module named users.social_pipeline
Internal Server Error: /api/login/social/token/facebook
Traceback (most recent call last):
  File "/usr/local/lib/python2.7/dist-packages/django/core/handlers/base.py", line 132, in get_response
    response = wrapped_callback(request, *callback_args, **callback_kwargs)
  File "/usr/local/lib/python2.7/dist-packages/django/views/decorators/csrf.py", line 58, in wrapped_view
    return view_func(*args, **kwargs)
  File "/usr/local/lib/python2.7/dist-packages/django/views/generic/base.py", line 71, in view
    return self.dispatch(request, *args, **kwargs)
  File "/usr/local/lib/python2.7/dist-packages/rest_framework/views.py", line 407, in dispatch
    response = self.handle_exception(exc)
  File "/usr/local/lib/python2.7/dist-packages/rest_framework/views.py", line 404, in dispatch
    response = handler(request, *args, **kwargs)
  File "/usr/local/lib/python2.7/dist-packages/django/utils/decorators.py", line 34, in _wrapper
    return bound_func(*args, **kwargs)
  File "/usr/local/lib/python2.7/dist-packages/django/views/decorators/cache.py", line 57, in _wrapped_view_func
    response = view_func(request, *args, **kwargs)
  File "/usr/local/lib/python2.7/dist-packages/django/utils/decorators.py", line 30, in bound_func
    return func.__get__(self, type(self))(*args2, **kwargs2)
  File "/usr/local/lib/python2.7/dist-packages/rest_social_auth/views.py", line 108, in post
    user = self.get_object()
  File "/usr/local/lib/python2.7/dist-packages/rest_social_auth/views.py", line 143, in get_object
    user = self.request.backend.complete(user=user)
  File "/usr/local/lib/python2.7/dist-packages/social/backends/base.py", line 41, in complete
    return self.auth_complete(*args, **kwargs)
  File "/usr/local/lib/python2.7/dist-packages/social/utils.py", line 229, in wrapper
    return func(*args, **kwargs)
  File "/usr/local/lib/python2.7/dist-packages/social/backends/facebook.py", line 87, in auth_complete
    return self.do_auth(access_token, response, *args, **kwargs)
  File "/usr/local/lib/python2.7/dist-packages/social/backends/facebook.py", line 119, in do_auth
    return self.strategy.authenticate(*args, **kwargs)
  File "/usr/local/lib/python2.7/dist-packages/social/strategies/django_strategy.py", line 96, in authenticate
    return authenticate(*args, **kwargs)
  File "/usr/local/lib/python2.7/dist-packages/django/contrib/auth/__init__.py", line 74, in authenticate
    user = backend.authenticate(**credentials)
  File "/usr/local/lib/python2.7/dist-packages/social/backends/base.py", line 82, in authenticate
    return self.pipeline(pipeline, *args, **kwargs)
  File "/usr/local/lib/python2.7/dist-packages/social/backends/base.py", line 85, in pipeline
    out = self.run_pipeline(pipeline, pipeline_index, *args, **kwargs)
  File "/usr/local/lib/python2.7/dist-packages/social/backends/base.py", line 112, in run_pipeline
    result = func(*args, **out) or {}
  File "/home/vagrant/django_shared/ecosistema/BackEnd/users/social_pipeline.py", line 25, in save_avatar
    if social_thumb and user.social_thumb != social_thumb:
AttributeError: 'CustomUser' object has no attribute 'social_thumb'
Internal Server Error: /api/login/social/token/facebook
Traceback (most recent call last):
  File "/usr/local/lib/python2.7/dist-packages/django/core/handlers/base.py", line 132, in get_response
    response = wrapped_callback(request, *callback_args, **callback_kwargs)
  File "/usr/local/lib/python2.7/dist-packages/django/views/decorators/csrf.py", line 58, in wrapped_view
    return view_func(*args, **kwargs)
  File "/usr/local/lib/python2.7/dist-packages/django/views/generic/base.py", line 71, in view
    return self.dispatch(request, *args, **kwargs)
  File "/usr/local/lib/python2.7/dist-packages/rest_framework/views.py", line 407, in dispatch
    response = self.handle_exception(exc)
  File "/usr/local/lib/python2.7/dist-packages/rest_framework/views.py", line 404, in dispatch
    response = handler(request, *args, **kwargs)
  File "/usr/local/lib/python2.7/dist-packages/django/utils/decorators.py", line 34, in _wrapper
    return bound_func(*args, **kwargs)
  File "/usr/local/lib/python2.7/dist-packages/django/views/decorators/cache.py", line 57, in _wrapped_view_func
    response = view_func(request, *args, **kwargs)
  File "/usr/local/lib/python2.7/dist-packages/django/utils/decorators.py", line 30, in bound_func
    return func.__get__(self, type(self))(*args2, **kwargs2)
  File "/usr/local/lib/python2.7/dist-packages/rest_social_auth/views.py", line 108, in post
    user = self.get_object()
  File "/usr/local/lib/python2.7/dist-packages/rest_social_auth/views.py", line 144, in get_object
    print("usuario datos", user.last_name)
AttributeError: 'CustomUser' object has no attribute 'last_name'
Internal Server Error: /api/login/social/token/facebook
Traceback (most recent call last):
  File "/usr/local/lib/python2.7/dist-packages/django/core/handlers/base.py", line 132, in get_response
    response = wrapped_callback(request, *callback_args, **callback_kwargs)
  File "/usr/local/lib/python2.7/dist-packages/django/views/decorators/csrf.py", line 58, in wrapped_view
    return view_func(*args, **kwargs)
  File "/usr/local/lib/python2.7/dist-packages/django/views/generic/base.py", line 71, in view
    return self.dispatch(request, *args, **kwargs)
  File "/usr/local/lib/python2.7/dist-packages/rest_framework/views.py", line 407, in dispatch
    response = self.handle_exception(exc)
  File "/usr/local/lib/python2.7/dist-packages/rest_framework/views.py", line 404, in dispatch
    response = handler(request, *args, **kwargs)
  File "/usr/local/lib/python2.7/dist-packages/django/utils/decorators.py", line 34, in _wrapper
    return bound_func(*args, **kwargs)
  File "/usr/local/lib/python2.7/dist-packages/django/views/decorators/cache.py", line 57, in _wrapped_view_func
    response = view_func(request, *args, **kwargs)
  File "/usr/local/lib/python2.7/dist-packages/django/utils/decorators.py", line 30, in bound_func
    return func.__get__(self, type(self))(*args2, **kwargs2)
  File "/usr/local/lib/python2.7/dist-packages/rest_social_auth/views.py", line 108, in post
    user = self.get_object()
  File "/usr/local/lib/python2.7/dist-packages/rest_social_auth/views.py", line 143, in get_object
    user = self.request.backend.complete(user=user)
  File "/usr/local/lib/python2.7/dist-packages/social/backends/base.py", line 41, in complete
    return self.auth_complete(*args, **kwargs)
  File "/usr/local/lib/python2.7/dist-packages/social/utils.py", line 229, in wrapper
    return func(*args, **kwargs)
  File "/usr/local/lib/python2.7/dist-packages/social/backends/facebook.py", line 87, in auth_complete
    return self.do_auth(access_token, response, *args, **kwargs)
  File "/usr/local/lib/python2.7/dist-packages/social/backends/facebook.py", line 119, in do_auth
    return self.strategy.authenticate(*args, **kwargs)
  File "/usr/local/lib/python2.7/dist-packages/social/strategies/django_strategy.py", line 96, in authenticate
    return authenticate(*args, **kwargs)
  File "/usr/local/lib/python2.7/dist-packages/django/contrib/auth/__init__.py", line 74, in authenticate
    user = backend.authenticate(**credentials)
  File "/usr/local/lib/python2.7/dist-packages/social/backends/base.py", line 82, in authenticate
    return self.pipeline(pipeline, *args, **kwargs)
  File "/usr/local/lib/python2.7/dist-packages/social/backends/base.py", line 85, in pipeline
    out = self.run_pipeline(pipeline, pipeline_index, *args, **kwargs)
  File "/usr/local/lib/python2.7/dist-packages/social/backends/base.py", line 112, in run_pipeline
    result = func(*args, **out) or {}
  File "/usr/local/lib/python2.7/dist-packages/social/pipeline/user.py", line 70, in create_user
    'user': strategy.create_user(**fields)
  File "/usr/local/lib/python2.7/dist-packages/social/strategies/base.py", line 53, in create_user
    return self.storage.user.create_user(*args, **kwargs)
  File "/usr/local/lib/python2.7/dist-packages/social/storage/django_orm.py", line 60, in create_user
    return cls.user_model().objects.create_user(*args, **kwargs)
TypeError: create_user() takes at least 2 arguments (2 given)
Internal Server Error: /api/login/social/token/facebook
Traceback (most recent call last):
  File "/usr/local/lib/python2.7/dist-packages/django/core/handlers/base.py", line 132, in get_response
    response = wrapped_callback(request, *callback_args, **callback_kwargs)
  File "/usr/local/lib/python2.7/dist-packages/django/views/decorators/csrf.py", line 58, in wrapped_view
    return view_func(*args, **kwargs)
  File "/usr/local/lib/python2.7/dist-packages/django/views/generic/base.py", line 71, in view
    return self.dispatch(request, *args, **kwargs)
  File "/usr/local/lib/python2.7/dist-packages/rest_framework/views.py", line 407, in dispatch
    response = self.handle_exception(exc)
  File "/usr/local/lib/python2.7/dist-packages/rest_framework/views.py", line 404, in dispatch
    response = handler(request, *args, **kwargs)
  File "/usr/local/lib/python2.7/dist-packages/django/utils/decorators.py", line 34, in _wrapper
    return bound_func(*args, **kwargs)
  File "/usr/local/lib/python2.7/dist-packages/django/views/decorators/cache.py", line 57, in _wrapped_view_func
    response = view_func(request, *args, **kwargs)
  File "/usr/local/lib/python2.7/dist-packages/django/utils/decorators.py", line 30, in bound_func
    return func.__get__(self, type(self))(*args2, **kwargs2)
  File "/usr/local/lib/python2.7/dist-packages/rest_social_auth/views.py", line 113, in post
    self.do_login(request.backend, user)
  File "/home/vagrant/django_shared/ecosistema/BackEnd/authentication_module/views.py", line 14, in do_login
    usuario = UsuarioSerializer(data=user)
NameError: global name 'UsuarioSerializer' is not defined
Internal Server Error: /api/login/social/token/facebook
Traceback (most recent call last):
  File "/usr/local/lib/python2.7/dist-packages/django/core/handlers/base.py", line 132, in get_response
    response = wrapped_callback(request, *callback_args, **callback_kwargs)
  File "/usr/local/lib/python2.7/dist-packages/django/views/decorators/csrf.py", line 58, in wrapped_view
    return view_func(*args, **kwargs)
  File "/usr/local/lib/python2.7/dist-packages/django/views/generic/base.py", line 71, in view
    return self.dispatch(request, *args, **kwargs)
  File "/usr/local/lib/python2.7/dist-packages/rest_framework/views.py", line 407, in dispatch
    response = self.handle_exception(exc)
  File "/usr/local/lib/python2.7/dist-packages/rest_framework/views.py", line 404, in dispatch
    response = handler(request, *args, **kwargs)
  File "/usr/local/lib/python2.7/dist-packages/django/utils/decorators.py", line 34, in _wrapper
    return bound_func(*args, **kwargs)
  File "/usr/local/lib/python2.7/dist-packages/django/views/decorators/cache.py", line 57, in _wrapped_view_func
    response = view_func(request, *args, **kwargs)
  File "/usr/local/lib/python2.7/dist-packages/django/utils/decorators.py", line 30, in bound_func
    return func.__get__(self, type(self))(*args2, **kwargs2)
  File "/usr/local/lib/python2.7/dist-packages/rest_social_auth/views.py", line 113, in post
    self.do_login(request.backend, user)
  File "/home/vagrant/django_shared/ecosistema/BackEnd/authentication_module/views.py", line 16, in do_login
    usuario.save()
  File "/usr/local/lib/python2.7/dist-packages/rest_framework/serializers.py", line 146, in save
    'You must call `.is_valid()` before calling `.save()`.'
AssertionError: You must call `.is_valid()` before calling `.save()`.
Internal Server Error: /api/login/social/token/facebook
Traceback (most recent call last):
  File "/usr/local/lib/python2.7/dist-packages/django/core/handlers/base.py", line 132, in get_response
    response = wrapped_callback(request, *callback_args, **callback_kwargs)
  File "/usr/local/lib/python2.7/dist-packages/django/views/decorators/csrf.py", line 58, in wrapped_view
    return view_func(*args, **kwargs)
  File "/usr/local/lib/python2.7/dist-packages/django/views/generic/base.py", line 71, in view
    return self.dispatch(request, *args, **kwargs)
  File "/usr/local/lib/python2.7/dist-packages/rest_framework/views.py", line 407, in dispatch
    response = self.handle_exception(exc)
  File "/usr/local/lib/python2.7/dist-packages/rest_framework/views.py", line 404, in dispatch
    response = handler(request, *args, **kwargs)
  File "/usr/local/lib/python2.7/dist-packages/django/utils/decorators.py", line 34, in _wrapper
    return bound_func(*args, **kwargs)
  File "/usr/local/lib/python2.7/dist-packages/django/views/decorators/cache.py", line 57, in _wrapped_view_func
    response = view_func(request, *args, **kwargs)
  File "/usr/local/lib/python2.7/dist-packages/django/utils/decorators.py", line 30, in bound_func
    return func.__get__(self, type(self))(*args2, **kwargs2)
  File "/usr/local/lib/python2.7/dist-packages/rest_social_auth/views.py", line 113, in post
    self.do_login(request.backend, user)
  File "/home/vagrant/django_shared/ecosistema/BackEnd/authentication_module/views.py", line 16, in do_login
    if user.is_valid():
AttributeError: 'CustomUser' object has no attribute 'is_valid'
Internal Server Error: /api/login/social/token/facebook
Traceback (most recent call last):
  File "/usr/local/lib/python2.7/dist-packages/django/core/handlers/base.py", line 132, in get_response
    response = wrapped_callback(request, *callback_args, **callback_kwargs)
  File "/usr/local/lib/python2.7/dist-packages/django/views/decorators/csrf.py", line 58, in wrapped_view
    return view_func(*args, **kwargs)
  File "/usr/local/lib/python2.7/dist-packages/django/views/generic/base.py", line 71, in view
    return self.dispatch(request, *args, **kwargs)
  File "/usr/local/lib/python2.7/dist-packages/rest_framework/views.py", line 407, in dispatch
    response = self.handle_exception(exc)
  File "/usr/local/lib/python2.7/dist-packages/rest_framework/views.py", line 404, in dispatch
    response = handler(request, *args, **kwargs)
  File "/usr/local/lib/python2.7/dist-packages/django/utils/decorators.py", line 34, in _wrapper
    return bound_func(*args, **kwargs)
  File "/usr/local/lib/python2.7/dist-packages/django/views/decorators/cache.py", line 57, in _wrapped_view_func
    response = view_func(request, *args, **kwargs)
  File "/usr/local/lib/python2.7/dist-packages/django/utils/decorators.py", line 30, in bound_func
    return func.__get__(self, type(self))(*args2, **kwargs2)
  File "/usr/local/lib/python2.7/dist-packages/rest_social_auth/views.py", line 113, in post
    self.do_login(request.backend, user)
  File "/home/vagrant/django_shared/ecosistema/BackEnd/authentication_module/views.py", line 16, in do_login
    if usuario.is_valid():
  File "/usr/local/lib/python2.7/dist-packages/rest_framework/serializers.py", line 186, in is_valid
    self._validated_data = self.run_validation(self.initial_data)
  File "/usr/local/lib/python2.7/dist-packages/rest_framework/serializers.py", line 364, in run_validation
    value = self.to_internal_value(data)
  File "/home/vagrant/django_shared/ecosistema/BackEnd/plataforma/serializers.py", line 53, in to_internal_value
    if data.get("tags") is not None:   # si existen tags
AttributeError: 'CustomUser' object has no attribute 'get'
Internal Server Error: /api/login/social/token/facebook
Traceback (most recent call last):
  File "/usr/local/lib/python2.7/dist-packages/django/core/handlers/base.py", line 132, in get_response
    response = wrapped_callback(request, *callback_args, **callback_kwargs)
  File "/usr/local/lib/python2.7/dist-packages/django/views/decorators/csrf.py", line 58, in wrapped_view
    return view_func(*args, **kwargs)
  File "/usr/local/lib/python2.7/dist-packages/django/views/generic/base.py", line 71, in view
    return self.dispatch(request, *args, **kwargs)
  File "/usr/local/lib/python2.7/dist-packages/rest_framework/views.py", line 407, in dispatch
    response = self.handle_exception(exc)
  File "/usr/local/lib/python2.7/dist-packages/rest_framework/views.py", line 404, in dispatch
    response = handler(request, *args, **kwargs)
  File "/usr/local/lib/python2.7/dist-packages/django/utils/decorators.py", line 34, in _wrapper
    return bound_func(*args, **kwargs)
  File "/usr/local/lib/python2.7/dist-packages/django/views/decorators/cache.py", line 57, in _wrapped_view_func
    response = view_func(request, *args, **kwargs)
  File "/usr/local/lib/python2.7/dist-packages/django/utils/decorators.py", line 30, in bound_func
    return func.__get__(self, type(self))(*args2, **kwargs2)
  File "/usr/local/lib/python2.7/dist-packages/rest_social_auth/views.py", line 113, in post
    self.do_login(request.backend, user)
  File "/home/vagrant/django_shared/ecosistema/BackEnd/authentication_module/views.py", line 21, in do_login
    if usuario.is_valid():
  File "/usr/local/lib/python2.7/dist-packages/rest_framework/serializers.py", line 180, in is_valid
    'Cannot call `.is_valid()` as no `data=` keyword argument was '
AssertionError: Cannot call `.is_valid()` as no `data=` keyword argument was passed when instantiating the serializer instance.
Internal Server Error: /api/login/social/token/facebook
Traceback (most recent call last):
  File "/usr/local/lib/python2.7/dist-packages/django/core/handlers/base.py", line 132, in get_response
    response = wrapped_callback(request, *callback_args, **callback_kwargs)
  File "/usr/local/lib/python2.7/dist-packages/django/views/decorators/csrf.py", line 58, in wrapped_view
    return view_func(*args, **kwargs)
  File "/usr/local/lib/python2.7/dist-packages/django/views/generic/base.py", line 71, in view
    return self.dispatch(request, *args, **kwargs)
  File "/usr/local/lib/python2.7/dist-packages/rest_framework/views.py", line 407, in dispatch
    response = self.handle_exception(exc)
  File "/usr/local/lib/python2.7/dist-packages/rest_framework/views.py", line 404, in dispatch
    response = handler(request, *args, **kwargs)
  File "/usr/local/lib/python2.7/dist-packages/django/utils/decorators.py", line 34, in _wrapper
    return bound_func(*args, **kwargs)
  File "/usr/local/lib/python2.7/dist-packages/django/views/decorators/cache.py", line 57, in _wrapped_view_func
    response = view_func(request, *args, **kwargs)
  File "/usr/local/lib/python2.7/dist-packages/django/utils/decorators.py", line 30, in bound_func
    return func.__get__(self, type(self))(*args2, **kwargs2)
  File "/usr/local/lib/python2.7/dist-packages/rest_social_auth/views.py", line 113, in post
    self.do_login(request.backend, user)
  File "/home/vagrant/django_shared/ecosistema/BackEnd/authentication_module/views.py", line 20, in do_login
    if usuario.is_valid():
  File "/usr/local/lib/python2.7/dist-packages/rest_framework/serializers.py", line 180, in is_valid
    'Cannot call `.is_valid()` as no `data=` keyword argument was '
AssertionError: Cannot call `.is_valid()` as no `data=` keyword argument was passed when instantiating the serializer instance.
Internal Server Error: /api/login/social/token/facebook
Traceback (most recent call last):
  File "/usr/local/lib/python2.7/dist-packages/django/core/handlers/base.py", line 132, in get_response
    response = wrapped_callback(request, *callback_args, **callback_kwargs)
  File "/usr/local/lib/python2.7/dist-packages/django/views/decorators/csrf.py", line 58, in wrapped_view
    return view_func(*args, **kwargs)
  File "/usr/local/lib/python2.7/dist-packages/django/views/generic/base.py", line 71, in view
    return self.dispatch(request, *args, **kwargs)
  File "/usr/local/lib/python2.7/dist-packages/rest_framework/views.py", line 407, in dispatch
    response = self.handle_exception(exc)
  File "/usr/local/lib/python2.7/dist-packages/rest_framework/views.py", line 404, in dispatch
    response = handler(request, *args, **kwargs)
  File "/usr/local/lib/python2.7/dist-packages/django/utils/decorators.py", line 34, in _wrapper
    return bound_func(*args, **kwargs)
  File "/usr/local/lib/python2.7/dist-packages/django/views/decorators/cache.py", line 57, in _wrapped_view_func
    response = view_func(request, *args, **kwargs)
  File "/usr/local/lib/python2.7/dist-packages/django/utils/decorators.py", line 30, in bound_func
    return func.__get__(self, type(self))(*args2, **kwargs2)
  File "/usr/local/lib/python2.7/dist-packages/rest_social_auth/views.py", line 113, in post
    self.do_login(request.backend, user)
  File "/home/vagrant/django_shared/ecosistema/BackEnd/authentication_module/views.py", line 16, in do_login
    nombre:user.first_name,
NameError: global name 'nombre' is not defined
Internal Server Error: /api/login/social/token/facebook
Traceback (most recent call last):
  File "/usr/local/lib/python2.7/dist-packages/django/core/handlers/base.py", line 132, in get_response
    response = wrapped_callback(request, *callback_args, **callback_kwargs)
  File "/usr/local/lib/python2.7/dist-packages/django/views/decorators/csrf.py", line 58, in wrapped_view
    return view_func(*args, **kwargs)
  File "/usr/local/lib/python2.7/dist-packages/django/views/generic/base.py", line 71, in view
    return self.dispatch(request, *args, **kwargs)
  File "/usr/local/lib/python2.7/dist-packages/rest_framework/views.py", line 407, in dispatch
    response = self.handle_exception(exc)
  File "/usr/local/lib/python2.7/dist-packages/rest_framework/views.py", line 404, in dispatch
    response = handler(request, *args, **kwargs)
  File "/usr/local/lib/python2.7/dist-packages/django/utils/decorators.py", line 34, in _wrapper
    return bound_func(*args, **kwargs)
  File "/usr/local/lib/python2.7/dist-packages/django/views/decorators/cache.py", line 57, in _wrapped_view_func
    response = view_func(request, *args, **kwargs)
  File "/usr/local/lib/python2.7/dist-packages/django/utils/decorators.py", line 30, in bound_func
    return func.__get__(self, type(self))(*args2, **kwargs2)
  File "/usr/local/lib/python2.7/dist-packages/rest_social_auth/views.py", line 113, in post
    self.do_login(request.backend, user)
  File "/home/vagrant/django_shared/ecosistema/BackEnd/authentication_module/views.py", line 17, in do_login
    "apellido1":ser.last_name,
NameError: global name 'ser' is not defined
Internal Server Error: /api/login/social/token/facebook
Traceback (most recent call last):
  File "/usr/local/lib/python2.7/dist-packages/django/core/handlers/base.py", line 108, in get_response
    response = middleware_method(request)
  File "/usr/local/lib/python2.7/dist-packages/django/middleware/common.py", line 74, in process_request
    if (not urlresolvers.is_valid_path(request.path_info, urlconf) and
  File "/usr/local/lib/python2.7/dist-packages/django/core/urlresolvers.py", line 647, in is_valid_path
    resolve(path, urlconf)
  File "/usr/local/lib/python2.7/dist-packages/django/core/urlresolvers.py", line 522, in resolve
    return get_resolver(urlconf).resolve(path)
  File "/usr/local/lib/python2.7/dist-packages/django/core/urlresolvers.py", line 366, in resolve
    for pattern in self.url_patterns:
  File "/usr/local/lib/python2.7/dist-packages/django/core/urlresolvers.py", line 402, in url_patterns
    patterns = getattr(self.urlconf_module, "urlpatterns", self.urlconf_module)
  File "/usr/local/lib/python2.7/dist-packages/django/core/urlresolvers.py", line 396, in urlconf_module
    self._urlconf_module = import_module(self.urlconf_name)
  File "/usr/lib/python2.7/importlib/__init__.py", line 37, in import_module
    __import__(name)
  File "/home/vagrant/django_shared/ecosistema/BackEnd/turismo/urls.py", line 6, in <module>
    from authentication_module import views as authentication_module_views
  File "/home/vagrant/django_shared/ecosistema/BackEnd/authentication_module/views.py", line 28
    else
       ^
SyntaxError: invalid syntax
Internal Server Error: /roles/cuestionarios
Traceback (most recent call last):
  File "/usr/local/lib/python2.7/dist-packages/django/core/handlers/base.py", line 132, in get_response
    response = wrapped_callback(request, *callback_args, **callback_kwargs)
  File "/usr/local/lib/python2.7/dist-packages/django/views/decorators/csrf.py", line 58, in wrapped_view
    return view_func(*args, **kwargs)
  File "/usr/local/lib/python2.7/dist-packages/rest_framework/viewsets.py", line 85, in view
    return self.dispatch(request, *args, **kwargs)
  File "/usr/local/lib/python2.7/dist-packages/rest_framework/views.py", line 407, in dispatch
    response = self.handle_exception(exc)
  File "/usr/local/lib/python2.7/dist-packages/rest_framework/views.py", line 404, in dispatch
    response = handler(request, *args, **kwargs)
  File "/home/vagrant/django_shared/ecosistema/BackEnd/plataforma/views.py", line 111, in create
    id_usuario = request.data['id_usuario']
KeyError: 'id_usuario'
Internal Server Error: /roles/cuestionarios
Traceback (most recent call last):
  File "/usr/local/lib/python2.7/dist-packages/django/core/handlers/base.py", line 132, in get_response
    response = wrapped_callback(request, *callback_args, **callback_kwargs)
  File "/usr/local/lib/python2.7/dist-packages/django/views/decorators/csrf.py", line 58, in wrapped_view
    return view_func(*args, **kwargs)
  File "/usr/local/lib/python2.7/dist-packages/rest_framework/viewsets.py", line 85, in view
    return self.dispatch(request, *args, **kwargs)
  File "/usr/local/lib/python2.7/dist-packages/rest_framework/views.py", line 407, in dispatch
    response = self.handle_exception(exc)
  File "/usr/local/lib/python2.7/dist-packages/rest_framework/views.py", line 404, in dispatch
    response = handler(request, *args, **kwargs)
  File "/home/vagrant/django_shared/ecosistema/BackEnd/plataforma/views.py", line 111, in create
    id_usuario = request.data['id_usuario']
KeyError: 'id_usuario'
